schematic = {
	size = {x=3, y=6, z=3},
	yslice_prob = {
		{ypos=0, prob=254},
		{ypos=1, prob=254},
		{ypos=2, prob=254},
		{ypos=3, prob=254},
		{ypos=4, prob=254},
		{ypos=5, prob=254},
	},
	data = {

		-- z=0, y=0
		{name="default:wood", prob=254, param2=0},
		{name="default:wood", prob=254, param2=0},
		{name="default:wood", prob=254, param2=0},

		-- z=0, y=1
		{name="default:wood", prob=254, param2=0},
		{name="doors:door_wood_b_1", prob=254, param2=0},
		{name="default:wood", prob=254, param2=0},

		-- z=0, y=2
		{name="default:wood", prob=254, param2=0},
		{name="doors:door_wood_t_1", prob=254, param2=0},
		{name="default:wood", prob=254, param2=0},

		-- z=0, y=3
		{name="default:stone", prob=254, param2=0},
		{name="default:stone", prob=254, param2=0},
		{name="default:stone", prob=254, param2=0},

		-- z=0, y=4
		{name="air", prob=254, param2=0},
		{name="air", prob=254, param2=0},
		{name="air", prob=254, param2=0},

		-- z=0, y=5
		{name="air", prob=254, param2=0},
		{name="air", prob=254, param2=0},
		{name="air", prob=254, param2=0},

		-- z=1, y=0
		{name="default:wood", prob=254, param2=0},
		{name="default:wood", prob=254, param2=0},
		{name="default:wood", prob=254, param2=0},

		-- z=1, y=1
		{name="default:wood", prob=254, param2=0},
		{name="air", prob=254, param2=0},
		{name="default:wood", prob=254, param2=0},

		-- z=1, y=2
		{name="default:glass", prob=254, param2=0},
		{name="air", prob=254, param2=0},
		{name="default:glass", prob=254, param2=0},

		-- z=1, y=3
		{name="default:stone", prob=254, param2=0},
		{name="default:stone", prob=254, param2=0},
		{name="default:stone", prob=254, param2=0},

		-- z=1, y=4
		{name="air", prob=254, param2=0},
		{name="default:stone", prob=254, param2=0},
		{name="air", prob=254, param2=0},

		-- z=1, y=5
		{name="air", prob=254, param2=0},
		{name="air", prob=254, param2=0},
		{name="air", prob=254, param2=0},

		-- z=2, y=0
		{name="default:wood", prob=254, param2=0},
		{name="default:wood", prob=254, param2=0},
		{name="default:wood", prob=254, param2=0},

		-- z=2, y=1
		{name="default:wood", prob=254, param2=0},
		{name="default:wood", prob=254, param2=0},
		{name="default:wood", prob=254, param2=0},

		-- z=2, y=2
		{name="default:wood", prob=254, param2=0},
		{name="default:wood", prob=254, param2=0},
		{name="default:wood", prob=254, param2=0},

		-- z=2, y=3
		{name="default:stone", prob=254, param2=0},
		{name="default:stone", prob=254, param2=0},
		{name="default:stone", prob=254, param2=0},

		-- z=2, y=4
		{name="air", prob=254, param2=0},
		{name="air", prob=254, param2=0},
		{name="air", prob=254, param2=0},

		-- z=2, y=5
		{name="air", prob=254, param2=0},
		{name="air", prob=254, param2=0},
		{name="air", prob=254, param2=0},
	},
}

return schematic