schematic = {
	size = {x=17, y=16, z=16},
	yslice_prob = {
		{ypos=0, prob=254},
		{ypos=1, prob=254},
		{ypos=2, prob=254},
		{ypos=3, prob=254},
		{ypos=4, prob=254},
		{ypos=5, prob=254},
		{ypos=6, prob=254},
		{ypos=7, prob=254},
		{ypos=8, prob=254},
		{ypos=9, prob=254},
		{ypos=10, prob=254},
		{ypos=11, prob=254},
		{ypos=12, prob=254},
		{ypos=13, prob=254},
		{ypos=14, prob=254},
		{ypos=15, prob=254},
	},
	data = {

		-- z=0, y=0
		{name="default:dirt_with_grass", prob=254, param2=0},
		{name="default:dirt_with_grass", prob=254, param2=0},
		{name="default:dirt_with_grass", prob=254, param2=0},
		{name="default:dirt_with_grass", prob=254, param2=0},
		{name="default:dirt_with_grass", prob=254, param2=0},
		{name="default:dirt_with_grass", prob=254, param2=0},
		{name="default:dirt_with_grass", prob=254, param2=0},
		{name="default:dirt_with_grass", prob=254, param2=0},
		{name="default:dirt_with_grass", prob=254, param2=0},
		{name="default:dirt_with_grass", prob=254, param2=0},
		{name="default:dirt_with_grass", prob=254, param2=0},
		{name="default:dirt_with_grass", prob=254, param2=0},
		{name="default:dirt_with_grass", prob=254, param2=0},
		{name="default:dirt_with_grass", prob=254, param2=0},
		{name="default:dirt_with_grass", prob=254, param2=0},
		{name="default:dirt_with_grass", prob=254, param2=0},
		{name="default:dirt_with_grass", prob=254, param2=0},

		-- z=0, y=1
		{name="air", prob=254, param2=0},
		{name="air", prob=254, param2=0},
		{name="air", prob=254, param2=0},
		{name="air", prob=254, param2=0},
		{name="air", prob=254, param2=0},
		{name="air", prob=254, param2=0},
		{name="air", prob=254, param2=0},
		{name="air", prob=254, param2=0},
		{name="air", prob=254, param2=0},
		{name="air", prob=254, param2=0},
		{name="air", prob=254, param2=0},
		{name="air", prob=254, param2=0},
		{name="air", prob=254, param2=0},
		{name="air", prob=254, param2=0},
		{name="air", prob=254, param2=0},
		{name="air", prob=254, param2=0},
		{name="air", prob=254, param2=0},

		-- z=0, y=2
		{name="air", prob=254, param2=0},
		{name="air", prob=254, param2=0},
		{name="air", prob=254, param2=0},
		{name="air", prob=254, param2=0},
		{name="air", prob=254, param2=0},
		{name="air", prob=254, param2=0},
		{name="air", prob=254, param2=0},
		{name="air", prob=254, param2=0},
		{name="air", prob=254, param2=0},
		{name="air", prob=254, param2=0},
		{name="air", prob=254, param2=0},
		{name="air", prob=254, param2=0},
		{name="air", prob=254, param2=0},
		{name="air", prob=254, param2=0},
		{name="air", prob=254, param2=0},
		{name="air", prob=254, param2=0},
		{name="air", prob=254, param2=0},

		-- z=0, y=3
		{name="air", prob=254, param2=0},
		{name="air", prob=254, param2=0},
		{name="air", prob=254, param2=0},
		{name="air", prob=254, param2=0},
		{name="air", prob=254, param2=0},
		{name="air", prob=254, param2=0},
		{name="air", prob=254, param2=0},
		{name="air", prob=254, param2=0},
		{name="air", prob=254, param2=0},
		{name="air", prob=254, param2=0},
		{name="air", prob=254, param2=0},
		{name="air", prob=254, param2=0},
		{name="air", prob=254, param2=0},
		{name="air", prob=254, param2=0},
		{name="air", prob=254, param2=0},
		{name="air", prob=254, param2=0},
		{name="air", prob=254, param2=0},

		-- z=0, y=4
		{name="air", prob=254, param2=0},
		{name="air", prob=254, param2=0},
		{name="air", prob=254, param2=0},
		{name="air", prob=254, param2=0},
		{name="air", prob=254, param2=0},
		{name="air", prob=254, param2=0},
		{name="air", prob=254, param2=0},
		{name="air", prob=254, param2=0},
		{name="air", prob=254, param2=0},
		{name="air", prob=254, param2=0},
		{name="air", prob=254, param2=0},
		{name="air", prob=254, param2=0},
		{name="air", prob=254, param2=0},
		{name="air", prob=254, param2=0},
		{name="air", prob=254, param2=0},
		{name="air", prob=254, param2=0},
		{name="air", prob=254, param2=0},

		-- z=0, y=5
		{name="air", prob=254, param2=0},
		{name="air", prob=254, param2=0},
		{name="air", prob=254, param2=0},
		{name="air", prob=254, param2=0},
		{name="air", prob=254, param2=0},
		{name="air", prob=254, param2=0},
		{name="air", prob=254, param2=0},
		{name="air", prob=254, param2=0},
		{name="air", prob=254, param2=0},
		{name="air", prob=254, param2=0},
		{name="air", prob=254, param2=0},
		{name="air", prob=254, param2=0},
		{name="air", prob=254, param2=0},
		{name="air", prob=254, param2=0},
		{name="air", prob=254, param2=0},
		{name="air", prob=254, param2=0},
		{name="air", prob=254, param2=0},

		-- z=0, y=6
		{name="air", prob=254, param2=0},
		{name="air", prob=254, param2=0},
		{name="air", prob=254, param2=0},
		{name="air", prob=254, param2=0},
		{name="air", prob=254, param2=0},
		{name="air", prob=254, param2=0},
		{name="air", prob=254, param2=0},
		{name="air", prob=254, param2=0},
		{name="air", prob=254, param2=0},
		{name="air", prob=254, param2=0},
		{name="air", prob=254, param2=0},
		{name="air", prob=254, param2=0},
		{name="air", prob=254, param2=0},
		{name="air", prob=254, param2=0},
		{name="air", prob=254, param2=0},
		{name="air", prob=254, param2=0},
		{name="air", prob=254, param2=0},

		-- z=0, y=7
		{name="air", prob=254, param2=0},
		{name="air", prob=254, param2=0},
		{name="air", prob=254, param2=0},
		{name="air", prob=254, param2=0},
		{name="air", prob=254, param2=0},
		{name="air", prob=254, param2=0},
		{name="air", prob=254, param2=0},
		{name="air", prob=254, param2=0},
		{name="air", prob=254, param2=0},
		{name="air", prob=254, param2=0},
		{name="air", prob=254, param2=0},
		{name="air", prob=254, param2=0},
		{name="air", prob=254, param2=0},
		{name="air", prob=254, param2=0},
		{name="air", prob=254, param2=0},
		{name="air", prob=254, param2=0},
		{name="air", prob=254, param2=0},

		-- z=0, y=8
		{name="air", prob=254, param2=0},
		{name="air", prob=254, param2=0},
		{name="air", prob=254, param2=0},
		{name="air", prob=254, param2=0},
		{name="air", prob=254, param2=0},
		{name="air", prob=254, param2=0},
		{name="air", prob=254, param2=0},
		{name="air", prob=254, param2=0},
		{name="air", prob=254, param2=0},
		{name="air", prob=254, param2=0},
		{name="air", prob=254, param2=0},
		{name="air", prob=254, param2=0},
		{name="air", prob=254, param2=0},
		{name="air", prob=254, param2=0},
		{name="air", prob=254, param2=0},
		{name="air", prob=254, param2=0},
		{name="air", prob=254, param2=0},

		-- z=0, y=9
		{name="air", prob=254, param2=0},
		{name="air", prob=254, param2=0},
		{name="air", prob=254, param2=0},
		{name="air", prob=254, param2=0},
		{name="air", prob=254, param2=0},
		{name="air", prob=254, param2=0},
		{name="air", prob=254, param2=0},
		{name="air", prob=254, param2=0},
		{name="air", prob=254, param2=0},
		{name="air", prob=254, param2=0},
		{name="air", prob=254, param2=0},
		{name="air", prob=254, param2=0},
		{name="air", prob=254, param2=0},
		{name="air", prob=254, param2=0},
		{name="air", prob=254, param2=0},
		{name="air", prob=254, param2=0},
		{name="air", prob=254, param2=0},

		-- z=0, y=10
		{name="stairs:slab_stonebrick", prob=254, param2=3},
		{name="stairs:slab_stonebrick", prob=254, param2=3},
		{name="stairs:slab_stonebrick", prob=254, param2=3},
		{name="stairs:slab_stonebrick", prob=254, param2=3},
		{name="stairs:slab_stonebrick", prob=254, param2=3},
		{name="stairs:slab_stonebrick", prob=254, param2=3},
		{name="stairs:slab_stonebrick", prob=254, param2=3},
		{name="stairs:slab_stonebrick", prob=254, param2=3},
		{name="stairs:slab_stonebrick", prob=254, param2=3},
		{name="stairs:slab_stonebrick", prob=254, param2=3},
		{name="stairs:slab_stonebrick", prob=254, param2=3},
		{name="stairs:slab_stonebrick", prob=254, param2=3},
		{name="stairs:slab_stonebrick", prob=254, param2=3},
		{name="stairs:slab_stonebrick", prob=254, param2=3},
		{name="stairs:slab_stonebrick", prob=254, param2=3},
		{name="stairs:slab_stonebrick", prob=254, param2=3},
		{name="stairs:slab_stonebrick", prob=254, param2=3},

		-- z=0, y=11
		{name="air", prob=254, param2=0},
		{name="air", prob=254, param2=0},
		{name="air", prob=254, param2=0},
		{name="air", prob=254, param2=0},
		{name="air", prob=254, param2=0},
		{name="air", prob=254, param2=0},
		{name="air", prob=254, param2=0},
		{name="air", prob=254, param2=0},
		{name="air", prob=254, param2=0},
		{name="air", prob=254, param2=0},
		{name="air", prob=254, param2=0},
		{name="air", prob=254, param2=0},
		{name="air", prob=254, param2=0},
		{name="air", prob=254, param2=0},
		{name="air", prob=254, param2=0},
		{name="air", prob=254, param2=0},
		{name="air", prob=254, param2=0},

		-- z=0, y=12
		{name="air", prob=254, param2=0},
		{name="air", prob=254, param2=0},
		{name="air", prob=254, param2=0},
		{name="air", prob=254, param2=0},
		{name="air", prob=254, param2=0},
		{name="air", prob=254, param2=0},
		{name="air", prob=254, param2=0},
		{name="air", prob=254, param2=0},
		{name="air", prob=254, param2=0},
		{name="air", prob=254, param2=0},
		{name="air", prob=254, param2=0},
		{name="air", prob=254, param2=0},
		{name="air", prob=254, param2=0},
		{name="air", prob=254, param2=0},
		{name="air", prob=254, param2=0},
		{name="air", prob=254, param2=0},
		{name="air", prob=254, param2=0},

		-- z=0, y=13
		{name="air", prob=254, param2=0},
		{name="air", prob=254, param2=0},
		{name="air", prob=254, param2=0},
		{name="air", prob=254, param2=0},
		{name="air", prob=254, param2=0},
		{name="air", prob=254, param2=0},
		{name="air", prob=254, param2=0},
		{name="air", prob=254, param2=0},
		{name="air", prob=254, param2=0},
		{name="air", prob=254, param2=0},
		{name="air", prob=254, param2=0},
		{name="air", prob=254, param2=0},
		{name="air", prob=254, param2=0},
		{name="air", prob=254, param2=0},
		{name="air", prob=254, param2=0},
		{name="air", prob=254, param2=0},
		{name="air", prob=254, param2=0},

		-- z=0, y=14
		{name="air", prob=254, param2=0},
		{name="air", prob=254, param2=0},
		{name="air", prob=254, param2=0},
		{name="air", prob=254, param2=0},
		{name="air", prob=254, param2=0},
		{name="air", prob=254, param2=0},
		{name="air", prob=254, param2=0},
		{name="air", prob=254, param2=0},
		{name="air", prob=254, param2=0},
		{name="air", prob=254, param2=0},
		{name="air", prob=254, param2=0},
		{name="air", prob=254, param2=0},
		{name="air", prob=254, param2=0},
		{name="air", prob=254, param2=0},
		{name="air", prob=254, param2=0},
		{name="air", prob=254, param2=0},
		{name="air", prob=254, param2=0},

		-- z=0, y=15
		{name="air", prob=254, param2=0},
		{name="air", prob=254, param2=0},
		{name="air", prob=254, param2=0},
		{name="air", prob=254, param2=0},
		{name="air", prob=254, param2=0},
		{name="air", prob=254, param2=0},
		{name="air", prob=254, param2=0},
		{name="air", prob=254, param2=0},
		{name="air", prob=254, param2=0},
		{name="air", prob=254, param2=0},
		{name="air", prob=254, param2=0},
		{name="air", prob=254, param2=7},
		{name="air", prob=254, param2=0},
		{name="air", prob=254, param2=0},
		{name="air", prob=254, param2=0},
		{name="air", prob=254, param2=0},
		{name="air", prob=254, param2=0},

		-- z=1, y=0
		{name="default:stonebrick", prob=254, param2=3},
		{name="default:stonebrick", prob=254, param2=3},
		{name="default:stonebrick", prob=254, param2=3},
		{name="default:stonebrick", prob=254, param2=3},
		{name="default:stonebrick", prob=254, param2=3},
		{name="default:stonebrick", prob=254, param2=3},
		{name="default:stonebrick", prob=254, param2=3},
		{name="default:stonebrick", prob=254, param2=3},
		{name="default:stonebrick", prob=254, param2=3},
		{name="default:stonebrick", prob=254, param2=3},
		{name="default:stonebrick", prob=254, param2=3},
		{name="default:stonebrick", prob=254, param2=3},
		{name="default:stonebrick", prob=254, param2=3},
		{name="default:stonebrick", prob=254, param2=3},
		{name="default:stonebrick", prob=254, param2=3},
		{name="default:stonebrick", prob=254, param2=3},
		{name="default:stonebrick", prob=254, param2=3},

		-- z=1, y=1
		{name="default:stonebrick", prob=254, param2=3},
		{name="default:stonebrick", prob=254, param2=3},
		{name="default:stonebrick", prob=254, param2=3},
		{name="default:stonebrick", prob=254, param2=3},
		{name="default:stonebrick", prob=254, param2=3},
		{name="default:stonebrick", prob=254, param2=3},
		{name="default:stonebrick", prob=254, param2=3},
		{name="default:stonebrick", prob=254, param2=3},
		{name="default:stonebrick", prob=254, param2=3},
		{name="default:stonebrick", prob=254, param2=3},
		{name="default:stonebrick", prob=254, param2=3},
		{name="default:stonebrick", prob=254, param2=3},
		{name="default:stonebrick", prob=254, param2=3},
		{name="default:stonebrick", prob=254, param2=3},
		{name="default:stonebrick", prob=254, param2=3},
		{name="default:stonebrick", prob=254, param2=3},
		{name="default:stonebrick", prob=254, param2=3},

		-- z=1, y=2
		{name="default:stonebrick", prob=254, param2=3},
		{name="default:stonebrick", prob=254, param2=3},
		{name="default:glass", prob=254, param2=0},
		{name="default:glass", prob=254, param2=0},
		{name="default:glass", prob=254, param2=0},
		{name="default:glass", prob=254, param2=0},
		{name="default:glass", prob=254, param2=0},
		{name="default:glass", prob=254, param2=0},
		{name="default:stonebrick", prob=254, param2=3},
		{name="default:glass", prob=254, param2=0},
		{name="default:glass", prob=254, param2=0},
		{name="default:glass", prob=254, param2=0},
		{name="default:glass", prob=254, param2=0},
		{name="default:glass", prob=254, param2=0},
		{name="default:glass", prob=254, param2=0},
		{name="default:stonebrick", prob=254, param2=3},
		{name="default:stonebrick", prob=254, param2=3},

		-- z=1, y=3
		{name="default:stonebrick", prob=254, param2=3},
		{name="default:stonebrick", prob=254, param2=3},
		{name="default:glass", prob=254, param2=0},
		{name="default:glass", prob=254, param2=0},
		{name="default:glass", prob=254, param2=0},
		{name="default:glass", prob=254, param2=0},
		{name="default:glass", prob=254, param2=0},
		{name="default:glass", prob=254, param2=0},
		{name="default:stonebrick", prob=254, param2=3},
		{name="default:glass", prob=254, param2=0},
		{name="default:glass", prob=254, param2=0},
		{name="default:glass", prob=254, param2=0},
		{name="default:glass", prob=254, param2=0},
		{name="default:glass", prob=254, param2=0},
		{name="default:glass", prob=254, param2=0},
		{name="default:stonebrick", prob=254, param2=3},
		{name="default:stonebrick", prob=254, param2=3},

		-- z=1, y=4
		{name="default:stonebrick", prob=254, param2=3},
		{name="default:stonebrick", prob=254, param2=3},
		{name="default:glass", prob=254, param2=0},
		{name="default:glass", prob=254, param2=0},
		{name="default:glass", prob=254, param2=0},
		{name="default:glass", prob=254, param2=0},
		{name="default:glass", prob=254, param2=0},
		{name="default:glass", prob=254, param2=0},
		{name="default:stonebrick", prob=254, param2=3},
		{name="default:glass", prob=254, param2=0},
		{name="default:glass", prob=254, param2=0},
		{name="default:glass", prob=254, param2=0},
		{name="default:glass", prob=254, param2=0},
		{name="default:glass", prob=254, param2=0},
		{name="default:glass", prob=254, param2=0},
		{name="default:stonebrick", prob=254, param2=3},
		{name="default:stonebrick", prob=254, param2=3},

		-- z=1, y=5
		{name="default:stonebrick", prob=254, param2=3},
		{name="default:stonebrick", prob=254, param2=3},
		{name="default:glass", prob=254, param2=0},
		{name="default:glass", prob=254, param2=0},
		{name="default:glass", prob=254, param2=0},
		{name="default:glass", prob=254, param2=0},
		{name="default:glass", prob=254, param2=0},
		{name="default:glass", prob=254, param2=0},
		{name="default:stonebrick", prob=254, param2=3},
		{name="default:glass", prob=254, param2=0},
		{name="default:glass", prob=254, param2=0},
		{name="default:glass", prob=254, param2=0},
		{name="default:glass", prob=254, param2=0},
		{name="default:glass", prob=254, param2=0},
		{name="default:glass", prob=254, param2=0},
		{name="default:stonebrick", prob=254, param2=3},
		{name="default:stonebrick", prob=254, param2=3},

		-- z=1, y=6
		{name="default:stonebrick", prob=254, param2=3},
		{name="default:stonebrick", prob=254, param2=3},
		{name="default:glass", prob=254, param2=0},
		{name="default:glass", prob=254, param2=0},
		{name="default:glass", prob=254, param2=0},
		{name="default:glass", prob=254, param2=0},
		{name="default:glass", prob=254, param2=0},
		{name="default:glass", prob=254, param2=0},
		{name="default:stonebrick", prob=254, param2=3},
		{name="default:glass", prob=254, param2=0},
		{name="default:glass", prob=254, param2=0},
		{name="default:glass", prob=254, param2=0},
		{name="default:glass", prob=254, param2=0},
		{name="default:glass", prob=254, param2=0},
		{name="default:glass", prob=254, param2=0},
		{name="default:stonebrick", prob=254, param2=3},
		{name="default:stonebrick", prob=254, param2=3},

		-- z=1, y=7
		{name="default:stonebrick", prob=254, param2=3},
		{name="default:stonebrick", prob=254, param2=3},
		{name="default:glass", prob=254, param2=0},
		{name="default:glass", prob=254, param2=0},
		{name="default:glass", prob=254, param2=0},
		{name="default:glass", prob=254, param2=0},
		{name="default:glass", prob=254, param2=0},
		{name="default:glass", prob=254, param2=0},
		{name="default:stonebrick", prob=254, param2=3},
		{name="default:glass", prob=254, param2=0},
		{name="default:glass", prob=254, param2=0},
		{name="default:glass", prob=254, param2=0},
		{name="default:glass", prob=254, param2=0},
		{name="default:glass", prob=254, param2=0},
		{name="default:glass", prob=254, param2=0},
		{name="default:stonebrick", prob=254, param2=3},
		{name="default:stonebrick", prob=254, param2=3},

		-- z=1, y=8
		{name="default:stonebrick", prob=254, param2=3},
		{name="default:stonebrick", prob=254, param2=3},
		{name="default:stonebrick", prob=254, param2=3},
		{name="default:glass", prob=254, param2=0},
		{name="default:glass", prob=254, param2=0},
		{name="default:glass", prob=254, param2=0},
		{name="default:glass", prob=254, param2=0},
		{name="default:stonebrick", prob=254, param2=3},
		{name="default:stonebrick", prob=254, param2=3},
		{name="default:stonebrick", prob=254, param2=3},
		{name="default:glass", prob=254, param2=0},
		{name="default:glass", prob=254, param2=0},
		{name="default:glass", prob=254, param2=0},
		{name="default:glass", prob=254, param2=0},
		{name="default:stonebrick", prob=254, param2=3},
		{name="default:stonebrick", prob=254, param2=3},
		{name="default:stonebrick", prob=254, param2=3},

		-- z=1, y=9
		{name="default:stonebrick", prob=254, param2=3},
		{name="default:stonebrick", prob=254, param2=3},
		{name="default:stonebrick", prob=254, param2=3},
		{name="default:stonebrick", prob=254, param2=3},
		{name="default:glass", prob=254, param2=0},
		{name="default:glass", prob=254, param2=0},
		{name="default:stonebrick", prob=254, param2=3},
		{name="default:stonebrick", prob=254, param2=3},
		{name="default:stonebrick", prob=254, param2=3},
		{name="default:stonebrick", prob=254, param2=3},
		{name="default:stonebrick", prob=254, param2=3},
		{name="default:glass", prob=254, param2=0},
		{name="default:glass", prob=254, param2=0},
		{name="default:stonebrick", prob=254, param2=3},
		{name="default:stonebrick", prob=254, param2=3},
		{name="default:stonebrick", prob=254, param2=3},
		{name="default:stonebrick", prob=254, param2=3},

		-- z=1, y=10
		{name="default:stonebrick", prob=254, param2=3},
		{name="default:stonebrick", prob=254, param2=3},
		{name="default:stonebrick", prob=254, param2=3},
		{name="default:stonebrick", prob=254, param2=3},
		{name="default:stonebrick", prob=254, param2=3},
		{name="default:stonebrick", prob=254, param2=3},
		{name="default:stonebrick", prob=254, param2=3},
		{name="default:stonebrick", prob=254, param2=3},
		{name="default:stonebrick", prob=254, param2=3},
		{name="default:stonebrick", prob=254, param2=3},
		{name="default:stonebrick", prob=254, param2=3},
		{name="default:stonebrick", prob=254, param2=3},
		{name="default:stonebrick", prob=254, param2=3},
		{name="default:stonebrick", prob=254, param2=3},
		{name="default:stonebrick", prob=254, param2=3},
		{name="default:stonebrick", prob=254, param2=3},
		{name="default:stonebrick", prob=254, param2=3},

		-- z=1, y=11
		{name="air", prob=254, param2=0},
		{name="air", prob=254, param2=0},
		{name="air", prob=254, param2=0},
		{name="air", prob=254, param2=0},
		{name="air", prob=254, param2=0},
		{name="air", prob=254, param2=0},
		{name="air", prob=254, param2=0},
		{name="air", prob=254, param2=0},
		{name="air", prob=254, param2=0},
		{name="air", prob=254, param2=0},
		{name="air", prob=254, param2=0},
		{name="air", prob=254, param2=0},
		{name="air", prob=254, param2=0},
		{name="air", prob=254, param2=0},
		{name="air", prob=254, param2=0},
		{name="air", prob=254, param2=0},
		{name="air", prob=254, param2=0},

		-- z=1, y=12
		{name="air", prob=254, param2=0},
		{name="air", prob=254, param2=0},
		{name="air", prob=254, param2=0},
		{name="air", prob=254, param2=0},
		{name="air", prob=254, param2=0},
		{name="air", prob=254, param2=0},
		{name="air", prob=254, param2=0},
		{name="air", prob=254, param2=0},
		{name="air", prob=254, param2=0},
		{name="air", prob=254, param2=0},
		{name="air", prob=254, param2=0},
		{name="air", prob=254, param2=0},
		{name="air", prob=254, param2=0},
		{name="air", prob=254, param2=0},
		{name="air", prob=254, param2=0},
		{name="air", prob=254, param2=0},
		{name="air", prob=254, param2=0},

		-- z=1, y=13
		{name="air", prob=254, param2=0},
		{name="air", prob=254, param2=0},
		{name="air", prob=254, param2=0},
		{name="air", prob=254, param2=0},
		{name="air", prob=254, param2=0},
		{name="air", prob=254, param2=0},
		{name="air", prob=254, param2=0},
		{name="air", prob=254, param2=0},
		{name="air", prob=254, param2=0},
		{name="air", prob=254, param2=0},
		{name="air", prob=254, param2=0},
		{name="air", prob=254, param2=0},
		{name="air", prob=254, param2=0},
		{name="air", prob=254, param2=0},
		{name="air", prob=254, param2=0},
		{name="air", prob=254, param2=0},
		{name="air", prob=254, param2=0},

		-- z=1, y=14
		{name="air", prob=254, param2=0},
		{name="air", prob=254, param2=0},
		{name="air", prob=254, param2=0},
		{name="air", prob=254, param2=0},
		{name="air", prob=254, param2=0},
		{name="air", prob=254, param2=0},
		{name="air", prob=254, param2=0},
		{name="air", prob=254, param2=0},
		{name="air", prob=254, param2=0},
		{name="air", prob=254, param2=0},
		{name="air", prob=254, param2=0},
		{name="air", prob=254, param2=0},
		{name="air", prob=254, param2=0},
		{name="air", prob=254, param2=0},
		{name="air", prob=254, param2=0},
		{name="air", prob=254, param2=0},
		{name="air", prob=254, param2=0},

		-- z=1, y=15
		{name="air", prob=254, param2=0},
		{name="air", prob=254, param2=0},
		{name="air", prob=254, param2=0},
		{name="air", prob=254, param2=0},
		{name="air", prob=254, param2=0},
		{name="air", prob=254, param2=0},
		{name="air", prob=254, param2=0},
		{name="air", prob=254, param2=0},
		{name="air", prob=254, param2=0},
		{name="air", prob=254, param2=0},
		{name="air", prob=254, param2=0},
		{name="air", prob=254, param2=0},
		{name="air", prob=254, param2=0},
		{name="air", prob=254, param2=0},
		{name="air", prob=254, param2=0},
		{name="air", prob=254, param2=0},
		{name="air", prob=254, param2=0},

		-- z=2, y=0
		{name="default:stonebrick", prob=254, param2=3},
		{name="wool:red", prob=254, param2=0},
		{name="wool:red", prob=254, param2=0},
		{name="wool:red", prob=254, param2=0},
		{name="wool:red", prob=254, param2=0},
		{name="wool:red", prob=254, param2=0},
		{name="wool:red", prob=254, param2=0},
		{name="wool:red", prob=254, param2=0},
		{name="wool:red", prob=254, param2=0},
		{name="wool:red", prob=254, param2=0},
		{name="wool:red", prob=254, param2=0},
		{name="wool:red", prob=254, param2=0},
		{name="wool:red", prob=254, param2=0},
		{name="default:stonebrick", prob=254, param2=3},
		{name="default:stonebrick", prob=254, param2=3},
		{name="default:stonebrick", prob=254, param2=3},
		{name="default:stonebrick", prob=254, param2=3},

		-- z=2, y=1
		{name="default:stonebrick", prob=254, param2=3},
		{name="air", prob=254, param2=0},
		{name="air", prob=254, param2=0},
		{name="air", prob=254, param2=0},
		{name="air", prob=254, param2=0},
		{name="air", prob=254, param2=0},
		{name="air", prob=254, param2=0},
		{name="air", prob=254, param2=0},
		{name="air", prob=254, param2=0},
		{name="air", prob=254, param2=0},
		{name="air", prob=254, param2=0},
		{name="air", prob=254, param2=0},
		{name="air", prob=254, param2=0},
		{name="stairs:slab_stonebrick", prob=254, param2=3},
		{name="stairs:stair_stonebrick", prob=254, param2=0},
		{name="stairs:stair_stonebrick", prob=254, param2=0},
		{name="default:stonebrick", prob=254, param2=3},

		-- z=2, y=2
		{name="default:stonebrick", prob=254, param2=3},
		{name="air", prob=254, param2=0},
		{name="air", prob=254, param2=0},
		{name="air", prob=254, param2=0},
		{name="air", prob=254, param2=0},
		{name="air", prob=254, param2=0},
		{name="air", prob=254, param2=0},
		{name="air", prob=254, param2=0},
		{name="air", prob=254, param2=0},
		{name="air", prob=254, param2=0},
		{name="air", prob=254, param2=0},
		{name="air", prob=254, param2=0},
		{name="air", prob=254, param2=0},
		{name="air", prob=254, param2=0},
		{name="air", prob=254, param2=0},
		{name="air", prob=254, param2=0},
		{name="default:stonebrick", prob=254, param2=3},

		-- z=2, y=3
		{name="default:stonebrick", prob=254, param2=3},
		{name="air", prob=254, param2=0},
		{name="air", prob=254, param2=0},
		{name="air", prob=254, param2=0},
		{name="air", prob=254, param2=0},
		{name="air", prob=254, param2=0},
		{name="air", prob=254, param2=0},
		{name="air", prob=254, param2=0},
		{name="default:fence_wood", prob=254, param2=0},
		{name="air", prob=254, param2=0},
		{name="air", prob=254, param2=0},
		{name="air", prob=254, param2=0},
		{name="air", prob=254, param2=0},
		{name="air", prob=254, param2=0},
		{name="air", prob=254, param2=0},
		{name="air", prob=254, param2=0},
		{name="default:stonebrick", prob=254, param2=3},

		-- z=2, y=4
		{name="default:stonebrick", prob=254, param2=3},
		{name="air", prob=254, param2=0},
		{name="air", prob=254, param2=0},
		{name="air", prob=254, param2=0},
		{name="air", prob=254, param2=0},
		{name="air", prob=254, param2=0},
		{name="air", prob=254, param2=0},
		{name="air", prob=254, param2=0},
		{name="default:torch_wall", prob=254, param2=1},
		{name="air", prob=254, param2=0},
		{name="air", prob=254, param2=0},
		{name="air", prob=254, param2=0},
		{name="air", prob=254, param2=0},
		{name="air", prob=254, param2=0},
		{name="air", prob=254, param2=0},
		{name="air", prob=254, param2=0},
		{name="default:stonebrick", prob=254, param2=3},

		-- z=2, y=5
		{name="default:stonebrick", prob=254, param2=3},
		{name="air", prob=254, param2=0},
		{name="air", prob=254, param2=0},
		{name="air", prob=254, param2=0},
		{name="air", prob=254, param2=0},
		{name="air", prob=254, param2=0},
		{name="air", prob=254, param2=0},
		{name="air", prob=254, param2=0},
		{name="air", prob=254, param2=0},
		{name="air", prob=254, param2=0},
		{name="air", prob=254, param2=0},
		{name="air", prob=254, param2=0},
		{name="air", prob=254, param2=0},
		{name="air", prob=254, param2=0},
		{name="air", prob=254, param2=0},
		{name="air", prob=254, param2=0},
		{name="default:stonebrick", prob=254, param2=3},

		-- z=2, y=6
		{name="default:stonebrick", prob=254, param2=3},
		{name="air", prob=254, param2=0},
		{name="air", prob=254, param2=0},
		{name="air", prob=254, param2=0},
		{name="air", prob=254, param2=0},
		{name="air", prob=254, param2=0},
		{name="air", prob=254, param2=0},
		{name="air", prob=254, param2=0},
		{name="air", prob=254, param2=0},
		{name="air", prob=254, param2=0},
		{name="air", prob=254, param2=0},
		{name="air", prob=254, param2=0},
		{name="air", prob=254, param2=0},
		{name="air", prob=254, param2=0},
		{name="air", prob=254, param2=0},
		{name="air", prob=254, param2=0},
		{name="default:stonebrick", prob=254, param2=3},

		-- z=2, y=7
		{name="default:stonebrick", prob=254, param2=3},
		{name="stairs:stair_stonebrick", prob=254, param2=22},
		{name="air", prob=254, param2=0},
		{name="air", prob=254, param2=0},
		{name="air", prob=254, param2=0},
		{name="air", prob=254, param2=0},
		{name="air", prob=254, param2=0},
		{name="air", prob=254, param2=0},
		{name="stairs:stair_stonebrick", prob=254, param2=22},
		{name="air", prob=254, param2=0},
		{name="air", prob=254, param2=0},
		{name="air", prob=254, param2=0},
		{name="air", prob=254, param2=0},
		{name="air", prob=254, param2=0},
		{name="air", prob=254, param2=0},
		{name="stairs:stair_stonebrick", prob=254, param2=22},
		{name="default:stonebrick", prob=254, param2=3},

		-- z=2, y=8
		{name="default:stonebrick", prob=254, param2=3},
		{name="default:stonebrick", prob=254, param2=3},
		{name="stairs:stair_stonebrick", prob=254, param2=22},
		{name="air", prob=254, param2=0},
		{name="air", prob=254, param2=0},
		{name="air", prob=254, param2=0},
		{name="air", prob=254, param2=0},
		{name="stairs:stair_stonebrick", prob=254, param2=22},
		{name="default:stonebrick", prob=254, param2=3},
		{name="stairs:stair_stonebrick", prob=254, param2=22},
		{name="air", prob=254, param2=0},
		{name="air", prob=254, param2=0},
		{name="air", prob=254, param2=0},
		{name="air", prob=254, param2=0},
		{name="stairs:stair_stonebrick", prob=254, param2=22},
		{name="default:stonebrick", prob=254, param2=3},
		{name="default:stonebrick", prob=254, param2=3},

		-- z=2, y=9
		{name="default:stonebrick", prob=254, param2=3},
		{name="default:stonebrick", prob=254, param2=3},
		{name="default:stonebrick", prob=254, param2=3},
		{name="stairs:stair_stonebrick", prob=254, param2=22},
		{name="air", prob=254, param2=0},
		{name="air", prob=254, param2=0},
		{name="stairs:stair_stonebrick", prob=254, param2=22},
		{name="default:stonebrick", prob=254, param2=3},
		{name="default:stonebrick", prob=254, param2=3},
		{name="default:stonebrick", prob=254, param2=3},
		{name="stairs:stair_stonebrick", prob=254, param2=22},
		{name="air", prob=254, param2=0},
		{name="air", prob=254, param2=0},
		{name="stairs:stair_stonebrick", prob=254, param2=22},
		{name="default:stonebrick", prob=254, param2=3},
		{name="default:stonebrick", prob=254, param2=3},
		{name="default:stonebrick", prob=254, param2=3},

		-- z=2, y=10
		{name="default:stonebrick", prob=254, param2=3},
		{name="default:stonebrick", prob=254, param2=3},
		{name="default:stonebrick", prob=254, param2=3},
		{name="default:stonebrick", prob=254, param2=3},
		{name="default:wood", prob=254, param2=3},
		{name="default:wood", prob=254, param2=3},
		{name="default:stonebrick", prob=254, param2=3},
		{name="default:stonebrick", prob=254, param2=3},
		{name="default:stonebrick", prob=254, param2=3},
		{name="default:stonebrick", prob=254, param2=3},
		{name="default:stonebrick", prob=254, param2=3},
		{name="default:wood", prob=254, param2=3},
		{name="default:wood", prob=254, param2=3},
		{name="default:stonebrick", prob=254, param2=3},
		{name="default:stonebrick", prob=254, param2=3},
		{name="default:stonebrick", prob=254, param2=3},
		{name="default:stonebrick", prob=254, param2=3},

		-- z=2, y=11
		{name="stairs:slab_stonebrick", prob=254, param2=3},
		{name="stairs:slab_stonebrick", prob=254, param2=3},
		{name="stairs:slab_stonebrick", prob=254, param2=3},
		{name="stairs:slab_stonebrick", prob=254, param2=3},
		{name="stairs:slab_stonebrick", prob=254, param2=3},
		{name="stairs:slab_stonebrick", prob=254, param2=3},
		{name="stairs:slab_stonebrick", prob=254, param2=3},
		{name="stairs:slab_stonebrick", prob=254, param2=3},
		{name="stairs:slab_stonebrick", prob=254, param2=3},
		{name="stairs:slab_stonebrick", prob=254, param2=3},
		{name="stairs:slab_stonebrick", prob=254, param2=3},
		{name="stairs:slab_stonebrick", prob=254, param2=3},
		{name="stairs:slab_stonebrick", prob=254, param2=3},
		{name="stairs:slab_stonebrick", prob=254, param2=3},
		{name="stairs:slab_stonebrick", prob=254, param2=3},
		{name="stairs:slab_stonebrick", prob=254, param2=3},
		{name="stairs:slab_stonebrick", prob=254, param2=3},

		-- z=2, y=12
		{name="air", prob=254, param2=0},
		{name="air", prob=254, param2=0},
		{name="air", prob=254, param2=0},
		{name="air", prob=254, param2=0},
		{name="air", prob=254, param2=0},
		{name="air", prob=254, param2=0},
		{name="air", prob=254, param2=0},
		{name="air", prob=254, param2=0},
		{name="air", prob=254, param2=0},
		{name="air", prob=254, param2=0},
		{name="air", prob=254, param2=0},
		{name="air", prob=254, param2=0},
		{name="air", prob=254, param2=0},
		{name="air", prob=254, param2=0},
		{name="air", prob=254, param2=0},
		{name="air", prob=254, param2=0},
		{name="air", prob=254, param2=0},

		-- z=2, y=13
		{name="air", prob=254, param2=0},
		{name="air", prob=254, param2=0},
		{name="air", prob=254, param2=0},
		{name="air", prob=254, param2=0},
		{name="air", prob=254, param2=0},
		{name="air", prob=254, param2=0},
		{name="air", prob=254, param2=0},
		{name="air", prob=254, param2=0},
		{name="air", prob=254, param2=0},
		{name="air", prob=254, param2=0},
		{name="air", prob=254, param2=0},
		{name="air", prob=254, param2=0},
		{name="air", prob=254, param2=0},
		{name="air", prob=254, param2=0},
		{name="air", prob=254, param2=0},
		{name="air", prob=254, param2=0},
		{name="air", prob=254, param2=0},

		-- z=2, y=14
		{name="air", prob=254, param2=0},
		{name="air", prob=254, param2=0},
		{name="air", prob=254, param2=0},
		{name="air", prob=254, param2=0},
		{name="air", prob=254, param2=0},
		{name="air", prob=254, param2=0},
		{name="air", prob=254, param2=0},
		{name="air", prob=254, param2=0},
		{name="air", prob=254, param2=0},
		{name="air", prob=254, param2=0},
		{name="air", prob=254, param2=0},
		{name="air", prob=254, param2=0},
		{name="air", prob=254, param2=0},
		{name="air", prob=254, param2=0},
		{name="air", prob=254, param2=0},
		{name="air", prob=254, param2=0},
		{name="air", prob=254, param2=0},

		-- z=2, y=15
		{name="air", prob=254, param2=0},
		{name="air", prob=254, param2=0},
		{name="air", prob=254, param2=0},
		{name="air", prob=254, param2=0},
		{name="air", prob=254, param2=0},
		{name="air", prob=254, param2=0},
		{name="air", prob=254, param2=0},
		{name="air", prob=254, param2=0},
		{name="air", prob=254, param2=0},
		{name="air", prob=254, param2=0},
		{name="air", prob=254, param2=0},
		{name="air", prob=254, param2=0},
		{name="air", prob=254, param2=0},
		{name="air", prob=254, param2=0},
		{name="air", prob=254, param2=0},
		{name="air", prob=254, param2=0},
		{name="air", prob=254, param2=0},

		-- z=3, y=0
		{name="default:stonebrick", prob=254, param2=3},
		{name="wool:red", prob=254, param2=0},
		{name="wool:yellow", prob=254, param2=0},
		{name="wool:yellow", prob=254, param2=0},
		{name="wool:yellow", prob=254, param2=0},
		{name="wool:yellow", prob=254, param2=0},
		{name="wool:yellow", prob=254, param2=0},
		{name="wool:yellow", prob=254, param2=0},
		{name="wool:yellow", prob=254, param2=0},
		{name="wool:yellow", prob=254, param2=0},
		{name="wool:yellow", prob=254, param2=0},
		{name="wool:yellow", prob=254, param2=0},
		{name="wool:red", prob=254, param2=0},
		{name="default:stonebrick", prob=254, param2=3},
		{name="default:stonebrick", prob=254, param2=3},
		{name="default:stonebrick", prob=254, param2=3},
		{name="default:stonebrick", prob=254, param2=3},

		-- z=3, y=1
		{name="default:stonebrick", prob=254, param2=3},
		{name="air", prob=254, param2=0},
		{name="stairs:stair_wood", prob=254, param2=3},
		{name="air", prob=254, param2=0},
		{name="stairs:stair_wood", prob=254, param2=3},
		{name="air", prob=254, param2=0},
		{name="stairs:stair_wood", prob=254, param2=3},
		{name="air", prob=254, param2=0},
		{name="stairs:stair_wood", prob=254, param2=3},
		{name="air", prob=254, param2=0},
		{name="stairs:stair_wood", prob=254, param2=3},
		{name="air", prob=254, param2=0},
		{name="air", prob=254, param2=0},
		{name="stairs:stair_stonebrick", prob=254, param2=1},
		{name="default:river_water_source", prob=254, param2=240},
		{name="default:river_water_source", prob=254, param2=0},
		{name="default:stonebrick", prob=254, param2=3},

		-- z=3, y=2
		{name="default:glass", prob=254, param2=0},
		{name="air", prob=254, param2=0},
		{name="air", prob=254, param2=0},
		{name="air", prob=254, param2=0},
		{name="air", prob=254, param2=0},
		{name="air", prob=254, param2=0},
		{name="air", prob=254, param2=0},
		{name="air", prob=254, param2=0},
		{name="air", prob=254, param2=0},
		{name="air", prob=254, param2=0},
		{name="air", prob=254, param2=0},
		{name="air", prob=254, param2=0},
		{name="air", prob=254, param2=0},
		{name="air", prob=254, param2=0},
		{name="air", prob=254, param2=0},
		{name="air", prob=254, param2=0},
		{name="default:glass", prob=254, param2=0},

		-- z=3, y=3
		{name="default:glass", prob=254, param2=0},
		{name="air", prob=254, param2=0},
		{name="air", prob=254, param2=0},
		{name="air", prob=254, param2=0},
		{name="air", prob=254, param2=0},
		{name="air", prob=254, param2=0},
		{name="air", prob=254, param2=0},
		{name="air", prob=254, param2=0},
		{name="air", prob=254, param2=0},
		{name="air", prob=254, param2=0},
		{name="air", prob=254, param2=0},
		{name="air", prob=254, param2=0},
		{name="air", prob=254, param2=0},
		{name="air", prob=254, param2=0},
		{name="air", prob=254, param2=0},
		{name="air", prob=254, param2=0},
		{name="default:glass", prob=254, param2=0},

		-- z=3, y=4
		{name="default:glass", prob=254, param2=0},
		{name="air", prob=254, param2=0},
		{name="air", prob=254, param2=0},
		{name="air", prob=254, param2=0},
		{name="air", prob=254, param2=0},
		{name="air", prob=254, param2=0},
		{name="air", prob=254, param2=0},
		{name="air", prob=254, param2=0},
		{name="air", prob=254, param2=0},
		{name="air", prob=254, param2=0},
		{name="air", prob=254, param2=0},
		{name="air", prob=254, param2=0},
		{name="air", prob=254, param2=0},
		{name="air", prob=254, param2=0},
		{name="air", prob=254, param2=0},
		{name="air", prob=254, param2=0},
		{name="default:glass", prob=254, param2=0},

		-- z=3, y=5
		{name="default:glass", prob=254, param2=0},
		{name="air", prob=254, param2=0},
		{name="air", prob=254, param2=0},
		{name="air", prob=254, param2=0},
		{name="air", prob=254, param2=0},
		{name="air", prob=254, param2=0},
		{name="air", prob=254, param2=0},
		{name="air", prob=254, param2=0},
		{name="air", prob=254, param2=0},
		{name="air", prob=254, param2=0},
		{name="air", prob=254, param2=0},
		{name="air", prob=254, param2=0},
		{name="air", prob=254, param2=0},
		{name="air", prob=254, param2=0},
		{name="air", prob=254, param2=0},
		{name="air", prob=254, param2=0},
		{name="default:glass", prob=254, param2=0},

		-- z=3, y=6
		{name="default:glass", prob=254, param2=0},
		{name="air", prob=254, param2=0},
		{name="air", prob=254, param2=0},
		{name="air", prob=254, param2=0},
		{name="air", prob=254, param2=0},
		{name="air", prob=254, param2=0},
		{name="air", prob=254, param2=0},
		{name="air", prob=254, param2=0},
		{name="air", prob=254, param2=0},
		{name="air", prob=254, param2=0},
		{name="air", prob=254, param2=0},
		{name="air", prob=254, param2=0},
		{name="air", prob=254, param2=0},
		{name="air", prob=254, param2=0},
		{name="air", prob=254, param2=0},
		{name="air", prob=254, param2=0},
		{name="default:glass", prob=254, param2=0},

		-- z=3, y=7
		{name="default:glass", prob=254, param2=0},
		{name="air", prob=254, param2=0},
		{name="air", prob=254, param2=0},
		{name="air", prob=254, param2=0},
		{name="air", prob=254, param2=0},
		{name="air", prob=254, param2=0},
		{name="air", prob=254, param2=0},
		{name="air", prob=254, param2=0},
		{name="air", prob=254, param2=0},
		{name="air", prob=254, param2=0},
		{name="air", prob=254, param2=0},
		{name="air", prob=254, param2=0},
		{name="air", prob=254, param2=0},
		{name="air", prob=254, param2=0},
		{name="air", prob=254, param2=0},
		{name="air", prob=254, param2=0},
		{name="default:glass", prob=254, param2=0},

		-- z=3, y=8
		{name="default:stonebrick", prob=254, param2=3},
		{name="stairs:stair_stonebrick", prob=254, param2=22},
		{name="air", prob=254, param2=0},
		{name="air", prob=254, param2=0},
		{name="air", prob=254, param2=0},
		{name="air", prob=254, param2=0},
		{name="air", prob=254, param2=0},
		{name="air", prob=254, param2=0},
		{name="stairs:stair_stonebrick", prob=254, param2=22},
		{name="air", prob=254, param2=0},
		{name="air", prob=254, param2=0},
		{name="air", prob=254, param2=0},
		{name="air", prob=254, param2=0},
		{name="air", prob=254, param2=0},
		{name="air", prob=254, param2=0},
		{name="stairs:stair_stonebrick", prob=254, param2=22},
		{name="default:stonebrick", prob=254, param2=3},

		-- z=3, y=9
		{name="default:stonebrick", prob=254, param2=3},
		{name="default:stonebrick", prob=254, param2=3},
		{name="default:stonebrick", prob=254, param2=3},
		{name="stairs:slab_stonebrick", prob=254, param2=21},
		{name="air", prob=254, param2=0},
		{name="air", prob=254, param2=0},
		{name="stairs:slab_stonebrick", prob=254, param2=21},
		{name="default:stonebrick", prob=254, param2=3},
		{name="default:stonebrick", prob=254, param2=3},
		{name="default:stonebrick", prob=254, param2=3},
		{name="stairs:slab_stonebrick", prob=254, param2=21},
		{name="air", prob=254, param2=0},
		{name="air", prob=254, param2=0},
		{name="stairs:slab_stonebrick", prob=254, param2=21},
		{name="default:stonebrick", prob=254, param2=3},
		{name="default:stonebrick", prob=254, param2=3},
		{name="default:stonebrick", prob=254, param2=3},

		-- z=3, y=10
		{name="default:stonebrick", prob=254, param2=3},
		{name="default:stonebrick", prob=254, param2=3},
		{name="default:stonebrick", prob=254, param2=3},
		{name="default:stonebrick", prob=254, param2=3},
		{name="default:wood", prob=254, param2=3},
		{name="default:wood", prob=254, param2=3},
		{name="default:stonebrick", prob=254, param2=3},
		{name="default:stonebrick", prob=254, param2=3},
		{name="default:stonebrick", prob=254, param2=3},
		{name="default:stonebrick", prob=254, param2=3},
		{name="default:stonebrick", prob=254, param2=3},
		{name="default:wood", prob=254, param2=3},
		{name="default:wood", prob=254, param2=3},
		{name="default:stonebrick", prob=254, param2=3},
		{name="default:stonebrick", prob=254, param2=3},
		{name="default:stonebrick", prob=254, param2=3},
		{name="default:stonebrick", prob=254, param2=3},

		-- z=3, y=11
		{name="default:stonebrick", prob=254, param2=3},
		{name="default:stonebrick", prob=254, param2=3},
		{name="default:stonebrick", prob=254, param2=3},
		{name="default:stonebrick", prob=254, param2=3},
		{name="default:stonebrick", prob=254, param2=3},
		{name="default:stonebrick", prob=254, param2=3},
		{name="default:stonebrick", prob=254, param2=3},
		{name="default:stonebrick", prob=254, param2=3},
		{name="default:stonebrick", prob=254, param2=3},
		{name="default:stonebrick", prob=254, param2=3},
		{name="default:stonebrick", prob=254, param2=3},
		{name="default:stonebrick", prob=254, param2=3},
		{name="default:stonebrick", prob=254, param2=3},
		{name="default:stonebrick", prob=254, param2=3},
		{name="default:stonebrick", prob=254, param2=3},
		{name="default:stonebrick", prob=254, param2=3},
		{name="default:stonebrick", prob=254, param2=3},

		-- z=3, y=12
		{name="air", prob=254, param2=0},
		{name="air", prob=254, param2=0},
		{name="air", prob=254, param2=0},
		{name="air", prob=254, param2=0},
		{name="air", prob=254, param2=0},
		{name="air", prob=254, param2=0},
		{name="air", prob=254, param2=0},
		{name="air", prob=254, param2=0},
		{name="air", prob=254, param2=0},
		{name="air", prob=254, param2=0},
		{name="air", prob=254, param2=0},
		{name="air", prob=254, param2=0},
		{name="air", prob=254, param2=0},
		{name="air", prob=254, param2=0},
		{name="air", prob=254, param2=0},
		{name="air", prob=254, param2=0},
		{name="air", prob=254, param2=0},

		-- z=3, y=13
		{name="air", prob=254, param2=0},
		{name="air", prob=254, param2=0},
		{name="air", prob=254, param2=0},
		{name="air", prob=254, param2=0},
		{name="air", prob=254, param2=0},
		{name="air", prob=254, param2=0},
		{name="air", prob=254, param2=0},
		{name="air", prob=254, param2=0},
		{name="air", prob=254, param2=0},
		{name="air", prob=254, param2=0},
		{name="air", prob=254, param2=0},
		{name="air", prob=254, param2=0},
		{name="air", prob=254, param2=0},
		{name="air", prob=254, param2=0},
		{name="air", prob=254, param2=0},
		{name="air", prob=254, param2=0},
		{name="air", prob=254, param2=0},

		-- z=3, y=14
		{name="air", prob=254, param2=0},
		{name="air", prob=254, param2=0},
		{name="air", prob=254, param2=0},
		{name="air", prob=254, param2=0},
		{name="air", prob=254, param2=0},
		{name="air", prob=254, param2=0},
		{name="air", prob=254, param2=0},
		{name="air", prob=254, param2=0},
		{name="air", prob=254, param2=0},
		{name="air", prob=254, param2=0},
		{name="air", prob=254, param2=0},
		{name="air", prob=254, param2=0},
		{name="air", prob=254, param2=0},
		{name="air", prob=254, param2=0},
		{name="air", prob=254, param2=0},
		{name="air", prob=254, param2=0},
		{name="air", prob=254, param2=0},

		-- z=3, y=15
		{name="air", prob=254, param2=0},
		{name="air", prob=254, param2=0},
		{name="air", prob=254, param2=0},
		{name="air", prob=254, param2=0},
		{name="air", prob=254, param2=0},
		{name="air", prob=254, param2=0},
		{name="air", prob=254, param2=0},
		{name="air", prob=254, param2=0},
		{name="air", prob=254, param2=0},
		{name="air", prob=254, param2=0},
		{name="air", prob=254, param2=0},
		{name="air", prob=254, param2=0},
		{name="air", prob=254, param2=0},
		{name="air", prob=254, param2=0},
		{name="air", prob=254, param2=0},
		{name="air", prob=254, param2=0},
		{name="air", prob=254, param2=0},

		-- z=4, y=0
		{name="default:stonebrick", prob=254, param2=3},
		{name="wool:red", prob=254, param2=0},
		{name="wool:yellow", prob=254, param2=0},
		{name="wool:yellow", prob=254, param2=0},
		{name="wool:yellow", prob=254, param2=0},
		{name="wool:yellow", prob=254, param2=0},
		{name="wool:yellow", prob=254, param2=0},
		{name="wool:yellow", prob=254, param2=0},
		{name="wool:yellow", prob=254, param2=0},
		{name="wool:yellow", prob=254, param2=0},
		{name="wool:yellow", prob=254, param2=0},
		{name="wool:yellow", prob=254, param2=0},
		{name="wool:red", prob=254, param2=0},
		{name="default:stonebrick", prob=254, param2=3},
		{name="default:stonebrick", prob=254, param2=3},
		{name="default:stonebrick", prob=254, param2=3},
		{name="default:stonebrick", prob=254, param2=3},

		-- z=4, y=1
		{name="default:stonebrick", prob=254, param2=3},
		{name="air", prob=254, param2=0},
		{name="stairs:stair_wood", prob=254, param2=3},
		{name="air", prob=254, param2=0},
		{name="stairs:stair_wood", prob=254, param2=3},
		{name="air", prob=254, param2=0},
		{name="stairs:stair_wood", prob=254, param2=3},
		{name="air", prob=254, param2=0},
		{name="stairs:stair_wood", prob=254, param2=3},
		{name="air", prob=254, param2=0},
		{name="stairs:stair_wood", prob=254, param2=3},
		{name="air", prob=254, param2=0},
		{name="air", prob=254, param2=0},
		{name="stairs:stair_stonebrick", prob=254, param2=1},
		{name="default:river_water_source", prob=254, param2=0},
		{name="default:river_water_source", prob=254, param2=240},
		{name="default:stonebrick", prob=254, param2=3},

		-- z=4, y=2
		{name="default:glass", prob=254, param2=0},
		{name="air", prob=254, param2=0},
		{name="air", prob=254, param2=0},
		{name="air", prob=254, param2=0},
		{name="air", prob=254, param2=0},
		{name="air", prob=254, param2=0},
		{name="air", prob=254, param2=0},
		{name="air", prob=254, param2=0},
		{name="air", prob=254, param2=0},
		{name="air", prob=254, param2=0},
		{name="air", prob=254, param2=0},
		{name="air", prob=254, param2=0},
		{name="air", prob=254, param2=0},
		{name="air", prob=254, param2=0},
		{name="air", prob=254, param2=0},
		{name="air", prob=254, param2=0},
		{name="default:glass", prob=254, param2=0},

		-- z=4, y=3
		{name="default:glass", prob=254, param2=0},
		{name="air", prob=254, param2=0},
		{name="air", prob=254, param2=0},
		{name="air", prob=254, param2=0},
		{name="air", prob=254, param2=0},
		{name="air", prob=254, param2=0},
		{name="air", prob=254, param2=0},
		{name="air", prob=254, param2=0},
		{name="air", prob=254, param2=0},
		{name="air", prob=254, param2=0},
		{name="air", prob=254, param2=0},
		{name="air", prob=254, param2=0},
		{name="air", prob=254, param2=0},
		{name="air", prob=254, param2=0},
		{name="air", prob=254, param2=0},
		{name="air", prob=254, param2=0},
		{name="default:glass", prob=254, param2=0},

		-- z=4, y=4
		{name="default:glass", prob=254, param2=0},
		{name="air", prob=254, param2=0},
		{name="air", prob=254, param2=0},
		{name="air", prob=254, param2=0},
		{name="air", prob=254, param2=0},
		{name="air", prob=254, param2=0},
		{name="air", prob=254, param2=0},
		{name="air", prob=254, param2=0},
		{name="air", prob=254, param2=0},
		{name="air", prob=254, param2=0},
		{name="air", prob=254, param2=0},
		{name="air", prob=254, param2=0},
		{name="air", prob=254, param2=0},
		{name="air", prob=254, param2=0},
		{name="air", prob=254, param2=0},
		{name="air", prob=254, param2=0},
		{name="default:glass", prob=254, param2=0},

		-- z=4, y=5
		{name="default:glass", prob=254, param2=0},
		{name="air", prob=254, param2=0},
		{name="air", prob=254, param2=0},
		{name="air", prob=254, param2=0},
		{name="air", prob=254, param2=0},
		{name="air", prob=254, param2=0},
		{name="air", prob=254, param2=0},
		{name="air", prob=254, param2=0},
		{name="air", prob=254, param2=0},
		{name="air", prob=254, param2=0},
		{name="air", prob=254, param2=0},
		{name="air", prob=254, param2=0},
		{name="air", prob=254, param2=0},
		{name="air", prob=254, param2=0},
		{name="air", prob=254, param2=0},
		{name="air", prob=254, param2=0},
		{name="default:glass", prob=254, param2=0},

		-- z=4, y=6
		{name="default:glass", prob=254, param2=0},
		{name="air", prob=254, param2=0},
		{name="air", prob=254, param2=0},
		{name="air", prob=254, param2=0},
		{name="air", prob=254, param2=0},
		{name="air", prob=254, param2=0},
		{name="air", prob=254, param2=0},
		{name="air", prob=254, param2=0},
		{name="air", prob=254, param2=0},
		{name="air", prob=254, param2=0},
		{name="air", prob=254, param2=0},
		{name="air", prob=254, param2=0},
		{name="air", prob=254, param2=0},
		{name="air", prob=254, param2=0},
		{name="air", prob=254, param2=0},
		{name="air", prob=254, param2=0},
		{name="default:glass", prob=254, param2=0},

		-- z=4, y=7
		{name="default:glass", prob=254, param2=0},
		{name="air", prob=254, param2=0},
		{name="air", prob=254, param2=0},
		{name="air", prob=254, param2=0},
		{name="air", prob=254, param2=0},
		{name="air", prob=254, param2=0},
		{name="air", prob=254, param2=0},
		{name="air", prob=254, param2=0},
		{name="air", prob=254, param2=0},
		{name="air", prob=254, param2=0},
		{name="air", prob=254, param2=0},
		{name="air", prob=254, param2=0},
		{name="air", prob=254, param2=0},
		{name="air", prob=254, param2=0},
		{name="air", prob=254, param2=0},
		{name="air", prob=254, param2=0},
		{name="default:glass", prob=254, param2=0},

		-- z=4, y=8
		{name="default:stonebrick", prob=254, param2=3},
		{name="air", prob=254, param2=0},
		{name="air", prob=254, param2=0},
		{name="air", prob=254, param2=0},
		{name="air", prob=254, param2=0},
		{name="air", prob=254, param2=0},
		{name="air", prob=254, param2=0},
		{name="air", prob=254, param2=0},
		{name="air", prob=254, param2=0},
		{name="air", prob=254, param2=0},
		{name="air", prob=254, param2=0},
		{name="air", prob=254, param2=0},
		{name="air", prob=254, param2=0},
		{name="air", prob=254, param2=0},
		{name="air", prob=254, param2=0},
		{name="air", prob=254, param2=0},
		{name="default:glass", prob=254, param2=0},

		-- z=4, y=9
		{name="default:stonebrick", prob=254, param2=3},
		{name="default:stonebrick", prob=254, param2=3},
		{name="stairs:slab_stonebrick", prob=254, param2=21},
		{name="air", prob=254, param2=0},
		{name="air", prob=254, param2=0},
		{name="air", prob=254, param2=0},
		{name="air", prob=254, param2=0},
		{name="stairs:slab_stonebrick", prob=254, param2=21},
		{name="default:stonebrick", prob=254, param2=3},
		{name="stairs:slab_stonebrick", prob=254, param2=21},
		{name="air", prob=254, param2=0},
		{name="air", prob=254, param2=0},
		{name="air", prob=254, param2=0},
		{name="air", prob=254, param2=0},
		{name="stairs:slab_stonebrick", prob=254, param2=21},
		{name="default:stonebrick", prob=254, param2=3},
		{name="default:stonebrick", prob=254, param2=3},

		-- z=4, y=10
		{name="default:stonebrick", prob=254, param2=3},
		{name="default:stonebrick", prob=254, param2=3},
		{name="default:stonebrick", prob=254, param2=3},
		{name="default:wood", prob=254, param2=3},
		{name="default:wood", prob=254, param2=3},
		{name="default:wood", prob=254, param2=3},
		{name="default:wood", prob=254, param2=3},
		{name="default:stonebrick", prob=254, param2=3},
		{name="default:stonebrick", prob=254, param2=3},
		{name="default:stonebrick", prob=254, param2=3},
		{name="default:wood", prob=254, param2=3},
		{name="default:wood", prob=254, param2=3},
		{name="default:wood", prob=254, param2=3},
		{name="default:wood", prob=254, param2=3},
		{name="default:stonebrick", prob=254, param2=3},
		{name="default:stonebrick", prob=254, param2=3},
		{name="default:stonebrick", prob=254, param2=3},

		-- z=4, y=11
		{name="default:stonebrick", prob=254, param2=3},
		{name="default:stonebrick", prob=254, param2=3},
		{name="default:stonebrick", prob=254, param2=3},
		{name="default:stonebrick", prob=254, param2=3},
		{name="default:stonebrick", prob=254, param2=3},
		{name="default:stonebrick", prob=254, param2=3},
		{name="default:stonebrick", prob=254, param2=3},
		{name="default:stonebrick", prob=254, param2=3},
		{name="default:stonebrick", prob=254, param2=3},
		{name="default:stonebrick", prob=254, param2=3},
		{name="default:stonebrick", prob=254, param2=3},
		{name="default:stonebrick", prob=254, param2=3},
		{name="default:stonebrick", prob=254, param2=3},
		{name="default:stonebrick", prob=254, param2=3},
		{name="default:stonebrick", prob=254, param2=3},
		{name="default:stonebrick", prob=254, param2=3},
		{name="default:stonebrick", prob=254, param2=3},

		-- z=4, y=12
		{name="stairs:slab_stonebrick", prob=254, param2=3},
		{name="stairs:slab_stonebrick", prob=254, param2=3},
		{name="stairs:slab_stonebrick", prob=254, param2=3},
		{name="stairs:slab_stonebrick", prob=254, param2=3},
		{name="stairs:slab_stonebrick", prob=254, param2=3},
		{name="stairs:slab_stonebrick", prob=254, param2=3},
		{name="stairs:slab_stonebrick", prob=254, param2=3},
		{name="stairs:slab_stonebrick", prob=254, param2=3},
		{name="stairs:slab_stonebrick", prob=254, param2=3},
		{name="stairs:slab_stonebrick", prob=254, param2=3},
		{name="stairs:slab_stonebrick", prob=254, param2=3},
		{name="stairs:slab_stonebrick", prob=254, param2=3},
		{name="stairs:slab_stonebrick", prob=254, param2=3},
		{name="stairs:slab_stonebrick", prob=254, param2=3},
		{name="stairs:slab_stonebrick", prob=254, param2=3},
		{name="stairs:slab_stonebrick", prob=254, param2=3},
		{name="stairs:slab_stonebrick", prob=254, param2=3},

		-- z=4, y=13
		{name="air", prob=254, param2=0},
		{name="air", prob=254, param2=0},
		{name="air", prob=254, param2=0},
		{name="air", prob=254, param2=0},
		{name="air", prob=254, param2=0},
		{name="air", prob=254, param2=0},
		{name="air", prob=254, param2=0},
		{name="air", prob=254, param2=0},
		{name="air", prob=254, param2=0},
		{name="air", prob=254, param2=0},
		{name="air", prob=254, param2=0},
		{name="air", prob=254, param2=0},
		{name="air", prob=254, param2=0},
		{name="air", prob=254, param2=0},
		{name="air", prob=254, param2=0},
		{name="air", prob=254, param2=0},
		{name="air", prob=254, param2=0},

		-- z=4, y=14
		{name="air", prob=254, param2=0},
		{name="air", prob=254, param2=0},
		{name="air", prob=254, param2=0},
		{name="air", prob=254, param2=0},
		{name="air", prob=254, param2=0},
		{name="air", prob=254, param2=0},
		{name="air", prob=254, param2=0},
		{name="air", prob=254, param2=0},
		{name="air", prob=254, param2=0},
		{name="air", prob=254, param2=0},
		{name="air", prob=254, param2=0},
		{name="air", prob=254, param2=0},
		{name="air", prob=254, param2=0},
		{name="air", prob=254, param2=0},
		{name="air", prob=254, param2=0},
		{name="air", prob=254, param2=0},
		{name="air", prob=254, param2=0},

		-- z=4, y=15
		{name="air", prob=254, param2=0},
		{name="air", prob=254, param2=0},
		{name="air", prob=254, param2=0},
		{name="air", prob=254, param2=0},
		{name="air", prob=254, param2=0},
		{name="air", prob=254, param2=0},
		{name="air", prob=254, param2=0},
		{name="air", prob=254, param2=0},
		{name="air", prob=254, param2=0},
		{name="air", prob=254, param2=0},
		{name="air", prob=254, param2=0},
		{name="air", prob=254, param2=0},
		{name="air", prob=254, param2=0},
		{name="air", prob=254, param2=0},
		{name="air", prob=254, param2=0},
		{name="air", prob=254, param2=0},
		{name="air", prob=254, param2=0},

		-- z=5, y=0
		{name="default:stonebrick", prob=254, param2=3},
		{name="wool:red", prob=254, param2=0},
		{name="wool:yellow", prob=254, param2=0},
		{name="wool:yellow", prob=254, param2=0},
		{name="wool:yellow", prob=254, param2=0},
		{name="wool:yellow", prob=254, param2=0},
		{name="wool:yellow", prob=254, param2=0},
		{name="wool:yellow", prob=254, param2=0},
		{name="wool:yellow", prob=254, param2=0},
		{name="wool:yellow", prob=254, param2=0},
		{name="wool:yellow", prob=254, param2=0},
		{name="wool:yellow", prob=254, param2=0},
		{name="wool:red", prob=254, param2=0},
		{name="default:stonebrick", prob=254, param2=3},
		{name="default:stonebrick", prob=254, param2=3},
		{name="default:stonebrick", prob=254, param2=3},
		{name="default:stonebrick", prob=254, param2=3},

		-- z=5, y=1
		{name="default:stonebrick", prob=254, param2=3},
		{name="air", prob=254, param2=0},
		{name="stairs:stair_wood", prob=254, param2=3},
		{name="air", prob=254, param2=0},
		{name="stairs:stair_wood", prob=254, param2=3},
		{name="air", prob=254, param2=0},
		{name="stairs:stair_wood", prob=254, param2=3},
		{name="air", prob=254, param2=0},
		{name="stairs:stair_wood", prob=254, param2=3},
		{name="air", prob=254, param2=0},
		{name="stairs:stair_wood", prob=254, param2=3},
		{name="air", prob=254, param2=0},
		{name="air", prob=254, param2=0},
		{name="stairs:slab_stonebrick", prob=254, param2=3},
		{name="stairs:stair_stonebrick", prob=254, param2=2},
		{name="stairs:stair_stonebrick", prob=254, param2=2},
		{name="default:stonebrick", prob=254, param2=3},

		-- z=5, y=2
		{name="default:stonebrick", prob=254, param2=3},
		{name="air", prob=254, param2=0},
		{name="air", prob=254, param2=0},
		{name="air", prob=254, param2=0},
		{name="air", prob=254, param2=0},
		{name="air", prob=254, param2=0},
		{name="air", prob=254, param2=0},
		{name="air", prob=254, param2=0},
		{name="air", prob=254, param2=0},
		{name="air", prob=254, param2=0},
		{name="air", prob=254, param2=0},
		{name="air", prob=254, param2=0},
		{name="air", prob=254, param2=0},
		{name="air", prob=254, param2=0},
		{name="air", prob=254, param2=0},
		{name="air", prob=254, param2=0},
		{name="default:glass", prob=254, param2=0},

		-- z=5, y=3
		{name="default:stonebrick", prob=254, param2=3},
		{name="default:fence_wood", prob=254, param2=0},
		{name="air", prob=254, param2=0},
		{name="air", prob=254, param2=0},
		{name="air", prob=254, param2=0},
		{name="air", prob=254, param2=0},
		{name="air", prob=254, param2=0},
		{name="air", prob=254, param2=0},
		{name="air", prob=254, param2=0},
		{name="air", prob=254, param2=0},
		{name="air", prob=254, param2=0},
		{name="air", prob=254, param2=0},
		{name="air", prob=254, param2=0},
		{name="air", prob=254, param2=0},
		{name="air", prob=254, param2=0},
		{name="air", prob=254, param2=0},
		{name="default:glass", prob=254, param2=0},

		-- z=5, y=4
		{name="default:stonebrick", prob=254, param2=3},
		{name="default:torch_wall", prob=254, param2=1},
		{name="air", prob=254, param2=0},
		{name="air", prob=254, param2=0},
		{name="air", prob=254, param2=0},
		{name="air", prob=254, param2=0},
		{name="air", prob=254, param2=0},
		{name="air", prob=254, param2=0},
		{name="air", prob=254, param2=0},
		{name="air", prob=254, param2=0},
		{name="air", prob=254, param2=0},
		{name="air", prob=254, param2=0},
		{name="air", prob=254, param2=0},
		{name="air", prob=254, param2=0},
		{name="air", prob=254, param2=0},
		{name="air", prob=254, param2=0},
		{name="default:glass", prob=254, param2=0},

		-- z=5, y=5
		{name="default:stonebrick", prob=254, param2=3},
		{name="air", prob=254, param2=0},
		{name="air", prob=254, param2=0},
		{name="air", prob=254, param2=0},
		{name="air", prob=254, param2=0},
		{name="air", prob=254, param2=0},
		{name="air", prob=254, param2=0},
		{name="air", prob=254, param2=0},
		{name="air", prob=254, param2=0},
		{name="air", prob=254, param2=0},
		{name="air", prob=254, param2=0},
		{name="air", prob=254, param2=0},
		{name="air", prob=254, param2=0},
		{name="air", prob=254, param2=0},
		{name="air", prob=254, param2=0},
		{name="air", prob=254, param2=0},
		{name="default:glass", prob=254, param2=0},

		-- z=5, y=6
		{name="default:glass", prob=254, param2=0},
		{name="air", prob=254, param2=0},
		{name="air", prob=254, param2=0},
		{name="air", prob=254, param2=0},
		{name="air", prob=254, param2=0},
		{name="air", prob=254, param2=0},
		{name="air", prob=254, param2=0},
		{name="air", prob=254, param2=0},
		{name="air", prob=254, param2=0},
		{name="air", prob=254, param2=0},
		{name="air", prob=254, param2=0},
		{name="air", prob=254, param2=0},
		{name="air", prob=254, param2=0},
		{name="air", prob=254, param2=0},
		{name="air", prob=254, param2=0},
		{name="air", prob=254, param2=0},
		{name="default:glass", prob=254, param2=0},

		-- z=5, y=7
		{name="default:glass", prob=254, param2=0},
		{name="air", prob=254, param2=0},
		{name="air", prob=254, param2=0},
		{name="air", prob=254, param2=0},
		{name="air", prob=254, param2=0},
		{name="air", prob=254, param2=0},
		{name="air", prob=254, param2=0},
		{name="air", prob=254, param2=0},
		{name="air", prob=254, param2=0},
		{name="air", prob=254, param2=0},
		{name="air", prob=254, param2=0},
		{name="air", prob=254, param2=0},
		{name="air", prob=254, param2=0},
		{name="air", prob=254, param2=0},
		{name="air", prob=254, param2=0},
		{name="air", prob=254, param2=0},
		{name="default:glass", prob=254, param2=0},

		-- z=5, y=8
		{name="default:glass", prob=254, param2=0},
		{name="air", prob=254, param2=0},
		{name="air", prob=254, param2=0},
		{name="air", prob=254, param2=0},
		{name="air", prob=254, param2=0},
		{name="air", prob=254, param2=0},
		{name="air", prob=254, param2=0},
		{name="air", prob=254, param2=0},
		{name="air", prob=254, param2=0},
		{name="air", prob=254, param2=0},
		{name="air", prob=254, param2=0},
		{name="air", prob=254, param2=0},
		{name="air", prob=254, param2=0},
		{name="air", prob=254, param2=0},
		{name="air", prob=254, param2=0},
		{name="air", prob=254, param2=0},
		{name="default:stonebrick", prob=254, param2=3},

		-- z=5, y=9
		{name="default:stonebrick", prob=254, param2=3},
		{name="stairs:slab_stonebrick", prob=254, param2=21},
		{name="air", prob=254, param2=0},
		{name="air", prob=254, param2=0},
		{name="air", prob=254, param2=0},
		{name="air", prob=254, param2=0},
		{name="air", prob=254, param2=0},
		{name="air", prob=254, param2=0},
		{name="stairs:slab_stonebrick", prob=254, param2=21},
		{name="air", prob=254, param2=0},
		{name="air", prob=254, param2=0},
		{name="air", prob=254, param2=0},
		{name="air", prob=254, param2=0},
		{name="air", prob=254, param2=0},
		{name="air", prob=254, param2=0},
		{name="stairs:slab_stonebrick", prob=254, param2=21},
		{name="default:stonebrick", prob=254, param2=3},

		-- z=5, y=10
		{name="default:stonebrick", prob=254, param2=3},
		{name="default:stonebrick", prob=254, param2=3},
		{name="default:wood", prob=254, param2=3},
		{name="default:wood", prob=254, param2=3},
		{name="default:wood", prob=254, param2=3},
		{name="default:wood", prob=254, param2=3},
		{name="default:wood", prob=254, param2=3},
		{name="default:wood", prob=254, param2=3},
		{name="default:stonebrick", prob=254, param2=3},
		{name="default:wood", prob=254, param2=3},
		{name="default:wood", prob=254, param2=3},
		{name="default:wood", prob=254, param2=3},
		{name="default:wood", prob=254, param2=3},
		{name="default:wood", prob=254, param2=3},
		{name="default:wood", prob=254, param2=3},
		{name="default:stonebrick", prob=254, param2=3},
		{name="default:stonebrick", prob=254, param2=3},

		-- z=5, y=11
		{name="default:stonebrick", prob=254, param2=3},
		{name="default:stonebrick", prob=254, param2=3},
		{name="default:stonebrick", prob=254, param2=3},
		{name="default:stonebrick", prob=254, param2=3},
		{name="default:stonebrick", prob=254, param2=3},
		{name="default:stonebrick", prob=254, param2=3},
		{name="default:stonebrick", prob=254, param2=3},
		{name="default:stonebrick", prob=254, param2=3},
		{name="default:stonebrick", prob=254, param2=3},
		{name="default:stonebrick", prob=254, param2=3},
		{name="default:stonebrick", prob=254, param2=3},
		{name="default:stonebrick", prob=254, param2=3},
		{name="default:stonebrick", prob=254, param2=3},
		{name="default:stonebrick", prob=254, param2=3},
		{name="default:stonebrick", prob=254, param2=3},
		{name="default:stonebrick", prob=254, param2=3},
		{name="default:stonebrick", prob=254, param2=3},

		-- z=5, y=12
		{name="stairs:stair_stonebrick", prob=254, param2=0},
		{name="stairs:stair_stonebrick", prob=254, param2=0},
		{name="stairs:stair_stonebrick", prob=254, param2=0},
		{name="stairs:stair_stonebrick", prob=254, param2=0},
		{name="stairs:stair_stonebrick", prob=254, param2=0},
		{name="stairs:stair_stonebrick", prob=254, param2=0},
		{name="stairs:stair_stonebrick", prob=254, param2=0},
		{name="stairs:stair_stonebrick", prob=254, param2=0},
		{name="stairs:stair_stonebrick", prob=254, param2=0},
		{name="stairs:stair_stonebrick", prob=254, param2=0},
		{name="stairs:stair_stonebrick", prob=254, param2=0},
		{name="stairs:stair_stonebrick", prob=254, param2=0},
		{name="stairs:stair_stonebrick", prob=254, param2=0},
		{name="stairs:stair_stonebrick", prob=254, param2=0},
		{name="stairs:stair_stonebrick", prob=254, param2=0},
		{name="stairs:stair_stonebrick", prob=254, param2=0},
		{name="stairs:stair_stonebrick", prob=254, param2=0},

		-- z=5, y=13
		{name="air", prob=254, param2=0},
		{name="air", prob=254, param2=0},
		{name="air", prob=254, param2=0},
		{name="air", prob=254, param2=0},
		{name="air", prob=254, param2=0},
		{name="air", prob=254, param2=0},
		{name="air", prob=254, param2=0},
		{name="air", prob=254, param2=0},
		{name="air", prob=254, param2=0},
		{name="air", prob=254, param2=0},
		{name="air", prob=254, param2=0},
		{name="air", prob=254, param2=0},
		{name="air", prob=254, param2=0},
		{name="air", prob=254, param2=0},
		{name="air", prob=254, param2=0},
		{name="air", prob=254, param2=0},
		{name="air", prob=254, param2=0},

		-- z=5, y=14
		{name="air", prob=254, param2=0},
		{name="air", prob=254, param2=0},
		{name="air", prob=254, param2=0},
		{name="air", prob=254, param2=0},
		{name="air", prob=254, param2=0},
		{name="air", prob=254, param2=0},
		{name="air", prob=254, param2=0},
		{name="air", prob=254, param2=0},
		{name="air", prob=254, param2=0},
		{name="air", prob=254, param2=0},
		{name="air", prob=254, param2=0},
		{name="air", prob=254, param2=0},
		{name="air", prob=254, param2=0},
		{name="air", prob=254, param2=0},
		{name="air", prob=254, param2=0},
		{name="air", prob=254, param2=0},
		{name="air", prob=254, param2=0},

		-- z=5, y=15
		{name="air", prob=254, param2=0},
		{name="air", prob=254, param2=0},
		{name="air", prob=254, param2=0},
		{name="air", prob=254, param2=0},
		{name="air", prob=254, param2=0},
		{name="air", prob=254, param2=0},
		{name="air", prob=254, param2=0},
		{name="air", prob=254, param2=0},
		{name="air", prob=254, param2=0},
		{name="air", prob=254, param2=0},
		{name="air", prob=254, param2=0},
		{name="air", prob=254, param2=0},
		{name="air", prob=254, param2=0},
		{name="air", prob=254, param2=0},
		{name="air", prob=254, param2=0},
		{name="air", prob=254, param2=0},
		{name="air", prob=254, param2=0},

		-- z=6, y=0
		{name="default:stonebrick", prob=254, param2=3},
		{name="wool:red", prob=254, param2=0},
		{name="wool:yellow", prob=254, param2=0},
		{name="wool:yellow", prob=254, param2=0},
		{name="wool:yellow", prob=254, param2=0},
		{name="wool:yellow", prob=254, param2=0},
		{name="wool:yellow", prob=254, param2=0},
		{name="wool:yellow", prob=254, param2=0},
		{name="wool:yellow", prob=254, param2=0},
		{name="wool:yellow", prob=254, param2=0},
		{name="wool:yellow", prob=254, param2=0},
		{name="wool:yellow", prob=254, param2=0},
		{name="wool:red", prob=254, param2=0},
		{name="wool:yellow", prob=254, param2=0},
		{name="wool:yellow", prob=254, param2=0},
		{name="wool:yellow", prob=254, param2=0},
		{name="default:stonebrick", prob=254, param2=3},

		-- z=6, y=1
		{name="default:glass", prob=254, param2=0},
		{name="air", prob=254, param2=0},
		{name="stairs:stair_wood", prob=254, param2=3},
		{name="air", prob=254, param2=0},
		{name="stairs:stair_wood", prob=254, param2=3},
		{name="air", prob=254, param2=0},
		{name="stairs:stair_wood", prob=254, param2=3},
		{name="air", prob=254, param2=0},
		{name="stairs:stair_wood", prob=254, param2=3},
		{name="air", prob=254, param2=0},
		{name="stairs:stair_wood", prob=254, param2=3},
		{name="air", prob=254, param2=0},
		{name="air", prob=254, param2=0},
		{name="air", prob=254, param2=0},
		{name="air", prob=254, param2=0},
		{name="air", prob=254, param2=0},
		{name="default:stonebrick", prob=254, param2=3},

		-- z=6, y=2
		{name="default:glass", prob=254, param2=0},
		{name="air", prob=254, param2=0},
		{name="air", prob=254, param2=0},
		{name="air", prob=254, param2=0},
		{name="air", prob=254, param2=0},
		{name="air", prob=254, param2=0},
		{name="air", prob=254, param2=0},
		{name="air", prob=254, param2=0},
		{name="air", prob=254, param2=0},
		{name="air", prob=254, param2=0},
		{name="air", prob=254, param2=0},
		{name="air", prob=254, param2=0},
		{name="air", prob=254, param2=0},
		{name="air", prob=254, param2=0},
		{name="air", prob=254, param2=0},
		{name="air", prob=254, param2=0},
		{name="default:stonebrick", prob=254, param2=3},

		-- z=6, y=3
		{name="default:glass", prob=254, param2=0},
		{name="air", prob=254, param2=0},
		{name="air", prob=254, param2=0},
		{name="air", prob=254, param2=0},
		{name="air", prob=254, param2=0},
		{name="air", prob=254, param2=0},
		{name="air", prob=254, param2=0},
		{name="air", prob=254, param2=0},
		{name="air", prob=254, param2=0},
		{name="air", prob=254, param2=0},
		{name="air", prob=254, param2=0},
		{name="air", prob=254, param2=0},
		{name="air", prob=254, param2=0},
		{name="air", prob=254, param2=0},
		{name="air", prob=254, param2=0},
		{name="air", prob=254, param2=0},
		{name="wool:red", prob=254, param2=0},

		-- z=6, y=4
		{name="default:glass", prob=254, param2=0},
		{name="air", prob=254, param2=0},
		{name="air", prob=254, param2=0},
		{name="air", prob=254, param2=0},
		{name="air", prob=254, param2=0},
		{name="air", prob=254, param2=0},
		{name="air", prob=254, param2=0},
		{name="air", prob=254, param2=0},
		{name="air", prob=254, param2=0},
		{name="air", prob=254, param2=0},
		{name="air", prob=254, param2=0},
		{name="air", prob=254, param2=0},
		{name="air", prob=254, param2=0},
		{name="air", prob=254, param2=0},
		{name="air", prob=254, param2=0},
		{name="default:fence_wood", prob=254, param2=0},
		{name="wool:yellow", prob=254, param2=0},

		-- z=6, y=5
		{name="stairs:stair_stonebrick", prob=254, param2=22},
		{name="air", prob=254, param2=0},
		{name="air", prob=254, param2=0},
		{name="air", prob=254, param2=0},
		{name="air", prob=254, param2=0},
		{name="air", prob=254, param2=0},
		{name="air", prob=254, param2=0},
		{name="air", prob=254, param2=0},
		{name="air", prob=254, param2=0},
		{name="air", prob=254, param2=0},
		{name="air", prob=254, param2=0},
		{name="air", prob=254, param2=0},
		{name="air", prob=254, param2=0},
		{name="air", prob=254, param2=0},
		{name="air", prob=254, param2=0},
		{name="default:torch_wall", prob=254, param2=1},
		{name="default:stonebrick", prob=254, param2=3},

		-- z=6, y=6
		{name="default:stonebrick", prob=254, param2=3},
		{name="air", prob=254, param2=0},
		{name="air", prob=254, param2=0},
		{name="air", prob=254, param2=0},
		{name="air", prob=254, param2=0},
		{name="air", prob=254, param2=0},
		{name="air", prob=254, param2=0},
		{name="air", prob=254, param2=0},
		{name="air", prob=254, param2=0},
		{name="air", prob=254, param2=0},
		{name="air", prob=254, param2=0},
		{name="air", prob=254, param2=0},
		{name="air", prob=254, param2=0},
		{name="air", prob=254, param2=0},
		{name="air", prob=254, param2=0},
		{name="air", prob=254, param2=0},
		{name="default:stonebrick", prob=254, param2=3},

		-- z=6, y=7
		{name="default:glass", prob=254, param2=0},
		{name="air", prob=254, param2=0},
		{name="air", prob=254, param2=0},
		{name="air", prob=254, param2=0},
		{name="air", prob=254, param2=0},
		{name="air", prob=254, param2=0},
		{name="air", prob=254, param2=0},
		{name="air", prob=254, param2=0},
		{name="air", prob=254, param2=0},
		{name="air", prob=254, param2=0},
		{name="air", prob=254, param2=0},
		{name="air", prob=254, param2=0},
		{name="air", prob=254, param2=0},
		{name="air", prob=254, param2=0},
		{name="air", prob=254, param2=0},
		{name="air", prob=254, param2=0},
		{name="default:stonebrick", prob=254, param2=3},

		-- z=6, y=8
		{name="default:glass", prob=254, param2=0},
		{name="air", prob=254, param2=0},
		{name="air", prob=254, param2=0},
		{name="air", prob=254, param2=0},
		{name="air", prob=254, param2=0},
		{name="air", prob=254, param2=0},
		{name="air", prob=254, param2=0},
		{name="air", prob=254, param2=0},
		{name="air", prob=254, param2=0},
		{name="air", prob=254, param2=0},
		{name="air", prob=254, param2=0},
		{name="air", prob=254, param2=0},
		{name="air", prob=254, param2=0},
		{name="air", prob=254, param2=0},
		{name="air", prob=254, param2=0},
		{name="air", prob=254, param2=0},
		{name="default:stonebrick", prob=254, param2=3},

		-- z=6, y=9
		{name="default:glass", prob=254, param2=0},
		{name="stairs:slab_stonebrick", prob=254, param2=21},
		{name="air", prob=254, param2=0},
		{name="air", prob=254, param2=0},
		{name="air", prob=254, param2=0},
		{name="air", prob=254, param2=0},
		{name="air", prob=254, param2=0},
		{name="air", prob=254, param2=0},
		{name="air", prob=254, param2=0},
		{name="air", prob=254, param2=0},
		{name="air", prob=254, param2=0},
		{name="air", prob=254, param2=0},
		{name="air", prob=254, param2=0},
		{name="air", prob=254, param2=0},
		{name="air", prob=254, param2=0},
		{name="stairs:slab_stonebrick", prob=254, param2=21},
		{name="default:stonebrick", prob=254, param2=3},

		-- z=6, y=10
		{name="default:stonebrick", prob=254, param2=3},
		{name="default:wood", prob=254, param2=3},
		{name="default:wood", prob=254, param2=3},
		{name="default:wood", prob=254, param2=3},
		{name="default:wood", prob=254, param2=3},
		{name="default:wood", prob=254, param2=3},
		{name="default:wood", prob=254, param2=3},
		{name="default:wood", prob=254, param2=3},
		{name="default:wood", prob=254, param2=3},
		{name="default:wood", prob=254, param2=3},
		{name="default:wood", prob=254, param2=3},
		{name="default:wood", prob=254, param2=3},
		{name="default:wood", prob=254, param2=3},
		{name="default:wood", prob=254, param2=3},
		{name="default:wood", prob=254, param2=3},
		{name="default:wood", prob=254, param2=3},
		{name="default:stonebrick", prob=254, param2=3},

		-- z=6, y=11
		{name="default:stonebrick", prob=254, param2=3},
		{name="default:stonebrick", prob=254, param2=3},
		{name="default:stonebrick", prob=254, param2=3},
		{name="default:stonebrick", prob=254, param2=3},
		{name="default:stonebrick", prob=254, param2=3},
		{name="default:stonebrick", prob=254, param2=3},
		{name="default:stonebrick", prob=254, param2=3},
		{name="default:stonebrick", prob=254, param2=3},
		{name="default:stonebrick", prob=254, param2=3},
		{name="default:stonebrick", prob=254, param2=3},
		{name="default:stonebrick", prob=254, param2=3},
		{name="default:stonebrick", prob=254, param2=3},
		{name="default:stonebrick", prob=254, param2=3},
		{name="default:stonebrick", prob=254, param2=3},
		{name="default:stonebrick", prob=254, param2=3},
		{name="default:stonebrick", prob=254, param2=3},
		{name="default:stonebrick", prob=254, param2=3},

		-- z=6, y=12
		{name="default:stonebrick", prob=254, param2=3},
		{name="default:stonebrick", prob=254, param2=3},
		{name="default:stonebrick", prob=254, param2=3},
		{name="default:stonebrick", prob=254, param2=3},
		{name="default:stonebrick", prob=254, param2=3},
		{name="default:stonebrick", prob=254, param2=3},
		{name="default:stonebrick", prob=254, param2=3},
		{name="default:stonebrick", prob=254, param2=3},
		{name="default:stonebrick", prob=254, param2=3},
		{name="default:stonebrick", prob=254, param2=3},
		{name="default:stonebrick", prob=254, param2=3},
		{name="default:stonebrick", prob=254, param2=3},
		{name="default:stonebrick", prob=254, param2=3},
		{name="default:stonebrick", prob=254, param2=3},
		{name="default:stonebrick", prob=254, param2=3},
		{name="default:stonebrick", prob=254, param2=3},
		{name="default:stonebrick", prob=254, param2=3},

		-- z=6, y=13
		{name="air", prob=254, param2=0},
		{name="air", prob=254, param2=0},
		{name="air", prob=254, param2=0},
		{name="air", prob=254, param2=0},
		{name="air", prob=254, param2=0},
		{name="air", prob=254, param2=0},
		{name="air", prob=254, param2=0},
		{name="air", prob=254, param2=0},
		{name="air", prob=254, param2=0},
		{name="air", prob=254, param2=0},
		{name="air", prob=254, param2=0},
		{name="air", prob=254, param2=0},
		{name="air", prob=254, param2=0},
		{name="air", prob=254, param2=0},
		{name="air", prob=254, param2=0},
		{name="air", prob=254, param2=0},
		{name="air", prob=254, param2=0},

		-- z=6, y=14
		{name="air", prob=254, param2=0},
		{name="air", prob=254, param2=0},
		{name="air", prob=254, param2=0},
		{name="air", prob=254, param2=0},
		{name="air", prob=254, param2=0},
		{name="air", prob=254, param2=0},
		{name="air", prob=254, param2=0},
		{name="air", prob=254, param2=0},
		{name="air", prob=254, param2=0},
		{name="air", prob=254, param2=0},
		{name="air", prob=254, param2=0},
		{name="air", prob=254, param2=0},
		{name="air", prob=254, param2=0},
		{name="air", prob=254, param2=0},
		{name="air", prob=254, param2=0},
		{name="air", prob=254, param2=0},
		{name="air", prob=254, param2=0},

		-- z=6, y=15
		{name="air", prob=254, param2=0},
		{name="air", prob=254, param2=0},
		{name="air", prob=254, param2=0},
		{name="air", prob=254, param2=0},
		{name="air", prob=254, param2=0},
		{name="air", prob=254, param2=0},
		{name="air", prob=254, param2=0},
		{name="air", prob=254, param2=0},
		{name="air", prob=254, param2=0},
		{name="air", prob=254, param2=0},
		{name="air", prob=254, param2=0},
		{name="air", prob=254, param2=0},
		{name="air", prob=254, param2=0},
		{name="air", prob=254, param2=0},
		{name="air", prob=254, param2=0},
		{name="air", prob=254, param2=0},
		{name="air", prob=254, param2=0},

		-- z=7, y=0
		{name="wool:red", prob=254, param2=0},
		{name="wool:red", prob=254, param2=0},
		{name="wool:red", prob=254, param2=0},
		{name="wool:red", prob=254, param2=0},
		{name="wool:red", prob=254, param2=0},
		{name="wool:red", prob=254, param2=0},
		{name="wool:red", prob=254, param2=0},
		{name="wool:red", prob=254, param2=0},
		{name="wool:red", prob=254, param2=0},
		{name="wool:red", prob=254, param2=0},
		{name="wool:red", prob=254, param2=0},
		{name="wool:red", prob=254, param2=0},
		{name="wool:red", prob=254, param2=0},
		{name="wool:red", prob=254, param2=0},
		{name="wool:red", prob=254, param2=0},
		{name="wool:red", prob=254, param2=0},
		{name="default:stonebrick", prob=254, param2=3},

		-- z=7, y=1
		{name="doors:door_glass_b", prob=254, param2=1},
		{name="air", prob=254, param2=0},
		{name="air", prob=254, param2=0},
		{name="air", prob=254, param2=0},
		{name="air", prob=254, param2=0},
		{name="air", prob=254, param2=0},
		{name="air", prob=254, param2=0},
		{name="air", prob=254, param2=0},
		{name="air", prob=254, param2=0},
		{name="air", prob=254, param2=0},
		{name="air", prob=254, param2=0},
		{name="air", prob=254, param2=0},
		{name="air", prob=254, param2=0},
		{name="air", prob=254, param2=0},
		{name="stairs:stair_wood", prob=254, param2=21},
		{name="cottages:wool_tent", prob=254, param2=1},
		{name="default:stonebrick", prob=254, param2=3},

		-- z=7, y=2
		{name="doors:hidden", prob=254, param2=0},
		{name="air", prob=254, param2=0},
		{name="air", prob=254, param2=0},
		{name="air", prob=254, param2=0},
		{name="air", prob=254, param2=0},
		{name="air", prob=254, param2=0},
		{name="air", prob=254, param2=0},
		{name="air", prob=254, param2=0},
		{name="air", prob=254, param2=0},
		{name="air", prob=254, param2=0},
		{name="air", prob=254, param2=0},
		{name="air", prob=254, param2=0},
		{name="air", prob=254, param2=0},
		{name="air", prob=254, param2=0},
		{name="air", prob=254, param2=0},
		{name="air", prob=254, param2=0},
		{name="wool:yellow", prob=254, param2=0},

		-- z=7, y=3
		{name="default:glass", prob=254, param2=0},
		{name="air", prob=254, param2=0},
		{name="air", prob=254, param2=0},
		{name="air", prob=254, param2=0},
		{name="air", prob=254, param2=0},
		{name="air", prob=254, param2=0},
		{name="air", prob=254, param2=0},
		{name="air", prob=254, param2=0},
		{name="air", prob=254, param2=0},
		{name="air", prob=254, param2=0},
		{name="air", prob=254, param2=0},
		{name="air", prob=254, param2=0},
		{name="air", prob=254, param2=0},
		{name="air", prob=254, param2=0},
		{name="air", prob=254, param2=0},
		{name="air", prob=254, param2=0},
		{name="wool:yellow", prob=254, param2=0},

		-- z=7, y=4
		{name="default:glass", prob=254, param2=0},
		{name="air", prob=254, param2=0},
		{name="air", prob=254, param2=0},
		{name="air", prob=254, param2=0},
		{name="air", prob=254, param2=0},
		{name="air", prob=254, param2=0},
		{name="air", prob=254, param2=0},
		{name="air", prob=254, param2=0},
		{name="air", prob=254, param2=0},
		{name="air", prob=254, param2=0},
		{name="air", prob=254, param2=0},
		{name="air", prob=254, param2=0},
		{name="air", prob=254, param2=0},
		{name="air", prob=254, param2=0},
		{name="air", prob=254, param2=0},
		{name="air", prob=254, param2=0},
		{name="wool:red", prob=254, param2=0},

		-- z=7, y=5
		{name="default:glass", prob=254, param2=0},
		{name="air", prob=254, param2=0},
		{name="air", prob=254, param2=0},
		{name="air", prob=254, param2=0},
		{name="air", prob=254, param2=0},
		{name="air", prob=254, param2=0},
		{name="air", prob=254, param2=0},
		{name="air", prob=254, param2=0},
		{name="air", prob=254, param2=0},
		{name="air", prob=254, param2=0},
		{name="air", prob=254, param2=0},
		{name="air", prob=254, param2=0},
		{name="air", prob=254, param2=0},
		{name="air", prob=254, param2=0},
		{name="air", prob=254, param2=0},
		{name="air", prob=254, param2=0},
		{name="wool:red", prob=254, param2=0},

		-- z=7, y=6
		{name="stairs:stair_stonebrick", prob=254, param2=22},
		{name="air", prob=254, param2=0},
		{name="air", prob=254, param2=0},
		{name="air", prob=254, param2=0},
		{name="air", prob=254, param2=0},
		{name="air", prob=254, param2=0},
		{name="air", prob=254, param2=0},
		{name="air", prob=254, param2=0},
		{name="air", prob=254, param2=0},
		{name="air", prob=254, param2=0},
		{name="air", prob=254, param2=0},
		{name="air", prob=254, param2=0},
		{name="air", prob=254, param2=0},
		{name="air", prob=254, param2=0},
		{name="air", prob=254, param2=0},
		{name="air", prob=254, param2=0},
		{name="wool:yellow", prob=254, param2=0},

		-- z=7, y=7
		{name="default:stonebrick", prob=254, param2=3},
		{name="air", prob=254, param2=0},
		{name="air", prob=254, param2=0},
		{name="air", prob=254, param2=0},
		{name="air", prob=254, param2=0},
		{name="air", prob=254, param2=0},
		{name="air", prob=254, param2=0},
		{name="default:torch_ceiling", prob=254, param2=0},
		{name="default:torch_ceiling", prob=254, param2=0},
		{name="default:torch_ceiling", prob=254, param2=0},
		{name="air", prob=254, param2=0},
		{name="air", prob=254, param2=0},
		{name="air", prob=254, param2=0},
		{name="air", prob=254, param2=0},
		{name="air", prob=254, param2=0},
		{name="air", prob=254, param2=0},
		{name="default:stonebrick", prob=254, param2=3},

		-- z=7, y=8
		{name="default:glass", prob=254, param2=0},
		{name="air", prob=254, param2=0},
		{name="air", prob=254, param2=0},
		{name="air", prob=254, param2=0},
		{name="air", prob=254, param2=0},
		{name="air", prob=254, param2=0},
		{name="air", prob=254, param2=0},
		{name="default:fence_wood", prob=254, param2=0},
		{name="default:fence_wood", prob=254, param2=0},
		{name="default:fence_wood", prob=254, param2=0},
		{name="air", prob=254, param2=0},
		{name="air", prob=254, param2=0},
		{name="air", prob=254, param2=0},
		{name="air", prob=254, param2=0},
		{name="air", prob=254, param2=0},
		{name="air", prob=254, param2=0},
		{name="default:stonebrick", prob=254, param2=3},

		-- z=7, y=9
		{name="default:glass", prob=254, param2=0},
		{name="stairs:slab_stonebrick", prob=254, param2=21},
		{name="air", prob=254, param2=0},
		{name="air", prob=254, param2=0},
		{name="air", prob=254, param2=0},
		{name="air", prob=254, param2=0},
		{name="air", prob=254, param2=0},
		{name="default:torch_wall", prob=254, param2=1},
		{name="default:fence_wood", prob=254, param2=0},
		{name="default:torch_wall", prob=254, param2=1},
		{name="air", prob=254, param2=0},
		{name="air", prob=254, param2=0},
		{name="air", prob=254, param2=0},
		{name="air", prob=254, param2=0},
		{name="air", prob=254, param2=0},
		{name="stairs:slab_stonebrick", prob=254, param2=21},
		{name="default:stonebrick", prob=254, param2=3},

		-- z=7, y=10
		{name="default:stonebrick", prob=254, param2=3},
		{name="default:wood", prob=254, param2=3},
		{name="default:wood", prob=254, param2=3},
		{name="default:wood", prob=254, param2=3},
		{name="default:wood", prob=254, param2=3},
		{name="default:wood", prob=254, param2=3},
		{name="default:wood", prob=254, param2=3},
		{name="default:wood", prob=254, param2=3},
		{name="default:wood", prob=254, param2=3},
		{name="default:wood", prob=254, param2=3},
		{name="default:wood", prob=254, param2=3},
		{name="default:wood", prob=254, param2=3},
		{name="default:wood", prob=254, param2=3},
		{name="default:wood", prob=254, param2=3},
		{name="default:wood", prob=254, param2=3},
		{name="default:wood", prob=254, param2=3},
		{name="default:stonebrick", prob=254, param2=3},

		-- z=7, y=11
		{name="default:stonebrick", prob=254, param2=3},
		{name="default:stonebrick", prob=254, param2=3},
		{name="default:stonebrick", prob=254, param2=3},
		{name="default:stonebrick", prob=254, param2=3},
		{name="default:stonebrick", prob=254, param2=3},
		{name="default:stonebrick", prob=254, param2=3},
		{name="default:stonebrick", prob=254, param2=3},
		{name="default:stonebrick", prob=254, param2=3},
		{name="default:stonebrick", prob=254, param2=3},
		{name="default:stonebrick", prob=254, param2=3},
		{name="default:stonebrick", prob=254, param2=3},
		{name="default:stonebrick", prob=254, param2=3},
		{name="default:stonebrick", prob=254, param2=3},
		{name="default:stonebrick", prob=254, param2=3},
		{name="default:stonebrick", prob=254, param2=3},
		{name="default:stonebrick", prob=254, param2=3},
		{name="default:stonebrick", prob=254, param2=3},

		-- z=7, y=12
		{name="default:stonebrick", prob=254, param2=3},
		{name="default:stonebrick", prob=254, param2=3},
		{name="default:stonebrick", prob=254, param2=3},
		{name="default:stonebrick", prob=254, param2=3},
		{name="default:stonebrick", prob=254, param2=3},
		{name="default:stonebrick", prob=254, param2=3},
		{name="default:stonebrick", prob=254, param2=3},
		{name="default:stonebrick", prob=254, param2=3},
		{name="default:stonebrick", prob=254, param2=3},
		{name="default:stonebrick", prob=254, param2=3},
		{name="default:stonebrick", prob=254, param2=3},
		{name="default:stonebrick", prob=254, param2=3},
		{name="default:stonebrick", prob=254, param2=3},
		{name="default:stonebrick", prob=254, param2=3},
		{name="default:stonebrick", prob=254, param2=3},
		{name="default:stonebrick", prob=254, param2=3},
		{name="default:stonebrick", prob=254, param2=3},

		-- z=7, y=13
		{name="air", prob=254, param2=0},
		{name="air", prob=254, param2=0},
		{name="air", prob=254, param2=0},
		{name="air", prob=254, param2=0},
		{name="air", prob=254, param2=0},
		{name="air", prob=254, param2=0},
		{name="air", prob=254, param2=0},
		{name="air", prob=254, param2=0},
		{name="air", prob=254, param2=0},
		{name="air", prob=254, param2=0},
		{name="air", prob=254, param2=0},
		{name="air", prob=254, param2=0},
		{name="air", prob=254, param2=0},
		{name="air", prob=254, param2=0},
		{name="air", prob=254, param2=0},
		{name="air", prob=254, param2=0},
		{name="air", prob=254, param2=0},

		-- z=7, y=14
		{name="air", prob=254, param2=0},
		{name="air", prob=254, param2=0},
		{name="air", prob=254, param2=0},
		{name="air", prob=254, param2=0},
		{name="air", prob=254, param2=0},
		{name="air", prob=254, param2=0},
		{name="air", prob=254, param2=0},
		{name="air", prob=254, param2=0},
		{name="air", prob=254, param2=0},
		{name="air", prob=254, param2=0},
		{name="air", prob=254, param2=0},
		{name="air", prob=254, param2=0},
		{name="air", prob=254, param2=0},
		{name="air", prob=254, param2=0},
		{name="air", prob=254, param2=0},
		{name="air", prob=254, param2=0},
		{name="air", prob=254, param2=0},

		-- z=7, y=15
		{name="air", prob=254, param2=0},
		{name="air", prob=254, param2=0},
		{name="air", prob=254, param2=0},
		{name="air", prob=254, param2=0},
		{name="air", prob=254, param2=0},
		{name="air", prob=254, param2=0},
		{name="air", prob=254, param2=0},
		{name="air", prob=254, param2=0},
		{name="air", prob=254, param2=0},
		{name="air", prob=254, param2=0},
		{name="air", prob=254, param2=0},
		{name="air", prob=254, param2=0},
		{name="air", prob=254, param2=0},
		{name="air", prob=254, param2=0},
		{name="air", prob=254, param2=0},
		{name="air", prob=254, param2=0},
		{name="air", prob=254, param2=0},

		-- z=8, y=0
		{name="wool:red", prob=254, param2=0},
		{name="wool:red", prob=254, param2=0},
		{name="wool:red", prob=254, param2=0},
		{name="wool:red", prob=254, param2=0},
		{name="wool:red", prob=254, param2=0},
		{name="wool:red", prob=254, param2=0},
		{name="wool:red", prob=254, param2=0},
		{name="wool:red", prob=254, param2=0},
		{name="wool:red", prob=254, param2=0},
		{name="wool:red", prob=254, param2=0},
		{name="wool:red", prob=254, param2=0},
		{name="wool:red", prob=254, param2=0},
		{name="wool:red", prob=254, param2=0},
		{name="wool:red", prob=254, param2=0},
		{name="wool:red", prob=254, param2=0},
		{name="wool:red", prob=254, param2=0},
		{name="default:stonebrick", prob=254, param2=3},

		-- z=8, y=1
		{name="doors:door_glass_a", prob=254, param2=1},
		{name="air", prob=254, param2=0},
		{name="air", prob=254, param2=0},
		{name="air", prob=254, param2=0},
		{name="air", prob=254, param2=0},
		{name="air", prob=254, param2=0},
		{name="air", prob=254, param2=0},
		{name="air", prob=254, param2=0},
		{name="air", prob=254, param2=0},
		{name="air", prob=254, param2=0},
		{name="air", prob=254, param2=0},
		{name="air", prob=254, param2=0},
		{name="air", prob=254, param2=0},
		{name="air", prob=254, param2=0},
		{name="stairs:stair_wood", prob=254, param2=21},
		{name="air", prob=254, param2=0},
		{name="default:stonebrick", prob=254, param2=3},

		-- z=8, y=2
		{name="doors:hidden", prob=254, param2=1},
		{name="air", prob=254, param2=0},
		{name="air", prob=254, param2=0},
		{name="air", prob=254, param2=0},
		{name="air", prob=254, param2=0},
		{name="air", prob=254, param2=0},
		{name="air", prob=254, param2=0},
		{name="air", prob=254, param2=0},
		{name="air", prob=254, param2=0},
		{name="air", prob=254, param2=0},
		{name="air", prob=254, param2=0},
		{name="air", prob=254, param2=0},
		{name="air", prob=254, param2=0},
		{name="air", prob=254, param2=0},
		{name="air", prob=254, param2=0},
		{name="air", prob=254, param2=0},
		{name="wool:red", prob=254, param2=0},

		-- z=8, y=3
		{name="default:glass", prob=254, param2=0},
		{name="air", prob=254, param2=0},
		{name="air", prob=254, param2=0},
		{name="air", prob=254, param2=0},
		{name="air", prob=254, param2=0},
		{name="air", prob=254, param2=0},
		{name="air", prob=254, param2=0},
		{name="air", prob=254, param2=0},
		{name="air", prob=254, param2=0},
		{name="air", prob=254, param2=0},
		{name="air", prob=254, param2=0},
		{name="air", prob=254, param2=0},
		{name="air", prob=254, param2=0},
		{name="air", prob=254, param2=0},
		{name="air", prob=254, param2=0},
		{name="air", prob=254, param2=0},
		{name="wool:red", prob=254, param2=0},

		-- z=8, y=4
		{name="default:glass", prob=254, param2=0},
		{name="air", prob=254, param2=0},
		{name="air", prob=254, param2=0},
		{name="air", prob=254, param2=0},
		{name="air", prob=254, param2=0},
		{name="air", prob=254, param2=0},
		{name="air", prob=254, param2=0},
		{name="air", prob=254, param2=0},
		{name="air", prob=254, param2=0},
		{name="air", prob=254, param2=0},
		{name="air", prob=254, param2=0},
		{name="air", prob=254, param2=0},
		{name="air", prob=254, param2=0},
		{name="air", prob=254, param2=0},
		{name="air", prob=254, param2=0},
		{name="air", prob=254, param2=0},
		{name="wool:yellow", prob=254, param2=0},

		-- z=8, y=5
		{name="default:glass", prob=254, param2=0},
		{name="air", prob=254, param2=0},
		{name="air", prob=254, param2=0},
		{name="air", prob=254, param2=0},
		{name="air", prob=254, param2=0},
		{name="air", prob=254, param2=0},
		{name="air", prob=254, param2=0},
		{name="air", prob=254, param2=0},
		{name="air", prob=254, param2=0},
		{name="air", prob=254, param2=0},
		{name="air", prob=254, param2=0},
		{name="air", prob=254, param2=0},
		{name="air", prob=254, param2=0},
		{name="air", prob=254, param2=0},
		{name="air", prob=254, param2=0},
		{name="air", prob=254, param2=0},
		{name="wool:yellow", prob=254, param2=0},

		-- z=8, y=6
		{name="stairs:stair_stonebrick", prob=254, param2=20},
		{name="air", prob=254, param2=0},
		{name="air", prob=254, param2=0},
		{name="air", prob=254, param2=0},
		{name="air", prob=254, param2=0},
		{name="air", prob=254, param2=0},
		{name="air", prob=254, param2=0},
		{name="air", prob=254, param2=0},
		{name="air", prob=254, param2=0},
		{name="air", prob=254, param2=0},
		{name="air", prob=254, param2=0},
		{name="air", prob=254, param2=0},
		{name="air", prob=254, param2=0},
		{name="air", prob=254, param2=0},
		{name="air", prob=254, param2=0},
		{name="air", prob=254, param2=0},
		{name="wool:red", prob=254, param2=0},

		-- z=8, y=7
		{name="default:stonebrick", prob=254, param2=3},
		{name="air", prob=254, param2=0},
		{name="air", prob=254, param2=0},
		{name="air", prob=254, param2=0},
		{name="air", prob=254, param2=0},
		{name="air", prob=254, param2=0},
		{name="air", prob=254, param2=0},
		{name="default:torch_ceiling", prob=254, param2=0},
		{name="default:torch_ceiling", prob=254, param2=0},
		{name="default:torch_ceiling", prob=254, param2=0},
		{name="air", prob=254, param2=0},
		{name="air", prob=254, param2=0},
		{name="air", prob=254, param2=0},
		{name="air", prob=254, param2=0},
		{name="air", prob=254, param2=0},
		{name="air", prob=254, param2=0},
		{name="default:stonebrick", prob=254, param2=3},

		-- z=8, y=8
		{name="default:glass", prob=254, param2=0},
		{name="air", prob=254, param2=0},
		{name="air", prob=254, param2=0},
		{name="air", prob=254, param2=0},
		{name="air", prob=254, param2=0},
		{name="air", prob=254, param2=0},
		{name="air", prob=254, param2=0},
		{name="default:fence_wood", prob=254, param2=0},
		{name="default:fence_wood", prob=254, param2=0},
		{name="default:fence_wood", prob=254, param2=0},
		{name="air", prob=254, param2=0},
		{name="air", prob=254, param2=0},
		{name="air", prob=254, param2=0},
		{name="air", prob=254, param2=0},
		{name="air", prob=254, param2=0},
		{name="air", prob=254, param2=0},
		{name="default:stonebrick", prob=254, param2=3},

		-- z=8, y=9
		{name="default:glass", prob=254, param2=0},
		{name="stairs:slab_stonebrick", prob=254, param2=21},
		{name="air", prob=254, param2=0},
		{name="air", prob=254, param2=0},
		{name="air", prob=254, param2=0},
		{name="air", prob=254, param2=0},
		{name="air", prob=254, param2=0},
		{name="default:torch_wall", prob=254, param2=1},
		{name="default:fence_wood", prob=254, param2=0},
		{name="default:torch_wall", prob=254, param2=1},
		{name="air", prob=254, param2=0},
		{name="air", prob=254, param2=0},
		{name="air", prob=254, param2=0},
		{name="air", prob=254, param2=0},
		{name="air", prob=254, param2=0},
		{name="stairs:slab_stonebrick", prob=254, param2=21},
		{name="default:stonebrick", prob=254, param2=3},

		-- z=8, y=10
		{name="default:stonebrick", prob=254, param2=3},
		{name="default:wood", prob=254, param2=3},
		{name="default:wood", prob=254, param2=3},
		{name="default:wood", prob=254, param2=3},
		{name="default:wood", prob=254, param2=3},
		{name="default:wood", prob=254, param2=3},
		{name="default:wood", prob=254, param2=3},
		{name="default:wood", prob=254, param2=3},
		{name="default:wood", prob=254, param2=3},
		{name="default:wood", prob=254, param2=3},
		{name="default:wood", prob=254, param2=3},
		{name="default:wood", prob=254, param2=3},
		{name="default:wood", prob=254, param2=3},
		{name="default:wood", prob=254, param2=3},
		{name="default:wood", prob=254, param2=3},
		{name="default:wood", prob=254, param2=3},
		{name="default:stonebrick", prob=254, param2=3},

		-- z=8, y=11
		{name="default:stonebrick", prob=254, param2=3},
		{name="default:stonebrick", prob=254, param2=3},
		{name="default:stonebrick", prob=254, param2=3},
		{name="default:stonebrick", prob=254, param2=3},
		{name="default:stonebrick", prob=254, param2=3},
		{name="default:stonebrick", prob=254, param2=3},
		{name="default:stonebrick", prob=254, param2=3},
		{name="default:stonebrick", prob=254, param2=3},
		{name="default:stonebrick", prob=254, param2=3},
		{name="default:stonebrick", prob=254, param2=3},
		{name="default:stonebrick", prob=254, param2=3},
		{name="default:stonebrick", prob=254, param2=3},
		{name="default:stonebrick", prob=254, param2=3},
		{name="default:stonebrick", prob=254, param2=3},
		{name="default:stonebrick", prob=254, param2=3},
