schematic = {
	size = {x=11, y=6, z=16},
	yslice_prob = {
		{ypos=0, prob=254},
		{ypos=1, prob=254},
		{ypos=2, prob=254},
		{ypos=3, prob=254},
		{ypos=4, prob=254},
		{ypos=5, prob=254},
	},
	data = {

		-- z=0, y=0
		{name="default:dirt", prob=254, param2=0},
		{name="default:water_source", prob=254, param2=0},
		{name="default:dirt", prob=254, param2=0},
		{name="default:dirt", prob=254, param2=0},
		{name="default:dirt", prob=254, param2=0},
		{name="default:dirt", prob=254, param2=0},
		{name="default:dirt", prob=254, param2=0},
		{name="default:dirt", prob=254, param2=0},
		{name="default:dirt", prob=254, param2=0},
		{name="default:dirt", prob=254, param2=0},
		{name="default:dirt", prob=254, param2=0},

		-- z=0, y=1
		{name="default:dirt", prob=254, param2=0},
		{name="default:water_source", prob=254, param2=0},
		{name="default:dirt", prob=254, param2=0},
		{name="default:dirt", prob=254, param2=0},
		{name="default:dirt", prob=254, param2=0},
		{name="default:dirt", prob=254, param2=0},
		{name="default:dirt", prob=254, param2=0},
		{name="default:dirt", prob=254, param2=0},
		{name="default:dirt", prob=254, param2=0},
		{name="default:dirt", prob=254, param2=0},
		{name="default:dirt", prob=254, param2=0},

		-- z=0, y=2
		{name="cottages:feldweg", prob=254, param2=0},
		{name="cottages:feldweg", prob=254, param2=0},
		{name="default:dirt_with_grass", prob=254, param2=1},
		{name="default:dirt_with_grass", prob=254, param2=1},
		{name="default:dirt_with_grass", prob=254, param2=1},
		{name="default:dirt_with_grass", prob=254, param2=1},
		{name="default:dirt_with_grass", prob=254, param2=1},
		{name="default:dirt_with_grass", prob=254, param2=1},
		{name="default:dirt_with_grass", prob=254, param2=1},
		{name="default:dirt_with_grass", prob=254, param2=1},
		{name="default:tree", prob=254, param2=0},

		-- z=0, y=3
		{name="air", prob=254, param2=0},
		{name="air", prob=254, param2=0},
		{name="air", prob=254, param2=0},
		{name="air", prob=254, param2=0},
		{name="air", prob=254, param2=0},
		{name="air", prob=254, param2=0},
		{name="air", prob=254, param2=0},
		{name="air", prob=254, param2=0},
		{name="air", prob=254, param2=0},
		{name="air", prob=254, param2=0},
		{name="default:leaves", prob=254, param2=0},

		-- z=0, y=4
		{name="air", prob=254, param2=0},
		{name="air", prob=254, param2=0},
		{name="air", prob=254, param2=0},
		{name="air", prob=254, param2=0},
		{name="air", prob=254, param2=0},
		{name="air", prob=254, param2=0},
		{name="air", prob=254, param2=0},
		{name="air", prob=254, param2=0},
		{name="air", prob=254, param2=0},
		{name="air", prob=254, param2=0},
		{name="air", prob=254, param2=0},

		-- z=0, y=5
		{name="air", prob=254, param2=0},
		{name="air", prob=254, param2=0},
		{name="air", prob=254, param2=0},
		{name="air", prob=254, param2=0},
		{name="air", prob=254, param2=0},
		{name="air", prob=254, param2=0},
		{name="air", prob=254, param2=0},
		{name="air", prob=254, param2=0},
		{name="air", prob=254, param2=0},
		{name="air", prob=254, param2=0},
		{name="air", prob=254, param2=0},

		-- z=1, y=0
		{name="default:dirt", prob=254, param2=0},
		{name="default:dirt", prob=254, param2=0},
		{name="default:dirt", prob=254, param2=0},
		{name="default:dirt", prob=254, param2=0},
		{name="default:dirt", prob=254, param2=0},
		{name="default:dirt", prob=254, param2=0},
		{name="default:dirt", prob=254, param2=0},
		{name="default:dirt", prob=254, param2=0},
		{name="default:dirt", prob=254, param2=0},
		{name="default:dirt", prob=254, param2=0},
		{name="default:dirt", prob=254, param2=0},

		-- z=1, y=1
		{name="default:dirt", prob=254, param2=240},
		{name="default:dirt", prob=254, param2=0},
		{name="default:dirt", prob=254, param2=0},
		{name="default:dirt", prob=254, param2=0},
		{name="default:dirt", prob=254, param2=0},
		{name="default:dirt", prob=254, param2=0},
		{name="default:dirt", prob=254, param2=0},
		{name="default:dirt", prob=254, param2=0},
		{name="default:dirt", prob=254, param2=0},
		{name="default:dirt", prob=254, param2=0},
		{name="default:dirt", prob=254, param2=0},

		-- z=1, y=2
		{name="cottages:feldweg", prob=254, param2=0},
		{name="cottages:feldweg", prob=254, param2=0},
		{name="default:water_source", prob=254, param2=0},
		{name="farming:soil_wet", prob=254, param2=0},
		{name="farming:soil_wet", prob=254, param2=0},
		{name="farming:soil_wet", prob=254, param2=0},
		{name="farming:soil_wet", prob=254, param2=0},
		{name="farming:soil_wet", prob=254, param2=0},
		{name="farming:soil_wet", prob=254, param2=0},
		{name="farming:soil_wet", prob=254, param2=0},
		{name="default:tree", prob=254, param2=0},

		-- z=1, y=3
		{name="air", prob=254, param2=0},
		{name="air", prob=254, param2=0},
		{name="air", prob=254, param2=0},
		{name="farming:wheat_1", prob=254, param2=0},
		{name="farming:wheat_1", prob=254, param2=0},
		{name="farming:wheat_1", prob=254, param2=0},
		{name="farming:wheat_1", prob=254, param2=0},
		{name="farming:wheat_1", prob=254, param2=0},
		{name="farming:wheat_1", prob=254, param2=0},
		{name="farming:wheat_1", prob=254, param2=0},
		{name="default:leaves", prob=254, param2=0},

		-- z=1, y=4
		{name="air", prob=254, param2=0},
		{name="air", prob=254, param2=0},
		{name="air", prob=254, param2=0},
		{name="air", prob=254, param2=0},
		{name="air", prob=254, param2=0},
		{name="air", prob=254, param2=0},
		{name="air", prob=254, param2=0},
		{name="air", prob=254, param2=0},
		{name="air", prob=254, param2=0},
		{name="air", prob=254, param2=0},
		{name="air", prob=254, param2=0},

		-- z=1, y=5
		{name="air", prob=254, param2=0},
		{name="air", prob=254, param2=0},
		{name="air", prob=254, param2=0},
		{name="air", prob=254, param2=0},
		{name="air", prob=254, param2=0},
		{name="air", prob=254, param2=0},
		{name="air", prob=254, param2=0},
		{name="air", prob=254, param2=0},
		{name="air", prob=254, param2=0},
		{name="air", prob=254, param2=0},
		{name="air", prob=254, param2=0},

		-- z=2, y=0
		{name="default:dirt", prob=254, param2=0},
		{name="default:dirt", prob=254, param2=0},
		{name="default:dirt", prob=254, param2=0},
		{name="default:dirt", prob=254, param2=0},
		{name="default:dirt", prob=254, param2=0},
		{name="default:dirt", prob=254, param2=0},
		{name="default:dirt", prob=254, param2=0},
		{name="default:dirt", prob=254, param2=0},
		{name="default:dirt", prob=254, param2=0},
		{name="default:dirt", prob=254, param2=0},
		{name="default:dirt", prob=254, param2=0},

		-- z=2, y=1
		{name="default:dirt", prob=254, param2=0},
		{name="default:dirt", prob=254, param2=0},
		{name="default:dirt", prob=254, param2=2},
		{name="default:dirt", prob=254, param2=0},
		{name="default:dirt", prob=254, param2=0},
		{name="default:dirt", prob=254, param2=0},
		{name="default:dirt", prob=254, param2=0},
		{name="default:dirt", prob=254, param2=0},
		{name="default:dirt", prob=254, param2=0},
		{name="default:dirt", prob=254, param2=0},
		{name="default:dirt", prob=254, param2=0},

		-- z=2, y=2
		{name="cottages:feldweg", prob=254, param2=0},
		{name="cottages:feldweg", prob=254, param2=0},
		{name="default:water_source", prob=254, param2=0},
		{name="farming:soil_wet", prob=254, param2=0},
		{name="farming:soil_wet", prob=254, param2=0},
		{name="farming:soil_wet", prob=254, param2=0},
		{name="farming:soil_wet", prob=254, param2=0},
		{name="farming:soil_wet", prob=254, param2=0},
		{name="farming:soil_wet", prob=254, param2=0},
		{name="farming:soil_wet", prob=254, param2=0},
		{name="default:tree", prob=254, param2=0},

		-- z=2, y=3
		{name="air", prob=254, param2=0},
		{name="air", prob=254, param2=0},
		{name="air", prob=254, param2=0},
		{name="farming:wheat_1", prob=254, param2=0},
		{name="farming:wheat_1", prob=254, param2=0},
		{name="farming:wheat_1", prob=254, param2=0},
		{name="farming:wheat_1", prob=254, param2=0},
		{name="farming:wheat_1", prob=254, param2=0},
		{name="farming:wheat_1", prob=254, param2=0},
		{name="farming:wheat_1", prob=254, param2=0},
		{name="default:leaves", prob=254, param2=0},

		-- z=2, y=4
		{name="air", prob=254, param2=0},
		{name="air", prob=254, param2=0},
		{name="air", prob=254, param2=0},
		{name="air", prob=254, param2=0},
		{name="air", prob=254, param2=0},
		{name="air", prob=254, param2=0},
		{name="air", prob=254, param2=0},
		{name="air", prob=254, param2=0},
		{name="air", prob=254, param2=0},
		{name="air", prob=254, param2=0},
		{name="air", prob=254, param2=0},

		-- z=2, y=5
		{name="air", prob=254, param2=0},
		{name="air", prob=254, param2=0},
		{name="air", prob=254, param2=0},
		{name="air", prob=254, param2=0},
		{name="air", prob=254, param2=0},
		{name="air", prob=254, param2=0},
		{name="air", prob=254, param2=0},
		{name="air", prob=254, param2=0},
		{name="air", prob=254, param2=0},
		{name="air", prob=254, param2=0},
		{name="air", prob=254, param2=0},

		-- z=3, y=0
		{name="default:dirt", prob=254, param2=0},
		{name="default:dirt", prob=254, param2=0},
		{name="default:dirt", prob=254, param2=0},
		{name="default:dirt", prob=254, param2=0},
		{name="default:dirt", prob=254, param2=0},
		{name="default:dirt", prob=254, param2=0},
		{name="default:dirt", prob=254, param2=0},
		{name="default:dirt", prob=254, param2=0},
		{name="default:dirt", prob=254, param2=0},
		{name="default:dirt", prob=254, param2=0},
		{name="default:dirt", prob=254, param2=0},

		-- z=3, y=1
		{name="default:dirt", prob=254, param2=0},
		{name="default:dirt", prob=254, param2=0},
		{name="default:dirt", prob=254, param2=3},
		{name="default:dirt", prob=254, param2=0},
		{name="default:dirt", prob=254, param2=0},
		{name="default:dirt", prob=254, param2=0},
		{name="default:dirt", prob=254, param2=0},
		{name="default:dirt", prob=254, param2=0},
		{name="default:dirt", prob=254, param2=0},
		{name="default:dirt", prob=254, param2=0},
		{name="default:dirt", prob=254, param2=0},

		-- z=3, y=2
		{name="cottages:feldweg", prob=254, param2=0},
		{name="cottages:feldweg", prob=254, param2=0},
		{name="default:water_source", prob=254, param2=0},
		{name="farming:soil_wet", prob=254, param2=0},
		{name="farming:soil_wet", prob=254, param2=0},
		{name="farming:soil_wet", prob=254, param2=0},
		{name="farming:soil_wet", prob=254, param2=0},
		{name="farming:soil_wet", prob=254, param2=0},
		{name="farming:soil_wet", prob=254, param2=0},
		{name="farming:soil_wet", prob=254, param2=0},
		{name="default:tree", prob=254, param2=0},

		-- z=3, y=3
		{name="air", prob=254, param2=0},
		{name="air", prob=254, param2=0},
		{name="air", prob=254, param2=0},
		{name="farming:wheat_1", prob=254, param2=0},
		{name="farming:wheat_1", prob=254, param2=0},
		{name="farming:wheat_1", prob=254, param2=0},
		{name="farming:wheat_1", prob=254, param2=0},
		{name="farming:wheat_1", prob=254, param2=0},
		{name="farming:wheat_1", prob=254, param2=0},
		{name="farming:wheat_1", prob=254, param2=0},
		{name="default:leaves", prob=254, param2=0},

		-- z=3, y=4
		{name="air", prob=254, param2=0},
		{name="air", prob=254, param2=0},
		{name="air", prob=254, param2=0},
		{name="air", prob=254, param2=0},
		{name="air", prob=254, param2=0},
		{name="air", prob=254, param2=0},
		{name="air", prob=254, param2=0},
		{name="air", prob=254, param2=0},
		{name="air", prob=254, param2=0},
		{name="air", prob=254, param2=0},
		{name="air", prob=254, param2=0},

		-- z=3, y=5
		{name="air", prob=254, param2=0},
		{name="air", prob=254, param2=0},
		{name="air", prob=254, param2=0},
		{name="air", prob=254, param2=0},
		{name="air", prob=254, param2=0},
		{name="air", prob=254, param2=0},
		{name="air", prob=254, param2=0},
		{name="air", prob=254, param2=0},
		{name="air", prob=254, param2=0},
		{name="air", prob=254, param2=0},
		{name="air", prob=254, param2=0},

		-- z=4, y=0
		{name="default:dirt", prob=254, param2=0},
		{name="default:dirt", prob=254, param2=0},
		{name="default:dirt", prob=254, param2=0},
		{name="default:dirt", prob=254, param2=0},
		{name="default:dirt", prob=254, param2=0},
		{name="default:dirt", prob=254, param2=0},
		{name="default:dirt", prob=254, param2=0},
		{name="default:dirt", prob=254, param2=0},
		{name="default:dirt", prob=254, param2=0},
		{name="default:dirt", prob=254, param2=0},
		{name="default:dirt", prob=254, param2=0},

		-- z=4, y=1
		{name="default:dirt", prob=254, param2=0},
		{name="default:dirt", prob=254, param2=0},
		{name="default:dirt", prob=254, param2=2},
		{name="default:dirt", prob=254, param2=0},
		{name="default:dirt", prob=254, param2=0},
		{name="default:dirt", prob=254, param2=0},
		{name="default:water_source", prob=254, param2=0},
		{name="default:dirt", prob=254, param2=0},
		{name="default:dirt", prob=254, param2=0},
		{name="default:dirt", prob=254, param2=0},
		{name="default:dirt", prob=254, param2=0},

		-- z=4, y=2
		{name="cottages:feldweg", prob=254, param2=0},
		{name="cottages:feldweg", prob=254, param2=0},
		{name="default:water_source", prob=254, param2=0},
		{name="farming:soil_wet", prob=254, param2=0},
		{name="farming:soil_wet", prob=254, param2=0},
		{name="farming:soil_wet", prob=254, param2=0},
		{name="farming:soil_wet", prob=254, param2=0},
		{name="farming:soil_wet", prob=254, param2=0},
		{name="farming:soil_wet", prob=254, param2=0},
		{name="farming:soil_wet", prob=254, param2=0},
		{name="default:tree", prob=254, param2=0},

		-- z=4, y=3
		{name="air", prob=254, param2=0},
		{name="air", prob=254, param2=0},
		{name="air", prob=254, param2=0},
		{name="farming:wheat_1", prob=254, param2=0},
		{name="farming:wheat_1", prob=254, param2=0},
		{name="farming:wheat_1", prob=254, param2=0},
		{name="farming:wheat_1", prob=254, param2=0},
		{name="farming:wheat_1", prob=254, param2=0},
		{name="farming:wheat_1", prob=254, param2=0},
		{name="farming:wheat_1", prob=254, param2=0},
		{name="default:leaves", prob=254, param2=0},

		-- z=4, y=4
		{name="air", prob=254, param2=0},
		{name="air", prob=254, param2=0},
		{name="air", prob=254, param2=0},
		{name="air", prob=254, param2=0},
		{name="air", prob=254, param2=0},
		{name="air", prob=254, param2=0},
		{name="air", prob=254, param2=0},
		{name="air", prob=254, param2=0},
		{name="air", prob=254, param2=0},
		{name="air", prob=254, param2=0},
		{name="air", prob=254, param2=0},

		-- z=4, y=5
		{name="air", prob=254, param2=0},
		{name="air", prob=254, param2=0},
		{name="air", prob=254, param2=0},
		{name="air", prob=254, param2=0},
		{name="air", prob=254, param2=0},
		{name="air", prob=254, param2=0},
		{name="air", prob=254, param2=0},
		{name="air", prob=254, param2=0},
		{name="air", prob=254, param2=0},
		{name="air", prob=254, param2=0},
		{name="air", prob=254, param2=0},

		-- z=5, y=0
		{name="default:dirt", prob=254, param2=0},
		{name="default:dirt", prob=254, param2=0},
		{name="default:dirt", prob=254, param2=0},
		{name="default:dirt", prob=254, param2=0},
		{name="default:dirt", prob=254, param2=0},
		{name="default:dirt", prob=254, param2=0},
		{name="default:dirt", prob=254, param2=0},
		{name="default:dirt", prob=254, param2=0},
		{name="default:dirt", prob=254, param2=0},
		{name="default:dirt", prob=254, param2=0},
		{name="default:dirt", prob=254, param2=0},

		-- z=5, y=1
		{name="default:dirt", prob=254, param2=0},
		{name="default:dirt", prob=254, param2=0},
		{name="default:dirt", prob=254, param2=3},
		{name="default:dirt", prob=254, param2=0},
		{name="default:dirt", prob=254, param2=0},
		{name="default:dirt", prob=254, param2=0},
		{name="default:dirt", prob=254, param2=0},
		{name="default:dirt", prob=254, param2=0},
		{name="default:dirt", prob=254, param2=0},
		{name="default:dirt", prob=254, param2=0},
		{name="default:dirt", prob=254, param2=0},

		-- z=5, y=2
		{name="cottages:feldweg", prob=254, param2=0},
		{name="cottages:feldweg", prob=254, param2=0},
		{name="default:water_source", prob=254, param2=0},
		{name="farming:soil_wet", prob=254, param2=0},
		{name="farming:soil_wet", prob=254, param2=0},
		{name="farming:soil_wet", prob=254, param2=0},
		{name="farming:soil_wet", prob=254, param2=0},
		{name="farming:soil_wet", prob=254, param2=0},
		{name="farming:soil_wet", prob=254, param2=0},
		{name="farming:soil_wet", prob=254, param2=0},
		{name="default:tree", prob=254, param2=0},

		-- z=5, y=3
		{name="air", prob=254, param2=0},
		{name="air", prob=254, param2=0},
		{name="air", prob=254, param2=0},
		{name="farming:wheat_1", prob=254, param2=0},
		{name="farming:wheat_1", prob=254, param2=0},
		{name="farming:wheat_1", prob=254, param2=0},
		{name="farming:wheat_1", prob=254, param2=0},
		{name="farming:wheat_1", prob=254, param2=0},
		{name="farming:wheat_1", prob=254, param2=0},
		{name="farming:wheat_1", prob=254, param2=0},
		{name="default:leaves", prob=254, param2=0},

		-- z=5, y=4
		{name="air", prob=254, param2=0},
		{name="air", prob=254, param2=0},
		{name="air", prob=254, param2=0},
		{name="air", prob=254, param2=0},
		{name="air", prob=254, param2=0},
		{name="air", prob=254, param2=0},
		{name="air", prob=254, param2=0},
		{name="air", prob=254, param2=0},
		{name="air", prob=254, param2=0},
		{name="air", prob=254, param2=0},
		{name="air", prob=254, param2=0},

		-- z=5, y=5
		{name="air", prob=254, param2=0},
		{name="air", prob=254, param2=0},
		{name="air", prob=254, param2=0},
		{name="air", prob=254, param2=0},
		{name="air", prob=254, param2=0},
		{name="air", prob=254, param2=0},
		{name="air", prob=254, param2=0},
		{name="air", prob=254, param2=0},
		{name="air", prob=254, param2=0},
		{name="air", prob=254, param2=0},
		{name="air", prob=254, param2=0},

		-- z=6, y=0
		{name="default:dirt", prob=254, param2=0},
		{name="default:dirt", prob=254, param2=0},
		{name="default:dirt", prob=254, param2=0},
		{name="default:dirt", prob=254, param2=0},
		{name="default:dirt", prob=254, param2=0},
		{name="default:dirt", prob=254, param2=0},
		{name="default:dirt", prob=254, param2=0},
		{name="default:dirt", prob=254, param2=0},
		{name="default:dirt", prob=254, param2=0},
		{name="default:dirt", prob=254, param2=0},
		{name="default:dirt", prob=254, param2=0},

		-- z=6, y=1
		{name="default:dirt", prob=254, param2=0},
		{name="default:dirt", prob=254, param2=0},
		{name="default:dirt", prob=254, param2=0},
		{name="default:dirt", prob=254, param2=0},
		{name="default:dirt", prob=254, param2=0},
		{name="default:dirt", prob=254, param2=0},
		{name="default:dirt", prob=254, param2=0},
		{name="default:dirt", prob=254, param2=0},
		{name="default:dirt", prob=254, param2=0},
		{name="default:dirt", prob=254, param2=0},
		{name="default:dirt", prob=254, param2=0},

		-- z=6, y=2
		{name="cottages:feldweg", prob=254, param2=0},
		{name="cottages:feldweg", prob=254, param2=0},
		{name="default:water_source", prob=254, param2=0},
		{name="farming:soil_wet", prob=254, param2=0},
		{name="farming:soil_wet", prob=254, param2=0},
		{name="farming:soil_wet", prob=254, param2=0},
		{name="farming:soil_wet", prob=254, param2=0},
		{name="farming:soil_wet", prob=254, param2=0},
		{name="farming:soil_wet", prob=254, param2=0},
		{name="farming:soil_wet", prob=254, param2=0},
		{name="default:tree", prob=254, param2=0},

		-- z=6, y=3
		{name="air", prob=254, param2=0},
		{name="air", prob=254, param2=0},
		{name="air", prob=254, param2=0},
		{name="farming:wheat_1", prob=254, param2=0},
		{name="farming:wheat_1", prob=254, param2=0},
		{name="farming:wheat_1", prob=254, param2=0},
		{name="farming:wheat_1", prob=254, param2=0},
		{name="farming:wheat_1", prob=254, param2=0},
		{name="farming:wheat_1", prob=254, param2=0},
		{name="farming:wheat_1", prob=254, param2=0},
		{name="default:leaves", prob=254, param2=0},

		-- z=6, y=4
		{name="air", prob=254, param2=0},
		{name="air", prob=254, param2=0},
		{name="air", prob=254, param2=0},
		{name="air", prob=254, param2=0},
		{name="air", prob=254, param2=0},
		{name="air", prob=254, param2=0},
		{name="air", prob=254, param2=0},
		{name="air", prob=254, param2=0},
		{name="air", prob=254, param2=0},
		{name="air", prob=254, param2=0},
		{name="air", prob=254, param2=0},

		-- z=6, y=5
		{name="air", prob=254, param2=0},
		{name="air", prob=254, param2=0},
		{name="air", prob=254, param2=0},
		{name="air", prob=254, param2=0},
		{name="air", prob=254, param2=0},
		{name="air", prob=254, param2=0},
		{name="air", prob=254, param2=0},
		{name="air", prob=254, param2=0},
		{name="air", prob=254, param2=0},
		{name="air", prob=254, param2=0},
		{name="air", prob=254, param2=0},

		-- z=7, y=0
		{name="default:dirt", prob=254, param2=0},
		{name="default:dirt", prob=254, param2=0},
		{name="default:dirt", prob=254, param2=0},
		{name="default:dirt", prob=254, param2=0},
		{name="default:dirt", prob=254, param2=0},
		{name="default:dirt", prob=254, param2=0},
		{name="default:dirt", prob=254, param2=0},
		{name="default:dirt", prob=254, param2=0},
		{name="default:dirt", prob=254, param2=0},
		{name="default:dirt", prob=254, param2=0},
		{name="default:dirt", prob=254, param2=0},

		-- z=7, y=1
		{name="default:dirt", prob=254, param2=0},
		{name="default:dirt", prob=254, param2=0},
		{name="default:dirt", prob=254, param2=0},
		{name="default:dirt", prob=254, param2=0},
		{name="default:dirt", prob=254, param2=0},
		{name="default:dirt", prob=254, param2=0},
		{name="default:dirt", prob=254, param2=0},
		{name="default:dirt", prob=254, param2=0},
		{name="default:dirt", prob=254, param2=0},
		{name="default:dirt", prob=254, param2=0},
		{name="default:dirt", prob=254, param2=0},

		-- z=7, y=2
		{name="cottages:feldweg", prob=254, param2=0},
		{name="cottages:feldweg", prob=254, param2=0},
		{name="default:water_source", prob=254, param2=0},
		{name="farming:soil_wet", prob=254, param2=0},
		{name="farming:soil_wet", prob=254, param2=0},
		{name="farming:soil_wet", prob=254, param2=0},
		{name="farming:soil_wet", prob=254, param2=0},
		{name="farming:soil_wet", prob=254, param2=0},
		{name="farming:soil_wet", prob=254, param2=0},
		{name="farming:soil_wet", prob=254, param2=0},
		{name="default:tree", prob=254, param2=0},

		-- z=7, y=3
		{name="air", prob=254, param2=0},
		{name="air", prob=254, param2=0},
		{name="air", prob=254, param2=0},
		{name="farming:wheat_1", prob=254, param2=0},
		{name="farming:wheat_1", prob=254, param2=0},
		{name="farming:wheat_1", prob=254, param2=0},
		{name="farming:wheat_1", prob=254, param2=0},
		{name="farming:wheat_1", prob=254, param2=0},
		{name="farming:wheat_1", prob=254, param2=0},
		{name="farming:wheat_1", prob=254, param2=0},
		{name="default:leaves", prob=254, param2=0},

		-- z=7, y=4
		{name="air", prob=254, param2=0},
		{name="air", prob=254, param2=0},
		{name="air", prob=254, param2=0},
		{name="air", prob=254, param2=0},
		{name="air", prob=254, param2=0},
		{name="air", prob=254, param2=0},
		{name="air", prob=254, param2=0},
		{name="air", prob=254, param2=0},
		{name="air", prob=254, param2=0},
		{name="air", prob=254, param2=0},
		{name="air", prob=254, param2=0},

		-- z=7, y=5
		{name="air", prob=254, param2=0},
		{name="air", prob=254, param2=0},
		{name="air", prob=254, param2=0},
		{name="air", prob=254, param2=0},
		{name="air", prob=254, param2=0},
		{name="air", prob=254, param2=0},
		{name="air", prob=254, param2=0},
		{name="air", prob=254, param2=0},
		{name="air", prob=254, param2=0},
		{name="air", prob=254, param2=0},
		{name="air", prob=254, param2=0},

		-- z=8, y=0
		{name="default:dirt", prob=254, param2=0},
		{name="default:dirt", prob=254, param2=0},
		{name="default:dirt", prob=254, param2=0},
		{name="default:dirt", prob=254, param2=0},
		{name="default:dirt", prob=254, param2=0},
		{name="default:dirt", prob=254, param2=0},
		{name="default:dirt", prob=254, param2=0},
		{name="default:dirt", prob=254, param2=0},
		{name="default:dirt", prob=254, param2=0},
		{name="default:dirt", prob=254, param2=0},
		{name="default:dirt", prob=254, param2=0},

		-- z=8, y=1
		{name="default:dirt", prob=254, param2=0},
		{name="default:dirt", prob=254, param2=0},
		{name="default:dirt", prob=254, param2=0},
		{name="default:dirt", prob=254, param2=0},
		{name="default:dirt", prob=254, param2=0},
		{name="default:dirt", prob=254, param2=0},
		{name="default:dirt", prob=254, param2=0},
		{name="default:dirt", prob=254, param2=0},
		{name="default:dirt", prob=254, param2=0},
		{name="default:dirt", prob=254, param2=0},
		{name="default:dirt", prob=254, param2=0},

		-- z=8, y=2
		{name="cottages:feldweg", prob=254, param2=0},
		{name="cottages:feldweg", prob=254, param2=0},
		{name="default:water_source", prob=254, param2=0},
		{name="farming:soil_wet", prob=254, param2=0},
		{name="farming:soil_wet", prob=254, param2=0},
		{name="farming:soil_wet", prob=254, param2=0},
		{name="farming:soil_wet", prob=254, param2=0},
		{name="farming:soil_wet", prob=254, param2=0},
		{name="farming:soil_wet", prob=254, param2=0},
		{name="farming:soil_wet", prob=254, param2=0},
		{name="default:tree", prob=254, param2=0},

		-- z=8, y=3
		{name="air", prob=254, param2=0},
		{name="air", prob=254, param2=0},
		{name="air", prob=254, param2=0},
		{name="farming:wheat_1", prob=254, param2=0},
		{name="farming:wheat_1", prob=254, param2=0},
		{name="farming:wheat_1", prob=254, param2=0},
		{name="farming:wheat_1", prob=254, param2=0},
		{name="farming:wheat_1", prob=254, param2=0},
		{name="farming:wheat_1", prob=254, param2=0},
		{name="farming:wheat_1", prob=254, param2=0},
		{name="default:leaves", prob=254, param2=0},

		-- z=8, y=4
		{name="air", prob=254, param2=0},
		{name="air", prob=254, param2=0},
		{name="air", prob=254, param2=0},
		{name="air", prob=254, param2=0},
		{name="air", prob=254, param2=0},
		{name="air", prob=254, param2=0},
		{name="air", prob=254, param2=0},
		{name="air", prob=254, param2=0},
		{name="air", prob=254, param2=0},
		{name="air", prob=254, param2=0},
		{name="air", prob=254, param2=0},

		-- z=8, y=5
		{name="air", prob=254, param2=0},
		{name="air", prob=254, param2=0},
		{name="air", prob=254, param2=0},
		{name="air", prob=254, param2=0},
		{name="air", prob=254, param2=0},
		{name="air", prob=254, param2=0},
		{name="air", prob=254, param2=0},
		{name="air", prob=254, param2=0},
		{name="air", prob=254, param2=0},
		{name="air", prob=254, param2=0},
		{name="air", prob=254, param2=0},

		-- z=9, y=0
		{name="default:dirt", prob=254, param2=0},
		{name="default:dirt", prob=254, param2=0},
		{name="default:dirt", prob=254, param2=0},
		{name="default:dirt", prob=254, param2=0},
		{name="default:dirt", prob=254, param2=0},
		{name="default:dirt", prob=254, param2=0},
		{name="default:dirt", prob=254, param2=0},
		{name="default:dirt", prob=254, param2=0},
		{name="default:dirt", prob=254, param2=0},
		{name="default:dirt", prob=254, param2=0},
		{name="default:dirt", prob=254, param2=0},

		-- z=9, y=1
		{name="default:dirt", prob=254, param2=0},
		{name="default:dirt", prob=254, param2=0},
		{name="default:dirt", prob=254, param2=7},
		{name="default:dirt", prob=254, param2=0},
		{name="default:dirt", prob=254, param2=0},
		{name="default:dirt", prob=254, param2=0},
		{name="default:dirt", prob=254, param2=0},
		{name="default:dirt", prob=254, param2=0},
		{name="default:dirt", prob=254, param2=0},
		{name="default:dirt", prob=254, param2=0},
		{name="default:dirt", prob=254, param2=0},

		-- z=9, y=2
		{name="cottages:feldweg", prob=254, param2=0},
		{name="cottages:feldweg", prob=254, param2=0},
		{name="default:water_source", prob=254, param2=0},
		{name="farming:soil_wet", prob=254, param2=0},
		{name="farming:soil_wet", prob=254, param2=0},
		{name="farming:soil_wet", prob=254, param2=0},
		{name="farming:soil_wet", prob=254, param2=0},
		{name="farming:soil_wet", prob=254, param2=0},
		{name="farming:soil_wet", prob=254, param2=0},
		{name="farming:soil_wet", prob=254, param2=0},
		{name="default:tree", prob=254, param2=0},

		-- z=9, y=3
		{name="air", prob=254, param2=0},
		{name="air", prob=254, param2=0},
		{name="air", prob=254, param2=0},
		{name="farming:wheat_1", prob=254, param2=0},
		{name="farming:wheat_1", prob=254, param2=0},
		{name="farming:wheat_1", prob=254, param2=0},
		{name="farming:wheat_1", prob=254, param2=0},
		{name="farming:wheat_1", prob=254, param2=0},
		{name="farming:wheat_1", prob=254, param2=0},
		{name="farming:wheat_1", prob=254, param2=0},
		{name="default:leaves", prob=254, param2=0},

		-- z=9, y=4
		{name="air", prob=254, param2=0},
		{name="air", prob=254, param2=0},
		{name="air", prob=254, param2=0},
		{name="air", prob=254, param2=0},
		{name="air", prob=254, param2=0},
		{name="air", prob=254, param2=0},
		{name="air", prob=254, param2=0},
		{name="air", prob=254, param2=0},
		{name="air", prob=254, param2=0},
		{name="air", prob=254, param2=0},
		{name="air", prob=254, param2=0},

		-- z=9, y=5
		{name="air", prob=254, param2=0},
		{name="air", prob=254, param2=0},
		{name="air", prob=254, param2=0},
		{name="air", prob=254, param2=0},
		{name="air", prob=254, param2=0},
		{name="air", prob=254, param2=0},
		{name="air", prob=254, param2=0},
		{name="air", prob=254, param2=0},
		{name="air", prob=254, param2=0},
		{name="air", prob=254, param2=0},
		{name="air", prob=254, param2=0},

		-- z=10, y=0
		{name="default:dirt", prob=254, param2=0},
		{name="default:dirt", prob=254, param2=0},
		{name="default:dirt", prob=254, param2=0},
		{name="default:dirt", prob=254, param2=0},
		{name="default:dirt", prob=254, param2=0},
		{name="default:dirt", prob=254, param2=0},
		{name="default:dirt", prob=254, param2=0},
		{name="default:dirt", prob=254, param2=0},
		{name="default:dirt", prob=254, param2=0},
		{name="default:dirt", prob=254, param2=0},
		{name="default:dirt", prob=254, param2=0},

		-- z=10, y=1
		{name="default:dirt", prob=254, param2=0},
		{name="default:dirt", prob=254, param2=0},
		{name="default:dirt", prob=254, param2=0},
		{name="default:dirt", prob=254, param2=0},
		{name="default:dirt", prob=254, param2=0},
		{name="default:dirt", prob=254, param2=0},
		{name="default:dirt", prob=254, param2=0},
		{name="default:dirt", prob=254, param2=0},
		{name="default:dirt", prob=254, param2=0},
		{name="default:dirt", prob=254, param2=0},
		{name="default:dirt", prob=254, param2=0},

		-- z=10, y=2
		{name="cottages:feldweg", prob=254, param2=0},
		{name="cottages:feldweg", prob=254, param2=0},
		{name="default:water_source", prob=254, param2=0},
		{name="farming:soil_wet", prob=254, param2=0},
		{name="farming:soil_wet", prob=254, param2=0},
		{name="farming:soil_wet", prob=254, param2=0},
		{name="farming:soil_wet", prob=254, param2=0},
		{name="farming:soil_wet", prob=254, param2=0},
		{name="farming:soil_wet", prob=254, param2=0},
		{name="farming:soil_wet", prob=254, param2=0},
		{name="default:tree", prob=254, param2=0},

		-- z=10, y=3
		{name="air", prob=254, param2=0},
		{name="air", prob=254, param2=0},
		{name="air", prob=254, param2=0},
		{name="farming:wheat_1", prob=254, param2=0},
		{name="farming:wheat_1", prob=254, param2=0},
		{name="farming:wheat_1", prob=254, param2=0},
		{name="farming:wheat_1", prob=254, param2=0},
		{name="farming:wheat_1", prob=254, param2=0},
		{name="farming:wheat_1", prob=254, param2=0},
		{name="farming:wheat_1", prob=254, param2=0},
		{name="default:leaves", prob=254, param2=0},

		-- z=10, y=4
		{name="air", prob=254, param2=0},
		{name="air", prob=254, param2=0},
		{name="air", prob=254, param2=0},
		{name="air", prob=254, param2=0},
		{name="air", prob=254, param2=0},
		{name="air", prob=254, param2=0},
		{name="air", prob=254, param2=0},
		{name="air", prob=254, param2=0},
		{name="air", prob=254, param2=0},
		{name="air", prob=254, param2=0},
		{name="air", prob=254, param2=0},

		-- z=10, y=5
		{name="air", prob=254, param2=0},
		{name="air", prob=254, param2=0},
		{name="air", prob=254, param2=0},
		{name="air", prob=254, param2=0},
		{name="air", prob=254, param2=0},
		{name="air", prob=254, param2=0},
		{name="air", prob=254, param2=0},
		{name="air", prob=254, param2=0},
		{name="air", prob=254, param2=0},
		{name="air", prob=254, param2=0},
		{name="air", prob=254, param2=0},

		-- z=11, y=0
		{name="default:dirt", prob=254, param2=0},
		{name="default:dirt", prob=254, param2=0},
		{name="default:dirt", prob=254, param2=0},
		{name="default:dirt", prob=254, param2=0},
		{name="default:dirt", prob=254, param2=0},
		{name="default:dirt", prob=254, param2=0},
		{name="default:dirt", prob=254, param2=0},
		{name="default:dirt", prob=254, param2=0},
		{name="default:dirt", prob=254, param2=0},
		{name="default:dirt", prob=254, param2=0},
		{name="default:dirt", prob=254, param2=0},

		-- z=11, y=1
		{name="default:dirt", prob=254, param2=0},
		{name="default:dirt", prob=254, param2=0},
		{name="default:dirt", prob=254, param2=0},
		{name="default:dirt", prob=254, param2=0},
		{name="default:dirt", prob=254, param2=0},
		{name="default:dirt", prob=254, param2=0},
		{name="default:water_source", prob=254, param2=0},
		{name="default:dirt", prob=254, param2=0},
		{name="default:dirt", prob=254, param2=0},
		{name="default:dirt", prob=254, param2=0},
		{name="default:dirt", prob=254, param2=0},

		-- z=11, y=2
		{name="cottages:feldweg", prob=254, param2=0},
		{name="cottages:feldweg", prob=254, param2=0},
		{name="default:water_source", prob=254, param2=0},
		{name="farming:soil_wet", prob=254, param2=0},
		{name="farming:soil_wet", prob=254, param2=0},
		{name="farming:soil_wet", prob=254, param2=0},
		{name="farming:soil_wet", prob=254, param2=0},
		{name="farming:soil_wet", prob=254, param2=0},
		{name="farming:soil_wet", prob=254, param2=0},
		{name="farming:soil_wet", prob=254, param2=0},
		{name="default:tree", prob=254, param2=0},

		-- z=11, y=3
		{name="air", prob=254, param2=0},
		{name="air", prob=254, param2=0},
		{name="air", prob=254, param2=0},
		{name="farming:wheat_1", prob=254, param2=0},
		{name="farming:wheat_1", prob=254, param2=0},
		{name="farming:wheat_1", prob=254, param2=0},
		{name="farming:wheat_1", prob=254, param2=0},
		{name="farming:wheat_1", prob=254, param2=0},
		{name="farming:wheat_1", prob=254, param2=0},
		{name="farming:wheat_1", prob=254, param2=0},
		{name="default:leaves", prob=254, param2=0},

		-- z=11, y=4
		{name="air", prob=254, param2=0},
		{name="air", prob=254, param2=0},
		{name="air", prob=254, param2=0},
		{name="air", prob=254, param2=0},
		{name="air", prob=254, param2=0},
		{name="air", prob=254, param2=0},
		{name="air", prob=254, param2=0},
		{name="air", prob=254, param2=0},
		{name="air", prob=254, param2=0},
		{name="air", prob=254, param2=0},
		{name="air", prob=254, param2=0},

		-- z=11, y=5
		{name="air", prob=254, param2=0},
		{name="air", prob=254, param2=0},
		{name="air", prob=254, param2=0},
		{name="air", prob=254, param2=0},
		{name="air", prob=254, param2=0},
		{name="air", prob=254, param2=0},
		{name="air", prob=254, param2=0},
		{name="air", prob=254, param2=0},
		{name="air", prob=254, param2=0},
		{name="air", prob=254, param2=0},
		{name="air", prob=254, param2=0},

		-- z=12, y=0
		{name="default:dirt", prob=254, param2=0},
		{name="default:dirt", prob=254, param2=0},
		{name="default:dirt", prob=254, param2=0},
		{name="default:dirt", prob=254, param2=0},
		{name="default:dirt", prob=254, param2=0},
		{name="default:dirt", prob=254, param2=0},
		{name="default:dirt", prob=254, param2=0},
		{name="default:dirt", prob=254, param2=0},
		{name="default:dirt", prob=254, param2=0},
		{name="default:dirt", prob=254, param2=0},
		{name="default:dirt", prob=254, param2=0},

		-- z=12, y=1
		{name="default:dirt", prob=254, param2=0},
		{name="default:dirt", prob=254, param2=0},
		{name="default:dirt", prob=254, param2=0},
		{name="default:dirt", prob=254, param2=0},
		{name="default:dirt", prob=254, param2=0},
		{name="default:dirt", prob=254, param2=0},
		{name="default:dirt", prob=254, param2=0},
		{name="default:dirt", prob=254, param2=0},
		{name="default:dirt", prob=254, param2=0},
		{name="default:dirt", prob=254, param2=0},
		{name="default:dirt", prob=254, param2=0},

		-- z=12, y=2
		{name="cottages:feldweg", prob=254, param2=0},
		{name="cottages:feldweg", prob=254, param2=0},
		{name="default:water_source", prob=254, param2=0},
		{name="farming:soil_wet", prob=254, param2=0},
		{name="farming:soil_wet", prob=254, param2=0},
		{name="farming:soil_wet", prob=254, param2=0},
		{name="farming:soil_wet", prob=254, param2=0},
		{name="farming:soil_wet", prob=254, param2=0},
		{name="farming:soil_wet", prob=254, param2=0},
		{name="farming:soil_wet", prob=254, param2=0},
		{name="default:tree", prob=254, param2=0},

		-- z=12, y=3
		{name="air", prob=254, param2=0},
		{name="air", prob=254, param2=0},
		{name="air", prob=254, param2=0},
		{name="farming:wheat_1", prob=254, param2=0},
		{name="farming:wheat_1", prob=254, param2=0},
		{name="farming:wheat_1", prob=254, param2=0},
		{name="farming:wheat_1", prob=254, param2=0},
		{name="farming:wheat_1", prob=254, param2=0},
		{name="farming:wheat_1", prob=254, param2=0},
		{name="farming:wheat_1", prob=254, param2=0},
		{name="default:leaves", prob=254, param2=0},

		-- z=12, y=4
		{name="air", prob=254, param2=0},
		{name="air", prob=254, param2=0},
		{name="air", prob=254, param2=0},
		{name="air", prob=254, param2=0},
		{name="air", prob=254, param2=0},
		{name="air", prob=254, param2=0},
		{name="air", prob=254, param2=0},
		{name="air", prob=254, param2=0},
		{name="air", prob=254, param2=0},
		{name="air", prob=254, param2=0},
		{name="air", prob=254, param2=0},

		-- z=12, y=5
		{name="air", prob=254, param2=0},
		{name="air", prob=254, param2=0},
		{name="air", prob=254, param2=0},
		{name="air", prob=254, param2=0},
		{name="air", prob=254, param2=0},
		{name="air", prob=254, param2=0},
		{name="air", prob=254, param2=0},
		{name="air", prob=254, param2=0},
		{name="air", prob=254, param2=0},
		{name="air", prob=254, param2=0},
		{name="air", prob=254, param2=0},

		-- z=13, y=0
		{name="default:dirt", prob=254, param2=0},
		{name="default:dirt", prob=254, param2=0},
		{name="default:dirt", prob=254, param2=0},
		{name="default:dirt", prob=254, param2=0},
		{name="default:dirt", prob=254, param2=0},
		{name="default:dirt", prob=254, param2=0},
		{name="default:dirt", prob=254, param2=0},
		{name="default:dirt", prob=254, param2=0},
		{name="default:dirt", prob=254, param2=0},
		{name="default:dirt", prob=254, param2=0},
		{name="default:dirt", prob=254, param2=0},

		-- z=13, y=1
		{name="default:dirt", prob=254, param2=0},
		{name="default:dirt", prob=254, param2=0},
		{name="default:dirt", prob=254, param2=0},
		{name="default:dirt", prob=254, param2=0},
		{name="default:dirt", prob=254, param2=0},
		{name="default:dirt", prob=254, param2=0},
		{name="default:dirt", prob=254, param2=0},
		{name="default:dirt", prob=254, param2=0},
		{name="default:dirt", prob=254, param2=0},
		{name="default:dirt", prob=254, param2=0},
		{name="default:dirt", prob=254, param2=0},

		-- z=13, y=2
		{name="cottages:feldweg", prob=254, param2=0},
		{name="cottages:feldweg", prob=254, param2=0},
		{name="default:water_source", prob=254, param2=0},
		{name="farming:soil_wet", prob=254, param2=0},
		{name="farming:soil_wet", prob=254, param2=0},
		{name="farming:soil_wet", prob=254, param2=0},
		{name="farming:soil_wet", prob=254, param2=0},
		{name="farming:soil_wet", prob=254, param2=0},
		{name="farming:soil_wet", prob=254, param2=0},
		{name="farming:soil_wet", prob=254, param2=0},
		{name="default:tree", prob=254, param2=0},

		-- z=13, y=3
		{name="air", prob=254, param2=0},
		{name="air", prob=254, param2=0},
		{name="air", prob=254, param2=0},
		{name="farming:wheat_1", prob=254, param2=0},
		{name="farming:wheat_1", prob=254, param2=0},
		{name="farming:wheat_1", prob=254, param2=0},
		{name="farming:wheat_1", prob=254, param2=0},
		{name="farming:wheat_1", prob=254, param2=0},
		{name="farming:wheat_1", prob=254, param2=0},
		{name="farming:wheat_1", prob=254, param2=0},
		{name="default:leaves", prob=254, param2=0},

		-- z=13, y=4
		{name="air", prob=254, param2=0},
		{name="air", prob=254, param2=0},
		{name="air", prob=254, param2=0},
		{name="air", prob=254, param2=0},
		{name="air", prob=254, param2=0},
		{name="air", prob=254, param2=0},
		{name="air", prob=254, param2=0},
		{name="air", prob=254, param2=0},
		{name="air", prob=254, param2=0},
		{name="air", prob=254, param2=0},
		{name="air", prob=254, param2=0},

		-- z=13, y=5
		{name="air", prob=254, param2=0},
		{name="air", prob=254, param2=0},
		{name="air", prob=254, param2=0},
		{name="air", prob=254, param2=0},
		{name="air", prob=254, param2=0},
		{name="air", prob=254, param2=0},
		{name="air", prob=254, param2=0},
		{name="air", prob=254, param2=0},
		{name="air", prob=254, param2=0},
		{name="air", prob=254, param2=0},
		{name="air", prob=254, param2=0},

		-- z=14, y=0
		{name="default:dirt", prob=254, param2=0},
		{name="default:dirt", prob=254, param2=0},
		{name="default:dirt", prob=254, param2=0},
		{name="default:dirt", prob=254, param2=0},
		{name="default:dirt", prob=254, param2=0},
		{name="default:dirt", prob=254, param2=0},
		{name="default:dirt", prob=254, param2=0},
		{name="default:dirt", prob=254, param2=0},
		{name="default:dirt", prob=254, param2=0},
		{name="default:dirt", prob=254, param2=0},
		{name="default:dirt", prob=254, param2=0},

		-- z=14, y=1
		{name="default:dirt", prob=254, param2=0},
		{name="default:dirt", prob=254, param2=240},
		{name="default:dirt", prob=254, param2=0},
		{name="default:dirt", prob=254, param2=0},
		{name="default:dirt", prob=254, param2=0},
		{name="default:dirt", prob=254, param2=0},
		{name="default:dirt", prob=254, param2=0},
		{name="default:dirt", prob=254, param2=0},
		{name="default:dirt", prob=254, param2=0},
		{name="default:dirt", prob=254, param2=0},
		{name="default:dirt", prob=254, param2=0},

		-- z=14, y=2
		{name="cottages:feldweg", prob=254, param2=0},
		{name="cottages:feldweg", prob=254, param2=0},
		{name="default:water_source", prob=254, param2=0},
		{name="farming:soil_wet", prob=254, param2=0},
		{name="farming:soil_wet", prob=254, param2=0},
		{name="farming:soil_wet", prob=254, param2=0},
		{name="farming:soil_wet", prob=254, param2=0},
		{name="farming:soil_wet", prob=254, param2=0},
		{name="farming:soil_wet", prob=254, param2=0},
		{name="farming:soil_wet", prob=254, param2=0},
		{name="default:tree", prob=254, param2=0},

		-- z=14, y=3
		{name="air", prob=254, param2=0},
		{name="air", prob=254, param2=0},
		{name="air", prob=254, param2=0},
		{name="farming:wheat_1", prob=254, param2=0},
		{name="farming:wheat_1", prob=254, param2=0},
		{name="farming:wheat_1", prob=254, param2=0},
		{name="farming:wheat_1", prob=254, param2=0},
		{name="farming:wheat_1", prob=254, param2=0},
		{name="farming:wheat_1", prob=254, param2=0},
		{name="farming:wheat_1", prob=254, param2=0},
		{name="default:leaves", prob=254, param2=0},

		-- z=14, y=4
		{name="air", prob=254, param2=0},
		{name="air", prob=254, param2=0},
		{name="air", prob=254, param2=0},
		{name="air", prob=254, param2=0},
		{name="air", prob=254, param2=0},
		{name="air", prob=254, param2=0},
		{name="air", prob=254, param2=0},
		{name="air", prob=254, param2=0},
		{name="air", prob=254, param2=0},
		{name="air", prob=254, param2=0},
		{name="air", prob=254, param2=0},

		-- z=14, y=5
		{name="air", prob=254, param2=0},
		{name="air", prob=254, param2=0},
		{name="air", prob=254, param2=0},
		{name="air", prob=254, param2=0},
		{name="air", prob=254, param2=0},
		{name="air", prob=254, param2=0},
		{name="air", prob=254, param2=0},
		{name="air", prob=254, param2=0},
		{name="air", prob=254, param2=0},
		{name="air", prob=254, param2=0},
		{name="air", prob=254, param2=0},

		-- z=15, y=0
		{name="default:water_source", prob=254, param2=0},
		{name="default:water_source", prob=254, param2=0},
		{name="default:dirt", prob=254, param2=0},
		{name="default:dirt", prob=254, param2=0},
		{name="default:dirt", prob=254, param2=0},
		{name="default:dirt", prob=254, param2=0},
		{name="default:dirt", prob=254, param2=0},
		{name="default:dirt", prob=254, param2=0},
		{name="default:dirt", prob=254, param2=0},
		{name="default:dirt", prob=254, param2=0},
		{name="default:dirt", prob=254, param2=0},

		-- z=15, y=1
		{name="default:water_source", prob=254, param2=0},
		{name="default:water_source", prob=254, param2=0},
		{name="default:dirt", prob=254, param2=0},
		{name="default:dirt", prob=254, param2=0},
		{name="default:dirt", prob=254, param2=0},
		{name="default:dirt", prob=254, param2=0},
		{name="default:dirt", prob=254, param2=0},
		{name="default:dirt", prob=254, param2=0},
		{name="default:dirt", prob=254, param2=0},
		{name="default:dirt", prob=254, param2=0},
		{name="default:dirt", prob=254, param2=0},

		-- z=15, y=2
		{name="cottages:feldweg", prob=254, param2=0},
		{name="cottages:feldweg", prob=254, param2=0},
		{name="default:dirt_with_grass", prob=254, param2=1},
		{name="default:dirt_with_grass", prob=254, param2=1},
		{name="default:dirt_with_grass", prob=254, param2=1},
		{name="default:dirt_with_grass", prob=254, param2=1},
		{name="default:dirt_with_grass", prob=254, param2=1},
		{name="default:dirt_with_grass", prob=254, param2=1},
		{name="default:dirt_with_grass", prob=254, param2=1},
		{name="default:dirt_with_grass", prob=254, param2=1},
		{name="default:tree", prob=254, param2=0},

		-- z=15, y=3
		{name="air", prob=254, param2=0},
		{name="air", prob=254, param2=0},
		{name="air", prob=254, param2=0},
		{name="air", prob=254, param2=0},
		{name="air", prob=254, param2=0},
		{name="air", prob=254, param2=0},
		{name="air", prob=254, param2=0},
		{name="air", prob=254, param2=0},
		{name="air", prob=254, param2=0},
		{name="air", prob=254, param2=0},
		{name="default:leaves", prob=254, param2=0},

		-- z=15, y=4
		{name="air", prob=254, param2=0},
		{name="air", prob=254, param2=0},
		{name="air", prob=254, param2=0},
		{name="air", prob=254, param2=0},
		{name="air", prob=254, param2=0},
		{name="air", prob=254, param2=0},
		{name="air", prob=254, param2=0},
		{name="air", prob=254, param2=0},
		{name="air", prob=254, param2=0},
		{name="air", prob=254, param2=0},
		{name="air", prob=254, param2=0},

		-- z=15, y=5
		{name="air", prob=254, param2=0},
		{name="air", prob=254, param2=0},
		{name="air", prob=254, param2=0},
		{name="air", prob=254, param2=0},
		{name="air", prob=254, param2=0},
		{name="air", prob=254, param2=0},
		{name="air", prob=254, param2=0},
		{name="air", prob=254, param2=0},
		{name="air", prob=254, param2=0},
		{name="air", prob=254, param2=0},
		{name="air", prob=254, param2=0},
	},
}

return schematic