schematic = {
	size = {x=8, y=6, z=9},
	yslice_prob = {
		{ypos=0, prob=254},
		{ypos=1, prob=254},
		{ypos=2, prob=254},
		{ypos=3, prob=254},
		{ypos=4, prob=254},
		{ypos=5, prob=254},
	},
	data = {

		-- z=0, y=0
		{name="default:stonebrick", prob=254, param2=0},
		{name="default:stonebrick", prob=254, param2=0},
		{name="default:stonebrick", prob=254, param2=0},
		{name="default:stonebrick", prob=254, param2=0},
		{name="default:stonebrick", prob=254, param2=0},
		{name="default:stonebrick", prob=254, param2=0},
		{name="default:stonebrick", prob=254, param2=0},
		{name="default:stonebrick", prob=254, param2=0},

		-- z=0, y=1
		{name="default:stonebrick", prob=254, param2=0},
		{name="default:stonebrick", prob=254, param2=0},
		{name="default:stonebrick", prob=254, param2=0},
		{name="default:stonebrick", prob=254, param2=0},
		{name="default:stonebrick", prob=254, param2=0},
		{name="default:stonebrick", prob=254, param2=0},
		{name="default:stonebrick", prob=254, param2=0},
		{name="default:stonebrick", prob=254, param2=0},

		-- z=0, y=2
		{name="default:stonebrick", prob=254, param2=0},
		{name="default:stonebrick", prob=254, param2=0},
		{name="default:stonebrick", prob=254, param2=0},
		{name="default:stonebrick", prob=254, param2=0},
		{name="default:stonebrick", prob=254, param2=0},
		{name="default:stonebrick", prob=254, param2=0},
		{name="default:stonebrick", prob=254, param2=0},
		{name="default:stonebrick", prob=254, param2=0},

		-- z=0, y=3
		{name="default:stonebrick", prob=254, param2=0},
		{name="default:stonebrick", prob=254, param2=0},
		{name="default:stonebrick", prob=254, param2=0},
		{name="default:stonebrick", prob=254, param2=0},
		{name="default:stonebrick", prob=254, param2=0},
		{name="default:stonebrick", prob=254, param2=0},
		{name="default:stonebrick", prob=254, param2=0},
		{name="default:stonebrick", prob=254, param2=0},

		-- z=0, y=4
		{name="stairs:slab_stonebrick", prob=254, param2=0},
		{name="stairs:stair_stonebrick", prob=254, param2=0},
		{name="stairs:stair_stonebrick", prob=254, param2=0},
		{name="stairs:stair_stonebrick", prob=254, param2=0},
		{name="stairs:stair_stonebrick", prob=254, param2=0},
		{name="stairs:stair_stonebrick", prob=254, param2=0},
		{name="stairs:stair_stonebrick", prob=254, param2=0},
		{name="stairs:slab_stonebrick", prob=254, param2=0},

		-- z=0, y=5
		{name="air", prob=254, param2=0},
		{name="air", prob=254, param2=0},
		{name="air", prob=254, param2=0},
		{name="air", prob=254, param2=0},
		{name="air", prob=254, param2=0},
		{name="air", prob=254, param2=0},
		{name="air", prob=254, param2=0},
		{name="air", prob=254, param2=0},

		-- z=1, y=0
		{name="default:stonebrick", prob=254, param2=0},
		{name="default:stonebrick", prob=254, param2=0},
		{name="default:stonebrick", prob=254, param2=0},
		{name="default:stonebrick", prob=254, param2=0},
		{name="default:stonebrick", prob=254, param2=0},
		{name="default:stonebrick", prob=254, param2=0},
		{name="default:stonebrick", prob=254, param2=0},
		{name="default:stonebrick", prob=254, param2=0},

		-- z=1, y=1
		{name="default:stonebrick", prob=254, param2=0},
		{name="default:furnace", prob=254, param2=2},
		{name="air", prob=254, param2=0},
		{name="default:chest", prob=254, param2=2},
		{name="default:stonebrick", prob=254, param2=0},
		{name="default:lava_source", prob=254, param2=0},
		{name="default:lava_source", prob=254, param2=0},
		{name="default:stonebrick", prob=254, param2=0},

		-- z=1, y=2
		{name="default:stonebrick", prob=254, param2=0},
		{name="air", prob=254, param2=0},
		{name="air", prob=254, param2=0},
		{name="default:torch_wall", prob=254, param2=5},
		{name="air", prob=254, param2=0},
		{name="air", prob=254, param2=0},
		{name="air", prob=254, param2=0},
		{name="default:stonebrick", prob=254, param2=0},

		-- z=1, y=3
		{name="default:stonebrick", prob=254, param2=0},
		{name="air", prob=254, param2=0},
		{name="air", prob=254, param2=0},
		{name="air", prob=254, param2=0},
		{name="air", prob=254, param2=0},
		{name="air", prob=254, param2=0},
		{name="air", prob=254, param2=0},
		{name="default:stonebrick", prob=254, param2=0},

		-- z=1, y=4
		{name="stairs:stair_stonebrick", prob=254, param2=1},
		{name="default:stonebrick", prob=254, param2=0},
		{name="default:stonebrick", prob=254, param2=0},
		{name="default:stonebrick", prob=254, param2=0},
		{name="default:stonebrick", prob=254, param2=0},
		{name="default:stonebrick", prob=254, param2=0},
		{name="default:stonebrick", prob=254, param2=0},
		{name="stairs:stair_stonebrick", prob=254, param2=3},

		-- z=1, y=5
		{name="air", prob=254, param2=0},
		{name="air", prob=254, param2=0},
		{name="air", prob=254, param2=0},
		{name="air", prob=254, param2=0},
		{name="stairs:slab_stonebrick", prob=254, param2=0},
		{name="stairs:stair_stonebrick", prob=254, param2=0},
		{name="stairs:slab_stonebrick", prob=254, param2=0},
		{name="air", prob=254, param2=0},

		-- z=2, y=0
		{name="default:stonebrick", prob=254, param2=0},
		{name="default:stonebrick", prob=254, param2=0},
		{name="default:stonebrick", prob=254, param2=0},
		{name="default:stonebrick", prob=254, param2=0},
		{name="default:stonebrick", prob=254, param2=0},
		{name="default:stonebrick", prob=254, param2=0},
		{name="default:stonebrick", prob=254, param2=0},
		{name="default:stonebrick", prob=254, param2=0},

		-- z=2, y=1
		{name="default:stonebrick", prob=254, param2=0},
		{name="air", prob=254, param2=0},
		{name="air", prob=254, param2=0},
		{name="air", prob=254, param2=0},
		{name="default:stonebrick", prob=254, param2=0},
		{name="default:lava_source", prob=254, param2=0},
		{name="default:lava_source", prob=254, param2=0},
		{name="default:stonebrick", prob=254, param2=0},

		-- z=2, y=2
		{name="default:stonebrick", prob=254, param2=0},
		{name="air", prob=254, param2=0},
		{name="air", prob=254, param2=0},
		{name="air", prob=254, param2=0},
		{name="air", prob=254, param2=0},
		{name="air", prob=254, param2=0},
		{name="air", prob=254, param2=0},
		{name="default:stonebrick", prob=254, param2=0},

		-- z=2, y=3
		{name="default:stonebrick", prob=254, param2=0},
		{name="air", prob=254, param2=0},
		{name="air", prob=254, param2=0},
		{name="air", prob=254, param2=0},
		{name="air", prob=254, param2=0},
		{name="air", prob=254, param2=0},
		{name="air", prob=254, param2=0},
		{name="default:stonebrick", prob=254, param2=0},

		-- z=2, y=4
		{name="stairs:stair_stonebrick", prob=254, param2=1},
		{name="default:stonebrick", prob=254, param2=0},
		{name="default:stonebrick", prob=254, param2=0},
		{name="default:stonebrick", prob=254, param2=0},
		{name="default:stonebrick", prob=254, param2=0},
		{name="air", prob=254, param2=0},
		{name="default:stonebrick", prob=254, param2=0},
		{name="stairs:stair_stonebrick", prob=254, param2=3},

		-- z=2, y=5
		{name="air", prob=254, param2=0},
		{name="air", prob=254, param2=0},
		{name="air", prob=254, param2=0},
		{name="air", prob=254, param2=0},
		{name="stairs:stair_stonebrick", prob=254, param2=1},
		{name="air", prob=254, param2=0},
		{name="stairs:stair_stonebrick", prob=254, param2=3},
		{name="air", prob=254, param2=0},

		-- z=3, y=0
		{name="default:stonebrick", prob=254, param2=0},
		{name="default:stonebrick", prob=254, param2=0},
		{name="default:stonebrick", prob=254, param2=0},
		{name="default:stonebrick", prob=254, param2=0},
		{name="default:stonebrick", prob=254, param2=0},
		{name="default:stonebrick", prob=254, param2=0},
		{name="default:stonebrick", prob=254, param2=0},
		{name="default:stonebrick", prob=254, param2=0},

		-- z=3, y=1
		{name="default:stonebrick", prob=254, param2=0},
		{name="air", prob=254, param2=0},
		{name="air", prob=254, param2=0},
		{name="air", prob=254, param2=0},
		{name="default:stonebrick", prob=254, param2=0},
		{name="default:stonebrick", prob=254, param2=0},
		{name="default:stonebrick", prob=254, param2=0},
		{name="default:stonebrick", prob=254, param2=0},

		-- z=3, y=2
		{name="default:stonebrick", prob=254, param2=0},
		{name="air", prob=254, param2=0},
		{name="air", prob=254, param2=0},
		{name="air", prob=254, param2=0},
		{name="air", prob=254, param2=0},
		{name="air", prob=254, param2=0},
		{name="air", prob=254, param2=0},
		{name="default:stonebrick", prob=254, param2=0},

		-- z=3, y=3
		{name="default:stonebrick", prob=254, param2=0},
		{name="air", prob=254, param2=0},
		{name="air", prob=254, param2=0},
		{name="air", prob=254, param2=0},
		{name="air", prob=254, param2=0},
		{name="air", prob=254, param2=0},
		{name="air", prob=254, param2=0},
		{name="default:stonebrick", prob=254, param2=0},

		-- z=3, y=4
		{name="stairs:stair_stonebrick", prob=254, param2=1},
		{name="default:stonebrick", prob=254, param2=0},
		{name="default:stonebrick", prob=254, param2=0},
		{name="default:stonebrick", prob=254, param2=0},
		{name="default:stonebrick", prob=254, param2=0},
		{name="default:stonebrick", prob=254, param2=0},
		{name="default:stonebrick", prob=254, param2=0},
		{name="stairs:stair_stonebrick", prob=254, param2=3},

		-- z=3, y=5
		{name="air", prob=254, param2=0},
		{name="air", prob=254, param2=0},
		{name="air", prob=254, param2=0},
		{name="air", prob=254, param2=0},
		{name="stairs:slab_stonebrick", prob=254, param2=0},
		{name="stairs:stair_stonebrick", prob=254, param2=2},
		{name="stairs:slab_stonebrick", prob=254, param2=0},
		{name="air", prob=254, param2=0},

		-- z=4, y=0
		{name="default:stonebrick", prob=254, param2=0},
		{name="default:stonebrick", prob=254, param2=0},
		{name="default:stonebrick", prob=254, param2=0},
		{name="default:stonebrick", prob=254, param2=0},
		{name="default:stonebrick", prob=254, param2=0},
		{name="default:stonebrick", prob=254, param2=0},
		{name="default:stonebrick", prob=254, param2=0},
		{name="default:stonebrick", prob=254, param2=0},

		-- z=4, y=1
		{name="doors:door_wood_a", prob=254, param2=1},
		{name="air", prob=254, param2=0},
		{name="air", prob=254, param2=0},
		{name="air", prob=254, param2=0},
		{name="air", prob=254, param2=0},
		{name="stairs:slab_stonebrick", prob=254, param2=0},
		{name="stairs:slab_stonebrick", prob=254, param2=0},
		{name="default:stonebrick", prob=254, param2=0},

		-- z=4, y=2
		{name="air", prob=254, param2=1},
		{name="air", prob=254, param2=0},
		{name="air", prob=254, param2=0},
		{name="air", prob=254, param2=0},
		{name="air", prob=254, param2=0},
		{name="air", prob=254, param2=0},
		{name="default:torch_wall", prob=254, param2=2},
		{name="default:stonebrick", prob=254, param2=0},

		-- z=4, y=3
		{name="default:stonebrick", prob=254, param2=0},
		{name="air", prob=254, param2=0},
		{name="air", prob=254, param2=0},
		{name="air", prob=254, param2=0},
		{name="air", prob=254, param2=0},
		{name="air", prob=254, param2=0},
		{name="air", prob=254, param2=0},
		{name="default:stonebrick", prob=254, param2=0},

		-- z=4, y=4
		{name="stairs:stair_stonebrick", prob=254, param2=1},
		{name="default:stonebrick", prob=254, param2=0},
		{name="default:stonebrick", prob=254, param2=0},
		{name="default:stonebrick", prob=254, param2=0},
		{name="default:stonebrick", prob=254, param2=0},
		{name="default:stonebrick", prob=254, param2=0},
		{name="default:stonebrick", prob=254, param2=0},
		{name="stairs:stair_stonebrick", prob=254, param2=3},

		-- z=4, y=5
		{name="air", prob=254, param2=0},
		{name="air", prob=254, param2=0},
		{name="air", prob=254, param2=0},
		{name="air", prob=254, param2=0},
		{name="air", prob=254, param2=0},
		{name="air", prob=254, param2=0},
		{name="air", prob=254, param2=0},
		{name="air", prob=254, param2=0},

		-- z=5, y=0
		{name="default:stonebrick", prob=254, param2=0},
		{name="default:stonebrick", prob=254, param2=0},
		{name="default:stonebrick", prob=254, param2=0},
		{name="default:stonebrick", prob=254, param2=0},
		{name="default:stonebrick", prob=254, param2=0},
		{name="default:stonebrick", prob=254, param2=0},
		{name="default:stonebrick", prob=254, param2=0},
		{name="default:stonebrick", prob=254, param2=0},

		-- z=5, y=1
		{name="default:stonebrick", prob=254, param2=0},
		{name="air", prob=254, param2=0},
		{name="air", prob=254, param2=0},
		{name="air", prob=254, param2=0},
		{name="default:stonebrick", prob=254, param2=0},
		{name="default:stonebrick", prob=254, param2=0},
		{name="default:stonebrick", prob=254, param2=0},
		{name="default:stonebrick", prob=254, param2=0},

		-- z=5, y=2
		{name="default:stonebrick", prob=254, param2=0},
		{name="air", prob=254, param2=0},
		{name="air", prob=254, param2=0},
		{name="air", prob=254, param2=0},
		{name="air", prob=254, param2=0},
		{name="air", prob=254, param2=0},
		{name="air", prob=254, param2=0},
		{name="default:stonebrick", prob=254, param2=0},

		-- z=5, y=3
		{name="default:stonebrick", prob=254, param2=0},
		{name="air", prob=254, param2=0},
		{name="air", prob=254, param2=0},
		{name="air", prob=254, param2=0},
		{name="air", prob=254, param2=0},
		{name="air", prob=254, param2=0},
		{name="air", prob=254, param2=0},
		{name="default:stonebrick", prob=254, param2=0},

		-- z=5, y=4
		{name="stairs:stair_stonebrick", prob=254, param2=1},
		{name="default:stonebrick", prob=254, param2=0},
		{name="default:stonebrick", prob=254, param2=0},
		{name="default:stonebrick", prob=254, param2=0},
		{name="default:stonebrick", prob=254, param2=0},
		{name="default:stonebrick", prob=254, param2=0},
		{name="default:stonebrick", prob=254, param2=0},
		{name="stairs:stair_stonebrick", prob=254, param2=3},

		-- z=5, y=5
		{name="air", prob=254, param2=0},
		{name="air", prob=254, param2=0},
		{name="air", prob=254, param2=0},
		{name="air", prob=254, param2=0},
		{name="stairs:slab_stonebrick", prob=254, param2=0},
		{name="stairs:stair_stonebrick", prob=254, param2=0},
		{name="stairs:slab_stonebrick", prob=254, param2=0},
		{name="air", prob=254, param2=0},

		-- z=6, y=0
		{name="default:stonebrick", prob=254, param2=0},
		{name="default:stonebrick", prob=254, param2=0},
		{name="default:stonebrick", prob=254, param2=0},
		{name="default:stonebrick", prob=254, param2=0},
		{name="default:stonebrick", prob=254, param2=0},
		{name="default:stonebrick", prob=254, param2=0},
		{name="default:stonebrick", prob=254, param2=0},
		{name="default:stonebrick", prob=254, param2=0},

		-- z=6, y=1
		{name="default:stonebrick", prob=254, param2=0},
		{name="air", prob=254, param2=0},
		{name="air", prob=254, param2=0},
		{name="air", prob=254, param2=0},
		{name="default:stonebrick", prob=254, param2=0},
		{name="default:lava_source", prob=254, param2=0},
		{name="default:lava_source", prob=254, param2=0},
		{name="default:stonebrick", prob=254, param2=0},

		-- z=6, y=2
		{name="default:stonebrick", prob=254, param2=0},
		{name="air", prob=254, param2=0},
		{name="air", prob=254, param2=0},
		{name="air", prob=254, param2=0},
		{name="air", prob=254, param2=0},
		{name="air", prob=254, param2=0},
		{name="air", prob=254, param2=0},
		{name="default:stonebrick", prob=254, param2=0},

		-- z=6, y=3
		{name="default:stonebrick", prob=254, param2=0},
		{name="air", prob=254, param2=0},
		{name="air", prob=254, param2=0},
		{name="air", prob=254, param2=0},
		{name="air", prob=254, param2=0},
		{name="air", prob=254, param2=0},
		{name="air", prob=254, param2=0},
		{name="default:stonebrick", prob=254, param2=0},

		-- z=6, y=4
		{name="stairs:stair_stonebrick", prob=254, param2=1},
		{name="default:stonebrick", prob=254, param2=0},
		{name="default:stonebrick", prob=254, param2=0},
		{name="default:stonebrick", prob=254, param2=0},
		{name="default:stonebrick", prob=254, param2=0},
		{name="air", prob=254, param2=0},
		{name="default:stonebrick", prob=254, param2=0},
		{name="stairs:stair_stonebrick", prob=254, param2=3},

		-- z=6, y=5
		{name="air", prob=254, param2=0},
		{name="air", prob=254, param2=0},
		{name="air", prob=254, param2=0},
		{name="air", prob=254, param2=0},
		{name="stairs:stair_stonebrick", prob=254, param2=1},
		{name="air", prob=254, param2=0},
		{name="stairs:stair_stonebrick", prob=254, param2=3},
		{name="air", prob=254, param2=0},

		-- z=7, y=0
		{name="default:stonebrick", prob=254, param2=0},
		{name="default:stonebrick", prob=254, param2=0},
		{name="default:stonebrick", prob=254, param2=0},
		{name="default:stonebrick", prob=254, param2=0},
		{name="default:stonebrick", prob=254, param2=0},
		{name="default:stonebrick", prob=254, param2=0},
		{name="default:stonebrick", prob=254, param2=0},
		{name="default:stonebrick", prob=254, param2=0},

		-- z=7, y=1
		{name="default:stonebrick", prob=254, param2=0},
		{name="default:chest", prob=254, param2=0},
		{name="air", prob=254, param2=0},
		{name="default:furnace", prob=254, param2=0},
		{name="default:stonebrick", prob=254, param2=0},
		{name="default:lava_source", prob=254, param2=0},
		{name="default:lava_source", prob=254, param2=0},
		{name="default:stonebrick", prob=254, param2=0},

		-- z=7, y=2
		{name="default:stonebrick", prob=254, param2=0},
		{name="air", prob=254, param2=0},
		{name="air", prob=254, param2=0},
		{name="default:torch_wall", prob=254, param2=4},
		{name="air", prob=254, param2=0},
		{name="air", prob=254, param2=0},
		{name="air", prob=254, param2=0},
		{name="default:stonebrick", prob=254, param2=0},

		-- z=7, y=3
		{name="default:stonebrick", prob=254, param2=0},
		{name="air", prob=254, param2=0},
		{name="air", prob=254, param2=0},
		{name="air", prob=254, param2=0},
		{name="air", prob=254, param2=0},
		{name="air", prob=254, param2=0},
		{name="air", prob=254, param2=0},
		{name="default:stonebrick", prob=254, param2=0},

		-- z=7, y=4
		{name="stairs:stair_stonebrick", prob=254, param2=1},
		{name="default:stonebrick", prob=254, param2=0},
		{name="default:stonebrick", prob=254, param2=0},
		{name="default:stonebrick", prob=254, param2=0},
		{name="default:stonebrick", prob=254, param2=0},
		{name="default:stonebrick", prob=254, param2=0},
		{name="default:stonebrick", prob=254, param2=0},
		{name="stairs:stair_stonebrick", prob=254, param2=3},

		-- z=7, y=5
		{name="air", prob=254, param2=0},
		{name="air", prob=254, param2=0},
		{name="air", prob=254, param2=0},
		{name="air", prob=254, param2=0},
		{name="stairs:slab_stonebrick", prob=254, param2=0},
		{name="stairs:stair_stonebrick", prob=254, param2=2},
		{name="stairs:slab_stonebrick", prob=254, param2=0},
		{name="air", prob=254, param2=0},

		-- z=8, y=0
		{name="default:stonebrick", prob=254, param2=0},
		{name="default:stonebrick", prob=254, param2=0},
		{name="default:stonebrick", prob=254, param2=0},
		{name="default:stonebrick", prob=254, param2=0},
		{name="default:stonebrick", prob=254, param2=0},
		{name="default:stonebrick", prob=254, param2=0},
		{name="default:stonebrick", prob=254, param2=0},
		{name="default:stonebrick", prob=254, param2=0},

		-- z=8, y=1
		{name="default:stonebrick", prob=254, param2=0},
		{name="default:stonebrick", prob=254, param2=0},
		{name="default:stonebrick", prob=254, param2=0},
		{name="default:stonebrick", prob=254, param2=0},
		{name="default:stonebrick", prob=254, param2=0},
		{name="default:stonebrick", prob=254, param2=0},
		{name="default:stonebrick", prob=254, param2=0},
		{name="default:stonebrick", prob=254, param2=0},

		-- z=8, y=2
		{name="default:stonebrick", prob=254, param2=0},
		{name="default:stonebrick", prob=254, param2=0},
		{name="default:stonebrick", prob=254, param2=0},
		{name="default:stonebrick", prob=254, param2=0},
		{name="default:stonebrick", prob=254, param2=0},
		{name="default:stonebrick", prob=254, param2=0},
		{name="default:stonebrick", prob=254, param2=0},
		{name="default:stonebrick", prob=254, param2=0},

		-- z=8, y=3
		{name="default:stonebrick", prob=254, param2=0},
		{name="default:stonebrick", prob=254, param2=0},
		{name="default:stonebrick", prob=254, param2=0},
		{name="default:stonebrick", prob=254, param2=0},
		{name="default:stonebrick", prob=254, param2=0},
		{name="default:stonebrick", prob=254, param2=0},
		{name="default:stonebrick", prob=254, param2=0},
		{name="default:stonebrick", prob=254, param2=0},

		-- z=8, y=4
		{name="stairs:slab_stonebrick", prob=254, param2=0},
		{name="stairs:stair_stonebrick", prob=254, param2=2},
		{name="stairs:stair_stonebrick", prob=254, param2=2},
		{name="stairs:stair_stonebrick", prob=254, param2=2},
		{name="stairs:stair_stonebrick", prob=254, param2=2},
		{name="stairs:stair_stonebrick", prob=254, param2=2},
		{name="stairs:stair_stonebrick", prob=254, param2=2},
		{name="stairs:slab_stonebrick", prob=254, param2=0},

		-- z=8, y=5
		{name="air", prob=254, param2=0},
		{name="air", prob=254, param2=0},
		{name="air", prob=254, param2=0},
		{name="air", prob=254, param2=0},
		{name="air", prob=254, param2=0},
		{name="air", prob=254, param2=0},
		{name="air", prob=254, param2=0},
		{name="air", prob=254, param2=0},
	},
}

return schematic