schematic = {
	size = {x=6, y=7, z=6},
	yslice_prob = {
		{ypos=0, prob=254},
		{ypos=1, prob=254},
		{ypos=2, prob=254},
		{ypos=3, prob=254},
		{ypos=4, prob=254},
		{ypos=5, prob=254},
		{ypos=6, prob=254},
	},
	data = {

		-- z=0, y=0
		{name="default:desert_sand", prob=254, param2=0},
		{name="default:desert_sand", prob=254, param2=0},
		{name="default:desert_sand", prob=254, param2=0},
		{name="default:desert_sand", prob=254, param2=0},
		{name="default:desert_sand", prob=254, param2=0},
		{name="default:desert_sand", prob=254, param2=0},

		-- z=0, y=1
		{name="air", prob=254, param2=0},
		{name="air", prob=254, param2=0},
		{name="dryplants:reed_slab", prob=254, param2=8},
		{name="cottages:half_door", prob=254, param2=0},
		{name="air", prob=254, param2=0},
		{name="air", prob=254, param2=0},

		-- z=0, y=2
		{name="air", prob=254, param2=0},
		{name="air", prob=254, param2=0},
		{name="dryplants:reed_slab", prob=254, param2=8},
		{name="cottages:half_door", prob=254, param2=0},
		{name="air", prob=254, param2=0},
		{name="air", prob=254, param2=0},

		-- z=0, y=3
		{name="air", prob=254, param2=0},
		{name="dryplants:wetreed_slab", prob=254, param2=2},
		{name="dryplants:wetreed_roof", prob=254, param2=0},
		{name="dryplants:wetreed_roof", prob=254, param2=0},
		{name="dryplants:wetreed_slab", prob=254, param2=2},
		{name="air", prob=254, param2=0},

		-- z=0, y=4
		{name="air", prob=254, param2=0},
		{name="air", prob=254, param2=0},
		{name="air", prob=254, param2=0},
		{name="air", prob=254, param2=0},
		{name="air", prob=254, param2=0},
		{name="air", prob=254, param2=0},

		-- z=0, y=5
		{name="air", prob=254, param2=0},
		{name="air", prob=254, param2=0},
		{name="air", prob=254, param2=0},
		{name="air", prob=254, param2=0},
		{name="air", prob=254, param2=0},
		{name="air", prob=254, param2=0},

		-- z=0, y=6
		{name="air", prob=254, param2=0},
		{name="air", prob=254, param2=0},
		{name="air", prob=254, param2=0},
		{name="air", prob=254, param2=0},
		{name="air", prob=254, param2=0},
		{name="air", prob=254, param2=0},

		-- z=1, y=0
		{name="default:desert_sand", prob=254, param2=0},
		{name="default:desert_sand", prob=254, param2=0},
		{name="default:desert_sand", prob=254, param2=0},
		{name="default:desert_sand", prob=254, param2=0},
		{name="default:desert_sand", prob=254, param2=0},
		{name="default:desert_sand", prob=254, param2=0},

		-- z=1, y=1
		{name="air", prob=254, param2=0},
		{name="dryplants:reed_roof", prob=254, param2=16},
		{name="air", prob=254, param2=0},
		{name="air", prob=254, param2=0},
		{name="dryplants:reed_roof", prob=254, param2=5},
		{name="air", prob=254, param2=0},

		-- z=1, y=2
		{name="air", prob=254, param2=0},
		{name="dryplants:reed_roof", prob=254, param2=16},
		{name="air", prob=254, param2=0},
		{name="air", prob=254, param2=0},
		{name="dryplants:reed_roof", prob=254, param2=5},
		{name="air", prob=254, param2=0},

		-- z=1, y=3
		{name="dryplants:wetreed_slab", prob=254, param2=2},
		{name="dryplants:wetreed_slab", prob=254, param2=21},
		{name="air", prob=254, param2=0},
		{name="air", prob=254, param2=0},
		{name="dryplants:wetreed_slab", prob=254, param2=21},
		{name="dryplants:wetreed_slab", prob=254, param2=2},

		-- z=1, y=4
		{name="air", prob=254, param2=0},
		{name="air", prob=254, param2=0},
		{name="dryplants:wetreed_slab", prob=254, param2=1},
		{name="dryplants:wetreed_slab", prob=254, param2=1},
		{name="air", prob=254, param2=0},
		{name="air", prob=254, param2=0},

		-- z=1, y=5
		{name="air", prob=254, param2=0},
		{name="air", prob=254, param2=0},
		{name="air", prob=254, param2=0},
		{name="air", prob=254, param2=0},
		{name="air", prob=254, param2=0},
		{name="air", prob=254, param2=0},

		-- z=1, y=6
		{name="air", prob=254, param2=0},
		{name="air", prob=254, param2=0},
		{name="air", prob=254, param2=0},
		{name="air", prob=254, param2=0},
		{name="air", prob=254, param2=0},
		{name="air", prob=254, param2=0},

		-- z=2, y=0
		{name="default:desert_sand", prob=254, param2=0},
		{name="default:desert_sand", prob=254, param2=0},
		{name="default:desert_sand", prob=254, param2=0},
		{name="default:desert_sand", prob=254, param2=0},
		{name="default:desert_sand", prob=254, param2=0},
		{name="default:desert_sand", prob=254, param2=0},

		-- z=2, y=1
		{name="dryplants:reed_slab", prob=254, param2=17},
		{name="cottages:sleeping_mat", prob=254, param2=0},
		{name="cottages:sleeping_mat", prob=254, param2=0},
		{name="cottages:sleeping_mat", prob=254, param2=0},
		{name="cottages:sleeping_mat", prob=254, param2=0},
		{name="dryplants:reed_slab", prob=254, param2=15},

		-- z=2, y=2
		{name="dryplants:reed_slab", prob=254, param2=17},
		{name="air", prob=254, param2=0},
		{name="air", prob=254, param2=0},
		{name="air", prob=254, param2=0},
		{name="air", prob=254, param2=0},
		{name="dryplants:reed_slab", prob=254, param2=15},

		-- z=2, y=3
		{name="dryplants:wetreed_roof", prob=254, param2=1},
		{name="air", prob=254, param2=0},
		{name="air", prob=254, param2=0},
		{name="air", prob=254, param2=0},
		{name="air", prob=254, param2=0},
		{name="dryplants:wetreed_roof", prob=254, param2=3},

		-- z=2, y=4
		{name="air", prob=254, param2=0},
		{name="dryplants:wetreed_slab", prob=254, param2=1},
		{name="dryplants:wetreed_slab", prob=254, param2=21},
		{name="dryplants:wetreed_slab", prob=254, param2=21},
		{name="dryplants:wetreed_slab", prob=254, param2=1},
		{name="air", prob=254, param2=0},

		-- z=2, y=5
		{name="air", prob=254, param2=0},
		{name="air", prob=254, param2=0},
		{name="air", prob=254, param2=0},
		{name="air", prob=254, param2=0},
		{name="air", prob=254, param2=0},
		{name="air", prob=254, param2=0},

		-- z=2, y=6
		{name="air", prob=254, param2=0},
		{name="air", prob=254, param2=0},
		{name="air", prob=254, param2=0},
		{name="air", prob=254, param2=0},
		{name="air", prob=254, param2=0},
		{name="air", prob=254, param2=0},

		-- z=3, y=0
		{name="default:desert_sand", prob=254, param2=0},
		{name="default:desert_sand", prob=254, param2=0},
		{name="default:desert_sand", prob=254, param2=0},
		{name="default:desert_sand", prob=254, param2=0},
		{name="default:desert_sand", prob=254, param2=0},
		{name="default:desert_sand", prob=254, param2=0},

		-- z=3, y=1
		{name="dryplants:reed_slab", prob=254, param2=17},
		{name="cottages:sleeping_mat_head", prob=254, param2=0},
		{name="cottages:sleeping_mat_head", prob=254, param2=0},
		{name="cottages:sleeping_mat_head", prob=254, param2=0},
		{name="cottages:sleeping_mat_head", prob=254, param2=0},
		{name="dryplants:reed_slab", prob=254, param2=15},

		-- z=3, y=2
		{name="cottages:half_door", prob=254, param2=1},
		{name="air", prob=254, param2=0},
		{name="air", prob=254, param2=0},
		{name="air", prob=254, param2=0},
		{name="air", prob=254, param2=0},
		{name="dryplants:reed_slab", prob=254, param2=15},

		-- z=3, y=3
		{name="dryplants:wetreed_roof", prob=254, param2=1},
		{name="air", prob=254, param2=0},
		{name="air", prob=254, param2=0},
		{name="air", prob=254, param2=0},
		{name="air", prob=254, param2=0},
		{name="dryplants:wetreed_roof", prob=254, param2=3},

		-- z=3, y=4
		{name="air", prob=254, param2=0},
		{name="dryplants:wetreed_slab", prob=254, param2=1},
		{name="dryplants:wetreed_slab", prob=254, param2=21},
		{name="dryplants:wetreed_slab", prob=254, param2=21},
		{name="dryplants:wetreed_slab", prob=254, param2=1},
		{name="air", prob=254, param2=0},

		-- z=3, y=5
		{name="air", prob=254, param2=0},
		{name="air", prob=254, param2=0},
		{name="air", prob=254, param2=0},
		{name="air", prob=254, param2=0},
		{name="air", prob=254, param2=0},
		{name="air", prob=254, param2=0},

		-- z=3, y=6
		{name="air", prob=254, param2=0},
		{name="air", prob=254, param2=0},
		{name="air", prob=254, param2=0},
		{name="air", prob=254, param2=0},
		{name="air", prob=254, param2=0},
		{name="air", prob=254, param2=0},

		-- z=4, y=0
		{name="default:desert_sand", prob=254, param2=0},
		{name="default:desert_sand", prob=254, param2=0},
		{name="default:desert_sand", prob=254, param2=0},
		{name="default:desert_sand", prob=254, param2=0},
		{name="default:desert_sand", prob=254, param2=0},
		{name="default:desert_sand", prob=254, param2=0},

		-- z=4, y=1
		{name="air", prob=254, param2=0},
		{name="dryplants:reed_roof", prob=254, param2=5},
		{name="default:chest", prob=254, param2=0},
		{name="default:chest", prob=254, param2=0},
		{name="dryplants:reed_roof", prob=254, param2=9},
		{name="air", prob=254, param2=0},

		-- z=4, y=2
		{name="air", prob=254, param2=0},
		{name="dryplants:reed_roof", prob=254, param2=5},
		{name="air", prob=254, param2=0},
		{name="air", prob=254, param2=0},
		{name="dryplants:reed_roof", prob=254, param2=9},
		{name="air", prob=254, param2=0},

		-- z=4, y=3
		{name="dryplants:wetreed_slab", prob=254, param2=2},
		{name="dryplants:wetreed_slab", prob=254, param2=21},
		{name="air", prob=254, param2=0},
		{name="air", prob=254, param2=0},
		{name="dryplants:wetreed_slab", prob=254, param2=21},
		{name="dryplants:wetreed_slab", prob=254, param2=2},

		-- z=4, y=4
		{name="air", prob=254, param2=0},
		{name="air", prob=254, param2=0},
		{name="dryplants:wetreed_slab", prob=254, param2=1},
		{name="dryplants:wetreed_slab", prob=254, param2=1},
		{name="air", prob=254, param2=0},
		{name="air", prob=254, param2=0},

		-- z=4, y=5
		{name="air", prob=254, param2=0},
		{name="air", prob=254, param2=0},
		{name="air", prob=254, param2=0},
		{name="air", prob=254, param2=0},
		{name="air", prob=254, param2=0},
		{name="air", prob=254, param2=0},

		-- z=4, y=6
		{name="air", prob=254, param2=0},
		{name="air", prob=254, param2=0},
		{name="air", prob=254, param2=0},
		{name="air", prob=254, param2=0},
		{name="air", prob=254, param2=0},
		{name="air", prob=254, param2=0},

		-- z=5, y=0
		{name="default:desert_sand", prob=254, param2=0},
		{name="default:desert_sand", prob=254, param2=0},
		{name="default:desert_sand", prob=254, param2=0},
		{name="default:desert_sand", prob=254, param2=0},
		{name="default:desert_sand", prob=254, param2=0},
		{name="default:desert_sand", prob=254, param2=0},

		-- z=5, y=1
		{name="air", prob=254, param2=0},
		{name="air", prob=254, param2=0},
		{name="dryplants:reed_slab", prob=254, param2=5},
		{name="dryplants:reed_slab", prob=254, param2=5},
		{name="air", prob=254, param2=0},
		{name="air", prob=254, param2=0},

		-- z=5, y=2
		{name="air", prob=254, param2=0},
		{name="air", prob=254, param2=0},
		{name="dryplants:reed_slab", prob=254, param2=5},
		{name="dryplants:reed_slab", prob=254, param2=5},
		{name="air", prob=254, param2=0},
		{name="air", prob=254, param2=0},

		-- z=5, y=3
		{name="air", prob=254, param2=0},
		{name="dryplants:wetreed_slab", prob=254, param2=2},
		{name="dryplants:wetreed_roof", prob=254, param2=2},
		{name="dryplants:wetreed_roof", prob=254, param2=2},
		{name="dryplants:wetreed_slab", prob=254, param2=2},
		{name="air", prob=254, param2=0},

		-- z=5, y=4
		{name="air", prob=254, param2=0},
		{name="air", prob=254, param2=0},
		{name="air", prob=254, param2=0},
		{name="air", prob=254, param2=0},
		{name="air", prob=254, param2=0},
		{name="air", prob=254, param2=0},

		-- z=5, y=5
		{name="air", prob=254, param2=0},
		{name="air", prob=254, param2=0},
		{name="air", prob=254, param2=0},
		{name="air", prob=254, param2=0},
		{name="air", prob=254, param2=0},
		{name="air", prob=254, param2=0},

		-- z=5, y=6
		{name="air", prob=254, param2=0},
		{name="air", prob=254, param2=0},
		{name="air", prob=254, param2=0},
		{name="air", prob=254, param2=0},
		{name="air", prob=254, param2=0},
		{name="air", prob=254, param2=0},
	},
}

return schematic