schematic = {
	size = {x=9, y=8, z=7},
	yslice_prob = {
		{ypos=0, prob=254},
		{ypos=1, prob=254},
		{ypos=2, prob=254},
		{ypos=3, prob=254},
		{ypos=4, prob=254},
		{ypos=5, prob=254},
		{ypos=6, prob=254},
		{ypos=7, prob=254},
	},
	data = {

		-- z=0, y=0
		{name="default:dirt_with_grass", prob=254, param2=0},
		{name="default:dirt_with_grass", prob=254, param2=0},
		{name="default:dirt_with_grass", prob=254, param2=0},
		{name="default:dirt_with_grass", prob=254, param2=0},
		{name="default:dirt_with_grass", prob=254, param2=0},
		{name="default:dirt_with_grass", prob=254, param2=0},
		{name="default:dirt_with_grass", prob=254, param2=0},
		{name="default:dirt_with_grass", prob=254, param2=0},
		{name="default:dirt_with_grass", prob=254, param2=0},

		-- z=0, y=1
		{name="air", prob=254, param2=0},
		{name="air", prob=254, param2=0},
		{name="air", prob=254, param2=0},
		{name="air", prob=254, param2=0},
		{name="air", prob=254, param2=0},
		{name="default:torch_wall", prob=254, param2=4},
		{name="air", prob=254, param2=0},
		{name="air", prob=254, param2=0},
		{name="air", prob=254, param2=0},

		-- z=0, y=2
		{name="cottages:roof_straw", prob=254, param2=0},
		{name="cottages:roof_straw", prob=254, param2=0},
		{name="cottages:roof_straw", prob=254, param2=0},
		{name="cottages:roof_straw", prob=254, param2=0},
		{name="cottages:roof_straw", prob=254, param2=0},
		{name="cottages:roof_straw", prob=254, param2=0},
		{name="cottages:roof_straw", prob=254, param2=0},
		{name="cottages:roof_straw", prob=254, param2=0},
		{name="cottages:roof_straw", prob=254, param2=0},

		-- z=0, y=3
		{name="air", prob=254, param2=0},
		{name="air", prob=254, param2=0},
		{name="air", prob=254, param2=0},
		{name="air", prob=254, param2=0},
		{name="air", prob=254, param2=0},
		{name="air", prob=254, param2=0},
		{name="air", prob=254, param2=0},
		{name="air", prob=254, param2=0},
		{name="air", prob=254, param2=0},

		-- z=0, y=4
		{name="air", prob=254, param2=0},
		{name="air", prob=254, param2=0},
		{name="air", prob=254, param2=0},
		{name="air", prob=254, param2=0},
		{name="air", prob=254, param2=0},
		{name="air", prob=254, param2=0},
		{name="air", prob=254, param2=0},
		{name="air", prob=254, param2=0},
		{name="air", prob=254, param2=0},

		-- z=0, y=5
		{name="air", prob=254, param2=0},
		{name="air", prob=254, param2=0},
		{name="air", prob=254, param2=0},
		{name="air", prob=254, param2=0},
		{name="air", prob=254, param2=0},
		{name="air", prob=254, param2=0},
		{name="air", prob=254, param2=0},
		{name="air", prob=254, param2=0},
		{name="air", prob=254, param2=0},

		-- z=0, y=6
		{name="air", prob=254, param2=0},
		{name="air", prob=254, param2=0},
		{name="air", prob=254, param2=0},
		{name="air", prob=254, param2=0},
		{name="air", prob=254, param2=0},
		{name="air", prob=254, param2=0},
		{name="air", prob=254, param2=0},
		{name="air", prob=254, param2=0},
		{name="air", prob=254, param2=0},

		-- z=0, y=7
		{name="air", prob=254, param2=0},
		{name="air", prob=254, param2=0},
		{name="air", prob=254, param2=0},
		{name="air", prob=254, param2=0},
		{name="air", prob=254, param2=0},
		{name="air", prob=254, param2=0},
		{name="air", prob=254, param2=0},
		{name="air", prob=254, param2=0},
		{name="air", prob=254, param2=0},

		-- z=1, y=0
		{name="default:dirt_with_grass", prob=254, param2=0},
		{name="default:dirt_with_grass", prob=254, param2=0},
		{name="default:tree", prob=254, param2=0},
		{name="default:sandstone", prob=254, param2=0},
		{name="default:sandstone", prob=254, param2=0},
		{name="default:sandstone", prob=254, param2=0},
		{name="default:sandstone", prob=254, param2=0},
		{name="default:tree", prob=254, param2=0},
		{name="default:dirt_with_grass", prob=254, param2=0},

		-- z=1, y=1
		{name="air", prob=254, param2=0},
		{name="air", prob=254, param2=8},
		{name="default:tree", prob=254, param2=0},
		{name="cottages:loam", prob=254, param2=0},
		{name="default:cobble", prob=254, param2=0},
		{name="cottages:loam", prob=254, param2=0},
		{name="cottages:loam", prob=254, param2=0},
		{name="default:tree", prob=254, param2=0},
		{name="air", prob=254, param2=0},

		-- z=1, y=2
		{name="air", prob=254, param2=0},
		{name="air", prob=254, param2=2},
		{name="default:tree", prob=254, param2=0},
		{name="cottages:loam", prob=254, param2=0},
		{name="default:cobble", prob=254, param2=0},
		{name="cottages:loam", prob=254, param2=0},
		{name="cottages:loam", prob=254, param2=0},
		{name="default:tree", prob=254, param2=0},
		{name="air", prob=254, param2=0},

		-- z=1, y=3
		{name="cottages:roof_straw", prob=254, param2=0},
		{name="cottages:roof_straw", prob=254, param2=0},
		{name="cottages:roof_connector_straw", prob=254, param2=0},
		{name="cottages:roof_connector_straw", prob=254, param2=0},
		{name="default:cobble", prob=254, param2=0},
		{name="cottages:roof_connector_straw", prob=254, param2=0},
		{name="cottages:roof_connector_straw", prob=254, param2=0},
		{name="cottages:roof_connector_straw", prob=254, param2=0},
		{name="cottages:roof_straw", prob=254, param2=0},

		-- z=1, y=4
		{name="air", prob=254, param2=0},
		{name="air", prob=254, param2=0},
		{name="air", prob=254, param2=0},
		{name="air", prob=254, param2=0},
		{name="default:cobble", prob=254, param2=0},
		{name="air", prob=254, param2=0},
		{name="air", prob=254, param2=0},
		{name="air", prob=254, param2=0},
		{name="air", prob=254, param2=0},

		-- z=1, y=5
		{name="air", prob=254, param2=0},
		{name="air", prob=254, param2=0},
		{name="air", prob=254, param2=0},
		{name="air", prob=254, param2=0},
		{name="default:furnace", prob=254, param2=0},
		{name="air", prob=254, param2=0},
		{name="air", prob=254, param2=0},
		{name="air", prob=254, param2=0},
		{name="air", prob=254, param2=0},

		-- z=1, y=6
		{name="air", prob=254, param2=0},
		{name="air", prob=254, param2=0},
		{name="air", prob=254, param2=0},
		{name="air", prob=254, param2=0},
		{name="air", prob=254, param2=0},
		{name="air", prob=254, param2=0},
		{name="air", prob=254, param2=0},
		{name="air", prob=254, param2=0},
		{name="air", prob=254, param2=0},

		-- z=1, y=7
		{name="air", prob=254, param2=0},
		{name="air", prob=254, param2=0},
		{name="air", prob=254, param2=0},
		{name="air", prob=254, param2=0},
		{name="air", prob=254, param2=0},
		{name="air", prob=254, param2=0},
		{name="air", prob=254, param2=0},
		{name="air", prob=254, param2=0},
		{name="air", prob=254, param2=0},

		-- z=2, y=0
		{name="default:dirt_with_grass", prob=254, param2=0},
		{name="default:dirt_with_grass", prob=254, param2=0},
		{name="default:sandstone", prob=254, param2=0},
		{name="default:sandstone", prob=254, param2=0},
		{name="default:sandstone", prob=254, param2=0},
		{name="default:sandstone", prob=254, param2=0},
		{name="default:sandstone", prob=254, param2=0},
		{name="default:sandstone", prob=254, param2=0},
		{name="default:dirt_with_grass", prob=254, param2=0},

		-- z=2, y=1
		{name="air", prob=254, param2=19},
		{name="air", prob=254, param2=0},
		{name="cottages:loam", prob=254, param2=0},
		{name="cottages:shelf", prob=254, param2=2},
		{name="default:furnace", prob=254, param2=2},
		{name="cottages:shelf", prob=254, param2=2},
		{name="cottages:bed_head", prob=254, param2=2},
		{name="cottages:loam", prob=254, param2=0},
		{name="air", prob=254, param2=0},

		-- z=2, y=2
		{name="air", prob=254, param2=19},
		{name="air", prob=254, param2=0},
		{name="cottages:loam", prob=254, param2=0},
		{name="air", prob=254, param2=0},
		{name="air", prob=254, param2=13},
		{name="default:ladder", prob=254, param2=2},
		{name="air", prob=254, param2=0},
		{name="cottages:loam", prob=254, param2=0},
		{name="air", prob=254, param2=0},

		-- z=2, y=3
		{name="air", prob=254, param2=0},
		{name="default:torch_wall", prob=254, param2=2},
		{name="cottages:loam", prob=254, param2=0},
		{name="air", prob=254, param2=20},
		{name="air", prob=254, param2=0},
		{name="default:ladder", prob=254, param2=2},
		{name="stairs:slab_wood", prob=254, param2=0},
		{name="cottages:loam", prob=254, param2=0},
		{name="air", prob=254, param2=0},

		-- z=2, y=4
		{name="cottages:roof_straw", prob=254, param2=0},
		{name="cottages:roof_straw", prob=254, param2=0},
		{name="cottages:roof_connector_straw", prob=254, param2=0},
		{name="cottages:roof_straw", prob=254, param2=0},
		{name="cottages:roof_straw", prob=254, param2=0},
		{name="cottages:roof_straw", prob=254, param2=0},
		{name="cottages:roof_straw", prob=254, param2=0},
		{name="cottages:roof_connector_straw", prob=254, param2=0},
		{name="cottages:roof_straw", prob=254, param2=0},

		-- z=2, y=5
		{name="air", prob=254, param2=0},
		{name="air", prob=254, param2=0},
		{name="air", prob=254, param2=0},
		{name="air", prob=254, param2=0},
		{name="air", prob=254, param2=0},
		{name="air", prob=254, param2=0},
		{name="air", prob=254, param2=0},
		{name="air", prob=254, param2=0},
		{name="air", prob=254, param2=0},

		-- z=2, y=6
		{name="air", prob=254, param2=0},
		{name="air", prob=254, param2=0},
		{name="air", prob=254, param2=0},
		{name="air", prob=254, param2=0},
		{name="air", prob=254, param2=0},
		{name="air", prob=254, param2=0},
		{name="air", prob=254, param2=0},
		{name="air", prob=254, param2=0},
		{name="air", prob=254, param2=0},

		-- z=2, y=7
		{name="air", prob=254, param2=0},
		{name="air", prob=254, param2=0},
		{name="air", prob=254, param2=0},
		{name="air", prob=254, param2=0},
		{name="air", prob=254, param2=0},
		{name="air", prob=254, param2=0},
		{name="air", prob=254, param2=0},
		{name="air", prob=254, param2=0},
		{name="air", prob=254, param2=0},

		-- z=3, y=0
		{name="default:dirt_with_grass", prob=254, param2=0},
		{name="default:dirt_with_grass", prob=254, param2=0},
		{name="default:sandstone", prob=254, param2=0},
		{name="default:sandstone", prob=254, param2=0},
		{name="default:sandstone", prob=254, param2=0},
		{name="default:sandstone", prob=254, param2=0},
		{name="default:sandstone", prob=254, param2=0},
		{name="default:sandstone", prob=254, param2=0},
		{name="default:dirt_with_grass", prob=254, param2=0},

		-- z=3, y=1
		{name="air", prob=254, param2=19},
		{name="air", prob=254, param2=3},
		{name="doors:door_wood_a", prob=254, param2=1},
		{name="air", prob=254, param2=1},
		{name="air", prob=254, param2=13},
		{name="air", prob=254, param2=0},
		{name="cottages:bed_foot", prob=254, param2=2},
		{name="cottages:loam", prob=254, param2=0},
		{name="air", prob=254, param2=0},

		-- z=3, y=2
		{name="air", prob=254, param2=3},
		{name="air", prob=254, param2=3},
		{name="air", prob=254, param2=1},
		{name="air", prob=254, param2=0},
		{name="air", prob=254, param2=1},
		{name="air", prob=254, param2=0},
		{name="air", prob=254, param2=0},
		{name="cottages:loam", prob=254, param2=0},
		{name="air", prob=254, param2=0},

		-- z=3, y=3
		{name="air", prob=254, param2=0},
		{name="air", prob=254, param2=20},
		{name="cottages:loam", prob=254, param2=0},
		{name="air", prob=254, param2=20},
		{name="air", prob=254, param2=0},
		{name="air", prob=254, param2=0},
		{name="cottages:chest_work", prob=254, param2=1},
		{name="cottages:loam", prob=254, param2=0},
		{name="default:torch_wall", prob=254, param2=3},

		-- z=3, y=4
		{name="air", prob=254, param2=0},
		{name="cottages:window_shutter_open", prob=254, param2=1},
		{name="cottages:glass_pane", prob=254, param2=3},
		{name="air", prob=254, param2=0},
		{name="air", prob=254, param2=0},
		{name="air", prob=254, param2=0},
		{name="cottages:shelf", prob=254, param2=1},
		{name="cottages:loam", prob=254, param2=0},
		{name="air", prob=254, param2=0},

		-- z=3, y=5
		{name="cottages:roof_flat_straw", prob=254, param2=1},
		{name="cottages:roof_flat_straw", prob=254, param2=1},
		{name="cottages:roof_flat_straw", prob=254, param2=1},
		{name="cottages:roof_flat_straw", prob=254, param2=3},
		{name="cottages:roof_flat_straw", prob=254, param2=3},
		{name="cottages:roof_flat_straw", prob=254, param2=3},
		{name="cottages:roof_flat_straw", prob=254, param2=3},
		{name="cottages:roof_flat_straw", prob=254, param2=3},
		{name="cottages:roof_flat_straw", prob=254, param2=3},

		-- z=3, y=6
		{name="air", prob=254, param2=0},
		{name="air", prob=254, param2=0},
		{name="air", prob=254, param2=0},
		{name="air", prob=254, param2=0},
		{name="air", prob=254, param2=0},
		{name="air", prob=254, param2=0},
		{name="air", prob=254, param2=0},
		{name="air", prob=254, param2=0},
		{name="air", prob=254, param2=0},

		-- z=3, y=7
		{name="air", prob=254, param2=0},
		{name="air", prob=254, param2=0},
		{name="air", prob=254, param2=0},
		{name="air", prob=254, param2=0},
		{name="air", prob=254, param2=0},
		{name="air", prob=254, param2=0},
		{name="air", prob=254, param2=0},
		{name="air", prob=254, param2=0},
		{name="air", prob=254, param2=0},

		-- z=4, y=0
		{name="default:dirt_with_grass", prob=254, param2=0},
		{name="default:dirt_with_grass", prob=254, param2=0},
		{name="default:sandstone", prob=254, param2=0},
		{name="default:sandstone", prob=254, param2=0},
		{name="default:sandstone", prob=254, param2=0},
		{name="default:sandstone", prob=254, param2=0},
		{name="default:sandstone", prob=254, param2=0},
		{name="default:sandstone", prob=254, param2=0},
		{name="default:dirt_with_grass", prob=254, param2=0},

		-- z=4, y=1
		{name="air", prob=254, param2=19},
		{name="air", prob=254, param2=3},
		{name="cottages:loam", prob=254, param2=0},
		{name="cottages:bench", prob=254, param2=3},
		{name="cottages:table", prob=254, param2=0},
		{name="default:ladder", prob=254, param2=4},
		{name="cottages:bench", prob=254, param2=1},
		{name="cottages:loam", prob=254, param2=0},
		{name="air", prob=254, param2=0},

		-- z=4, y=2
		{name="air", prob=254, param2=19},
		{name="air", prob=254, param2=3},
		{name="cottages:loam", prob=254, param2=0},
		{name="air", prob=254, param2=0},
		{name="air", prob=254, param2=13},
		{name="default:ladder", prob=254, param2=4},
		{name="air", prob=254, param2=0},
		{name="cottages:glass_pane", prob=254, param2=1},
		{name="cottages:window_shutter_open", prob=254, param2=3},

		-- z=4, y=3
		{name="air", prob=254, param2=0},
		{name="default:torch_wall", prob=254, param2=2},
		{name="cottages:loam", prob=254, param2=0},
		{name="air", prob=254, param2=20},
		{name="air", prob=254, param2=0},
		{name="default:ladder", prob=254, param2=4},
		{name="stairs:slab_wood", prob=254, param2=0},
		{name="cottages:loam", prob=254, param2=0},
		{name="air", prob=254, param2=0},

		-- z=4, y=4
		{name="cottages:roof_straw", prob=254, param2=2},
		{name="cottages:roof_straw", prob=254, param2=2},
		{name="cottages:roof_connector_straw", prob=254, param2=2},
		{name="cottages:roof_straw", prob=254, param2=2},
		{name="cottages:roof_straw", prob=254, param2=2},
		{name="cottages:roof_straw", prob=254, param2=2},
		{name="cottages:roof_straw", prob=254, param2=2},
		{name="cottages:roof_connector_straw", prob=254, param2=2},
		{name="cottages:roof_straw", prob=254, param2=2},

		-- z=4, y=5
		{name="air", prob=254, param2=0},
		{name="air", prob=254, param2=0},
		{name="air", prob=254, param2=0},
		{name="air", prob=254, param2=0},
		{name="air", prob=254, param2=0},
		{name="air", prob=254, param2=0},
		{name="air", prob=254, param2=0},
		{name="air", prob=254, param2=0},
		{name="air", prob=254, param2=0},

		-- z=4, y=6
		{name="air", prob=254, param2=0},
		{name="air", prob=254, param2=0},
		{name="air", prob=254, param2=0},
		{name="air", prob=254, param2=0},
		{name="air", prob=254, param2=0},
		{name="air", prob=254, param2=0},
		{name="air", prob=254, param2=0},
		{name="air", prob=254, param2=0},
		{name="air", prob=254, param2=0},

		-- z=4, y=7
		{name="air", prob=254, param2=0},
		{name="air", prob=254, param2=0},
		{name="air", prob=254, param2=0},
		{name="air", prob=254, param2=0},
		{name="air", prob=254, param2=0},
		{name="air", prob=254, param2=0},
		{name="air", prob=254, param2=0},
		{name="air", prob=254, param2=0},
		{name="air", prob=254, param2=0},

		-- z=5, y=0
		{name="default:dirt_with_grass", prob=254, param2=0},
		{name="default:dirt_with_grass", prob=254, param2=0},
		{name="default:tree", prob=254, param2=0},
		{name="default:sandstone", prob=254, param2=0},
		{name="default:sandstone", prob=254, param2=0},
		{name="default:sandstone", prob=254, param2=0},
		{name="default:sandstone", prob=254, param2=0},
		{name="default:tree", prob=254, param2=0},
		{name="default:dirt_with_grass", prob=254, param2=0},

		-- z=5, y=1
		{name="air", prob=254, param2=0},
		{name="air", prob=254, param2=4},
		{name="default:tree", prob=254, param2=0},
		{name="cottages:loam", prob=254, param2=0},
		{name="cottages:loam", prob=254, param2=0},
		{name="cottages:loam", prob=254, param2=0},
		{name="cottages:loam", prob=254, param2=0},
		{name="default:tree", prob=254, param2=0},
		{name="air", prob=254, param2=0},

		-- z=5, y=2
		{name="air", prob=254, param2=0},
		{name="air", prob=254, param2=4},
		{name="default:tree", prob=254, param2=0},
		{name="cottages:loam", prob=254, param2=0},
		{name="cottages:glass_pane", prob=254, param2=0},
		{name="cottages:loam", prob=254, param2=0},
		{name="cottages:loam", prob=254, param2=0},
		{name="default:tree", prob=254, param2=0},
		{name="air", prob=254, param2=0},

		-- z=5, y=3
		{name="cottages:roof_straw", prob=254, param2=2},
		{name="cottages:roof_straw", prob=254, param2=2},
		{name="cottages:roof_connector_straw", prob=254, param2=2},
		{name="cottages:roof_connector_straw", prob=254, param2=2},
		{name="cottages:roof_connector_straw", prob=254, param2=2},
		{name="cottages:roof_connector_straw", prob=254, param2=2},
		{name="cottages:roof_connector_straw", prob=254, param2=2},
		{name="cottages:roof_connector_straw", prob=254, param2=2},
		{name="cottages:roof_straw", prob=254, param2=2},

		-- z=5, y=4
		{name="air", prob=254, param2=0},
		{name="air", prob=254, param2=0},
		{name="air", prob=254, param2=0},
		{name="air", prob=254, param2=0},
		{name="air", prob=254, param2=0},
		{name="air", prob=254, param2=0},
		{name="air", prob=254, param2=0},
		{name="air", prob=254, param2=0},
		{name="air", prob=254, param2=0},

		-- z=5, y=5
		{name="air", prob=254, param2=0},
		{name="air", prob=254, param2=0},
		{name="air", prob=254, param2=0},
		{name="air", prob=254, param2=0},
		{name="air", prob=254, param2=0},
		{name="air", prob=254, param2=0},
		{name="air", prob=254, param2=0},
		{name="air", prob=254, param2=0},
		{name="air", prob=254, param2=0},

		-- z=5, y=6
		{name="air", prob=254, param2=0},
		{name="air", prob=254, param2=0},
		{name="air", prob=254, param2=0},
		{name="air", prob=254, param2=0},
		{name="air", prob=254, param2=0},
		{name="air", prob=254, param2=0},
		{name="air", prob=254, param2=0},
		{name="air", prob=254, param2=0},
		{name="air", prob=254, param2=0},

		-- z=5, y=7
		{name="air", prob=254, param2=0},
		{name="air", prob=254, param2=0},
		{name="air", prob=254, param2=0},
		{name="air", prob=254, param2=0},
		{name="air", prob=254, param2=0},
		{name="air", prob=254, param2=0},
		{name="air", prob=254, param2=0},
		{name="air", prob=254, param2=0},
		{name="air", prob=254, param2=0},

		-- z=6, y=0
		{name="default:dirt_with_grass", prob=254, param2=0},
		{name="default:dirt_with_grass", prob=254, param2=0},
		{name="default:dirt_with_grass", prob=254, param2=0},
		{name="default:dirt_with_grass", prob=254, param2=0},
		{name="default:dirt_with_grass", prob=254, param2=0},
		{name="default:dirt_with_grass", prob=254, param2=0},
		{name="default:dirt_with_grass", prob=254, param2=0},
		{name="default:dirt_with_grass", prob=254, param2=0},
		{name="default:dirt_with_grass", prob=254, param2=0},

		-- z=6, y=1
		{name="air", prob=254, param2=0},
		{name="air", prob=254, param2=0},
		{name="air", prob=254, param2=0},
		{name="air", prob=254, param2=0},
		{name="default:torch_wall", prob=254, param2=5},
		{name="air", prob=254, param2=0},
		{name="air", prob=254, param2=0},
		{name="air", prob=254, param2=0},
		{name="air", prob=254, param2=0},

		-- z=6, y=2
		{name="cottages:roof_straw", prob=254, param2=2},
		{name="cottages:roof_straw", prob=254, param2=2},
		{name="cottages:roof_straw", prob=254, param2=2},
		{name="cottages:roof_straw", prob=254, param2=2},
		{name="cottages:roof_straw", prob=254, param2=2},
		{name="cottages:roof_straw", prob=254, param2=2},
		{name="cottages:roof_straw", prob=254, param2=2},
		{name="cottages:roof_straw", prob=254, param2=2},
		{name="cottages:roof_straw", prob=254, param2=2},

		-- z=6, y=3
		{name="air", prob=254, param2=0},
		{name="air", prob=254, param2=0},
		{name="air", prob=254, param2=0},
		{name="air", prob=254, param2=0},
		{name="air", prob=254, param2=0},
		{name="air", prob=254, param2=0},
		{name="air", prob=254, param2=0},
		{name="air", prob=254, param2=0},
		{name="air", prob=254, param2=0},

		-- z=6, y=4
		{name="air", prob=254, param2=0},
		{name="air", prob=254, param2=0},
		{name="air", prob=254, param2=0},
		{name="air", prob=254, param2=0},
		{name="air", prob=254, param2=0},
		{name="air", prob=254, param2=0},
		{name="air", prob=254, param2=0},
		{name="air", prob=254, param2=0},
		{name="air", prob=254, param2=0},

		-- z=6, y=5
		{name="air", prob=254, param2=0},
		{name="air", prob=254, param2=0},
		{name="air", prob=254, param2=0},
		{name="air", prob=254, param2=0},
		{name="air", prob=254, param2=0},
		{name="air", prob=254, param2=0},
		{name="air", prob=254, param2=0},
		{name="air", prob=254, param2=0},
		{name="air", prob=254, param2=0},

		-- z=6, y=6
		{name="air", prob=254, param2=0},
		{name="air", prob=254, param2=0},
		{name="air", prob=254, param2=0},
		{name="air", prob=254, param2=0},
		{name="air", prob=254, param2=0},
		{name="air", prob=254, param2=0},
		{name="air", prob=254, param2=0},
		{name="air", prob=254, param2=0},
		{name="air", prob=254, param2=0},

		-- z=6, y=7
		{name="air", prob=254, param2=0},
		{name="air", prob=254, param2=0},
		{name="air", prob=254, param2=0},
		{name="air", prob=254, param2=0},
		{name="air", prob=254, param2=0},
		{name="air", prob=254, param2=0},
		{name="air", prob=254, param2=0},
		{name="air", prob=254, param2=0},
		{name="air", prob=254, param2=0},
	},
}

return schematic