schematic = {
	size = {x=7, y=14, z=15},
	yslice_prob = {
		{ypos=0, prob=254},
		{ypos=1, prob=254},
		{ypos=2, prob=254},
		{ypos=3, prob=254},
		{ypos=4, prob=254},
		{ypos=5, prob=254},
		{ypos=6, prob=254},
		{ypos=7, prob=254},
		{ypos=8, prob=254},
		{ypos=9, prob=254},
		{ypos=10, prob=254},
		{ypos=11, prob=254},
		{ypos=12, prob=254},
		{ypos=13, prob=254},
	},
	data = {

		-- z=0, y=0
		{name="default:wood", prob=254, param2=1},
		{name="default:wood", prob=254, param2=1},
		{name="default:wood", prob=254, param2=1},
		{name="default:wood", prob=254, param2=1},
		{name="default:wood", prob=254, param2=1},
		{name="default:wood", prob=254, param2=1},
		{name="default:wood", prob=254, param2=1},

		-- z=0, y=1
		{name="default:tree", prob=254, param2=1},
		{name="default:stonebrick", prob=254, param2=1},
		{name="default:stonebrick", prob=254, param2=1},
		{name="default:stonebrick", prob=254, param2=1},
		{name="default:stonebrick", prob=254, param2=1},
		{name="default:stonebrick", prob=254, param2=1},
		{name="default:tree", prob=254, param2=1},

		-- z=0, y=2
		{name="default:tree", prob=254, param2=1},
		{name="default:stonebrick", prob=254, param2=1},
		{name="default:stonebrick", prob=254, param2=1},
		{name="default:stonebrick", prob=254, param2=1},
		{name="default:glass", prob=254, param2=0},
		{name="default:stonebrick", prob=254, param2=1},
		{name="default:tree", prob=254, param2=1},

		-- z=0, y=3
		{name="default:tree", prob=254, param2=1},
		{name="default:stonebrick", prob=254, param2=1},
		{name="default:stonebrick", prob=254, param2=1},
		{name="default:stonebrick", prob=254, param2=1},
		{name="default:stonebrick", prob=254, param2=1},
		{name="default:stonebrick", prob=254, param2=1},
		{name="default:tree", prob=254, param2=1},

		-- z=0, y=4
		{name="default:tree", prob=254, param2=1},
		{name="default:stonebrick", prob=254, param2=1},
		{name="default:stonebrick", prob=254, param2=1},
		{name="default:stonebrick", prob=254, param2=1},
		{name="default:stonebrick", prob=254, param2=1},
		{name="default:stonebrick", prob=254, param2=1},
		{name="default:tree", prob=254, param2=1},

		-- z=0, y=5
		{name="default:tree", prob=254, param2=1},
		{name="default:stonebrick", prob=254, param2=1},
		{name="default:stonebrick", prob=254, param2=1},
		{name="default:stonebrick", prob=254, param2=1},
		{name="default:stonebrick", prob=254, param2=1},
		{name="default:stonebrick", prob=254, param2=1},
		{name="default:tree", prob=254, param2=1},

		-- z=0, y=6
		{name="default:tree", prob=254, param2=1},
		{name="default:stonebrick", prob=254, param2=1},
		{name="default:glass", prob=254, param2=0},
		{name="default:glass", prob=254, param2=0},
		{name="default:glass", prob=254, param2=0},
		{name="default:stonebrick", prob=254, param2=1},
		{name="default:tree", prob=254, param2=1},

		-- z=0, y=7
		{name="default:tree", prob=254, param2=1},
		{name="default:stonebrick", prob=254, param2=1},
		{name="default:glass", prob=254, param2=0},
		{name="default:glass", prob=254, param2=0},
		{name="default:glass", prob=254, param2=0},
		{name="default:stonebrick", prob=254, param2=1},
		{name="default:tree", prob=254, param2=1},

		-- z=0, y=8
		{name="stairs:stair_wood", prob=254, param2=1},
		{name="default:wood", prob=254, param2=1},
		{name="default:wood", prob=254, param2=1},
		{name="default:wood", prob=254, param2=1},
		{name="default:wood", prob=254, param2=1},
		{name="default:wood", prob=254, param2=1},
		{name="stairs:stair_wood", prob=254, param2=3},

		-- z=0, y=9
		{name="air", prob=254, param2=0},
		{name="stairs:stair_wood", prob=254, param2=1},
		{name="default:wood", prob=254, param2=1},
		{name="default:wood", prob=254, param2=1},
		{name="default:wood", prob=254, param2=1},
		{name="stairs:stair_wood", prob=254, param2=3},
		{name="air", prob=254, param2=0},

		-- z=0, y=10
		{name="air", prob=254, param2=0},
		{name="air", prob=254, param2=0},
		{name="stairs:stair_wood", prob=254, param2=1},
		{name="default:wood", prob=254, param2=1},
		{name="stairs:stair_wood", prob=254, param2=3},
		{name="air", prob=254, param2=0},
		{name="air", prob=254, param2=0},

		-- z=0, y=11
		{name="air", prob=254, param2=0},
		{name="air", prob=254, param2=0},
		{name="air", prob=254, param2=0},
		{name="stairs:slab_wood", prob=254, param2=1},
		{name="air", prob=254, param2=0},
		{name="air", prob=254, param2=0},
		{name="air", prob=254, param2=0},

		-- z=0, y=12
		{name="air", prob=254, param2=0},
		{name="air", prob=254, param2=0},
		{name="air", prob=254, param2=0},
		{name="air", prob=254, param2=0},
		{name="air", prob=254, param2=0},
		{name="air", prob=254, param2=0},
		{name="air", prob=254, param2=0},

		-- z=0, y=13
		{name="air", prob=254, param2=0},
		{name="air", prob=254, param2=0},
		{name="air", prob=254, param2=0},
		{name="air", prob=254, param2=0},
		{name="air", prob=254, param2=0},
		{name="air", prob=254, param2=0},
		{name="air", prob=254, param2=0},

		-- z=1, y=0
		{name="default:wood", prob=254, param2=1},
		{name="default:wood", prob=254, param2=1},
		{name="default:wood", prob=254, param2=1},
		{name="default:wood", prob=254, param2=1},
		{name="default:wood", prob=254, param2=1},
		{name="default:wood", prob=254, param2=1},
		{name="default:wood", prob=254, param2=1},

		-- z=1, y=1
		{name="default:stonebrick", prob=254, param2=1},
		{name="air", prob=254, param2=0},
		{name="stairs:stair_wood", prob=254, param2=1},
		{name="default:chest", prob=254, param2=3},
		{name="beds:bed_top", prob=254, param2=2},
		{name="air", prob=254, param2=0},
		{name="default:stonebrick", prob=254, param2=1},

		-- z=1, y=2
		{name="default:stonebrick", prob=254, param2=1},
		{name="air", prob=254, param2=0},
		{name="air", prob=254, param2=0},
		{name="stairs:stair_wood", prob=254, param2=1},
		{name="air", prob=254, param2=0},
		{name="air", prob=254, param2=0},
		{name="default:stonebrick", prob=254, param2=1},

		-- z=1, y=3
		{name="default:stonebrick", prob=254, param2=1},
		{name="air", prob=254, param2=0},
		{name="air", prob=254, param2=0},
		{name="air", prob=254, param2=0},
		{name="stairs:stair_wood", prob=254, param2=1},
		{name="default:torch_wall", prob=254, param2=5},
		{name="default:stonebrick", prob=254, param2=1},

		-- z=1, y=4
		{name="default:stonebrick", prob=254, param2=1},
		{name="default:wood", prob=254, param2=1},
		{name="air", prob=254, param2=0},
		{name="air", prob=254, param2=0},
		{name="air", prob=254, param2=0},
		{name="stairs:stair_wood", prob=254, param2=1},
		{name="default:stonebrick", prob=254, param2=1},

		-- z=1, y=5
		{name="default:stonebrick", prob=254, param2=1},
		{name="default:chest", prob=254, param2=3},
		{name="air", prob=254, param2=0},
		{name="air", prob=254, param2=0},
		{name="air", prob=254, param2=0},
		{name="air", prob=254, param2=0},
		{name="default:stonebrick", prob=254, param2=1},

		-- z=1, y=6
		{name="default:stonebrick", prob=254, param2=1},
		{name="default:chest", prob=254, param2=3},
		{name="air", prob=254, param2=0},
		{name="air", prob=254, param2=0},
		{name="air", prob=254, param2=0},
		{name="air", prob=254, param2=0},
		{name="default:stonebrick", prob=254, param2=1},

		-- z=1, y=7
		{name="default:stonebrick", prob=254, param2=1},
		{name="default:torch_wall", prob=254, param2=5},
		{name="air", prob=254, param2=0},
		{name="air", prob=254, param2=0},
		{name="air", prob=254, param2=0},
		{name="default:torch_wall", prob=254, param2=5},
		{name="default:stonebrick", prob=254, param2=1},

		-- z=1, y=8
		{name="stairs:stair_wood", prob=254, param2=1},
		{name="default:wood", prob=254, param2=1},
		{name="default:wood", prob=254, param2=1},
		{name="default:wood", prob=254, param2=1},
		{name="default:wood", prob=254, param2=1},
		{name="default:wood", prob=254, param2=1},
		{name="stairs:stair_wood", prob=254, param2=3},

		-- z=1, y=9
		{name="air", prob=254, param2=0},
		{name="stairs:stair_wood", prob=254, param2=1},
		{name="default:wood", prob=254, param2=1},
		{name="default:wood", prob=254, param2=1},
		{name="default:wood", prob=254, param2=1},
		{name="stairs:stair_wood", prob=254, param2=3},
		{name="air", prob=254, param2=0},

		-- z=1, y=10
		{name="air", prob=254, param2=0},
		{name="air", prob=254, param2=0},
		{name="stairs:stair_wood", prob=254, param2=1},
		{name="default:wood", prob=254, param2=1},
		{name="stairs:stair_wood", prob=254, param2=3},
		{name="air", prob=254, param2=0},
		{name="air", prob=254, param2=0},

		-- z=1, y=11
		{name="air", prob=254, param2=0},
		{name="air", prob=254, param2=0},
		{name="air", prob=254, param2=0},
		{name="stairs:slab_wood", prob=254, param2=1},
		{name="air", prob=254, param2=0},
		{name="air", prob=254, param2=0},
		{name="air", prob=254, param2=0},

		-- z=1, y=12
		{name="air", prob=254, param2=0},
		{name="air", prob=254, param2=0},
		{name="air", prob=254, param2=0},
		{name="air", prob=254, param2=0},
		{name="air", prob=254, param2=0},
		{name="air", prob=254, param2=0},
		{name="air", prob=254, param2=0},

		-- z=1, y=13
		{name="air", prob=254, param2=0},
		{name="air", prob=254, param2=0},
		{name="air", prob=254, param2=0},
		{name="air", prob=254, param2=0},
		{name="air", prob=254, param2=0},
		{name="air", prob=254, param2=0},
		{name="air", prob=254, param2=0},

		-- z=2, y=0
		{name="default:wood", prob=254, param2=1},
		{name="default:wood", prob=254, param2=1},
		{name="default:wood", prob=254, param2=1},
		{name="default:wood", prob=254, param2=1},
		{name="default:wood", prob=254, param2=1},
		{name="default:wood", prob=254, param2=1},
		{name="default:wood", prob=254, param2=1},

		-- z=2, y=1
		{name="default:stonebrick", prob=254, param2=1},
		{name="doors:door_wood_b", prob=254, param2=3},
		{name="default:wood", prob=254, param2=1},
		{name="default:wood", prob=254, param2=1},
		{name="beds:bed_bottom", prob=254, param2=2},
		{name="air", prob=254, param2=0},
		{name="default:stonebrick", prob=254, param2=1},

		-- z=2, y=2
		{name="default:stonebrick", prob=254, param2=1},
		{name="doors:hidden", prob=254, param2=0},
		{name="default:wood", prob=254, param2=1},
		{name="default:wood", prob=254, param2=1},
		{name="air", prob=254, param2=0},
		{name="air", prob=254, param2=0},
		{name="default:stonebrick", prob=254, param2=1},

		-- z=2, y=3
		{name="default:stonebrick", prob=254, param2=1},
		{name="default:wood", prob=254, param2=1},
		{name="default:wood", prob=254, param2=1},
		{name="default:wood", prob=254, param2=1},
		{name="default:wood", prob=254, param2=1},
		{name="default:wood", prob=254, param2=1},
		{name="default:stonebrick", prob=254, param2=1},

		-- z=2, y=4
		{name="default:stonebrick", prob=254, param2=1},
		{name="default:wood", prob=254, param2=1},
		{name="default:wood", prob=254, param2=1},
		{name="default:wood", prob=254, param2=1},
		{name="default:wood", prob=254, param2=1},
		{name="default:wood", prob=254, param2=1},
		{name="default:stonebrick", prob=254, param2=1},

		-- z=2, y=5
		{name="default:stonebrick", prob=254, param2=1},
		{name="air", prob=254, param2=0},
		{name="air", prob=254, param2=0},
		{name="air", prob=254, param2=0},
		{name="air", prob=254, param2=0},
		{name="air", prob=254, param2=0},
		{name="default:stonebrick", prob=254, param2=1},

		-- z=2, y=6
		{name="default:glass", prob=254, param2=0},
		{name="air", prob=254, param2=0},
		{name="air", prob=254, param2=0},
		{name="air", prob=254, param2=0},
		{name="air", prob=254, param2=0},
		{name="air", prob=254, param2=0},
		{name="default:glass", prob=254, param2=0},

		-- z=2, y=7
		{name="default:glass", prob=254, param2=0},
		{name="air", prob=254, param2=0},
		{name="air", prob=254, param2=0},
		{name="air", prob=254, param2=0},
		{name="air", prob=254, param2=0},
		{name="air", prob=254, param2=0},
		{name="default:glass", prob=254, param2=0},

		-- z=2, y=8
		{name="stairs:stair_wood", prob=254, param2=1},
		{name="default:wood", prob=254, param2=1},
		{name="default:wood", prob=254, param2=1},
		{name="default:wood", prob=254, param2=1},
		{name="default:wood", prob=254, param2=1},
		{name="default:wood", prob=254, param2=1},
		{name="stairs:stair_wood", prob=254, param2=3},

		-- z=2, y=9
		{name="air", prob=254, param2=0},
		{name="stairs:stair_wood", prob=254, param2=1},
		{name="default:wood", prob=254, param2=1},
		{name="default:wood", prob=254, param2=1},
		{name="default:wood", prob=254, param2=1},
		{name="stairs:stair_wood", prob=254, param2=3},
		{name="air", prob=254, param2=0},

		-- z=2, y=10
		{name="air", prob=254, param2=0},
		{name="air", prob=254, param2=0},
		{name="stairs:stair_wood", prob=254, param2=1},
		{name="default:wood", prob=254, param2=1},
		{name="stairs:stair_wood", prob=254, param2=3},
		{name="air", prob=254, param2=0},
		{name="air", prob=254, param2=0},

		-- z=2, y=11
		{name="air", prob=254, param2=0},
		{name="air", prob=254, param2=0},
		{name="air", prob=254, param2=0},
		{name="stairs:slab_wood", prob=254, param2=1},
		{name="air", prob=254, param2=0},
		{name="air", prob=254, param2=0},
		{name="air", prob=254, param2=0},

		-- z=2, y=12
		{name="air", prob=254, param2=0},
		{name="air", prob=254, param2=0},
		{name="air", prob=254, param2=0},
		{name="air", prob=254, param2=0},
		{name="air", prob=254, param2=0},
		{name="air", prob=254, param2=0},
		{name="air", prob=254, param2=0},

		-- z=2, y=13
		{name="air", prob=254, param2=0},
		{name="air", prob=254, param2=0},
		{name="air", prob=254, param2=0},
		{name="air", prob=254, param2=0},
		{name="air", prob=254, param2=0},
		{name="air", prob=254, param2=0},
		{name="air", prob=254, param2=0},

		-- z=3, y=0
		{name="default:wood", prob=254, param2=1},
		{name="default:wood", prob=254, param2=1},
		{name="default:wood", prob=254, param2=1},
		{name="default:wood", prob=254, param2=1},
		{name="default:wood", prob=254, param2=1},
		{name="default:wood", prob=254, param2=1},
		{name="default:wood", prob=254, param2=1},

		-- z=3, y=1
		{name="default:stonebrick", prob=254, param2=1},
		{name="air", prob=254, param2=0},
		{name="air", prob=254, param2=0},
		{name="air", prob=254, param2=0},
		{name="default:wood", prob=254, param2=1},
		{name="doors:door_wood_a", prob=254, param2=2},
		{name="default:stonebrick", prob=254, param2=1},

		-- z=3, y=2
		{name="default:glass", prob=254, param2=0},
		{name="air", prob=254, param2=0},
		{name="air", prob=254, param2=0},
		{name="air", prob=254, param2=0},
		{name="default:wood", prob=254, param2=1},
		{name="doors:hidden", prob=254, param2=2},
		{name="default:stonebrick", prob=254, param2=1},

		-- z=3, y=3
		{name="default:glass", prob=254, param2=0},
		{name="air", prob=254, param2=0},
		{name="air", prob=254, param2=0},
		{name="default:torch_wall", prob=254, param2=2},
		{name="default:wood", prob=254, param2=1},
		{name="default:wood", prob=254, param2=1},
		{name="default:stonebrick", prob=254, param2=1},

		-- z=3, y=4
		{name="default:stonebrick", prob=254, param2=1},
		{name="default:wood", prob=254, param2=1},
		{name="default:wood", prob=254, param2=1},
		{name="default:wood", prob=254, param2=1},
		{name="default:wood", prob=254, param2=1},
		{name="default:wood", prob=254, param2=1},
		{name="default:stonebrick", prob=254, param2=1},

		-- z=3, y=5
		{name="default:stonebrick", prob=254, param2=1},
		{name="stairs:stair_wood", prob=254, param2=2},
		{name="air", prob=254, param2=0},
		{name="air", prob=254, param2=0},
		{name="air", prob=254, param2=0},
		{name="air", prob=254, param2=0},
		{name="default:stonebrick", prob=254, param2=1},

		-- z=3, y=6
		{name="default:glass", prob=254, param2=0},
		{name="air", prob=254, param2=0},
		{name="air", prob=254, param2=0},
		{name="air", prob=254, param2=0},
		{name="air", prob=254, param2=0},
		{name="air", prob=254, param2=0},
		{name="default:glass", prob=254, param2=0},

		-- z=3, y=7
		{name="default:glass", prob=254, param2=0},
		{name="air", prob=254, param2=0},
		{name="air", prob=254, param2=0},
		{name="default:torch_ceiling", prob=254, param2=0},
		{name="air", prob=254, param2=0},
		{name="air", prob=254, param2=0},
		{name="default:glass", prob=254, param2=0},

		-- z=3, y=8
		{name="stairs:stair_wood", prob=254, param2=1},
		{name="default:wood", prob=254, param2=1},
		{name="default:wood", prob=254, param2=1},
		{name="default:wood", prob=254, param2=1},
		{name="default:wood", prob=254, param2=1},
		{name="default:wood", prob=254, param2=1},
		{name="stairs:stair_wood", prob=254, param2=3},

		-- z=3, y=9
		{name="air", prob=254, param2=0},
		{name="stairs:stair_wood", prob=254, param2=1},
		{name="default:wood", prob=254, param2=1},
		{name="default:wood", prob=254, param2=1},
		{name="default:wood", prob=254, param2=1},
		{name="stairs:stair_wood", prob=254, param2=3},
		{name="air", prob=254, param2=0},

		-- z=3, y=10
		{name="air", prob=254, param2=0},
		{name="air", prob=254, param2=0},
		{name="stairs:stair_wood", prob=254, param2=1},
		{name="default:wood", prob=254, param2=1},
		{name="stairs:stair_wood", prob=254, param2=3},
		{name="air", prob=254, param2=0},
		{name="air", prob=254, param2=0},

		-- z=3, y=11
		{name="air", prob=254, param2=0},
		{name="air", prob=254, param2=0},
		{name="air", prob=254, param2=0},
		{name="stairs:slab_wood", prob=254, param2=1},
		{name="air", prob=254, param2=0},
		{name="air", prob=254, param2=0},
		{name="air", prob=254, param2=0},

		-- z=3, y=12
		{name="air", prob=254, param2=0},
		{name="air", prob=254, param2=0},
		{name="air", prob=254, param2=0},
		{name="air", prob=254, param2=0},
		{name="air", prob=254, param2=0},
		{name="air", prob=254, param2=0},
		{name="air", prob=254, param2=0},

		-- z=3, y=13
		{name="air", prob=254, param2=0},
		{name="air", prob=254, param2=0},
		{name="air", prob=254, param2=0},
		{name="air", prob=254, param2=0},
		{name="air", prob=254, param2=0},
		{name="air", prob=254, param2=0},
		{name="air", prob=254, param2=0},

		-- z=4, y=0
		{name="default:wood", prob=254, param2=1},
		{name="default:wood", prob=254, param2=1},
		{name="default:wood", prob=254, param2=1},
		{name="default:wood", prob=254, param2=1},
		{name="default:wood", prob=254, param2=1},
		{name="default:wood", prob=254, param2=1},
		{name="default:wood", prob=254, param2=1},

		-- z=4, y=1
		{name="default:stonebrick", prob=254, param2=1},
		{name="air", prob=254, param2=0},
		{name="air", prob=254, param2=0},
		{name="air", prob=254, param2=0},
		{name="air", prob=254, param2=0},
		{name="air", prob=254, param2=0},
		{name="default:stonebrick", prob=254, param2=1},

		-- z=4, y=2
		{name="default:glass", prob=254, param2=0},
		{name="air", prob=254, param2=0},
		{name="air", prob=254, param2=0},
		{name="air", prob=254, param2=0},
		{name="air", prob=254, param2=0},
		{name="air", prob=254, param2=0},
		{name="default:glass", prob=254, param2=0},

		-- z=4, y=3
		{name="default:glass", prob=254, param2=0},
		{name="air", prob=254, param2=0},
		{name="air", prob=254, param2=0},
		{name="air", prob=254, param2=0},
		{name="air", prob=254, param2=0},
		{name="air", prob=254, param2=0},
		{name="default:glass", prob=254, param2=0},

		-- z=4, y=4
		{name="default:stonebrick", prob=254, param2=1},
		{name="default:wood", prob=254, param2=1},
		{name="default:wood", prob=254, param2=1},
		{name="default:wood", prob=254, param2=1},
		{name="default:wood", prob=254, param2=1},
		{name="default:wood", prob=254, param2=1},
		{name="default:stonebrick", prob=254, param2=1},

		-- z=4, y=5
		{name="default:stonebrick", prob=254, param2=1},
		{name="stairs:stair_wood", prob=254, param2=22},
		{name="air", prob=254, param2=0},
		{name="beds:bed_bottom", prob=254, param2=0},
		{name="beds:bed_bottom", prob=254, param2=0},
		{name="air", prob=254, param2=0},
		{name="default:stonebrick", prob=254, param2=1},

		-- z=4, y=6
		{name="default:glass", prob=254, param2=0},
		{name="air", prob=254, param2=0},
		{name="air", prob=254, param2=0},
		{name="air", prob=254, param2=0},
		{name="air", prob=254, param2=0},
		{name="air", prob=254, param2=0},
		{name="default:glass", prob=254, param2=0},

		-- z=4, y=7
		{name="default:glass", prob=254, param2=0},
		{name="air", prob=254, param2=0},
		{name="air", prob=254, param2=0},
		{name="default:torch_ceiling", prob=254, param2=0},
		{name="air", prob=254, param2=0},
		{name="air", prob=254, param2=0},
		{name="default:glass", prob=254, param2=0},

		-- z=4, y=8
		{name="stairs:stair_wood", prob=254, param2=1},
		{name="default:wood", prob=254, param2=1},
		{name="default:wood", prob=254, param2=1},
		{name="default:wood", prob=254, param2=1},
		{name="default:wood", prob=254, param2=1},
		{name="default:wood", prob=254, param2=1},
		{name="stairs:stair_wood", prob=254, param2=3},

		-- z=4, y=9
		{name="air", prob=254, param2=0},
		{name="stairs:stair_wood", prob=254, param2=1},
		{name="default:wood", prob=254, param2=1},
		{name="default:wood", prob=254, param2=1},
		{name="default:wood", prob=254, param2=1},
		{name="stairs:stair_wood", prob=254, param2=3},
		{name="air", prob=254, param2=0},

		-- z=4, y=10
		{name="air", prob=254, param2=0},
		{name="air", prob=254, param2=0},
		{name="stairs:stair_wood", prob=254, param2=1},
		{name="default:wood", prob=254, param2=1},
		{name="stairs:stair_wood", prob=254, param2=3},
		{name="air", prob=254, param2=0},
		{name="air", prob=254, param2=0},

		-- z=4, y=11
		{name="air", prob=254, param2=0},
		{name="air", prob=254, param2=0},
		{name="air", prob=254, param2=0},
		{name="stairs:slab_wood", prob=254, param2=1},
		{name="air", prob=254, param2=0},
		{name="air", prob=254, param2=0},
		{name="air", prob=254, param2=0},

		-- z=4, y=12
		{name="air", prob=254, param2=0},
		{name="air", prob=254, param2=0},
		{name="air", prob=254, param2=0},
		{name="air", prob=254, param2=0},
		{name="air", prob=254, param2=0},
		{name="air", prob=254, param2=0},
		{name="air", prob=254, param2=0},

		-- z=4, y=13
		{name="air", prob=254, param2=0},
		{name="air", prob=254, param2=0},
		{name="air", prob=254, param2=0},
		{name="air", prob=254, param2=0},
		{name="air", prob=254, param2=0},
		{name="air", prob=254, param2=0},
		{name="air", prob=254, param2=0},

		-- z=5, y=0
		{name="default:wood", prob=254, param2=1},
		{name="default:wood", prob=254, param2=1},
		{name="default:wood", prob=254, param2=1},
		{name="default:wood", prob=254, param2=1},
		{name="default:wood", prob=254, param2=1},
		{name="default:wood", prob=254, param2=1},
		{name="default:wood", prob=254, param2=1},

		-- z=5, y=1
		{name="default:stonebrick", prob=254, param2=1},
		{name="air", prob=254, param2=0},
		{name="air", prob=254, param2=0},
		{name="air", prob=254, param2=0},
		{name="air", prob=254, param2=0},
		{name="air", prob=254, param2=0},
		{name="default:stonebrick", prob=254, param2=1},

		-- z=5, y=2
		{name="default:glass", prob=254, param2=0},
		{name="air", prob=254, param2=0},
		{name="air", prob=254, param2=0},
		{name="air", prob=254, param2=0},
		{name="air", prob=254, param2=0},
		{name="air", prob=254, param2=0},
		{name="default:glass", prob=254, param2=0},

		-- z=5, y=3
		{name="default:glass", prob=254, param2=0},
		{name="air", prob=254, param2=0},
		{name="air", prob=254, param2=0},
		{name="air", prob=254, param2=0},
		{name="air", prob=254, param2=0},
		{name="air", prob=254, param2=0},
		{name="default:glass", prob=254, param2=0},

		-- z=5, y=4
		{name="default:stonebrick", prob=254, param2=1},
		{name="default:wood", prob=254, param2=1},
		{name="default:wood", prob=254, param2=1},
		{name="default:wood", prob=254, param2=1},
		{name="default:wood", prob=254, param2=1},
		{name="default:wood", prob=254, param2=1},
		{name="default:stonebrick", prob=254, param2=1},

		-- z=5, y=5
		{name="default:stonebrick", prob=254, param2=1},
		{name="stairs:stair_wood", prob=254, param2=20},
		{name="air", prob=254, param2=0},
		{name="beds:bed_top", prob=254, param2=0},
		{name="beds:bed_top", prob=254, param2=0},
		{name="air", prob=254, param2=0},
		{name="default:stonebrick", prob=254, param2=1},

		-- z=5, y=6
		{name="default:glass", prob=254, param2=0},
		{name="air", prob=254, param2=0},
		{name="air", prob=254, param2=0},
		{name="air", prob=254, param2=0},
		{name="air", prob=254, param2=0},
		{name="air", prob=254, param2=0},
		{name="default:glass", prob=254, param2=0},

		-- z=5, y=7
		{name="default:glass", prob=254, param2=0},
		{name="air", prob=254, param2=0},
		{name="air", prob=254, param2=0},
		{name="air", prob=254, param2=0},
		{name="air", prob=254, param2=0},
		{name="air", prob=254, param2=0},
		{name="default:glass", prob=254, param2=0},

		-- z=5, y=8
		{name="stairs:stair_wood", prob=254, param2=1},
		{name="default:wood", prob=254, param2=1},
		{name="default:wood", prob=254, param2=1},
		{name="default:wood", prob=254, param2=1},
		{name="default:wood", prob=254, param2=1},
		{name="default:wood", prob=254, param2=1},
		{name="stairs:stair_wood", prob=254, param2=3},

		-- z=5, y=9
		{name="air", prob=254, param2=0},
		{name="stairs:stair_wood", prob=254, param2=1},
		{name="default:wood", prob=254, param2=1},
		{name="default:wood", prob=254, param2=1},
		{name="default:wood", prob=254, param2=1},
		{name="stairs:stair_wood", prob=254, param2=3},
		{name="air", prob=254, param2=0},

		-- z=5, y=10
		{name="air", prob=254, param2=0},
		{name="air", prob=254, param2=0},
		{name="stairs:stair_wood", prob=254, param2=1},
		{name="default:wood", prob=254, param2=1},
		{name="stairs:stair_wood", prob=254, param2=3},
		{name="air", prob=254, param2=0},
		{name="air", prob=254, param2=0},

		-- z=5, y=11
		{name="air", prob=254, param2=0},
		{name="air", prob=254, param2=0},
		{name="air", prob=254, param2=0},
		{name="stairs:slab_wood", prob=254, param2=1},
		{name="air", prob=254, param2=0},
		{name="air", prob=254, param2=0},
		{name="air", prob=254, param2=0},

		-- z=5, y=12
		{name="air", prob=254, param2=0},
		{name="air", prob=254, param2=0},
		{name="air", prob=254, param2=0},
		{name="air", prob=254, param2=0},
		{name="air", prob=254, param2=0},
		{name="air", prob=254, param2=0},
		{name="air", prob=254, param2=0},

		-- z=5, y=13
		{name="air", prob=254, param2=0},
		{name="air", prob=254, param2=0},
		{name="air", prob=254, param2=0},
		{name="air", prob=254, param2=0},
		{name="air", prob=254, param2=0},
		{name="air", prob=254, param2=0},
		{name="air", prob=254, param2=0},

		-- z=6, y=0
		{name="default:wood", prob=254, param2=1},
		{name="default:wood", prob=254, param2=1},
		{name="default:wood", prob=254, param2=1},
		{name="default:wood", prob=254, param2=1},
		{name="default:wood", prob=254, param2=1},
		{name="default:wood", prob=254, param2=1},
		{name="default:wood", prob=254, param2=1},

		-- z=6, y=1
		{name="default:stonebrick", prob=254, param2=1},
		{name="air", prob=254, param2=0},
		{name="air", prob=254, param2=0},
		{name="air", prob=254, param2=0},
		{name="stairs:stair_wood", prob=254, param2=22},
		{name="air", prob=254, param2=0},
		{name="default:stonebrick", prob=254, param2=1},

		-- z=6, y=2
		{name="default:stonebrick", prob=254, param2=1},
		{name="air", prob=254, param2=0},
		{name="air", prob=254, param2=0},
		{name="air", prob=254, param2=0},
		{name="air", prob=254, param2=0},
		{name="air", prob=254, param2=0},
		{name="default:glass", prob=254, param2=0},

		-- z=6, y=3
		{name="default:stonebrick", prob=254, param2=1},
		{name="default:torch_wall", prob=254, param2=3},
		{name="air", prob=254, param2=0},
		{name="air", prob=254, param2=0},
		{name="air", prob=254, param2=0},
		{name="air", prob=254, param2=0},
		{name="default:glass", prob=254, param2=0},

		-- z=6, y=4
		{name="default:stonebrick", prob=254, param2=1},
		{name="default:wood", prob=254, param2=1},
		{name="default:wood", prob=254, param2=1},
		{name="default:wood", prob=254, param2=1},
		{name="default:wood", prob=254, param2=1},
		{name="default:wood", prob=254, param2=1},
		{name="default:stonebrick", prob=254, param2=1},

		-- z=6, y=5
		{name="default:stonebrick", prob=254, param2=1},
		{name="stairs:stair_wood", prob=254, param2=0},
		{name="air", prob=254, param2=0},
		{name="stairs:stair_wood", prob=254, param2=0},
		{name="stairs:stair_wood", prob=254, param2=0},
		{name="default:chest", prob=254, param2=0},
		{name="default:stonebrick", prob=254, param2=1},

		-- z=6, y=6
		{name="default:stonebrick", prob=254, param2=1},
		{name="air", prob=254, param2=0},
		{name="air", prob=254, param2=0},
		{name="air", prob=254, param2=0},
		{name="air", prob=254, param2=0},
		{name="air", prob=254, param2=0},
		{name="default:stonebrick", prob=254, param2=1},

		-- z=6, y=7
		{name="default:stonebrick", prob=254, param2=1},
		{name="default:torch_wall", prob=254, param2=4},
		{name="air", prob=254, param2=0},
		{name="air", prob=254, param2=0},
		{name="air", prob=254, param2=0},
		{name="default:torch_wall", prob=254, param2=4},
		{name="default:stonebrick", prob=254, param2=1},

		-- z=6, y=8
		{name="stairs:stair_wood", prob=254, param2=1},
		{name="default:wood", prob=254, param2=1},
		{name="default:wood", prob=254, param2=1},
		{name="default:wood", prob=254, param2=1},
		{name="default:wood", prob=254, param2=1},
		{name="default:wood", prob=254, param2=1},
		{name="stairs:stair_wood", prob=254, param2=3},

		-- z=6, y=9
		{name="air", prob=254, param2=0},
		{name="stairs:stair_wood", prob=254, param2=1},
		{name="default:wood", prob=254, param2=1},
		{name="default:wood", prob=254, param2=1},
		{name="default:wood", prob=254, param2=1},
		{name="stairs:stair_wood", prob=254, param2=3},
		{name="air", prob=254, param2=0},

		-- z=6, y=10
		{name="air", prob=254, param2=0},
		{name="air", prob=254, param2=0},
		{name="stairs:stair_wood", prob=254, param2=1},
		{name="default:wood", prob=254, param2=1},
		{name="stairs:stair_wood", prob=254, param2=3},
		{name="air", prob=254, param2=0},
		{name="air", prob=254, param2=0},

		-- z=6, y=11
		{name="air", prob=254, param2=0},
		{name="air", prob=254, param2=0},
		{name="air", prob=254, param2=0},
		{name="stairs:slab_wood", prob=254, param2=1},
		{name="air", prob=254, param2=0},
		{name="air", prob=254, param2=0},
		{name="air", prob=254, param2=0},

		-- z=6, y=12
		{name="air", prob=254, param2=0},
		{name="air", prob=254, param2=0},
		{name="air", prob=254, param2=0},
		{name="air", prob=254, param2=0},
		{name="air", prob=254, param2=0},
		{name="air", prob=254, param2=0},
		{name="air", prob=254, param2=0},

		-- z=6, y=13
		{name="air", prob=254, param2=0},
		{name="air", prob=254, param2=0},
		{name="air", prob=254, param2=0},
		{name="air", prob=254, param2=1},
		{name="air", prob=254, param2=0},
		{name="air", prob=254, param2=0},
		{name="air", prob=254, param2=0},

		-- z=7, y=0
		{name="default:wood", prob=254, param2=1},
		{name="default:wood", prob=254, param2=1},
		{name="default:wood", prob=254, param2=1},
		{name="default:wood", prob=254, param2=1},
		{name="default:wood", prob=254, param2=1},
		{name="default:wood", prob=254, param2=1},
		{name="default:wood", prob=254, param2=1},

		-- z=7, y=1
		{name="doors:door_wood_a", prob=254, param2=1},
		{name="air", prob=254, param2=0},
		{name="air", prob=254, param2=0},
		{name="air", prob=254, param2=0},
		{name="stairs:slab_wood", prob=254, param2=23},
		{name="air", prob=254, param2=0},
		{name="default:stonebrick", prob=254, param2=1},

		-- z=7, y=2
		{name="doors:hidden", prob=254, param2=1},
		{name="air", prob=254, param2=0},
		{name="air", prob=254, param2=0},
		{name="air", prob=254, param2=0},
		{name="air", prob=254, param2=0},
		{name="air", prob=254, param2=0},
		{name="default:stonebrick", prob=254, param2=1},

		-- z=7, y=3
		{name="default:stonebrick", prob=254, param2=1},
		{name="air", prob=254, param2=0},
		{name="air", prob=254, param2=0},
		{name="air", prob=254, param2=0},
		{name="air", prob=254, param2=0},
		{name="default:torch_wall", prob=254, param2=2},
		{name="default:stonebrick", prob=254, param2=1},

		-- z=7, y=4
		{name="default:stonebrick", prob=254, param2=1},
		{name="default:wood", prob=254, param2=1},
		{name="default:wood", prob=254, param2=1},
		{name="default:wood", prob=254, param2=1},
		{name="default:wood", prob=254, param2=1},
		{name="default:wood", prob=254, param2=1},
		{name="default:stonebrick", prob=254, param2=1},

		-- z=7, y=5
		{name="default:stonebrick", prob=254, param2=1},
		{name="default:wood", prob=254, param2=1},
		{name="default:wood", prob=254, param2=1},
		{name="default:wood", prob=254, param2=1},
		{name="default:wood", prob=254, param2=1},
		{name="default:wood", prob=254, param2=1},
		{name="default:stonebrick", prob=254, param2=1},

		-- z=7, y=6
		{name="default:stonebrick", prob=254, param2=1},
		{name="default:wood", prob=254, param2=1},
		{name="default:wood", prob=254, param2=1},
		{name="default:wood", prob=254, param2=1},
		{name="default:wood", prob=254, param2=1},
		{name="default:wood", prob=254, param2=1},
		{name="default:stonebrick", prob=254, param2=1},

		-- z=7, y=7
		{name="default:stonebrick", prob=254, param2=1},
		{name="default:wood", prob=254, param2=1},
		{name="default:wood", prob=254, param2=1},
		{name="default:wood", prob=254, param2=1},
		{name="default:wood", prob=254, param2=1},
		{name="default:wood", prob=254, param2=1},
		{name="default:stonebrick", prob=254, param2=1},

		-- z=7, y=8
		{name="stairs:stair_wood", prob=254, param2=1},
		{name="default:wood", prob=254, param2=1},
		{name="default:wood", prob=254, param2=1},
		{name="default:wood", prob=254, param2=1},
		{name="default:wood", prob=254, param2=1},
		{name="default:wood", prob=254, param2=1},
		{name="stairs:stair_wood", prob=254, param2=3},

		-- z=7, y=9
		{name="air", prob=254, param2=0},
		{name="stairs:stair_wood", prob=254, param2=1},
		{name="default:wood", prob=254, param2=1},
		{name="default:wood", prob=254, param2=1},
		{name="default:wood", prob=254, param2=1},
		{name="stairs:stair_wood", prob=254, param2=3},
		{name="air", prob=254, param2=0},

		-- z=7, y=10
		{name="air", prob=254, param2=0},
		{name="air", prob=254, param2=0},
		{name="stairs:stair_wood", prob=254, param2=1},
		{name="default:wood", prob=254, param2=1},
		{name="stairs:stair_wood", prob=254, param2=3},
		{name="air", prob=254, param2=0},
		{name="air", prob=254, param2=0},

		-- z=7, y=11
		{name="air", prob=254, param2=0},
		{name="air", prob=254, param2=0},
		{name="air", prob=254, param2=0},
		{name="stairs:slab_wood", prob=254, param2=1},
		{name="air", prob=254, param2=0},
		{name="air", prob=254, param2=0},
		{name="air", prob=254, param2=0},

		-- z=7, y=12
		{name="air", prob=254, param2=0},
		{name="air", prob=254, param2=0},
		{name="air", prob=254, param2=0},
		{name="air", prob=254, param2=0},
		{name="air", prob=254, param2=0},
		{name="air", prob=254, param2=0},
		{name="air", prob=254, param2=0},

		-- z=7, y=13
		{name="air", prob=254, param2=0},
		{name="air", prob=254, param2=0},
		{name="air", prob=254, param2=0},
		{name="air", prob=254, param2=1},
		{name="air", prob=254, param2=0},
		{name="air", prob=254, param2=5},
		{name="air", prob=254, param2=0},

		-- z=8, y=0
		{name="default:wood", prob=254, param2=1},
		{name="default:wood", prob=254, param2=1},
		{name="default:wood", prob=254, param2=1},
		{name="default:wood", prob=254, param2=1},
		{name="default:wood", prob=254, param2=1},
		{name="default:wood", prob=254, param2=1},
		{name="default:wood", prob=254, param2=1},

		-- z=8, y=1
		{name="default:stonebrick", prob=254, param2=1},
		{name="air", prob=254, param2=0},
		{name="air", prob=254, param2=0},
		{name="air", prob=254, param2=0},
		{name="stairs:slab_wood", prob=254, param2=23},
		{name="cottages:wool_tent", prob=254, param2=1},
		{name="default:stonebrick", prob=254, param2=1},

		-- z=8, y=2
		{name="default:stonebrick", prob=254, param2=1},
		{name="air", prob=254, param2=0},
		{name="air", prob=254, param2=0},
		{name="air", prob=254, param2=0},
		{name="air", prob=254, param2=0},
		{name="air", prob=254, param2=0},
		{name="default:glass", prob=254, param2=0},

		-- z=8, y=3
		{name="default:stonebrick", prob=254, param2=1},
		{name="default:torch_wall", prob=254, param2=3},
		{name="air", prob=254, param2=0},
		{name="air", prob=254, param2=0},
		{name="air", prob=254, param2=0},
		{name="air", prob=254, param2=0},
		{name="default:glass", prob=254, param2=0},

		-- z=8, y=4
		{name="default:stonebrick", prob=254, param2=1},
		{name="default:wood", prob=254, param2=1},
		{name="default:wood", prob=254, param2=1},
		{name="default:wood", prob=254, param2=1},
		{name="default:wood", prob=254, param2=1},
		{name="default:wood", prob=254, param2=1},
		{name="default:stonebrick", prob=254, param2=1},

		-- z=8, y=5
		{name="default:stonebrick", prob=254, param2=1},
		{name="stairs:stair_wood", prob=254, param2=2},
		{name="air", prob=254, param2=0},
		{name="stairs:stair_wood", prob=254, param2=2},
		{name="stairs:stair_wood", prob=254, param2=2},
		{name="default:chest", prob=254, param2=2},
		{name="default:stonebrick", prob=254, param2=1},

		-- z=8, y=6
		{name="default:stonebrick", prob=254, param2=1},
		{name="air", prob=254, param2=0},
		{name="air", prob=254, param2=0},
		{name="air", prob=254, param2=0},
		{name="air", prob=254, param2=0},
		{name="air", prob=254, param2=0},
		{name="default:stonebrick", prob=254, param2=1},

		-- z=8, y=7
		{name="default:stonebrick", prob=254, param2=1},
		{name="default:torch_wall", prob=254, param2=5},
		{name="air", prob=254, param2=0},
		{name="air", prob=254, param2=0},
		{name="air", prob=254, param2=0},
		{name="default:torch_wall", prob=254, param2=5},
		{name="default:stonebrick", prob=254, param2=1},

		-- z=8, y=8
		{name="stairs:stair_wood", prob=254, param2=1},
		{name="default:wood", prob=254, param2=1},
		{name="default:wood", prob=254, param2=1},
		{name="default:wood", prob=254, param2=1},
		{name="default:wood", prob=254, param2=1},
		{name="default:wood", prob=254, param2=1},
		{name="stairs:stair_wood", prob=254, param2=3},

		-- z=8, y=9
		{name="air", prob=254, param2=0},
		{name="stairs:stair_wood", prob=254, param2=1},
		{name="default:wood", prob=254, param2=1},
		{name="default:wood", prob=254, param2=1},
		{name="default:wood", prob=254, param2=1},
		{name="stairs:stair_wood", prob=254, param2=3},
		{name="air", prob=254, param2=0},

		-- z=8, y=10
		{name="air", prob=254, param2=0},
		{name="air", prob=254, param2=0},
		{name="stairs:stair_wood", prob=254, param2=1},
		{name="default:wood", prob=254, param2=1},
		{name="stairs:stair_wood", prob=254, param2=3},
		{name="air", prob=254, param2=0},
		{name="air", prob=254, param2=0},

		-- z=8, y=11
		{name="air", prob=254, param2=0},
		{name="air", prob=254, param2=0},
		{name="air", prob=254, param2=0},
		{name="stairs:slab_wood", prob=254, param2=1},
		{name="air", prob=254, param2=0},
		{name="air", prob=254, param2=0},
		{name="air", prob=254, param2=0},

		-- z=8, y=12
		{name="air", prob=254, param2=0},
		{name="air", prob=254, param2=0},
		{name="air", prob=254, param2=0},
		{name="air", prob=254, param2=0},
		{name="air", prob=254, param2=0},
		{name="air", prob=254, param2=0},
		{name="air", prob=254, param2=0},

		-- z=8, y=13
		{name="air", prob=254, param2=0},
		{name="air", prob=254, param2=0},
		{name="air", prob=254, param2=0},
		{name="air", prob=254, param2=1},
		{name="air", prob=254, param2=0},
		{name="air", prob=254, param2=0},
		{name="air", prob=254, param2=0},

		-- z=9, y=0
		{name="default:wood", prob=254, param2=1},
		{name="default:wood", prob=254, param2=1},
		{name="default:wood", prob=254, param2=1},
		{name="default:wood", prob=254, param2=1},
		{name="default:wood", prob=254, param2=1},
		{name="default:wood", prob=254, param2=1},
		{name="default:wood", prob=254, param2=1},

		-- z=9, y=1
		{name="default:stonebrick", prob=254, param2=1},
		{name="air", prob=254, param2=0},
		{name="air", prob=254, param2=0},
		{name="air", prob=254, param2=0},
		{name="stairs:stair_wood", prob=254, param2=20},
		{name="air", prob=254, param2=0},
		{name="default:stonebrick", prob=254, param2=1},

		-- z=9, y=2
		{name="default:glass", prob=254, param2=0},
		{name="air", prob=254, param2=0},
		{name="air", prob=254, param2=0},
		{name="air", prob=254, param2=0},
		{name="air", prob=254, param2=0},
		{name="air", prob=254, param2=0},
		{name="default:glass", prob=254, param2=0},

		-- z=9, y=3
		{name="default:glass", prob=254, param2=0},
		{name="air", prob=254, param2=0},
		{name="air", prob=254, param2=0},
		{name="air", prob=254, param2=0},
		{name="air", prob=254, param2=0},
		{name="air", prob=254, param2=0},
		{name="default:glass", prob=254, param2=0},

		-- z=9, y=4
		{name="default:stonebrick", prob=254, param2=1},
		{name="default:wood", prob=254, param2=1},
		{name="default:wood", prob=254, param2=1},
		{name="default:wood", prob=254, param2=1},
		{name="default:wood", prob=254, param2=1},
		{name="default:wood", prob=254, param2=1},
		{name="default:stonebrick", prob=254, param2=1},

		-- z=9, y=5
		{name="default:stonebrick", prob=254, param2=1},
		{name="stairs:stair_wood", prob=254, param2=22},
		{name="air", prob=254, param2=0},
		{name="beds:bed_top", prob=254, param2=2},
		{name="beds:bed_top", prob=254, param2=2},
		{name="air", prob=254, param2=0},
		{name="default:stonebrick", prob=254, param2=1},

		-- z=9, y=6
		{name="default:glass", prob=254, param2=0},
		{name="air", prob=254, param2=0},
		{name="air", prob=254, param2=0},
		{name="air", prob=254, param2=0},
		{name="air", prob=254, param2=0},
		{name="air", prob=254, param2=0},
		{name="default:glass", prob=254, param2=0},

		-- z=9, y=7
		{name="default:glass", prob=254, param2=0},
		{name="air", prob=254, param2=0},
		{name="air", prob=254, param2=0},
		{name="air", prob=254, param2=0},
		{name="air", prob=254, param2=0},
		{name="air", prob=254, param2=0},
		{name="default:glass", prob=254, param2=0},

		-- z=9, y=8
		{name="stairs:stair_wood", prob=254, param2=1},
		{name="default:wood", prob=254, param2=1},
		{name="default:wood", prob=254, param2=1},
		{name="default:wood", prob=254, param2=1},
		{name="default:wood", prob=254, param2=1},
		{name="default:wood", prob=254, param2=1},
		{name="stairs:stair_wood", prob=254, param2=3},

		-- z=9, y=9
		{name="air", prob=254, param2=0},
		{name="stairs:stair_wood", prob=254, param2=1},
		{name="default:wood", prob=254, param2=1},
		{name="default:wood", prob=254, param2=1},
		{name="default:wood", prob=254, param2=1},
		{name="stairs:stair_wood", prob=254, param2=3},
		{name="air", prob=254, param2=0},

		-- z=9, y=10
		{name="air", prob=254, param2=0},
		{name="air", prob=254, param2=0},
		{name="stairs:stair_wood", prob=254, param2=1},
		{name="default:wood", prob=254, param2=1},
		{name="stairs:stair_wood", prob=254, param2=3},
		{name="air", prob=254, param2=0},
		{name="air", prob=254, param2=0},

		-- z=9, y=11
		{name="air", prob=254, param2=0},
		{name="air", prob=254, param2=0},
		{name="air", prob=254, param2=0},
		{name="stairs:slab_wood", prob=254, param2=1},
		{name="air", prob=254, param2=0},
		{name="air", prob=254, param2=0},
		{name="air", prob=254, param2=0},

		-- z=9, y=12
		{name="air", prob=254, param2=0},
		{name="air", prob=254, param2=0},
		{name="air", prob=254, param2=0},
		{name="air", prob=254, param2=0},
		{name="air", prob=254, param2=0},
		{name="air", prob=254, param2=0},
		{name="air", prob=254, param2=0},

		-- z=9, y=13
		{name="air", prob=254, param2=0},
		{name="air", prob=254, param2=0},
		{name="air", prob=254, param2=0},
		{name="air", prob=254, param2=1},
		{name="air", prob=254, param2=0},
		{name="air", prob=254, param2=3},
		{name="air", prob=254, param2=0},

		-- z=10, y=0
		{name="default:wood", prob=254, param2=1},
		{name="default:wood", prob=254, param2=1},
		{name="default:wood", prob=254, param2=1},
		{name="default:wood", prob=254, param2=1},
		{name="default:wood", prob=254, param2=1},
		{name="default:wood", prob=254, param2=1},
		{name="default:wood", prob=254, param2=1},

		-- z=10, y=1
		{name="default:stonebrick", prob=254, param2=1},
		{name="air", prob=254, param2=0},
		{name="air", prob=254, param2=0},
		{name="air", prob=254, param2=0},
		{name="air", prob=254, param2=0},
		{name="air", prob=254, param2=0},
		{name="default:stonebrick", prob=254, param2=1},

		-- z=10, y=2
		{name="default:glass", prob=254, param2=0},
		{name="air", prob=254, param2=0},
		{name="air", prob=254, param2=0},
		{name="air", prob=254, param2=0},
		{name="air", prob=254, param2=0},
		{name="air", prob=254, param2=0},
		{name="default:glass", prob=254, param2=0},

		-- z=10, y=3
		{name="default:glass", prob=254, param2=0},
		{name="air", prob=254, param2=0},
		{name="air", prob=254, param2=0},
		{name="air", prob=254, param2=0},
		{name="air", prob=254, param2=0},
		{name="air", prob=254, param2=0},
		{name="default:glass", prob=254, param2=0},

		-- z=10, y=4
		{name="default:stonebrick", prob=254, param2=1},
		{name="default:wood", prob=254, param2=1},
		{name="default:wood", prob=254, param2=1},
		{name="default:wood", prob=254, param2=1},
		{name="default:wood", prob=254, param2=1},
		{name="default:wood", prob=254, param2=1},
		{name="default:stonebrick", prob=254, param2=1},

		-- z=10, y=5
		{name="default:stonebrick", prob=254, param2=1},
		{name="stairs:stair_wood", prob=254, param2=20},
		{name="air", prob=254, param2=0},
		{name="beds:bed_bottom", prob=254, param2=2},
		{name="beds:bed_bottom", prob=254, param2=2},
		{name="air", prob=254, param2=0},
		{name="default:stonebrick", prob=254, param2=1},

		-- z=10, y=6
		{name="default:glass", prob=254, param2=0},
		{name="air", prob=254, param2=0},
		{name="air", prob=254, param2=0},
		{name="air", prob=254, param2=0},
		{name="air", prob=254, param2=0},
		{name="air", prob=254, param2=0},
		{name="default:glass", prob=254, param2=0},

		-- z=10, y=7
		{name="default:glass", prob=254, param2=0},
		{name="air", prob=254, param2=0},
		{name="air", prob=254, param2=0},
		{name="default:torch_ceiling", prob=254, param2=0},
		{name="air", prob=254, param2=0},
		{name="air", prob=254, param2=0},
		{name="default:glass", prob=254, param2=0},

		-- z=10, y=8
		{name="stairs:stair_wood", prob=254, param2=1},
		{name="default:wood", prob=254, param2=1},
		{name="default:wood", prob=254, param2=1},
		{name="default:wood", prob=254, param2=1},
		{name="default:wood", prob=254, param2=1},
		{name="default:wood", prob=254, param2=1},
		{name="stairs:stair_wood", prob=254, param2=3},

		-- z=10, y=9
		{name="air", prob=254, param2=0},
		{name="stairs:stair_wood", prob=254, param2=1},
		{name="default:wood", prob=254, param2=1},
		{name="default:wood", prob=254, param2=1},
		{name="default:wood", prob=254, param2=1},
		{name="stairs:stair_wood", prob=254, param2=3},
		{name="air", prob=254, param2=0},

		-- z=10, y=10
		{name="air", prob=254, param2=0},
		{name="air", prob=254, param2=0},
		{name="stairs:stair_wood", prob=254, param2=1},
		{name="default:wood", prob=254, param2=1},
		{name="stairs:stair_wood", prob=254, param2=3},
		{name="air", prob=254, param2=0},
		{name="air", prob=254, param2=0},

		-- z=10, y=11
		{name="air", prob=254, param2=0},
		{name="air", prob=254, param2=0},
		{name="air", prob=254, param2=0},
		{name="stairs:slab_wood", prob=254, param2=1},
		{name="air", prob=254, param2=0},
		{name="air", prob=254, param2=0},
		{name="air", prob=254, param2=0},

		-- z=10, y=12
		{name="air", prob=254, param2=0},
		{name="air", prob=254, param2=0},
		{name="air", prob=254, param2=0},
		{name="air", prob=254, param2=0},
		{name="air", prob=254, param2=0},
		{name="air", prob=254, param2=0},
		{name="air", prob=254, param2=0},

		-- z=10, y=13
		{name="air", prob=254, param2=0},
		{name="air", prob=254, param2=0},
		{name="air", prob=254, param2=0},
		{name="air", prob=254, param2=1},
		{name="air", prob=254, param2=0},
		{name="air", prob=254, param2=4},
		{name="air", prob=254, param2=0},

		-- z=11, y=0
		{name="default:wood", prob=254, param2=1},
		{name="default:wood", prob=254, param2=1},
		{name="default:wood", prob=254, param2=1},
		{name="default:wood", prob=254, param2=1},
		{name="default:wood", prob=254, param2=1},
		{name="default:wood", prob=254, param2=1},
		{name="default:wood", prob=254, param2=1},

		-- z=11, y=1
		{name="default:stonebrick", prob=254, param2=1},
		{name="air", prob=254, param2=0},
		{name="air", prob=254, param2=0},
		{name="air", prob=254, param2=0},
		{name="default:wood", prob=254, param2=1},
		{name="doors:door_wood_a", prob=254, param2=0},
		{name="default:stonebrick", prob=254, param2=1},

		-- z=11, y=2
		{name="default:glass", prob=254, param2=0},
		{name="air", prob=254, param2=0},
		{name="air", prob=254, param2=0},
		{name="air", prob=254, param2=0},
		{name="default:wood", prob=254, param2=1},
		{name="doors:hidden", prob=254, param2=0},
		{name="default:stonebrick", prob=254, param2=1},

		-- z=11, y=3
		{name="default:glass", prob=254, param2=0},
		{name="air", prob=254, param2=0},
		{name="air", prob=254, param2=0},
		{name="default:torch_wall", prob=254, param2=2},
		{name="default:wood", prob=254, param2=1},
		{name="default:wood", prob=254, param2=1},
		{name="default:stonebrick", prob=254, param2=1},

		-- z=11, y=4
		{name="default:stonebrick", prob=254, param2=1},
		{name="default:wood", prob=254, param2=1},
		{name="default:wood", prob=254, param2=1},
		{name="default:wood", prob=254, param2=1},
		{name="default:wood", prob=254, param2=1},
		{name="default:wood", prob=254, param2=1},
		{name="default:stonebrick", prob=254, param2=1},

		-- z=11, y=5
		{name="default:stonebrick", prob=254, param2=1},
		{name="stairs:stair_wood", prob=254, param2=0},
		{name="air", prob=254, param2=0},
		{name="air", prob=254, param2=0},
		{name="air", prob=254, param2=0},
		{name="air", prob=254, param2=0},
		{name="default:stonebrick", prob=254, param2=1},

		-- z=11, y=6
		{name="default:glass", prob=254, param2=0},
		{name="air", prob=254, param2=0},
		{name="air", prob=254, param2=0},
		{name="air", prob=254, param2=0},
		{name="air", prob=254, param2=0},
		{name="air", prob=254, param2=0},
		{name="default:glass", prob=254, param2=0},

		-- z=11, y=7
		{name="default:glass", prob=254, param2=0},
		{name="air", prob=254, param2=0},
		{name="air", prob=254, param2=0},
		{name="default:torch_ceiling", prob=254, param2=0},
		{name="air", prob=254, param2=0},
		{name="air", prob=254, param2=0},
		{name="default:glass", prob=254, param2=0},

		-- z=11, y=8
		{name="stairs:stair_wood", prob=254, param2=1},
		{name="default:wood", prob=254, param2=1},
		{name="default:wood", prob=254, param2=1},
		{name="default:wood", prob=254, param2=1},
		{name="default:wood", prob=254, param2=1},
		{name="default:wood", prob=254, param2=1},
		{name="stairs:stair_wood", prob=254, param2=3},

		-- z=11, y=9
		{name="air", prob=254, param2=0},
		{name="stairs:stair_wood", prob=254, param2=1},
		{name="default:wood", prob=254, param2=1},
		{name="default:wood", prob=254, param2=1},
		{name="default:wood", prob=254, param2=1},
		{name="stairs:stair_wood", prob=254, param2=3},
		{name="air", prob=254, param2=0},

		-- z=11, y=10
		{name="air", prob=254, param2=0},
		{name="air", prob=254, param2=0},
		{name="stairs:stair_wood", prob=254, param2=1},
		{name="default:wood", prob=254, param2=1},
		{name="stairs:stair_wood", prob=254, param2=3},
		{name="air", prob=254, param2=0},
		{name="air", prob=254, param2=0},

		-- z=11, y=11
		{name="air", prob=254, param2=0},
		{name="air", prob=254, param2=0},
		{name="air", prob=254, param2=0},
		{name="stairs:slab_wood", prob=254, param2=1},
		{name="air", prob=254, param2=0},
		{name="air", prob=254, param2=0},
		{name="air", prob=254, param2=0},

		-- z=11, y=12
		{name="air", prob=254, param2=0},
		{name="air", prob=254, param2=0},
		{name="air", prob=254, param2=0},
		{name="air", prob=254, param2=0},
		{name="air", prob=254, param2=0},
		{name="air", prob=254, param2=0},
		{name="air", prob=254, param2=0},

		-- z=11, y=13
		{name="air", prob=254, param2=0},
		{name="air", prob=254, param2=0},
		{name="air", prob=254, param2=0},
		{name="air", prob=254, param2=1},
		{name="air", prob=254, param2=0},
		{name="air", prob=254, param2=0},
		{name="air", prob=254, param2=0},

		-- z=12, y=0
		{name="default:wood", prob=254, param2=1},
		{name="default:wood", prob=254, param2=1},
		{name="default:wood", prob=254, param2=1},
		{name="default:wood", prob=254, param2=1},
		{name="default:wood", prob=254, param2=1},
		{name="default:wood", prob=254, param2=1},
		{name="default:wood", prob=254, param2=1},

		-- z=12, y=1
		{name="default:stonebrick", prob=254, param2=1},
		{name="doors:door_wood_a", prob=254, param2=0},
		{name="default:wood", prob=254, param2=1},
		{name="default:wood", prob=254, param2=1},
		{name="beds:bed_bottom", prob=254, param2=0},
		{name="air", prob=254, param2=0},
		{name="default:stonebrick", prob=254, param2=1},

		-- z=12, y=2
		{name="default:stonebrick", prob=254, param2=1},
		{name="doors:hidden", prob=254, param2=0},
		{name="default:wood", prob=254, param2=1},
		{name="default:wood", prob=254, param2=1},
		{name="air", prob=254, param2=0},
		{name="air", prob=254, param2=0},
		{name="default:stonebrick", prob=254, param2=1},

		-- z=12, y=3
		{name="default:stonebrick", prob=254, param2=1},
		{name="default:wood", prob=254, param2=1},
		{name="default:wood", prob=254, param2=1},
		{name="default:wood", prob=254, param2=1},
		{name="default:wood", prob=254, param2=1},
		{name="default:wood", prob=254, param2=1},
		{name="default:stonebrick", prob=254, param2=1},

		-- z=12, y=4
		{name="default:stonebrick", prob=254, param2=1},
		{name="default:wood", prob=254, param2=1},
		{name="default:wood", prob=254, param2=1},
		{name="default:wood", prob=254, param2=1},
		{name="default:wood", prob=254, param2=1},
		{name="default:wood", prob=254, param2=1},
		{name="default:stonebrick", prob=254, param2=1},

		-- z=12, y=5
		{name="default:stonebrick", prob=254, param2=1},
		{name="air", prob=254, param2=0},
		{name="air", prob=254, param2=0},
		{name="air", prob=254, param2=0},
		{name="air", prob=254, param2=0},
		{name="air", prob=254, param2=0},
		{name="default:stonebrick", prob=254, param2=1},

		-- z=12, y=6
		{name="default:glass", prob=254, param2=0},
		{name="air", prob=254, param2=0},
		{name="air", prob=254, param2=0},
		{name="air", prob=254, param2=0},
		{name="air", prob=254, param2=0},
		{name="air", prob=254, param2=0},
		{name="default:glass", prob=254, param2=0},

		-- z=12, y=7
		{name="default:glass", prob=254, param2=0},
		{name="air", prob=254, param2=0},
		{name="air", prob=254, param2=0},
		{name="air", prob=254, param2=0},
		{name="air", prob=254, param2=0},
		{name="air", prob=254, param2=0},
		{name="default:glass", prob=254, param2=0},

		-- z=12, y=8
		{name="stairs:stair_wood", prob=254, param2=1},
		{name="default:wood", prob=254, param2=1},
		{name="default:wood", prob=254, param2=1},
		{name="default:wood", prob=254, param2=1},
		{name="default:wood", prob=254, param2=1},
		{name="default:wood", prob=254, param2=1},
		{name="stairs:stair_wood", prob=254, param2=3},

		-- z=12, y=9
		{name="air", prob=254, param2=0},
		{name="stairs:stair_wood", prob=254, param2=1},
		{name="default:wood", prob=254, param2=1},
		{name="default:wood", prob=254, param2=1},
		{name="default:wood", prob=254, param2=1},
		{name="stairs:stair_wood", prob=254, param2=3},
		{name="air", prob=254, param2=0},

		-- z=12, y=10
		{name="air", prob=254, param2=0},
		{name="air", prob=254, param2=0},
		{name="stairs:stair_wood", prob=254, param2=1},
		{name="default:wood", prob=254, param2=1},
		{name="stairs:stair_wood", prob=254, param2=3},
		{name="air", prob=254, param2=0},
		{name="air", prob=254, param2=0},

		-- z=12, y=11
		{name="air", prob=254, param2=0},
		{name="air", prob=254, param2=0},
		{name="air", prob=254, param2=0},
		{name="stairs:slab_wood", prob=254, param2=1},
		{name="air", prob=254, param2=0},
		{name="air", prob=254, param2=0},
		{name="air", prob=254, param2=0},

		-- z=12, y=12
		{name="air", prob=254, param2=0},
		{name="air", prob=254, param2=0},
		{name="air", prob=254, param2=0},
		{name="air", prob=254, param2=0},
		{name="air", prob=254, param2=0},
		{name="air", prob=254, param2=0},
		{name="air", prob=254, param2=0},

		-- z=12, y=13
		{name="air", prob=254, param2=0},
		{name="air", prob=254, param2=0},
		{name="air", prob=254, param2=0},
		{name="air", prob=254, param2=2},
		{name="air", prob=254, param2=2},
		{name="air", prob=254, param2=2},
		{name="air", prob=254, param2=2},

		-- z=13, y=0
		{name="default:wood", prob=254, param2=1},
		{name="default:wood", prob=254, param2=1},
		{name="default:wood", prob=254, param2=1},
		{name="default:wood", prob=254, param2=1},
		{name="default:wood", prob=254, param2=1},
		{name="default:wood", prob=254, param2=1},
		{name="default:wood", prob=254, param2=1},

		-- z=13, y=1
		{name="default:stonebrick", prob=254, param2=1},
		{name="air", prob=254, param2=0},
		{name="stairs:stair_wood", prob=254, param2=1},
		{name="default:chest", prob=254, param2=3},
		{name="beds:bed_top", prob=254, param2=0},
		{name="air", prob=254, param2=0},
		{name="default:stonebrick", prob=254, param2=1},

		-- z=13, y=2
		{name="default:stonebrick", prob=254, param2=1},
		{name="air", prob=254, param2=0},
		{name="air", prob=254, param2=0},
		{name="stairs:stair_wood", prob=254, param2=1},
		{name="air", prob=254, param2=0},
		{name="air", prob=254, param2=0},
		{name="default:stonebrick", prob=254, param2=1},

		-- z=13, y=3
		{name="default:stonebrick", prob=254, param2=1},
		{name="air", prob=254, param2=0},
		{name="air", prob=254, param2=0},
		{name="air", prob=254, param2=0},
		{name="stairs:stair_wood", prob=254, param2=1},
		{name="default:torch_wall", prob=254, param2=4},
		{name="default:stonebrick", prob=254, param2=1},

		-- z=13, y=4
		{name="default:stonebrick", prob=254, param2=1},
		{name="default:wood", prob=254, param2=1},
		{name="air", prob=254, param2=0},
		{name="air", prob=254, param2=0},
		{name="air", prob=254, param2=0},
		{name="stairs:stair_wood", prob=254, param2=1},
		{name="default:stonebrick", prob=254, param2=1},

		-- z=13, y=5
		{name="default:stonebrick", prob=254, param2=1},
		{name="default:chest", prob=254, param2=3},
		{name="air", prob=254, param2=0},
		{name="air", prob=254, param2=0},
		{name="air", prob=254, param2=0},
		{name="air", prob=254, param2=0},
		{name="default:stonebrick", prob=254, param2=1},

		-- z=13, y=6
		{name="default:stonebrick", prob=254, param2=1},
		{name="default:chest", prob=254, param2=3},
		{name="air", prob=254, param2=0},
		{name="air", prob=254, param2=0},
		{name="air", prob=254, param2=0},
		{name="air", prob=254, param2=0},
		{name="default:stonebrick", prob=254, param2=1},

		-- z=13, y=7
		{name="default:stonebrick", prob=254, param2=1},
		{name="default:torch_wall", prob=254, param2=4},
		{name="air", prob=254, param2=0},
		{name="air", prob=254, param2=0},
		{name="air", prob=254, param2=0},
		{name="default:torch_wall", prob=254, param2=4},
		{name="default:stonebrick", prob=254, param2=1},

		-- z=13, y=8
		{name="stairs:stair_wood", prob=254, param2=1},
		{name="default:wood", prob=254, param2=1},
		{name="default:wood", prob=254, param2=1},
		{name="default:wood", prob=254, param2=1},
		{name="default:wood", prob=254, param2=1},
		{name="default:wood", prob=254, param2=1},
		{name="stairs:stair_wood", prob=254, param2=3},

		-- z=13, y=9
		{name="air", prob=254, param2=0},
		{name="stairs:stair_wood", prob=254, param2=1},
		{name="default:wood", prob=254, param2=1},
		{name="default:wood", prob=254, param2=1},
		{name="default:wood", prob=254, param2=1},
		{name="stairs:stair_wood", prob=254, param2=3},
		{name="air", prob=254, param2=0},

		-- z=13, y=10
		{name="air", prob=254, param2=0},
		{name="air", prob=254, param2=0},
		{name="stairs:stair_wood", prob=254, param2=1},
		{name="default:wood", prob=254, param2=1},
		{name="stairs:stair_wood", prob=254, param2=3},
		{name="air", prob=254, param2=0},
		{name="air", prob=254, param2=0},

		-- z=13, y=11
		{name="air", prob=254, param2=0},
		{name="air", prob=254, param2=0},
		{name="air", prob=254, param2=0},
		{name="stairs:slab_wood", prob=254, param2=1},
		{name="air", prob=254, param2=0},
		{name="air", prob=254, param2=0},
		{name="air", prob=254, param2=0},

		-- z=13, y=12
		{name="air", prob=254, param2=0},
		{name="air", prob=254, param2=0},
		{name="air", prob=254, param2=0},
		{name="air", prob=254, param2=0},
		{name="air", prob=254, param2=0},
		{name="air", prob=254, param2=0},
		{name="air", prob=254, param2=0},

		-- z=13, y=13
		{name="air", prob=254, param2=0},
		{name="air", prob=254, param2=0},
		{name="air", prob=254, param2=0},
		{name="air", prob=254, param2=0},
		{name="air", prob=254, param2=0},
		{name="air", prob=254, param2=0},
		{name="air", prob=254, param2=0},

		-- z=14, y=0
		{name="default:wood", prob=254, param2=1},
		{name="default:wood", prob=254, param2=1},
		{name="default:wood", prob=254, param2=1},
		{name="default:wood", prob=254, param2=1},
		{name="default:wood", prob=254, param2=1},
		{name="default:wood", prob=254, param2=1},
		{name="default:wood", prob=254, param2=1},

		-- z=14, y=1
		{name="default:tree", prob=254, param2=1},
		{name="default:stonebrick", prob=254, param2=1},
		{name="default:stonebrick", prob=254, param2=1},
		{name="default:stonebrick", prob=254, param2=1},
		{name="default:stonebrick", prob=254, param2=1},
		{name="default:stonebrick", prob=254, param2=1},
		{name="default:tree", prob=254, param2=1},

		-- z=14, y=2
		{name="default:tree", prob=254, param2=1},
		{name="default:stonebrick", prob=254, param2=1},
		{name="default:stonebrick", prob=254, param2=1},
		{name="default:stonebrick", prob=254, param2=1},
		{name="default:glass", prob=254, param2=0},
		{name="default:stonebrick", prob=254, param2=1},
		{name="default:tree", prob=254, param2=1},

		-- z=14, y=3
		{name="default:tree", prob=254, param2=1},
		{name="default:stonebrick", prob=254, param2=1},
		{name="default:stonebrick", prob=254, param2=1},
		{name="default:stonebrick", prob=254, param2=1},
		{name="default:stonebrick", prob=254, param2=1},
		{name="default:stonebrick", prob=254, param2=1},
		{name="default:tree", prob=254, param2=1},

		-- z=14, y=4
		{name="default:tree", prob=254, param2=1},
		{name="default:stonebrick", prob=254, param2=1},
		{name="default:stonebrick", prob=254, param2=1},
		{name="default:stonebrick", prob=254, param2=1},
		{name="default:stonebrick", prob=254, param2=1},
		{name="default:stonebrick", prob=254, param2=1},
		{name="default:tree", prob=254, param2=1},

		-- z=14, y=5
		{name="default:tree", prob=254, param2=1},
		{name="default:stonebrick", prob=254, param2=1},
		{name="default:stonebrick", prob=254, param2=1},
		{name="default:stonebrick", prob=254, param2=1},
		{name="default:stonebrick", prob=254, param2=1},
		{name="default:stonebrick", prob=254, param2=1},
		{name="default:tree", prob=254, param2=1},

		-- z=14, y=6
		{name="default:tree", prob=254, param2=1},
		{name="default:stonebrick", prob=254, param2=1},
		{name="default:glass", prob=254, param2=0},
		{name="default:glass", prob=254, param2=0},
		{name="default:glass", prob=254, param2=0},
		{name="default:stonebrick", prob=254, param2=1},
		{name="default:tree", prob=254, param2=1},

		-- z=14, y=7
		{name="default:tree", prob=254, param2=1},
		{name="default:stonebrick", prob=254, param2=1},
		{name="default:glass", prob=254, param2=0},
		{name="default:glass", prob=254, param2=0},
		{name="default:glass", prob=254, param2=0},
		{name="default:stonebrick", prob=254, param2=1},
		{name="default:tree", prob=254, param2=1},

		-- z=14, y=8
		{name="stairs:stair_wood", prob=254, param2=1},
		{name="default:wood", prob=254, param2=1},
		{name="default:wood", prob=254, param2=1},
		{name="default:wood", prob=254, param2=1},
		{name="default:wood", prob=254, param2=1},
		{name="default:wood", prob=254, param2=1},
		{name="stairs:stair_wood", prob=254, param2=3},

		-- z=14, y=9
		{name="air", prob=254, param2=0},
		{name="stairs:stair_wood", prob=254, param2=1},
		{name="default:wood", prob=254, param2=1},
		{name="default:wood", prob=254, param2=1},
		{name="default:wood", prob=254, param2=1},
		{name="stairs:stair_wood", prob=254, param2=3},
		{name="air", prob=254, param2=0},

		-- z=14, y=10
		{name="air", prob=254, param2=0},
		{name="air", prob=254, param2=0},
		{name="stairs:stair_wood", prob=254, param2=1},
		{name="default:wood", prob=254, param2=1},
		{name="stairs:stair_wood", prob=254, param2=3},
		{name="air", prob=254, param2=0},
		{name="air", prob=254, param2=0},

		-- z=14, y=11
		{name="air", prob=254, param2=0},
		{name="air", prob=254, param2=0},
		{name="air", prob=254, param2=0},
		{name="stairs:slab_wood", prob=254, param2=1},
		{name="air", prob=254, param2=0},
		{name="air", prob=254, param2=0},
		{name="air", prob=254, param2=0},

		-- z=14, y=12
		{name="air", prob=254, param2=0},
		{name="air", prob=254, param2=0},
		{name="air", prob=254, param2=0},
		{name="air", prob=254, param2=0},
		{name="air", prob=254, param2=0},
		{name="air", prob=254, param2=0},
		{name="air", prob=254, param2=0},

		-- z=14, y=13
		{name="air", prob=254, param2=0},
		{name="air", prob=254, param2=0},
		{name="air", prob=254, param2=0},
		{name="air", prob=254, param2=0},
		{name="air", prob=254, param2=0},
		{name="air", prob=254, param2=0},
		{name="air", prob=254, param2=0},
	},
}

return schematic