schematic = {
	size = {x=5, y=11, z=7},
	yslice_prob = {
		{ypos=0, prob=254},
		{ypos=1, prob=254},
		{ypos=2, prob=254},
		{ypos=3, prob=254},
		{ypos=4, prob=254},
		{ypos=5, prob=254},
		{ypos=6, prob=254},
		{ypos=7, prob=254},
		{ypos=8, prob=254},
		{ypos=9, prob=254},
		{ypos=10, prob=254},
	},
	data = {

		-- z=0, y=0
		{name="default:gravel", prob=254, param2=0},
		{name="default:junglewood", prob=254, param2=0},
		{name="default:junglewood", prob=254, param2=0},
		{name="default:junglewood", prob=254, param2=0},
		{name="default:gravel", prob=254, param2=0},

		-- z=0, y=1
		{name="default:fence_wood", prob=254, param2=0},
		{name="air", prob=254, param2=0},
		{name="air", prob=254, param2=0},
		{name="air", prob=254, param2=0},
		{name="default:fence_wood", prob=254, param2=0},

		-- z=0, y=2
		{name="default:fence_wood", prob=254, param2=0},
		{name="air", prob=254, param2=0},
		{name="air", prob=254, param2=0},
		{name="air", prob=254, param2=0},
		{name="default:fence_wood", prob=254, param2=0},

		-- z=0, y=3
		{name="stairs:stair_cobble", prob=254, param2=1},
		{name="stairs:slab_wood", prob=254, param2=8},
		{name="cottages:glass_pane_side", prob=254, param2=2},
		{name="stairs:slab_wood", prob=254, param2=8},
		{name="stairs:stair_cobble", prob=254, param2=3},

		-- z=0, y=4
		{name="air", prob=254, param2=0},
		{name="stairs:stair_cobble", prob=254, param2=1},
		{name="cottages:glass_pane_side", prob=254, param2=2},
		{name="stairs:stair_cobble", prob=254, param2=3},
		{name="air", prob=254, param2=0},

		-- z=0, y=5
		{name="air", prob=254, param2=0},
		{name="air", prob=254, param2=0},
		{name="stairs:slab_cobble", prob=254, param2=0},
		{name="air", prob=254, param2=0},
		{name="air", prob=254, param2=0},

		-- z=0, y=6
		{name="air", prob=254, param2=0},
		{name="air", prob=254, param2=0},
		{name="air", prob=254, param2=0},
		{name="air", prob=254, param2=0},
		{name="air", prob=254, param2=0},

		-- z=0, y=7
		{name="air", prob=254, param2=0},
		{name="air", prob=254, param2=0},
		{name="air", prob=254, param2=0},
		{name="air", prob=254, param2=0},
		{name="air", prob=254, param2=0},

		-- z=0, y=8
		{name="air", prob=254, param2=0},
		{name="air", prob=254, param2=0},
		{name="air", prob=254, param2=0},
		{name="air", prob=254, param2=0},
		{name="air", prob=254, param2=0},

		-- z=0, y=9
		{name="air", prob=254, param2=0},
		{name="air", prob=254, param2=0},
		{name="air", prob=254, param2=0},
		{name="air", prob=254, param2=0},
		{name="air", prob=254, param2=0},

		-- z=0, y=10
		{name="air", prob=254, param2=0},
		{name="air", prob=254, param2=0},
		{name="air", prob=254, param2=0},
		{name="air", prob=254, param2=0},
		{name="air", prob=254, param2=0},

		-- z=1, y=0
		{name="default:gravel", prob=254, param2=0},
		{name="default:junglewood", prob=254, param2=0},
		{name="default:junglewood", prob=254, param2=0},
		{name="default:junglewood", prob=254, param2=0},
		{name="default:gravel", prob=254, param2=0},

		-- z=1, y=1
		{name="cottages:barrel", prob=254, param2=0},
		{name="cottages:table", prob=254, param2=0},
		{name="air", prob=254, param2=0},
		{name="air", prob=254, param2=0},
		{name="air", prob=254, param2=0},

		-- z=1, y=2
		{name="air", prob=254, param2=0},
		{name="cottages:wood_flat", prob=254, param2=20},
		{name="cottages:wood_flat", prob=254, param2=20},
		{name="cottages:wood_flat", prob=254, param2=20},
		{name="air", prob=254, param2=0},

		-- z=1, y=3
		{name="stairs:stair_cobble", prob=254, param2=1},
		{name="cottages:sleeping_mat_head", prob=254, param2=2},
		{name="cottages:sleeping_mat_head", prob=254, param2=2},
		{name="cottages:sleeping_mat_head", prob=254, param2=2},
		{name="stairs:stair_cobble", prob=254, param2=3},

		-- z=1, y=4
		{name="air", prob=254, param2=0},
		{name="stairs:stair_cobble", prob=254, param2=1},
		{name="air", prob=254, param2=0},
		{name="stairs:stair_cobble", prob=254, param2=3},
		{name="air", prob=254, param2=0},

		-- z=1, y=5
		{name="air", prob=254, param2=0},
		{name="air", prob=254, param2=0},
		{name="stairs:slab_cobble", prob=254, param2=0},
		{name="air", prob=254, param2=0},
		{name="air", prob=254, param2=0},

		-- z=1, y=6
		{name="air", prob=254, param2=0},
		{name="air", prob=254, param2=0},
		{name="air", prob=254, param2=0},
		{name="air", prob=254, param2=0},
		{name="air", prob=254, param2=0},

		-- z=1, y=7
		{name="air", prob=254, param2=0},
		{name="air", prob=254, param2=0},
		{name="air", prob=254, param2=0},
		{name="air", prob=254, param2=0},
		{name="air", prob=254, param2=0},

		-- z=1, y=8
		{name="air", prob=254, param2=0},
		{name="air", prob=254, param2=0},
		{name="air", prob=254, param2=0},
		{name="air", prob=254, param2=0},
		{name="air", prob=254, param2=0},

		-- z=1, y=9
		{name="air", prob=254, param2=0},
		{name="air", prob=254, param2=0},
		{name="air", prob=254, param2=0},
		{name="air", prob=254, param2=0},
		{name="air", prob=254, param2=0},

		-- z=1, y=10
		{name="air", prob=254, param2=0},
		{name="air", prob=254, param2=0},
		{name="air", prob=254, param2=0},
		{name="air", prob=254, param2=0},
		{name="air", prob=254, param2=0},

		-- z=2, y=0
		{name="default:gravel", prob=254, param2=0},
		{name="default:junglewood", prob=254, param2=0},
		{name="default:junglewood", prob=254, param2=0},
		{name="default:junglewood", prob=254, param2=0},
		{name="default:gravel", prob=254, param2=0},

		-- z=2, y=1
		{name="stairs:slab_wood", prob=254, param2=19},
		{name="stairs:stair_wood", prob=254, param2=0},
		{name="stairs:stair_wood", prob=254, param2=0},
		{name="doors:door_wood_a", prob=254, param2=2},
		{name="stairs:slab_wood", prob=254, param2=13},

		-- z=2, y=2
		{name="stairs:slab_wood", prob=254, param2=19},
		{name="cottages:glass_pane_side", prob=254, param2=2},
		{name="stairs:stair_wood", prob=254, param2=20},
		{name="doors:hidden", prob=254, param2=2},
		{name="stairs:slab_wood", prob=254, param2=13},

		-- z=2, y=3
		{name="stairs:stair_cobble", prob=254, param2=1},
		{name="cottages:sleeping_mat", prob=254, param2=2},
		{name="cottages:sleeping_mat", prob=254, param2=2},
		{name="cottages:sleeping_mat", prob=254, param2=2},
		{name="stairs:stair_cobble", prob=254, param2=3},

		-- z=2, y=4
		{name="air", prob=254, param2=0},
		{name="stairs:stair_cobble", prob=254, param2=1},
		{name="air", prob=254, param2=0},
		{name="stairs:stair_cobble", prob=254, param2=3},
		{name="air", prob=254, param2=0},

		-- z=2, y=5
		{name="air", prob=254, param2=0},
		{name="air", prob=254, param2=0},
		{name="stairs:slab_cobble", prob=254, param2=0},
		{name="air", prob=254, param2=0},
		{name="air", prob=254, param2=0},

		-- z=2, y=6
		{name="air", prob=254, param2=0},
		{name="air", prob=254, param2=0},
		{name="air", prob=254, param2=0},
		{name="air", prob=254, param2=0},
		{name="air", prob=254, param2=0},

		-- z=2, y=7
		{name="air", prob=254, param2=0},
		{name="air", prob=254, param2=0},
		{name="air", prob=254, param2=0},
		{name="air", prob=254, param2=0},
		{name="air", prob=254, param2=0},

		-- z=2, y=8
		{name="air", prob=254, param2=0},
		{name="air", prob=254, param2=0},
		{name="air", prob=254, param2=0},
		{name="air", prob=254, param2=0},
		{name="air", prob=254, param2=0},

		-- z=2, y=9
		{name="air", prob=254, param2=0},
		{name="air", prob=254, param2=0},
		{name="air", prob=254, param2=0},
		{name="air", prob=254, param2=0},
		{name="air", prob=254, param2=0},

		-- z=2, y=10
		{name="air", prob=254, param2=0},
		{name="air", prob=254, param2=0},
		{name="air", prob=254, param2=0},
		{name="air", prob=254, param2=0},
		{name="air", prob=254, param2=0},

		-- z=3, y=0
		{name="default:gravel", prob=254, param2=0},
		{name="default:junglewood", prob=254, param2=0},
		{name="default:junglewood", prob=254, param2=0},
		{name="default:junglewood", prob=254, param2=0},
		{name="default:gravel", prob=254, param2=0},

		-- z=3, y=1
		{name="stairs:slab_wood", prob=254, param2=19},
		{name="default:bookshelf", prob=254, param2=3},
		{name="default:ladder_wood", prob=254, param2=5},
		{name="air", prob=254, param2=0},
		{name="stairs:slab_wood", prob=254, param2=13},

		-- z=3, y=2
		{name="stairs:slab_wood", prob=254, param2=19},
		{name="default:dry_shrub", prob=254, param2=0},
		{name="default:ladder_wood", prob=254, param2=5},
		{name="air", prob=254, param2=0},
		{name="stairs:slab_wood", prob=254, param2=13},

		-- z=3, y=3
		{name="stairs:stair_cobble", prob=254, param2=1},
		{name="stairs:slab_wood", prob=254, param2=4},
		{name="air", prob=254, param2=0},
		{name="stairs:slab_wood", prob=254, param2=4},
		{name="stairs:stair_cobble", prob=254, param2=3},

		-- z=3, y=4
		{name="air", prob=254, param2=0},
		{name="stairs:stair_cobble", prob=254, param2=1},
		{name="air", prob=254, param2=0},
		{name="stairs:stair_cobble", prob=254, param2=3},
		{name="air", prob=254, param2=0},

		-- z=3, y=5
		{name="air", prob=254, param2=0},
		{name="air", prob=254, param2=0},
		{name="stairs:slab_cobble", prob=254, param2=0},
		{name="air", prob=254, param2=0},
		{name="air", prob=254, param2=0},

		-- z=3, y=6
		{name="air", prob=254, param2=0},
		{name="air", prob=254, param2=0},
		{name="air", prob=254, param2=0},
		{name="air", prob=254, param2=0},
		{name="air", prob=254, param2=0},

		-- z=3, y=7
		{name="air", prob=254, param2=0},
		{name="air", prob=254, param2=0},
		{name="air", prob=254, param2=0},
		{name="air", prob=254, param2=0},
		{name="air", prob=254, param2=0},

		-- z=3, y=8
		{name="air", prob=254, param2=0},
		{name="air", prob=254, param2=0},
		{name="air", prob=254, param2=0},
		{name="air", prob=254, param2=0},
		{name="air", prob=254, param2=0},

		-- z=3, y=9
		{name="air", prob=254, param2=0},
		{name="air", prob=254, param2=0},
		{name="air", prob=254, param2=0},
		{name="air", prob=254, param2=0},
		{name="air", prob=254, param2=0},

		-- z=3, y=10
		{name="air", prob=254, param2=0},
		{name="air", prob=254, param2=0},
		{name="air", prob=254, param2=0},
		{name="air", prob=254, param2=0},
		{name="air", prob=254, param2=0},

		-- z=4, y=0
		{name="default:gravel", prob=254, param2=0},
		{name="default:junglewood", prob=254, param2=0},
		{name="default:junglewood", prob=254, param2=0},
		{name="default:junglewood", prob=254, param2=0},
		{name="default:gravel", prob=254, param2=0},

		-- z=4, y=1
		{name="stairs:slab_wood", prob=254, param2=19},
		{name="cottages:table", prob=254, param2=3},
		{name="cottages:bench", prob=254, param2=3},
		{name="air", prob=254, param2=0},
		{name="stairs:slab_wood", prob=254, param2=13},

		-- z=4, y=2
		{name="cottages:glass_pane_side", prob=254, param2=3},
		{name="cottages:window_shutter_open", prob=254, param2=3},
		{name="air", prob=254, param2=0},
		{name="air", prob=254, param2=0},
		{name="stairs:slab_wood", prob=254, param2=13},

		-- z=4, y=3
		{name="stairs:stair_cobble", prob=254, param2=1},
		{name="air", prob=254, param2=0},
		{name="air", prob=254, param2=0},
		{name="air", prob=254, param2=0},
		{name="stairs:stair_cobble", prob=254, param2=3},

		-- z=4, y=4
		{name="air", prob=254, param2=0},
		{name="stairs:stair_cobble", prob=254, param2=1},
		{name="air", prob=254, param2=0},
		{name="stairs:stair_cobble", prob=254, param2=3},
		{name="air", prob=254, param2=0},

		-- z=4, y=5
		{name="air", prob=254, param2=0},
		{name="air", prob=254, param2=0},
		{name="stairs:slab_cobble", prob=254, param2=0},
		{name="air", prob=254, param2=0},
		{name="air", prob=254, param2=0},

		-- z=4, y=6
		{name="air", prob=254, param2=0},
		{name="air", prob=254, param2=0},
		{name="air", prob=254, param2=0},
		{name="air", prob=254, param2=0},
		{name="air", prob=254, param2=0},

		-- z=4, y=7
		{name="air", prob=254, param2=0},
		{name="air", prob=254, param2=0},
		{name="air", prob=254, param2=0},
		{name="air", prob=254, param2=0},
		{name="air", prob=254, param2=0},

		-- z=4, y=8
		{name="air", prob=254, param2=0},
		{name="air", prob=254, param2=0},
		{name="air", prob=254, param2=0},
		{name="air", prob=254, param2=0},
		{name="air", prob=254, param2=0},

		-- z=4, y=9
		{name="air", prob=254, param2=0},
		{name="air", prob=254, param2=0},
		{name="air", prob=254, param2=0},
		{name="air", prob=254, param2=0},
		{name="air", prob=254, param2=0},

		-- z=4, y=10
		{name="air", prob=254, param2=0},
		{name="air", prob=254, param2=0},
		{name="air", prob=254, param2=0},
		{name="air", prob=254, param2=0},
		{name="air", prob=254, param2=0},

		-- z=5, y=0
		{name="default:gravel", prob=254, param2=0},
		{name="default:junglewood", prob=254, param2=0},
		{name="default:junglewood", prob=254, param2=0},
		{name="default:junglewood", prob=254, param2=0},
		{name="default:gravel", prob=254, param2=0},

		-- z=5, y=1
		{name="stairs:slab_wood", prob=254, param2=19},
		{name="cottages:bench", prob=254, param2=0},
		{name="air", prob=254, param2=0},
		{name="cottages:shelf", prob=254, param2=0},
		{name="stairs:slab_wood", prob=254, param2=13},

		-- z=5, y=2
		{name="stairs:slab_wood", prob=254, param2=19},
		{name="cottages:wood_flat", prob=254, param2=20},
		{name="air", prob=254, param2=0},
		{name="cottages:shelf", prob=254, param2=0},
		{name="stairs:slab_wood", prob=254, param2=13},

		-- z=5, y=3
		{name="stairs:stair_cobble", prob=254, param2=1},
		{name="default:chest", prob=254, param2=0},
		{name="default:torch_wall", prob=254, param2=4},
		{name="default:chest", prob=254, param2=0},
		{name="stairs:stair_cobble", prob=254, param2=3},

		-- z=5, y=4
		{name="air", prob=254, param2=0},
		{name="stairs:stair_cobble", prob=254, param2=1},
		{name="air", prob=254, param2=0},
		{name="stairs:stair_cobble", prob=254, param2=3},
		{name="air", prob=254, param2=0},

		-- z=5, y=5
		{name="air", prob=254, param2=0},
		{name="air", prob=254, param2=0},
		{name="stairs:slab_cobble", prob=254, param2=0},
		{name="air", prob=254, param2=0},
		{name="air", prob=254, param2=0},

		-- z=5, y=6
		{name="air", prob=254, param2=0},
		{name="air", prob=254, param2=0},
		{name="air", prob=254, param2=0},
		{name="air", prob=254, param2=0},
		{name="air", prob=254, param2=0},

		-- z=5, y=7
		{name="air", prob=254, param2=0},
		{name="air", prob=254, param2=0},
		{name="air", prob=254, param2=0},
		{name="air", prob=254, param2=0},
		{name="air", prob=254, param2=0},

		-- z=5, y=8
		{name="air", prob=254, param2=0},
		{name="air", prob=254, param2=0},
		{name="air", prob=254, param2=0},
		{name="air", prob=254, param2=0},
		{name="air", prob=254, param2=0},

		-- z=5, y=9
		{name="air", prob=254, param2=0},
		{name="air", prob=254, param2=0},
		{name="air", prob=254, param2=0},
		{name="air", prob=254, param2=0},
		{name="air", prob=254, param2=0},

		-- z=5, y=10
		{name="air", prob=254, param2=0},
		{name="air", prob=254, param2=0},
		{name="air", prob=254, param2=0},
		{name="air", prob=254, param2=0},
		{name="air", prob=254, param2=0},

		-- z=6, y=0
		{name="default:gravel", prob=254, param2=0},
		{name="default:gravel", prob=254, param2=0},
		{name="default:gravel", prob=254, param2=0},
		{name="default:gravel", prob=254, param2=0},
		{name="default:gravel", prob=254, param2=0},

		-- z=6, y=1
		{name="air", prob=254, param2=0},
		{name="stairs:slab_wood", prob=254, param2=4},
		{name="default:furnace", prob=254, param2=0},
		{name="stairs:slab_wood", prob=254, param2=4},
		{name="air", prob=254, param2=0},

		-- z=6, y=2
		{name="air", prob=254, param2=0},
		{name="stairs:slab_wood", prob=254, param2=4},
		{name="default:stonebrick", prob=254, param2=0},
		{name="stairs:slab_wood", prob=254, param2=4},
		{name="air", prob=254, param2=0},

		-- z=6, y=3
		{name="stairs:stair_cobble", prob=254, param2=1},
		{name="stairs:slab_wood", prob=254, param2=4},
		{name="default:stonebrick", prob=254, param2=0},
		{name="stairs:slab_wood", prob=254, param2=4},
		{name="stairs:stair_cobble", prob=254, param2=3},

		-- z=6, y=4
		{name="air", prob=254, param2=0},
		{name="stairs:stair_cobble", prob=254, param2=1},
		{name="default:stonebrick", prob=254, param2=0},
		{name="stairs:stair_cobble", prob=254, param2=3},
		{name="air", prob=254, param2=0},

		-- z=6, y=5
		{name="air", prob=254, param2=0},
		{name="air", prob=254, param2=0},
		{name="default:stonebrick", prob=254, param2=0},
		{name="air", prob=254, param2=0},
		{name="air", prob=254, param2=0},

		-- z=6, y=6
		{name="air", prob=254, param2=0},
		{name="air", prob=254, param2=0},
		{name="default:stonebrick", prob=254, param2=0},
		{name="air", prob=254, param2=0},
		{name="air", prob=254, param2=0},

		-- z=6, y=7
		{name="air", prob=254, param2=0},
		{name="air", prob=254, param2=0},
		{name="air", prob=254, param2=0},
		{name="air", prob=254, param2=0},
		{name="air", prob=254, param2=0},

		-- z=6, y=8
		{name="air", prob=254, param2=0},
		{name="air", prob=254, param2=0},
		{name="air", prob=254, param2=0},
		{name="air", prob=254, param2=0},
		{name="air", prob=254, param2=0},

		-- z=6, y=9
		{name="air", prob=254, param2=0},
		{name="air", prob=254, param2=0},
		{name="air", prob=254, param2=0},
		{name="air", prob=254, param2=0},
		{name="air", prob=254, param2=0},

		-- z=6, y=10
		{name="air", prob=254, param2=0},
		{name="air", prob=254, param2=0},
		{name="air", prob=254, param2=0},
		{name="air", prob=254, param2=0},
		{name="air", prob=254, param2=0},
	},
}

return schematic