schematic = {
	size = {x=7, y=7, z=6},
	yslice_prob = {
		{ypos=0, prob=254},
		{ypos=1, prob=254},
		{ypos=2, prob=254},
		{ypos=3, prob=254},
		{ypos=4, prob=254},
		{ypos=5, prob=254},
		{ypos=6, prob=254},
	},
	data = {

		-- z=0, y=0
		{name="default:dirt_with_grass", prob=254, param2=0},
		{name="default:dirt_with_grass", prob=254, param2=0},
		{name="default:dirt_with_grass", prob=254, param2=0},
		{name="default:dirt_with_grass", prob=254, param2=0},
		{name="default:dirt_with_grass", prob=254, param2=0},
		{name="default:dirt_with_grass", prob=254, param2=0},
		{name="default:dirt_with_grass", prob=254, param2=0},

		-- z=0, y=1
		{name="air", prob=254, param2=0},
		{name="air", prob=254, param2=0},
		{name="air", prob=254, param2=0},
		{name="air", prob=254, param2=0},
		{name="air", prob=254, param2=0},
		{name="air", prob=254, param2=0},
		{name="air", prob=254, param2=0},

		-- z=0, y=2
		{name="air", prob=254, param2=0},
		{name="air", prob=254, param2=0},
		{name="air", prob=254, param2=0},
		{name="air", prob=254, param2=0},
		{name="air", prob=254, param2=0},
		{name="air", prob=254, param2=0},
		{name="air", prob=254, param2=0},

		-- z=0, y=3
		{name="air", prob=254, param2=0},
		{name="air", prob=254, param2=0},
		{name="air", prob=254, param2=0},
		{name="air", prob=254, param2=0},
		{name="air", prob=254, param2=0},
		{name="air", prob=254, param2=0},
		{name="air", prob=254, param2=0},

		-- z=0, y=4
		{name="air", prob=254, param2=0},
		{name="air", prob=254, param2=0},
		{name="air", prob=254, param2=0},
		{name="air", prob=254, param2=0},
		{name="air", prob=254, param2=0},
		{name="air", prob=254, param2=0},
		{name="air", prob=254, param2=0},

		-- z=0, y=5
		{name="air", prob=254, param2=0},
		{name="cottages:roof_flat_straw", prob=254, param2=0},
		{name="cottages:roof_flat_straw", prob=254, param2=0},
		{name="cottages:roof_flat_straw", prob=254, param2=0},
		{name="cottages:roof_flat_straw", prob=254, param2=0},
		{name="cottages:roof_flat_straw", prob=254, param2=0},
		{name="air", prob=254, param2=0},

		-- z=0, y=6
		{name="air", prob=254, param2=0},
		{name="air", prob=254, param2=0},
		{name="air", prob=254, param2=0},
		{name="air", prob=254, param2=0},
		{name="air", prob=254, param2=0},
		{name="air", prob=254, param2=0},
		{name="air", prob=254, param2=0},

		-- z=1, y=0
		{name="default:dirt_with_grass", prob=254, param2=0},
		{name="default:gravel", prob=254, param2=0},
		{name="default:gravel", prob=254, param2=0},
		{name="default:gravel", prob=254, param2=0},
		{name="default:gravel", prob=254, param2=0},
		{name="default:gravel", prob=254, param2=0},
		{name="default:dirt_with_grass", prob=254, param2=0},

		-- z=1, y=1
		{name="air", prob=254, param2=0},
		{name="default:fence_wood", prob=254, param2=3},
		{name="air", prob=254, param2=0},
		{name="default:fence_wood", prob=254, param2=0},
		{name="air", prob=254, param2=0},
		{name="default:fence_wood", prob=254, param2=1},
		{name="air", prob=254, param2=0},

		-- z=1, y=2
		{name="air", prob=254, param2=0},
		{name="default:fence_wood", prob=254, param2=3},
		{name="air", prob=254, param2=0},
		{name="default:fence_wood", prob=254, param2=0},
		{name="air", prob=254, param2=0},
		{name="default:fence_wood", prob=254, param2=0},
		{name="air", prob=254, param2=0},

		-- z=1, y=3
		{name="air", prob=254, param2=0},
		{name="stairs:stair_wood", prob=254, param2=22},
		{name="stairs:stair_wood", prob=254, param2=22},
		{name="stairs:stair_wood", prob=254, param2=22},
		{name="stairs:stair_wood", prob=254, param2=22},
		{name="stairs:stair_wood", prob=254, param2=22},
		{name="air", prob=254, param2=0},

		-- z=1, y=4
		{name="stairs:slab_wood", prob=254, param2=16},
		{name="stairs:slab_wood", prob=254, param2=4},
		{name="cottages:fence_small", prob=254, param2=2},
		{name="stairs:slab_wood", prob=254, param2=4},
		{name="cottages:fence_small", prob=254, param2=2},
		{name="stairs:slab_wood", prob=254, param2=4},
		{name="stairs:slab_wood", prob=254, param2=12},

		-- z=1, y=5
		{name="cottages:roof_straw", prob=254, param2=0},
		{name="cottages:roof_straw", prob=254, param2=0},
		{name="cottages:roof_straw", prob=254, param2=0},
		{name="cottages:roof_straw", prob=254, param2=0},
		{name="cottages:roof_straw", prob=254, param2=0},
		{name="cottages:roof_straw", prob=254, param2=0},
		{name="cottages:roof_straw", prob=254, param2=0},

		-- z=1, y=6
		{name="air", prob=254, param2=0},
		{name="air", prob=254, param2=0},
		{name="air", prob=254, param2=0},
		{name="air", prob=254, param2=0},
		{name="air", prob=254, param2=0},
		{name="air", prob=254, param2=0},
		{name="air", prob=254, param2=0},

		-- z=2, y=0
		{name="default:dirt_with_grass", prob=254, param2=0},
		{name="default:gravel", prob=254, param2=0},
		{name="default:gravel", prob=254, param2=0},
		{name="default:gravel", prob=254, param2=0},
		{name="default:gravel", prob=254, param2=0},
		{name="default:gravel", prob=254, param2=0},
		{name="default:dirt_with_grass", prob=254, param2=0},

		-- z=2, y=1
		{name="air", prob=254, param2=0},
		{name="air", prob=254, param2=0},
		{name="air", prob=254, param2=0},
		{name="air", prob=254, param2=0},
		{name="air", prob=254, param2=0},
		{name="air", prob=254, param2=0},
		{name="air", prob=254, param2=0},

		-- z=2, y=2
		{name="air", prob=254, param2=0},
		{name="air", prob=254, param2=0},
		{name="air", prob=254, param2=0},
		{name="air", prob=254, param2=0},
		{name="air", prob=254, param2=0},
		{name="air", prob=254, param2=0},
		{name="air", prob=254, param2=0},

		-- z=2, y=3
		{name="air", prob=254, param2=0},
		{name="stairs:slab_wood", prob=254, param2=20},
		{name="stairs:slab_wood", prob=254, param2=20},
		{name="stairs:slab_wood", prob=254, param2=20},
		{name="stairs:slab_wood", prob=254, param2=20},
		{name="stairs:slab_wood", prob=254, param2=20},
		{name="air", prob=254, param2=0},

		-- z=2, y=4
		{name="stairs:slab_wood", prob=254, param2=16},
		{name="cottages:straw_bale", prob=254, param2=0},
		{name="air", prob=254, param2=0},
		{name="air", prob=254, param2=0},
		{name="air", prob=254, param2=0},
		{name="air", prob=254, param2=0},
		{name="cottages:half_door_inverted", prob=254, param2=1},

		-- z=2, y=5
		{name="stairs:slab_wood", prob=254, param2=16},
		{name="air", prob=254, param2=0},
		{name="air", prob=254, param2=0},
		{name="air", prob=254, param2=0},
		{name="air", prob=254, param2=0},
		{name="air", prob=254, param2=0},
		{name="cottages:half_door_inverted", prob=254, param2=1},

		-- z=2, y=6
		{name="cottages:roof_flat_straw", prob=254, param2=3},
		{name="cottages:roof_flat_straw", prob=254, param2=3},
		{name="cottages:roof_flat_straw", prob=254, param2=3},
		{name="cottages:roof_flat_straw", prob=254, param2=3},
		{name="cottages:roof_flat_straw", prob=254, param2=3},
		{name="cottages:roof_flat_straw", prob=254, param2=3},
		{name="cottages:roof_flat_straw", prob=254, param2=3},

		-- z=3, y=0
		{name="default:dirt", prob=254, param2=0},
		{name="default:gravel", prob=254, param2=0},
		{name="default:gravel", prob=254, param2=0},
		{name="default:gravel", prob=254, param2=0},
		{name="default:gravel", prob=254, param2=0},
		{name="default:gravel", prob=254, param2=0},
		{name="default:dirt", prob=254, param2=0},

		-- z=3, y=1
		{name="air", prob=254, param2=0},
		{name="air", prob=254, param2=0},
		{name="air", prob=254, param2=0},
		{name="default:ladder", prob=254, param2=4},
		{name="air", prob=254, param2=0},
		{name="air", prob=254, param2=0},
		{name="air", prob=254, param2=0},

		-- z=3, y=2
		{name="air", prob=254, param2=0},
		{name="air", prob=254, param2=0},
		{name="air", prob=254, param2=0},
		{name="default:ladder", prob=254, param2=4},
		{name="air", prob=254, param2=0},
		{name="air", prob=254, param2=0},
		{name="air", prob=254, param2=0},

		-- z=3, y=3
		{name="air", prob=254, param2=0},
		{name="stairs:slab_wood", prob=254, param2=20},
		{name="stairs:slab_wood", prob=254, param2=20},
		{name="default:ladder", prob=254, param2=4},
		{name="stairs:slab_wood", prob=254, param2=20},
		{name="stairs:slab_wood", prob=254, param2=20},
		{name="air", prob=254, param2=0},

		-- z=3, y=4
		{name="stairs:slab_wood", prob=254, param2=16},
		{name="cottages:straw_bale", prob=254, param2=0},
		{name="cottages:straw_bale", prob=254, param2=0},
		{name="default:ladder", prob=254, param2=4},
		{name="air", prob=254, param2=0},
		{name="air", prob=254, param2=0},
		{name="cottages:half_door", prob=254, param2=3},

		-- z=3, y=5
		{name="stairs:slab_wood", prob=254, param2=16},
		{name="cottages:straw_bale", prob=254, param2=0},
		{name="air", prob=254, param2=0},
		{name="default:ladder", prob=254, param2=4},
		{name="air", prob=254, param2=0},
		{name="air", prob=254, param2=0},
		{name="cottages:half_door", prob=254, param2=3},

		-- z=3, y=6
		{name="cottages:roof_flat_straw", prob=254, param2=3},
		{name="cottages:roof_flat_straw", prob=254, param2=3},
		{name="cottages:roof_flat_straw", prob=254, param2=3},
		{name="cottages:roof_flat_straw", prob=254, param2=3},
		{name="cottages:roof_flat_straw", prob=254, param2=3},
		{name="cottages:roof_flat_straw", prob=254, param2=3},
		{name="cottages:roof_flat_straw", prob=254, param2=3},

		-- z=4, y=0
		{name="default:dirt", prob=254, param2=0},
		{name="default:gravel", prob=254, param2=0},
		{name="default:gravel", prob=254, param2=0},
		{name="default:gravel", prob=254, param2=0},
		{name="default:gravel", prob=254, param2=0},
		{name="default:gravel", prob=254, param2=0},
		{name="default:dirt_with_grass", prob=254, param2=0},

		-- z=4, y=1
		{name="air", prob=254, param2=0},
		{name="default:fence_wood", prob=254, param2=3},
		{name="air", prob=254, param2=0},
		{name="default:fence_wood", prob=254, param2=0},
		{name="air", prob=254, param2=0},
		{name="default:fence_wood", prob=254, param2=0},
		{name="air", prob=254, param2=0},

		-- z=4, y=2
		{name="air", prob=254, param2=0},
		{name="default:fence_wood", prob=254, param2=3},
		{name="air", prob=254, param2=0},
		{name="default:fence_wood", prob=254, param2=0},
		{name="air", prob=254, param2=0},
		{name="default:fence_wood", prob=254, param2=0},
		{name="air", prob=254, param2=0},

		-- z=4, y=3
		{name="air", prob=254, param2=0},
		{name="stairs:stair_wood", prob=254, param2=20},
		{name="stairs:stair_wood", prob=254, param2=20},
		{name="stairs:slab_wood", prob=254, param2=8},
		{name="stairs:stair_wood", prob=254, param2=20},
		{name="stairs:stair_wood", prob=254, param2=20},
		{name="air", prob=254, param2=0},

		-- z=4, y=4
		{name="stairs:slab_wood", prob=254, param2=16},
		{name="stairs:slab_wood", prob=254, param2=8},
		{name="cottages:fence_small", prob=254, param2=0},
		{name="stairs:slab_wood", prob=254, param2=8},
		{name="cottages:fence_small", prob=254, param2=0},
		{name="stairs:slab_wood", prob=254, param2=8},
		{name="stairs:slab_wood", prob=254, param2=12},

		-- z=4, y=5
		{name="cottages:roof_straw", prob=254, param2=2},
		{name="cottages:roof_straw", prob=254, param2=2},
		{name="cottages:roof_straw", prob=254, param2=2},
		{name="cottages:roof_straw", prob=254, param2=2},
		{name="cottages:roof_straw", prob=254, param2=2},
		{name="cottages:roof_straw", prob=254, param2=2},
		{name="cottages:roof_straw", prob=254, param2=2},

		-- z=4, y=6
		{name="air", prob=254, param2=0},
		{name="air", prob=254, param2=0},
		{name="air", prob=254, param2=0},
		{name="air", prob=254, param2=0},
		{name="air", prob=254, param2=0},
		{name="air", prob=254, param2=0},
		{name="air", prob=254, param2=0},

		-- z=5, y=0
		{name="default:dirt_with_grass", prob=254, param2=0},
		{name="default:dirt_with_grass", prob=254, param2=0},
		{name="default:dirt_with_grass", prob=254, param2=0},
		{name="default:dirt_with_grass", prob=254, param2=0},
		{name="default:dirt_with_grass", prob=254, param2=0},
		{name="default:dirt_with_grass", prob=254, param2=0},
		{name="default:dirt_with_grass", prob=254, param2=0},

		-- z=5, y=1
		{name="air", prob=254, param2=0},
		{name="air", prob=254, param2=0},
		{name="air", prob=254, param2=0},
		{name="air", prob=254, param2=0},
		{name="air", prob=254, param2=0},
		{name="air", prob=254, param2=0},
		{name="air", prob=254, param2=0},

		-- z=5, y=2
		{name="air", prob=254, param2=0},
		{name="air", prob=254, param2=0},
		{name="air", prob=254, param2=0},
		{name="air", prob=254, param2=0},
		{name="air", prob=254, param2=0},
		{name="air", prob=254, param2=0},
		{name="air", prob=254, param2=0},

		-- z=5, y=3
		{name="air", prob=254, param2=0},
		{name="air", prob=254, param2=0},
		{name="air", prob=254, param2=0},
		{name="air", prob=254, param2=0},
		{name="air", prob=254, param2=0},
		{name="air", prob=254, param2=0},
		{name="air", prob=254, param2=0},

		-- z=5, y=4
		{name="air", prob=254, param2=0},
		{name="air", prob=254, param2=0},
		{name="air", prob=254, param2=0},
		{name="air", prob=254, param2=0},
		{name="air", prob=254, param2=0},
		{name="air", prob=254, param2=0},
		{name="air", prob=254, param2=0},

		-- z=5, y=5
		{name="air", prob=254, param2=0},
		{name="cottages:roof_flat_straw", prob=254, param2=2},
		{name="cottages:roof_flat_straw", prob=254, param2=2},
		{name="cottages:roof_flat_straw", prob=254, param2=2},
		{name="cottages:roof_flat_straw", prob=254, param2=2},
		{name="cottages:roof_flat_straw", prob=254, param2=2},
		{name="air", prob=254, param2=0},

		-- z=5, y=6
		{name="air", prob=254, param2=0},
		{name="air", prob=254, param2=0},
		{name="air", prob=254, param2=0},
		{name="air", prob=254, param2=0},
		{name="air", prob=254, param2=0},
		{name="air", prob=254, param2=0},
		{name="air", prob=254, param2=0},
	},
}

return schematic