schematic = {
	size = {x=5, y=4, z=5},
	yslice_prob = {
		{ypos=0, prob=254},
		{ypos=1, prob=254},
		{ypos=2, prob=254},
		{ypos=3, prob=254},
	},
	data = {

		-- z=0, y=0
		{name="default:gravel", prob=254, param2=0},
		{name="default:gravel", prob=254, param2=0},
		{name="default:gravel", prob=254, param2=0},
		{name="default:gravel", prob=254, param2=0},
		{name="default:gravel", prob=254, param2=0},

		-- z=0, y=1
		{name="default:fence_wood", prob=254, param2=0},
		{name="cottages:wool_tent", prob=254, param2=9},
		{name="air", prob=254, param2=0},
		{name="cottages:wool_tent", prob=254, param2=9},
		{name="default:fence_wood", prob=254, param2=0},

		-- z=0, y=2
		{name="default:fence_wood", prob=254, param2=0},
		{name="cottages:wool_tent", prob=254, param2=9},
		{name="air", prob=254, param2=0},
		{name="cottages:wool_tent", prob=254, param2=9},
		{name="default:fence_wood", prob=254, param2=0},

		-- z=0, y=3
		{name="default:fence_wood", prob=254, param2=0},
		{name="air", prob=254, param2=0},
		{name="air", prob=254, param2=0},
		{name="air", prob=254, param2=0},
		{name="default:fence_wood", prob=254, param2=0},

		-- z=1, y=0
		{name="default:gravel", prob=254, param2=0},
		{name="default:gravel", prob=254, param2=0},
		{name="default:gravel", prob=254, param2=0},
		{name="default:gravel", prob=254, param2=0},
		{name="default:gravel", prob=254, param2=0},

		-- z=1, y=1
		{name="cottages:wool_tent", prob=254, param2=18},
		{name="air", prob=254, param2=0},
		{name="cottages:sleeping_mat", prob=254, param2=4},
		{name="air", prob=254, param2=0},
		{name="cottages:wool_tent", prob=254, param2=12},

		-- z=1, y=2
		{name="cottages:wool_tent", prob=254, param2=18},
		{name="air", prob=254, param2=0},
		{name="cottages:sleeping_mat", prob=254, param2=4},
		{name="air", prob=254, param2=0},
		{name="cottages:wool_tent", prob=254, param2=12},

		-- z=1, y=3
		{name="air", prob=254, param2=0},
		{name="cottages:wool_tent", prob=254, param2=3},
		{name="cottages:wool_tent", prob=254, param2=3},
		{name="cottages:wool_tent", prob=254, param2=3},
		{name="air", prob=254, param2=0},

		-- z=2, y=0
		{name="default:gravel", prob=254, param2=0},
		{name="default:gravel", prob=254, param2=0},
		{name="default:gravel", prob=254, param2=0},
		{name="default:gravel", prob=254, param2=0},
		{name="default:gravel", prob=254, param2=0},

		-- z=2, y=1
		{name="cottages:wool_tent", prob=254, param2=18},
		{name="cottages:bench", prob=254, param2=3},
		{name="air", prob=254, param2=0},
		{name="cottages:tub", prob=254, param2=0},
		{name="cottages:wool_tent", prob=254, param2=12},

		-- z=2, y=2
		{name="cottages:wool_tent", prob=254, param2=18},
		{name="default:torch_wall", prob=254, param2=3},
		{name="cottages:wool_tent", prob=254, param2=21},
		{name="air", prob=254, param2=0},
		{name="cottages:hatch_wood", prob=254, param2=15},

		-- z=2, y=3
		{name="air", prob=254, param2=0},
		{name="cottages:wool_tent", prob=254, param2=3},
		{name="air", prob=254, param2=0},
		{name="cottages:wool_tent", prob=254, param2=3},
		{name="air", prob=254, param2=0},

		-- z=3, y=0
		{name="default:gravel", prob=254, param2=0},
		{name="default:gravel", prob=254, param2=0},
		{name="default:gravel", prob=254, param2=0},
		{name="default:gravel", prob=254, param2=0},
		{name="default:gravel", prob=254, param2=0},

		-- z=3, y=1
		{name="cottages:wool_tent", prob=254, param2=18},
		{name="default:chest", prob=254, param2=0},
		{name="cottages:bench", prob=254, param2=0},
		{name="air", prob=254, param2=0},
		{name="cottages:wool_tent", prob=254, param2=12},

		-- z=3, y=2
		{name="cottages:wool_tent", prob=254, param2=18},
		{name="air", prob=254, param2=0},
		{name="air", prob=254, param2=0},
		{name="air", prob=254, param2=0},
		{name="cottages:wool_tent", prob=254, param2=12},

		-- z=3, y=3
		{name="air", prob=254, param2=0},
		{name="cottages:wool_tent", prob=254, param2=3},
		{name="cottages:wool_tent", prob=254, param2=3},
		{name="cottages:wool_tent", prob=254, param2=3},
		{name="air", prob=254, param2=0},

		-- z=4, y=0
		{name="default:gravel", prob=254, param2=0},
		{name="default:gravel", prob=254, param2=0},
		{name="default:gravel", prob=254, param2=0},
		{name="default:gravel", prob=254, param2=0},
		{name="default:gravel", prob=254, param2=0},

		-- z=4, y=1
		{name="default:fence_wood", prob=254, param2=0},
		{name="cottages:wool_tent", prob=254, param2=7},
		{name="cottages:wool_tent", prob=254, param2=7},
		{name="cottages:wool_tent", prob=254, param2=7},
		{name="default:fence_wood", prob=254, param2=0},

		-- z=4, y=2
		{name="default:fence_wood", prob=254, param2=0},
		{name="cottages:wool_tent", prob=254, param2=7},
		{name="cottages:wool_tent", prob=254, param2=7},
		{name="cottages:wool_tent", prob=254, param2=7},
		{name="default:fence_wood", prob=254, param2=0},

		-- z=4, y=3
		{name="default:fence_wood", prob=254, param2=0},
		{name="air", prob=254, param2=0},
		{name="air", prob=254, param2=0},
		{name="air", prob=254, param2=0},
		{name="default:fence_wood", prob=254, param2=0},
	},
}

return schematic