schematic = {
	size = {x=9, y=7, z=13},
	yslice_prob = {
		{ypos=0, prob=254},
		{ypos=1, prob=254},
		{ypos=2, prob=254},
		{ypos=3, prob=254},
		{ypos=4, prob=254},
		{ypos=5, prob=254},
		{ypos=6, prob=254},
	},
	data = {

		-- z=0, y=0
		{name="air", prob=254, param2=0},
		{name="air", prob=254, param2=0},
		{name="air", prob=254, param2=0},
		{name="air", prob=254, param2=0},
		{name="air", prob=254, param2=0},
		{name="air", prob=254, param2=0},
		{name="air", prob=254, param2=0},
		{name="air", prob=254, param2=0},
		{name="air", prob=254, param2=0},

		-- z=0, y=1
		{name="air", prob=254, param2=0},
		{name="air", prob=254, param2=0},
		{name="air", prob=254, param2=0},
		{name="air", prob=254, param2=0},
		{name="air", prob=254, param2=0},
		{name="air", prob=254, param2=0},
		{name="air", prob=254, param2=0},
		{name="air", prob=254, param2=0},
		{name="air", prob=254, param2=0},

		-- z=0, y=2
		{name="air", prob=254, param2=0},
		{name="air", prob=254, param2=0},
		{name="air", prob=254, param2=0},
		{name="air", prob=254, param2=0},
		{name="air", prob=254, param2=0},
		{name="air", prob=254, param2=0},
		{name="air", prob=254, param2=0},
		{name="air", prob=254, param2=0},
		{name="air", prob=254, param2=0},

		-- z=0, y=3
		{name="air", prob=254, param2=0},
		{name="air", prob=254, param2=0},
		{name="air", prob=254, param2=0},
		{name="air", prob=254, param2=0},
		{name="air", prob=254, param2=0},
		{name="air", prob=254, param2=0},
		{name="air", prob=254, param2=0},
		{name="air", prob=254, param2=0},
		{name="air", prob=254, param2=0},

		-- z=0, y=4
		{name="air", prob=254, param2=0},
		{name="air", prob=254, param2=0},
		{name="air", prob=254, param2=0},
		{name="air", prob=254, param2=0},
		{name="air", prob=254, param2=0},
		{name="air", prob=254, param2=0},
		{name="air", prob=254, param2=0},
		{name="air", prob=254, param2=0},
		{name="air", prob=254, param2=0},

		-- z=0, y=5
		{name="air", prob=254, param2=0},
		{name="air", prob=254, param2=0},
		{name="air", prob=254, param2=0},
		{name="air", prob=254, param2=0},
		{name="air", prob=254, param2=0},
		{name="air", prob=254, param2=0},
		{name="air", prob=254, param2=0},
		{name="air", prob=254, param2=0},
		{name="air", prob=254, param2=0},

		-- z=0, y=6
		{name="air", prob=254, param2=0},
		{name="air", prob=254, param2=0},
		{name="air", prob=254, param2=0},
		{name="air", prob=254, param2=0},
		{name="air", prob=254, param2=0},
		{name="air", prob=254, param2=0},
		{name="air", prob=254, param2=0},
		{name="air", prob=254, param2=0},
		{name="air", prob=254, param2=0},

		-- z=1, y=0
		{name="air", prob=254, param2=0},
		{name="air", prob=254, param2=0},
		{name="air", prob=254, param2=0},
		{name="air", prob=254, param2=0},
		{name="air", prob=254, param2=0},
		{name="default:sand", prob=254, param2=9},
		{name="default:sand", prob=254, param2=9},
		{name="default:clay", prob=254, param2=9},
		{name="air", prob=254, param2=0},

		-- z=1, y=1
		{name="air", prob=254, param2=0},
		{name="air", prob=254, param2=0},
		{name="air", prob=254, param2=0},
		{name="air", prob=254, param2=0},
		{name="air", prob=254, param2=0},
		{name="air", prob=254, param2=0},
		{name="default:sand", prob=254, param2=9},
		{name="air", prob=254, param2=0},
		{name="air", prob=254, param2=0},

		-- z=1, y=2
		{name="air", prob=254, param2=0},
		{name="air", prob=254, param2=0},
		{name="air", prob=254, param2=0},
		{name="air", prob=254, param2=0},
		{name="air", prob=254, param2=0},
		{name="air", prob=254, param2=0},
		{name="air", prob=254, param2=0},
		{name="air", prob=254, param2=0},
		{name="air", prob=254, param2=0},

		-- z=1, y=3
		{name="air", prob=254, param2=0},
		{name="air", prob=254, param2=0},
		{name="air", prob=254, param2=0},
		{name="air", prob=254, param2=0},
		{name="air", prob=254, param2=0},
		{name="air", prob=254, param2=0},
		{name="air", prob=254, param2=0},
		{name="air", prob=254, param2=0},
		{name="air", prob=254, param2=0},

		-- z=1, y=4
		{name="air", prob=254, param2=0},
		{name="air", prob=254, param2=0},
		{name="air", prob=254, param2=0},
		{name="air", prob=254, param2=0},
		{name="air", prob=254, param2=0},
		{name="air", prob=254, param2=0},
		{name="air", prob=254, param2=0},
		{name="air", prob=254, param2=0},
		{name="air", prob=254, param2=0},

		-- z=1, y=5
		{name="air", prob=254, param2=0},
		{name="air", prob=254, param2=0},
		{name="air", prob=254, param2=0},
		{name="air", prob=254, param2=0},
		{name="air", prob=254, param2=0},
		{name="air", prob=254, param2=0},
		{name="air", prob=254, param2=0},
		{name="air", prob=254, param2=0},
		{name="air", prob=254, param2=0},

		-- z=1, y=6
		{name="air", prob=254, param2=0},
		{name="air", prob=254, param2=0},
		{name="air", prob=254, param2=0},
		{name="air", prob=254, param2=0},
		{name="air", prob=254, param2=0},
		{name="air", prob=254, param2=0},
		{name="air", prob=254, param2=0},
		{name="air", prob=254, param2=0},
		{name="air", prob=254, param2=0},

		-- z=2, y=0
		{name="air", prob=254, param2=0},
		{name="air", prob=254, param2=0},
		{name="default:furnace", prob=254, param2=3},
		{name="air", prob=254, param2=0},
		{name="air", prob=254, param2=0},
		{name="default:clay", prob=254, param2=9},
		{name="default:clay", prob=254, param2=9},
		{name="default:clay", prob=254, param2=9},
		{name="air", prob=254, param2=0},

		-- z=2, y=1
		{name="air", prob=254, param2=0},
		{name="air", prob=254, param2=0},
		{name="air", prob=254, param2=0},
		{name="air", prob=254, param2=0},
		{name="air", prob=254, param2=0},
		{name="default:clay", prob=254, param2=9},
		{name="default:clay", prob=254, param2=9},
		{name="air", prob=254, param2=0},
		{name="air", prob=254, param2=0},

		-- z=2, y=2
		{name="air", prob=254, param2=0},
		{name="air", prob=254, param2=0},
		{name="air", prob=254, param2=0},
		{name="air", prob=254, param2=0},
		{name="air", prob=254, param2=0},
		{name="air", prob=254, param2=0},
		{name="air", prob=254, param2=0},
		{name="air", prob=254, param2=0},
		{name="air", prob=254, param2=0},

		-- z=2, y=3
		{name="air", prob=254, param2=0},
		{name="air", prob=254, param2=0},
		{name="air", prob=254, param2=0},
		{name="air", prob=254, param2=0},
		{name="air", prob=254, param2=0},
		{name="air", prob=254, param2=0},
		{name="air", prob=254, param2=0},
		{name="air", prob=254, param2=0},
		{name="air", prob=254, param2=0},

		-- z=2, y=4
		{name="air", prob=254, param2=0},
		{name="air", prob=254, param2=0},
		{name="air", prob=254, param2=0},
		{name="air", prob=254, param2=0},
		{name="air", prob=254, param2=0},
		{name="air", prob=254, param2=0},
		{name="air", prob=254, param2=0},
		{name="air", prob=254, param2=0},
		{name="air", prob=254, param2=0},

		-- z=2, y=5
		{name="air", prob=254, param2=0},
		{name="air", prob=254, param2=0},
		{name="air", prob=254, param2=0},
		{name="air", prob=254, param2=0},
		{name="air", prob=254, param2=0},
		{name="air", prob=254, param2=0},
		{name="air", prob=254, param2=0},
		{name="air", prob=254, param2=0},
		{name="air", prob=254, param2=0},

		-- z=2, y=6
		{name="air", prob=254, param2=0},
		{name="air", prob=254, param2=0},
		{name="air", prob=254, param2=0},
		{name="air", prob=254, param2=0},
		{name="air", prob=254, param2=0},
		{name="air", prob=254, param2=0},
		{name="air", prob=254, param2=0},
		{name="air", prob=254, param2=0},
		{name="air", prob=254, param2=0},

		-- z=3, y=0
		{name="air", prob=254, param2=0},
		{name="air", prob=254, param2=0},
		{name="default:furnace", prob=254, param2=3},
		{name="air", prob=254, param2=0},
		{name="air", prob=254, param2=0},
		{name="default:glass", prob=254, param2=0},
		{name="default:desert_sand", prob=254, param2=9},
		{name="default:desert_sand", prob=254, param2=9},
		{name="air", prob=254, param2=0},

		-- z=3, y=1
		{name="air", prob=254, param2=0},
		{name="air", prob=254, param2=0},
		{name="default:furnace", prob=254, param2=3},
		{name="air", prob=254, param2=0},
		{name="air", prob=254, param2=0},
		{name="air", prob=254, param2=0},
		{name="default:desert_sand", prob=254, param2=9},
		{name="air", prob=254, param2=0},
		{name="air", prob=254, param2=0},

		-- z=3, y=2
		{name="air", prob=254, param2=0},
		{name="air", prob=254, param2=0},
		{name="air", prob=254, param2=0},
		{name="air", prob=254, param2=0},
		{name="air", prob=254, param2=0},
		{name="air", prob=254, param2=0},
		{name="air", prob=254, param2=0},
		{name="air", prob=254, param2=0},
		{name="air", prob=254, param2=0},

		-- z=3, y=3
		{name="air", prob=254, param2=0},
		{name="air", prob=254, param2=0},
		{name="air", prob=254, param2=0},
		{name="air", prob=254, param2=0},
		{name="air", prob=254, param2=0},
		{name="air", prob=254, param2=0},
		{name="air", prob=254, param2=0},
		{name="air", prob=254, param2=0},
		{name="air", prob=254, param2=0},

		-- z=3, y=4
		{name="air", prob=254, param2=0},
		{name="air", prob=254, param2=0},
		{name="air", prob=254, param2=0},
		{name="air", prob=254, param2=0},
		{name="air", prob=254, param2=0},
		{name="air", prob=254, param2=0},
		{name="air", prob=254, param2=0},
		{name="air", prob=254, param2=0},
		{name="air", prob=254, param2=0},

		-- z=3, y=5
		{name="air", prob=254, param2=0},
		{name="air", prob=254, param2=0},
		{name="air", prob=254, param2=0},
		{name="air", prob=254, param2=0},
		{name="air", prob=254, param2=0},
		{name="air", prob=254, param2=0},
		{name="air", prob=254, param2=0},
		{name="air", prob=254, param2=0},
		{name="air", prob=254, param2=0},

		-- z=3, y=6
		{name="air", prob=254, param2=0},
		{name="air", prob=254, param2=0},
		{name="air", prob=254, param2=0},
		{name="air", prob=254, param2=0},
		{name="air", prob=254, param2=0},
		{name="air", prob=254, param2=0},
		{name="air", prob=254, param2=0},
		{name="air", prob=254, param2=0},
		{name="air", prob=254, param2=0},

		-- z=4, y=0
		{name="air", prob=254, param2=0},
		{name="air", prob=254, param2=0},
		{name="default:furnace", prob=254, param2=3},
		{name="air", prob=254, param2=0},
		{name="air", prob=254, param2=0},
		{name="air", prob=254, param2=0},
		{name="default:glass", prob=254, param2=0},
		{name="default:desert_sand", prob=254, param2=9},
		{name="air", prob=254, param2=0},

		-- z=4, y=1
		{name="air", prob=254, param2=0},
		{name="air", prob=254, param2=0},
		{name="air", prob=254, param2=0},
		{name="air", prob=254, param2=0},
		{name="air", prob=254, param2=0},
		{name="air", prob=254, param2=0},
		{name="air", prob=254, param2=0},
		{name="air", prob=254, param2=0},
		{name="air", prob=254, param2=0},

		-- z=4, y=2
		{name="air", prob=254, param2=0},
		{name="air", prob=254, param2=0},
		{name="air", prob=254, param2=0},
		{name="air", prob=254, param2=0},
		{name="air", prob=254, param2=0},
		{name="air", prob=254, param2=0},
		{name="air", prob=254, param2=0},
		{name="air", prob=254, param2=0},
		{name="air", prob=254, param2=0},

		-- z=4, y=3
		{name="air", prob=254, param2=0},
		{name="air", prob=254, param2=0},
		{name="air", prob=254, param2=0},
		{name="air", prob=254, param2=0},
		{name="air", prob=254, param2=0},
		{name="air", prob=254, param2=0},
		{name="air", prob=254, param2=0},
		{name="air", prob=254, param2=0},
		{name="air", prob=254, param2=0},

		-- z=4, y=4
		{name="air", prob=254, param2=0},
		{name="air", prob=254, param2=0},
		{name="air", prob=254, param2=0},
		{name="air", prob=254, param2=0},
		{name="air", prob=254, param2=0},
		{name="air", prob=254, param2=0},
		{name="air", prob=254, param2=0},
		{name="air", prob=254, param2=0},
		{name="air", prob=254, param2=0},

		-- z=4, y=5
		{name="air", prob=254, param2=0},
		{name="air", prob=254, param2=0},
		{name="air", prob=254, param2=0},
		{name="air", prob=254, param2=0},
		{name="air", prob=254, param2=0},
		{name="air", prob=254, param2=0},
		{name="air", prob=254, param2=0},
		{name="air", prob=254, param2=0},
		{name="air", prob=254, param2=0},

		-- z=4, y=6
		{name="air", prob=254, param2=0},
		{name="air", prob=254, param2=0},
		{name="air", prob=254, param2=0},
		{name="air", prob=254, param2=0},
		{name="air", prob=254, param2=0},
		{name="air", prob=254, param2=0},
		{name="air", prob=254, param2=0},
		{name="air", prob=254, param2=0},
		{name="air", prob=254, param2=0},

		-- z=5, y=0
		{name="air", prob=254, param2=0},
		{name="air", prob=254, param2=0},
		{name="air", prob=254, param2=0},
		{name="air", prob=254, param2=0},
		{name="air", prob=254, param2=0},
		{name="air", prob=254, param2=0},
		{name="air", prob=254, param2=0},
		{name="air", prob=254, param2=0},
		{name="air", prob=254, param2=0},

		-- z=5, y=1
		{name="air", prob=254, param2=0},
		{name="air", prob=254, param2=0},
		{name="air", prob=254, param2=0},
		{name="air", prob=254, param2=0},
		{name="air", prob=254, param2=0},
		{name="air", prob=254, param2=0},
		{name="air", prob=254, param2=0},
		{name="air", prob=254, param2=0},
		{name="air", prob=254, param2=0},

		-- z=5, y=2
		{name="air", prob=254, param2=0},
		{name="air", prob=254, param2=0},
		{name="air", prob=254, param2=0},
		{name="air", prob=254, param2=0},
		{name="air", prob=254, param2=0},
		{name="air", prob=254, param2=0},
		{name="air", prob=254, param2=0},
		{name="air", prob=254, param2=0},
		{name="air", prob=254, param2=0},

		-- z=5, y=3
		{name="air", prob=254, param2=0},
		{name="air", prob=254, param2=0},
		{name="air", prob=254, param2=0},
		{name="air", prob=254, param2=0},
		{name="air", prob=254, param2=0},
		{name="air", prob=254, param2=0},
		{name="air", prob=254, param2=0},
		{name="air", prob=254, param2=0},
		{name="air", prob=254, param2=0},

		-- z=5, y=4
		{name="air", prob=254, param2=0},
		{name="air", prob=254, param2=0},
		{name="air", prob=254, param2=0},
		{name="air", prob=254, param2=0},
		{name="air", prob=254, param2=0},
		{name="air", prob=254, param2=0},
		{name="air", prob=254, param2=0},
		{name="air", prob=254, param2=0},
		{name="air", prob=254, param2=0},

		-- z=5, y=5
		{name="air", prob=254, param2=0},
		{name="air", prob=254, param2=0},
		{name="air", prob=254, param2=0},
		{name="air", prob=254, param2=0},
		{name="air", prob=254, param2=0},
		{name="air", prob=254, param2=0},
		{name="air", prob=254, param2=0},
		{name="air", prob=254, param2=0},
		{name="air", prob=254, param2=0},

		-- z=5, y=6
		{name="air", prob=254, param2=0},
		{name="air", prob=254, param2=0},
		{name="air", prob=254, param2=0},
		{name="air", prob=254, param2=0},
		{name="air", prob=254, param2=0},
		{name="air", prob=254, param2=0},
		{name="air", prob=254, param2=0},
		{name="air", prob=254, param2=0},
		{name="air", prob=254, param2=0},

		-- z=6, y=0
		{name="air", prob=254, param2=3},
		{name="default:ladder_wood", prob=254, param2=4},
		{name="stairs:slab_brick", prob=254, param2=3},
		{name="stairs:slab_brick", prob=254, param2=3},
		{name="stairs:slab_brick", prob=254, param2=3},
		{name="stairs:slab_brick", prob=254, param2=3},
		{name="stairs:slab_brick", prob=254, param2=3},
		{name="default:chest", prob=254, param2=0},
		{name="air", prob=254, param2=0},

		-- z=6, y=1
		{name="air", prob=254, param2=0},
		{name="default:ladder_wood", prob=254, param2=4},
		{name="air", prob=254, param2=0},
		{name="air", prob=254, param2=0},
		{name="air", prob=254, param2=0},
		{name="air", prob=254, param2=0},
		{name="air", prob=254, param2=0},
		{name="default:ladder_wood", prob=254, param2=4},
		{name="air", prob=254, param2=0},

		-- z=6, y=2
		{name="air", prob=254, param2=0},
		{name="default:ladder_wood", prob=254, param2=4},
		{name="air", prob=254, param2=0},
		{name="default:torch_wall", prob=254, param2=4},
		{name="air", prob=254, param2=0},
		{name="default:torch_wall", prob=254, param2=4},
		{name="air", prob=254, param2=0},
		{name="default:ladder_wood", prob=254, param2=4},
		{name="air", prob=254, param2=0},

		-- z=6, y=3
		{name="air", prob=254, param2=0},
		{name="default:ladder_wood", prob=254, param2=4},
		{name="air", prob=254, param2=0},
		{name="air", prob=254, param2=0},
		{name="air", prob=254, param2=0},
		{name="air", prob=254, param2=0},
		{name="air", prob=254, param2=0},
		{name="default:ladder_wood", prob=254, param2=4},
		{name="air", prob=254, param2=0},

		-- z=6, y=4
		{name="air", prob=254, param2=0},
		{name="air", prob=254, param2=0},
		{name="air", prob=254, param2=0},
		{name="air", prob=254, param2=0},
		{name="air", prob=254, param2=0},
		{name="air", prob=254, param2=0},
		{name="air", prob=254, param2=0},
		{name="air", prob=254, param2=0},
		{name="air", prob=254, param2=0},

		-- z=6, y=5
		{name="air", prob=254, param2=0},
		{name="air", prob=254, param2=0},
		{name="air", prob=254, param2=0},
		{name="air", prob=254, param2=0},
		{name="air", prob=254, param2=0},
		{name="air", prob=254, param2=0},
		{name="air", prob=254, param2=0},
		{name="air", prob=254, param2=0},
		{name="air", prob=254, param2=0},

		-- z=6, y=6
		{name="air", prob=254, param2=0},
		{name="air", prob=254, param2=0},
		{name="air", prob=254, param2=0},
		{name="air", prob=254, param2=0},
		{name="air", prob=254, param2=0},
		{name="air", prob=254, param2=0},
		{name="air", prob=254, param2=0},
		{name="air", prob=254, param2=0},
		{name="air", prob=254, param2=0},

		-- z=7, y=0
		{name="air", prob=254, param2=0},
		{name="default:brick", prob=254, param2=0},
		{name="default:brick", prob=254, param2=0},
		{name="default:brick", prob=254, param2=0},
		{name="default:brick", prob=254, param2=0},
		{name="default:brick", prob=254, param2=0},
		{name="default:brick", prob=254, param2=0},
		{name="default:brick", prob=254, param2=0},
		{name="air", prob=254, param2=0},

		-- z=7, y=1
		{name="air", prob=254, param2=0},
		{name="default:brick", prob=254, param2=0},
		{name="default:brick", prob=254, param2=0},
		{name="default:brick", prob=254, param2=0},
		{name="doors:door_wood_a", prob=254, param2=0},
		{name="default:brick", prob=254, param2=0},
		{name="default:brick", prob=254, param2=0},
		{name="default:brick", prob=254, param2=0},
		{name="air", prob=254, param2=0},

		-- z=7, y=2
		{name="default:torch_wall", prob=254, param2=2},
		{name="default:brick", prob=254, param2=0},
		{name="default:glass", prob=254, param2=0},
		{name="default:brick", prob=254, param2=0},
		{name="doors:hidden", prob=254, param2=0},
		{name="default:brick", prob=254, param2=0},
		{name="default:glass", prob=254, param2=0},
		{name="default:brick", prob=254, param2=0},
		{name="default:torch_wall", prob=254, param2=3},

		-- z=7, y=3
		{name="air", prob=254, param2=0},
		{name="default:brick", prob=254, param2=0},
		{name="default:brick", prob=254, param2=0},
		{name="default:brick", prob=254, param2=0},
		{name="default:brick", prob=254, param2=0},
		{name="default:brick", prob=254, param2=0},
		{name="default:brick", prob=254, param2=0},
		{name="default:brick", prob=254, param2=0},
		{name="air", prob=254, param2=0},

		-- z=7, y=4
		{name="air", prob=254, param2=0},
		{name="air", prob=254, param2=0},
		{name="air", prob=254, param2=0},
		{name="air", prob=254, param2=0},
		{name="air", prob=254, param2=0},
		{name="air", prob=254, param2=0},
		{name="air", prob=254, param2=0},
		{name="air", prob=254, param2=0},
		{name="air", prob=254, param2=0},

		-- z=7, y=5
		{name="air", prob=254, param2=0},
		{name="air", prob=254, param2=0},
		{name="air", prob=254, param2=0},
		{name="air", prob=254, param2=0},
		{name="air", prob=254, param2=0},
		{name="air", prob=254, param2=0},
		{name="air", prob=254, param2=0},
		{name="air", prob=254, param2=0},
		{name="air", prob=254, param2=0},

		-- z=7, y=6
		{name="air", prob=254, param2=0},
		{name="air", prob=254, param2=0},
		{name="air", prob=254, param2=0},
		{name="air", prob=254, param2=0},
		{name="air", prob=254, param2=0},
		{name="air", prob=254, param2=0},
		{name="air", prob=254, param2=0},
		{name="air", prob=254, param2=0},
		{name="air", prob=254, param2=0},

		-- z=8, y=0
		{name="air", prob=254, param2=0},
		{name="default:brick", prob=254, param2=0},
		{name="default:brick", prob=254, param2=0},
		{name="default:brick", prob=254, param2=0},
		{name="default:brick", prob=254, param2=0},
		{name="default:brick", prob=254, param2=0},
		{name="default:brick", prob=254, param2=0},
		{name="default:brick", prob=254, param2=0},
		{name="air", prob=254, param2=0},

		-- z=8, y=1
		{name="air", prob=254, param2=0},
		{name="default:brick", prob=254, param2=0},
		{name="cottages:bench", prob=254, param2=3},
		{name="cottages:bench", prob=254, param2=2},
		{name="air", prob=254, param2=0},
		{name="cottages:bed_foot", prob=254, param2=1},
		{name="cottages:bed_head", prob=254, param2=1},
		{name="default:brick", prob=254, param2=0},
		{name="air", prob=254, param2=0},

		-- z=8, y=2
		{name="air", prob=254, param2=0},
		{name="default:glass", prob=254, param2=0},
		{name="air", prob=254, param2=0},
		{name="default:torch_wall", prob=254, param2=5},
		{name="air", prob=254, param2=0},
		{name="default:torch_wall", prob=254, param2=5},
		{name="air", prob=254, param2=0},
		{name="default:glass", prob=254, param2=0},
		{name="air", prob=254, param2=0},

		-- z=8, y=3
		{name="air", prob=254, param2=0},
		{name="default:brick", prob=254, param2=0},
		{name="stairs:slab_brick", prob=254, param2=3},
		{name="stairs:slab_brick", prob=254, param2=3},
		{name="stairs:slab_brick", prob=254, param2=3},
		{name="stairs:slab_brick", prob=254, param2=3},
		{name="stairs:slab_brick", prob=254, param2=3},
		{name="default:brick", prob=254, param2=0},
		{name="air", prob=254, param2=0},

		-- z=8, y=4
		{name="air", prob=254, param2=0},
		{name="air", prob=254, param2=0},
		{name="air", prob=254, param2=0},
		{name="air", prob=254, param2=0},
		{name="air", prob=254, param2=0},
		{name="air", prob=254, param2=0},
		{name="air", prob=254, param2=0},
		{name="air", prob=254, param2=0},
		{name="air", prob=254, param2=0},

		-- z=8, y=5
		{name="air", prob=254, param2=0},
		{name="air", prob=254, param2=0},
		{name="air", prob=254, param2=0},
		{name="air", prob=254, param2=0},
		{name="air", prob=254, param2=0},
		{name="air", prob=254, param2=0},
		{name="air", prob=254, param2=0},
		{name="air", prob=254, param2=0},
		{name="air", prob=254, param2=0},

		-- z=8, y=6
		{name="air", prob=254, param2=0},
		{name="air", prob=254, param2=0},
		{name="air", prob=254, param2=0},
		{name="air", prob=254, param2=0},
		{name="air", prob=254, param2=0},
		{name="air", prob=254, param2=0},
		{name="air", prob=254, param2=0},
		{name="air", prob=254, param2=0},
		{name="air", prob=254, param2=0},

		-- z=9, y=0
		{name="air", prob=254, param2=0},
		{name="default:brick", prob=254, param2=0},
		{name="default:brick", prob=254, param2=0},
		{name="default:brick", prob=254, param2=0},
		{name="default:brick", prob=254, param2=0},
		{name="default:brick", prob=254, param2=0},
		{name="default:brick", prob=254, param2=0},
		{name="default:brick", prob=254, param2=0},
		{name="air", prob=254, param2=0},

		-- z=9, y=1
		{name="air", prob=254, param2=0},
		{name="default:brick", prob=254, param2=0},
		{name="default:furnace", prob=254, param2=3},
		{name="air", prob=254, param2=0},
		{name="air", prob=254, param2=0},
		{name="air", prob=254, param2=0},
		{name="default:chest", prob=254, param2=1},
		{name="default:brick", prob=254, param2=0},
		{name="air", prob=254, param2=0},

		-- z=9, y=2
		{name="air", prob=254, param2=0},
		{name="default:brick", prob=254, param2=0},
		{name="default:stone", prob=254, param2=9},
		{name="air", prob=254, param2=0},
		{name="air", prob=254, param2=0},
		{name="air", prob=254, param2=0},
		{name="default:chest", prob=254, param2=1},
		{name="default:brick", prob=254, param2=0},
		{name="air", prob=254, param2=0},

		-- z=9, y=3
		{name="air", prob=254, param2=0},
		{name="default:brick", prob=254, param2=0},
		{name="default:stone", prob=254, param2=9},
		{name="stairs:slab_brick", prob=254, param2=3},
		{name="stairs:slab_brick", prob=254, param2=3},
		{name="stairs:slab_brick", prob=254, param2=3},
		{name="stairs:slab_brick", prob=254, param2=3},
		{name="default:brick", prob=254, param2=0},
		{name="air", prob=254, param2=0},

		-- z=9, y=4
		{name="air", prob=254, param2=0},
		{name="air", prob=254, param2=0},
		{name="default:stone", prob=254, param2=9},
		{name="air", prob=254, param2=0},
		{name="air", prob=254, param2=0},
		{name="air", prob=254, param2=0},
		{name="air", prob=254, param2=0},
		{name="air", prob=254, param2=0},
		{name="air", prob=254, param2=0},

		-- z=9, y=5
		{name="air", prob=254, param2=0},
		{name="air", prob=254, param2=0},
		{name="default:stone", prob=254, param2=9},
		{name="air", prob=254, param2=0},
		{name="air", prob=254, param2=0},
		{name="air", prob=254, param2=0},
		{name="air", prob=254, param2=0},
		{name="air", prob=254, param2=0},
		{name="air", prob=254, param2=0},

		-- z=9, y=6
		{name="air", prob=254, param2=0},
		{name="air", prob=254, param2=0},
		{name="air", prob=254, param2=0},
		{name="air", prob=254, param2=0},
		{name="air", prob=254, param2=0},
		{name="air", prob=254, param2=0},
		{name="air", prob=254, param2=0},
		{name="air", prob=254, param2=0},
		{name="air", prob=254, param2=0},

		-- z=10, y=0
		{name="air", prob=254, param2=0},
		{name="default:brick", prob=254, param2=0},
		{name="default:brick", prob=254, param2=0},
		{name="default:brick", prob=254, param2=0},
		{name="default:brick", prob=254, param2=0},
		{name="default:brick", prob=254, param2=0},
		{name="default:brick", prob=254, param2=0},
		{name="default:brick", prob=254, param2=0},
		{name="air", prob=254, param2=0},

		-- z=10, y=1
		{name="air", prob=254, param2=0},
		{name="default:brick", prob=254, param2=0},
		{name="cottages:bench", prob=254, param2=3},
		{name="cottages:wool_tent", prob=254, param2=0},
		{name="default:bookshelf", prob=254, param2=0},
		{name="cottages:bed_foot", prob=254, param2=1},
		{name="cottages:bed_head", prob=254, param2=1},
		{name="default:brick", prob=254, param2=0},
		{name="air", prob=254, param2=0},

		-- z=10, y=2
		{name="air", prob=254, param2=0},
		{name="default:glass", prob=254, param2=0},
		{name="air", prob=254, param2=0},
		{name="default:torch_wall", prob=254, param2=4},
		{name="default:bookshelf", prob=254, param2=0},
		{name="default:torch_wall", prob=254, param2=4},
		{name="air", prob=254, param2=0},
		{name="default:glass", prob=254, param2=0},
		{name="air", prob=254, param2=0},

		-- z=10, y=3
		{name="air", prob=254, param2=0},
		{name="default:brick", prob=254, param2=0},
		{name="stairs:slab_brick", prob=254, param2=3},
		{name="stairs:slab_brick", prob=254, param2=3},
		{name="stairs:slab_brick", prob=254, param2=3},
		{name="stairs:slab_brick", prob=254, param2=3},
		{name="stairs:slab_brick", prob=254, param2=3},
		{name="default:brick", prob=254, param2=0},
		{name="air", prob=254, param2=0},

		-- z=10, y=4
		{name="air", prob=254, param2=0},
		{name="air", prob=254, param2=0},
		{name="air", prob=254, param2=0},
		{name="air", prob=254, param2=0},
		{name="air", prob=254, param2=0},
		{name="air", prob=254, param2=0},
		{name="air", prob=254, param2=0},
		{name="air", prob=254, param2=0},
		{name="air", prob=254, param2=0},

		-- z=10, y=5
		{name="air", prob=254, param2=0},
		{name="air", prob=254, param2=0},
		{name="air", prob=254, param2=0},
		{name="air", prob=254, param2=0},
		{name="air", prob=254, param2=0},
		{name="air", prob=254, param2=0},
		{name="air", prob=254, param2=0},
		{name="air", prob=254, param2=0},
		{name="air", prob=254, param2=0},

		-- z=10, y=6
		{name="air", prob=254, param2=0},
		{name="air", prob=254, param2=0},
		{name="air", prob=254, param2=0},
		{name="air", prob=254, param2=0},
		{name="air", prob=254, param2=0},
		{name="air", prob=254, param2=0},
		{name="air", prob=254, param2=0},
		{name="air", prob=254, param2=0},
		{name="air", prob=254, param2=0},

		-- z=11, y=0
		{name="air", prob=254, param2=0},
		{name="default:brick", prob=254, param2=0},
		{name="default:brick", prob=254, param2=0},
		{name="default:brick", prob=254, param2=0},
		{name="default:brick", prob=254, param2=0},
		{name="default:brick", prob=254, param2=0},
		{name="default:brick", prob=254, param2=0},
		{name="default:brick", prob=254, param2=0},
		{name="air", prob=254, param2=0},

		-- z=11, y=1
		{name="air", prob=254, param2=0},
		{name="default:brick", prob=254, param2=0},
		{name="default:brick", prob=254, param2=0},
		{name="default:brick", prob=254, param2=0},
		{name="default:brick", prob=254, param2=0},
		{name="default:brick", prob=254, param2=0},
		{name="default:brick", prob=254, param2=0},
		{name="default:brick", prob=254, param2=0},
		{name="air", prob=254, param2=0},

		-- z=11, y=2
		{name="default:torch_wall", prob=254, param2=2},
		{name="default:brick", prob=254, param2=0},
		{name="default:brick", prob=254, param2=0},
		{name="default:brick", prob=254, param2=0},
		{name="default:brick", prob=254, param2=0},
		{name="default:brick", prob=254, param2=0},
		{name="default:brick", prob=254, param2=0},
		{name="default:brick", prob=254, param2=0},
		{name="default:torch_wall", prob=254, param2=3},

		-- z=11, y=3
		{name="air", prob=254, param2=0},
		{name="default:brick", prob=254, param2=0},
		{name="default:brick", prob=254, param2=0},
		{name="default:brick", prob=254, param2=0},
		{name="default:brick", prob=254, param2=0},
		{name="default:brick", prob=254, param2=0},
		{name="default:brick", prob=254, param2=0},
		{name="default:brick", prob=254, param2=0},
		{name="air", prob=254, param2=0},

		-- z=11, y=4
		{name="air", prob=254, param2=0},
		{name="default:torch_wall", prob=254, param2=1},
		{name="air", prob=254, param2=0},
		{name="air", prob=254, param2=0},
		{name="air", prob=254, param2=0},
		{name="air", prob=254, param2=0},
		{name="air", prob=254, param2=0},
		{name="default:torch_wall", prob=254, param2=1},
		{name="air", prob=254, param2=0},

		-- z=11, y=5
		{name="air", prob=254, param2=0},
		{name="air", prob=254, param2=0},
		{name="air", prob=254, param2=0},
		{name="air", prob=254, param2=0},
		{name="air", prob=254, param2=0},
		{name="air", prob=254, param2=0},
		{name="air", prob=254, param2=0},
		{name="air", prob=254, param2=0},
		{name="air", prob=254, param2=0},

		-- z=11, y=6
		{name="air", prob=254, param2=0},
		{name="air", prob=254, param2=0},
		{name="air", prob=254, param2=0},
		{name="air", prob=254, param2=0},
		{name="air", prob=254, param2=0},
		{name="air", prob=254, param2=0},
		{name="air", prob=254, param2=0},
		{name="air", prob=254, param2=0},
		{name="air", prob=254, param2=0},

		-- z=12, y=0
		{name="air", prob=254, param2=0},
		{name="air", prob=254, param2=0},
		{name="air", prob=254, param2=0},
		{name="air", prob=254, param2=0},
		{name="air", prob=254, param2=0},
		{name="air", prob=254, param2=0},
		{name="air", prob=254, param2=0},
		{name="air", prob=254, param2=0},
		{name="air", prob=254, param2=0},

		-- z=12, y=1
		{name="air", prob=254, param2=0},
		{name="air", prob=254, param2=0},
		{name="air", prob=254, param2=0},
		{name="air", prob=254, param2=0},
		{name="air", prob=254, param2=0},
		{name="air", prob=254, param2=0},
		{name="air", prob=254, param2=0},
		{name="air", prob=254, param2=0},
		{name="air", prob=254, param2=0},

		-- z=12, y=2
		{name="air", prob=254, param2=0},
		{name="air", prob=254, param2=0},
		{name="default:torch_wall", prob=254, param2=5},
		{name="air", prob=254, param2=0},
		{name="air", prob=254, param2=0},
		{name="air", prob=254, param2=0},
		{name="default:torch_wall", prob=254, param2=5},
		{name="air", prob=254, param2=0},
		{name="air", prob=254, param2=0},

		-- z=12, y=3
		{name="air", prob=254, param2=0},
		{name="air", prob=254, param2=0},
		{name="air", prob=254, param2=0},
		{name="air", prob=254, param2=0},
		{name="air", prob=254, param2=0},
		{name="air", prob=254, param2=0},
		{name="air", prob=254, param2=0},
		{name="air", prob=254, param2=0},
		{name="air", prob=254, param2=0},

		-- z=12, y=4
		{name="air", prob=254, param2=0},
		{name="air", prob=254, param2=0},
		{name="air", prob=254, param2=0},
		{name="air", prob=254, param2=0},
		{name="air", prob=254, param2=0},
		{name="air", prob=254, param2=0},
		{name="air", prob=254, param2=0},
		{name="air", prob=254, param2=0},
		{name="air", prob=254, param2=0},

		-- z=12, y=5
		{name="air", prob=254, param2=0},
		{name="air", prob=254, param2=0},
		{name="air", prob=254, param2=0},
		{name="air", prob=254, param2=0},
		{name="air", prob=254, param2=0},
		{name="air", prob=254, param2=0},
		{name="air", prob=254, param2=0},
		{name="air", prob=254, param2=0},
		{name="air", prob=254, param2=0},

		-- z=12, y=6
		{name="air", prob=254, param2=0},
		{name="air", prob=254, param2=0},
		{name="air", prob=254, param2=0},
		{name="air", prob=254, param2=0},
		{name="air", prob=254, param2=0},
		{name="air", prob=254, param2=0},
		{name="air", prob=254, param2=0},
		{name="air", prob=254, param2=0},
		{name="air", prob=254, param2=0},
	},
}

return schematic