schematic = {
	size = {x=3, y=5, z=3},
	yslice_prob = {
		{ypos=0, prob=254},
		{ypos=1, prob=254},
		{ypos=2, prob=254},
		{ypos=3, prob=254},
		{ypos=4, prob=254},
	},
	data = {

		-- z=0, y=0
		{name="default:dirt_with_grass", prob=254, param2=0},
		{name="default:dirt", prob=254, param2=0},
		{name="default:dirt_with_grass", prob=254, param2=0},

		-- z=0, y=1
		{name="air", prob=254, param2=0},
		{name="default:cobble", prob=254, param2=0},
		{name="air", prob=254, param2=0},

		-- z=0, y=2
		{name="air", prob=254, param2=0},
		{name="default:fence_wood", prob=254, param2=0},
		{name="air", prob=254, param2=0},

		-- z=0, y=3
		{name="cottages:roof_straw", prob=254, param2=1},
		{name="default:fence_wood", prob=254, param2=0},
		{name="cottages:roof_straw", prob=254, param2=3},

		-- z=0, y=4
		{name="air", prob=254, param2=0},
		{name="cottages:roof_flat_straw", prob=254, param2=0},
		{name="air", prob=254, param2=0},

		-- z=1, y=0
		{name="default:dirt", prob=254, param2=0},
		{name="default:dirt", prob=254, param2=0},
		{name="default:dirt", prob=254, param2=0},

		-- z=1, y=1
		{name="default:cobble", prob=254, param2=0},
		{name="default:water_source", prob=254, param2=0},
		{name="default:cobble", prob=254, param2=0},

		-- z=1, y=2
		{name="air", prob=254, param2=0},
		{name="air", prob=254, param2=0},
		{name="air", prob=254, param2=0},

		-- z=1, y=3
		{name="cottages:roof_straw", prob=254, param2=1},
		{name="default:fence_wood", prob=254, param2=0},
		{name="cottages:roof_straw", prob=254, param2=3},

		-- z=1, y=4
		{name="air", prob=254, param2=0},
		{name="cottages:roof_flat_straw", prob=254, param2=0},
		{name="air", prob=254, param2=0},

		-- z=2, y=0
		{name="default:dirt_with_grass", prob=254, param2=0},
		{name="default:dirt", prob=254, param2=0},
		{name="default:dirt_with_grass", prob=254, param2=0},

		-- z=2, y=1
		{name="air", prob=254, param2=0},
		{name="default:cobble", prob=254, param2=0},
		{name="air", prob=254, param2=0},

		-- z=2, y=2
		{name="air", prob=254, param2=0},
		{name="default:fence_wood", prob=254, param2=0},
		{name="air", prob=254, param2=0},

		-- z=2, y=3
		{name="cottages:roof_straw", prob=254, param2=1},
		{name="default:fence_wood", prob=254, param2=0},
		{name="cottages:roof_straw", prob=254, param2=3},

		-- z=2, y=4
		{name="air", prob=254, param2=0},
		{name="cottages:roof_flat_straw", prob=254, param2=2},
		{name="air", prob=254, param2=0},
	},
}

return schematic