schematic = {
	size = {x=9, y=2, z=9},
	yslice_prob = {
		{ypos=0, prob=254},
		{ypos=1, prob=254},
	},
	data = {

		-- z=0, y=0
		{name="farming:soil_wet", prob=254, param2=0},
		{name="farming:soil_wet", prob=254, param2=0},
		{name="farming:soil_wet", prob=254, param2=0},
		{name="farming:soil_wet", prob=254, param2=0},
		{name="farming:soil_wet", prob=254, param2=0},
		{name="farming:soil_wet", prob=254, param2=0},
		{name="farming:soil_wet", prob=254, param2=0},
		{name="farming:soil_wet", prob=254, param2=0},
		{name="farming:soil_wet", prob=254, param2=0},

		-- z=0, y=1
		{name="farming:wheat_8", prob=254, param2=0},
		{name="farming:wheat_8", prob=254, param2=0},
		{name="farming:wheat_8", prob=254, param2=0},
		{name="farming:wheat_8", prob=254, param2=0},
		{name="farming:wheat_8", prob=254, param2=0},
		{name="farming:wheat_8", prob=254, param2=0},
		{name="farming:wheat_8", prob=254, param2=0},
		{name="farming:wheat_8", prob=254, param2=0},
		{name="farming:wheat_8", prob=254, param2=0},

		-- z=1, y=0
		{name="default:water_source", prob=254, param2=0},
		{name="default:water_source", prob=254, param2=0},
		{name="default:water_source", prob=254, param2=0},
		{name="default:water_source", prob=254, param2=0},
		{name="default:water_source", prob=254, param2=0},
		{name="default:water_source", prob=254, param2=0},
		{name="default:water_source", prob=254, param2=0},
		{name="default:water_source", prob=254, param2=0},
		{name="default:water_source", prob=254, param2=0},

		-- z=1, y=1
		{name="air", prob=254, param2=0},
		{name="air", prob=254, param2=0},
		{name="air", prob=254, param2=0},
		{name="air", prob=254, param2=0},
		{name="air", prob=254, param2=0},
		{name="air", prob=254, param2=0},
		{name="air", prob=254, param2=0},
		{name="air", prob=254, param2=0},
		{name="air", prob=254, param2=0},

		-- z=2, y=0
		{name="farming:soil_wet", prob=254, param2=0},
		{name="farming:soil_wet", prob=254, param2=0},
		{name="farming:soil_wet", prob=254, param2=0},
		{name="farming:soil_wet", prob=254, param2=0},
		{name="farming:soil_wet", prob=254, param2=0},
		{name="farming:soil_wet", prob=254, param2=0},
		{name="farming:soil_wet", prob=254, param2=0},
		{name="farming:soil_wet", prob=254, param2=0},
		{name="farming:soil_wet", prob=254, param2=0},

		-- z=2, y=1
		{name="farming:wheat_8", prob=254, param2=0},
		{name="farming:wheat_8", prob=254, param2=0},
		{name="farming:wheat_8", prob=254, param2=0},
		{name="farming:wheat_8", prob=254, param2=0},
		{name="farming:wheat_8", prob=254, param2=0},
		{name="farming:wheat_8", prob=254, param2=0},
		{name="farming:wheat_8", prob=254, param2=0},
		{name="farming:wheat_8", prob=254, param2=0},
		{name="farming:wheat_8", prob=254, param2=0},

		-- z=3, y=0
		{name="farming:soil_wet", prob=254, param2=0},
		{name="farming:soil_wet", prob=254, param2=0},
		{name="farming:soil_wet", prob=254, param2=0},
		{name="farming:soil_wet", prob=254, param2=0},
		{name="farming:soil_wet", prob=254, param2=0},
		{name="farming:soil_wet", prob=254, param2=0},
		{name="farming:soil_wet", prob=254, param2=0},
		{name="farming:soil_wet", prob=254, param2=0},
		{name="farming:soil_wet", prob=254, param2=0},

		-- z=3, y=1
		{name="farming:wheat_8", prob=254, param2=0},
		{name="farming:wheat_8", prob=254, param2=0},
		{name="farming:wheat_8", prob=254, param2=0},
		{name="farming:wheat_8", prob=254, param2=0},
		{name="farming:wheat_8", prob=254, param2=0},
		{name="farming:wheat_8", prob=254, param2=0},
		{name="farming:wheat_8", prob=254, param2=0},
		{name="farming:wheat_8", prob=254, param2=0},
		{name="farming:wheat_8", prob=254, param2=0},

		-- z=4, y=0
		{name="default:water_source", prob=254, param2=0},
		{name="default:water_source", prob=254, param2=0},
		{name="default:water_source", prob=254, param2=0},
		{name="default:water_source", prob=254, param2=0},
		{name="default:water_source", prob=254, param2=0},
		{name="default:water_source", prob=254, param2=0},
		{name="default:water_source", prob=254, param2=0},
		{name="default:water_source", prob=254, param2=0},
		{name="default:water_source", prob=254, param2=0},

		-- z=4, y=1
		{name="air", prob=254, param2=0},
		{name="air", prob=254, param2=0},
		{name="air", prob=254, param2=0},
		{name="air", prob=254, param2=0},
		{name="air", prob=254, param2=0},
		{name="air", prob=254, param2=0},
		{name="air", prob=254, param2=0},
		{name="air", prob=254, param2=0},
		{name="air", prob=254, param2=0},

		-- z=5, y=0
		{name="farming:soil_wet", prob=254, param2=0},
		{name="farming:soil_wet", prob=254, param2=0},
		{name="farming:soil_wet", prob=254, param2=0},
		{name="farming:soil_wet", prob=254, param2=0},
		{name="farming:soil_wet", prob=254, param2=0},
		{name="farming:soil_wet", prob=254, param2=0},
		{name="farming:soil_wet", prob=254, param2=0},
		{name="farming:soil_wet", prob=254, param2=0},
		{name="farming:soil_wet", prob=254, param2=0},

		-- z=5, y=1
		{name="farming:wheat_8", prob=254, param2=0},
		{name="farming:wheat_8", prob=254, param2=0},
		{name="farming:wheat_8", prob=254, param2=0},
		{name="farming:wheat_8", prob=254, param2=0},
		{name="farming:wheat_8", prob=254, param2=0},
		{name="farming:wheat_8", prob=254, param2=0},
		{name="farming:wheat_8", prob=254, param2=0},
		{name="farming:wheat_8", prob=254, param2=0},
		{name="farming:wheat_8", prob=254, param2=0},

		-- z=6, y=0
		{name="farming:soil_wet", prob=254, param2=0},
		{name="farming:soil_wet", prob=254, param2=0},
		{name="farming:soil_wet", prob=254, param2=0},
		{name="farming:soil_wet", prob=254, param2=0},
		{name="farming:soil_wet", prob=254, param2=0},
		{name="farming:soil_wet", prob=254, param2=0},
		{name="farming:soil_wet", prob=254, param2=0},
		{name="farming:soil_wet", prob=254, param2=0},
		{name="farming:soil_wet", prob=254, param2=0},

		-- z=6, y=1
		{name="farming:wheat_8", prob=254, param2=0},
		{name="farming:wheat_8", prob=254, param2=0},
		{name="farming:wheat_8", prob=254, param2=0},
		{name="farming:wheat_8", prob=254, param2=0},
		{name="farming:wheat_8", prob=254, param2=0},
		{name="farming:wheat_8", prob=254, param2=0},
		{name="farming:wheat_8", prob=254, param2=0},
		{name="farming:wheat_8", prob=254, param2=0},
		{name="farming:wheat_8", prob=254, param2=0},

		-- z=7, y=0
		{name="default:water_source", prob=254, param2=0},
		{name="default:water_source", prob=254, param2=0},
		{name="default:water_source", prob=254, param2=0},
		{name="default:water_source", prob=254, param2=0},
		{name="default:water_source", prob=254, param2=0},
		{name="default:water_source", prob=254, param2=0},
		{name="default:water_source", prob=254, param2=0},
		{name="default:water_source", prob=254, param2=0},
		{name="default:water_source", prob=254, param2=0},

		-- z=7, y=1
		{name="air", prob=254, param2=0},
		{name="air", prob=254, param2=0},
		{name="air", prob=254, param2=0},
		{name="air", prob=254, param2=0},
		{name="air", prob=254, param2=0},
		{name="air", prob=254, param2=0},
		{name="air", prob=254, param2=0},
		{name="air", prob=254, param2=0},
		{name="air", prob=254, param2=0},

		-- z=8, y=0
		{name="farming:soil_wet", prob=254, param2=0},
		{name="farming:soil_wet", prob=254, param2=0},
		{name="farming:soil_wet", prob=254, param2=0},
		{name="farming:soil_wet", prob=254, param2=0},
		{name="farming:soil_wet", prob=254, param2=0},
		{name="farming:soil_wet", prob=254, param2=0},
		{name="farming:soil_wet", prob=254, param2=0},
		{name="farming:soil_wet", prob=254, param2=0},
		{name="farming:soil_wet", prob=254, param2=0},

		-- z=8, y=1
		{name="farming:wheat_8", prob=254, param2=0},
		{name="farming:wheat_8", prob=254, param2=0},
		{name="farming:wheat_8", prob=254, param2=0},
		{name="farming:wheat_8", prob=254, param2=0},
		{name="farming:wheat_8", prob=254, param2=0},
		{name="farming:wheat_8", prob=254, param2=0},
		{name="farming:wheat_8", prob=254, param2=0},
		{name="farming:wheat_8", prob=254, param2=0},
		{name="farming:wheat_8", prob=254, param2=0},
	},
}

return schematic