schematic = {
	size = {x=10, y=7, z=7},
	yslice_prob = {
		{ypos=0, prob=254},
		{ypos=1, prob=254},
		{ypos=2, prob=254},
		{ypos=3, prob=254},
		{ypos=4, prob=254},
		{ypos=5, prob=254},
		{ypos=6, prob=254},
	},
	data = {

		-- z=0, y=0
		{name="default:stone", prob=254, param2=0},
		{name="default:stone", prob=254, param2=0},
		{name="default:stone", prob=254, param2=0},
		{name="default:stone", prob=254, param2=0},
		{name="default:stone", prob=254, param2=0},
		{name="default:stone", prob=254, param2=0},
		{name="default:stone", prob=254, param2=0},
		{name="default:stone", prob=254, param2=0},
		{name="default:stone", prob=254, param2=0},
		{name="default:stone", prob=254, param2=0},

		-- z=0, y=1
		{name="default:stone", prob=254, param2=0},
		{name="default:stone", prob=254, param2=0},
		{name="default:stone", prob=254, param2=0},
		{name="default:stone", prob=254, param2=0},
		{name="default:stone", prob=254, param2=0},
		{name="default:stone", prob=254, param2=0},
		{name="default:stone", prob=254, param2=0},
		{name="default:cobble", prob=254, param2=0},
		{name="default:stone", prob=254, param2=0},
		{name="default:dirt_with_grass", prob=254, param2=0},

		-- z=0, y=2
		{name="default:cobble", prob=254, param2=0},
		{name="default:cobble", prob=254, param2=0},
		{name="default:cobble", prob=254, param2=0},
		{name="default:cobble", prob=254, param2=0},
		{name="default:cobble", prob=254, param2=0},
		{name="default:cobble", prob=254, param2=0},
		{name="default:cobble", prob=254, param2=0},
		{name="default:cobble", prob=254, param2=0},
		{name="default:cobble", prob=254, param2=0},
		{name="air", prob=254, param2=0},

		-- z=0, y=3
		{name="default:cobble", prob=254, param2=0},
		{name="default:stone", prob=254, param2=0},
		{name="default:stone", prob=254, param2=0},
		{name="default:stone", prob=254, param2=0},
		{name="default:stone", prob=254, param2=0},
		{name="default:stone", prob=254, param2=0},
		{name="default:stone", prob=254, param2=0},
		{name="default:stone", prob=254, param2=0},
		{name="default:cobble", prob=254, param2=0},
		{name="air", prob=254, param2=0},

		-- z=0, y=4
		{name="default:cobble", prob=254, param2=0},
		{name="default:stone", prob=254, param2=0},
		{name="default:stone", prob=254, param2=0},
		{name="default:stone", prob=254, param2=0},
		{name="default:stone", prob=254, param2=0},
		{name="default:stone", prob=254, param2=0},
		{name="default:stone", prob=254, param2=0},
		{name="default:stone", prob=254, param2=0},
		{name="default:cobble", prob=254, param2=0},
		{name="air", prob=254, param2=0},

		-- z=0, y=5
		{name="stairs:slab_cobble", prob=254, param2=3},
		{name="stairs:slab_cobble", prob=254, param2=3},
		{name="stairs:slab_cobble", prob=254, param2=3},
		{name="stairs:slab_cobble", prob=254, param2=3},
		{name="stairs:slab_cobble", prob=254, param2=3},
		{name="stairs:slab_cobble", prob=254, param2=3},
		{name="stairs:slab_cobble", prob=254, param2=3},
		{name="stairs:slab_cobble", prob=254, param2=3},
		{name="stairs:slab_cobble", prob=254, param2=3},
		{name="air", prob=254, param2=0},

		-- z=0, y=6
		{name="air", prob=254, param2=0},
		{name="air", prob=254, param2=0},
		{name="air", prob=254, param2=0},
		{name="air", prob=254, param2=0},
		{name="air", prob=254, param2=0},
		{name="air", prob=254, param2=0},
		{name="air", prob=254, param2=0},
		{name="air", prob=254, param2=0},
		{name="air", prob=254, param2=0},
		{name="air", prob=254, param2=0},

		-- z=1, y=0
		{name="default:stone", prob=254, param2=0},
		{name="default:stone", prob=254, param2=0},
		{name="default:stone", prob=254, param2=0},
		{name="default:stone", prob=254, param2=0},
		{name="default:stone", prob=254, param2=0},
		{name="default:stone", prob=254, param2=0},
		{name="default:stone", prob=254, param2=0},
		{name="default:stone", prob=254, param2=0},
		{name="default:stone", prob=254, param2=0},
		{name="default:stone", prob=254, param2=0},

		-- z=1, y=1
		{name="default:stone", prob=254, param2=0},
		{name="default:gravel", prob=254, param2=0},
		{name="default:gravel", prob=254, param2=0},
		{name="default:gravel", prob=254, param2=0},
		{name="default:gravel", prob=254, param2=0},
		{name="default:gravel", prob=254, param2=0},
		{name="default:cobble", prob=254, param2=0},
		{name="default:cobble", prob=254, param2=0},
		{name="default:cobble", prob=254, param2=0},
		{name="default:stone", prob=254, param2=0},

		-- z=1, y=2
		{name="default:cobble", prob=254, param2=0},
		{name="default:furnace", prob=254, param2=2},
		{name="air", prob=254, param2=0},
		{name="air", prob=254, param2=0},
		{name="air", prob=254, param2=0},
		{name="air", prob=254, param2=0},
		{name="stairs:stair_cobble", prob=254, param2=1},
		{name="default:cobble", prob=254, param2=0},
		{name="default:cobble", prob=254, param2=0},
		{name="default:cobble", prob=254, param2=0},

		-- z=1, y=3
		{name="default:stone", prob=254, param2=0},
		{name="default:furnace", prob=254, param2=2},
		{name="air", prob=254, param2=0},
		{name="air", prob=254, param2=0},
		{name="air", prob=254, param2=0},
		{name="air", prob=254, param2=0},
		{name="air", prob=254, param2=0},
		{name="default:cobble", prob=254, param2=0},
		{name="default:cobble", prob=254, param2=0},
		{name="default:cobble", prob=254, param2=0},

		-- z=1, y=4
		{name="default:cobble", prob=254, param2=0},
		{name="air", prob=254, param2=0},
		{name="air", prob=254, param2=0},
		{name="air", prob=254, param2=0},
		{name="air", prob=254, param2=0},
		{name="air", prob=254, param2=0},
		{name="air", prob=254, param2=0},
		{name="air", prob=254, param2=0},
		{name="default:cobble", prob=254, param2=0},
		{name="air", prob=254, param2=0},

		-- z=1, y=5
		{name="default:stone", prob=254, param2=0},
		{name="default:stone", prob=254, param2=0},
		{name="default:stone", prob=254, param2=0},
		{name="default:stone", prob=254, param2=0},
		{name="default:stone", prob=254, param2=0},
		{name="default:stone", prob=254, param2=0},
		{name="default:stone", prob=254, param2=0},
		{name="default:stone", prob=254, param2=0},
		{name="default:cobble", prob=254, param2=0},
		{name="air", prob=254, param2=0},

		-- z=1, y=6
		{name="air", prob=254, param2=0},
		{name="air", prob=254, param2=0},
		{name="air", prob=254, param2=0},
		{name="air", prob=254, param2=0},
		{name="air", prob=254, param2=0},
		{name="air", prob=254, param2=0},
		{name="air", prob=254, param2=0},
		{name="air", prob=254, param2=0},
		{name="default:cobble", prob=254, param2=0},
		{name="air", prob=254, param2=0},

		-- z=2, y=0
		{name="default:stone", prob=254, param2=0},
		{name="default:stone", prob=254, param2=0},
		{name="default:stone", prob=254, param2=0},
		{name="default:stone", prob=254, param2=0},
		{name="default:stone", prob=254, param2=0},
		{name="default:stone", prob=254, param2=0},
		{name="default:stone", prob=254, param2=0},
		{name="default:stone", prob=254, param2=0},
		{name="default:stone", prob=254, param2=0},
		{name="default:stone", prob=254, param2=0},

		-- z=2, y=1
		{name="default:stone", prob=254, param2=0},
		{name="default:gravel", prob=254, param2=0},
		{name="default:gravel", prob=254, param2=0},
		{name="default:gravel", prob=254, param2=0},
		{name="default:gravel", prob=254, param2=0},
		{name="default:gravel", prob=254, param2=0},
		{name="default:cobble", prob=254, param2=0},
		{name="default:cobble", prob=254, param2=0},
		{name="default:cobble", prob=254, param2=0},
		{name="default:stone", prob=254, param2=0},

		-- z=2, y=2
		{name="default:cobble", prob=254, param2=0},
		{name="air", prob=254, param2=0},
		{name="air", prob=254, param2=0},
		{name="stairs:stair_stone", prob=254, param2=22},
		{name="air", prob=254, param2=0},
		{name="air", prob=254, param2=0},
		{name="stairs:stair_cobble", prob=254, param2=1},
		{name="default:lava_flowing", prob=254, param2=7},
		{name="default:lava_source", prob=254, param2=0},
		{name="default:cobble", prob=254, param2=0},

		-- z=2, y=3
		{name="default:fence_wood", prob=254, param2=0},
		{name="air", prob=254, param2=0},
		{name="air", prob=254, param2=0},
		{name="air", prob=254, param2=0},
		{name="air", prob=254, param2=0},
		{name="air", prob=254, param2=0},
		{name="air", prob=254, param2=0},
		{name="stairs:slab_cobble", prob=254, param2=23},
		{name="air", prob=254, param2=0},
		{name="default:cobble", prob=254, param2=0},

		-- z=2, y=4
		{name="default:cobble", prob=254, param2=0},
		{name="air", prob=254, param2=0},
		{name="air", prob=254, param2=0},
		{name="air", prob=254, param2=0},
		{name="air", prob=254, param2=0},
		{name="air", prob=254, param2=0},
		{name="air", prob=254, param2=0},
		{name="default:cobble", prob=254, param2=0},
		{name="air", prob=254, param2=0},
		{name="default:cobble", prob=254, param2=0},

		-- z=2, y=5
		{name="default:stone", prob=254, param2=0},
		{name="default:stone", prob=254, param2=0},
		{name="default:stone", prob=254, param2=0},
		{name="default:stone", prob=254, param2=0},
		{name="default:stone", prob=254, param2=0},
		{name="default:stone", prob=254, param2=0},
		{name="default:stone", prob=254, param2=0},
		{name="default:cobble", prob=254, param2=0},
		{name="air", prob=254, param2=0},
		{name="default:cobble", prob=254, param2=0},

		-- z=2, y=6
		{name="air", prob=254, param2=0},
		{name="air", prob=254, param2=0},
		{name="air", prob=254, param2=0},
		{name="air", prob=254, param2=0},
		{name="air", prob=254, param2=0},
		{name="air", prob=254, param2=0},
		{name="air", prob=254, param2=0},
		{name="default:cobble", prob=254, param2=0},
		{name="air", prob=254, param2=0},
		{name="default:cobble", prob=254, param2=0},

		-- z=3, y=0
		{name="default:stone", prob=254, param2=0},
		{name="default:stone", prob=254, param2=0},
		{name="default:stone", prob=254, param2=0},
		{name="default:stone", prob=254, param2=0},
		{name="default:stone", prob=254, param2=0},
		{name="default:stone", prob=254, param2=0},
		{name="default:stone", prob=254, param2=0},
		{name="default:stone", prob=254, param2=0},
		{name="default:stone", prob=254, param2=0},
		{name="default:stone", prob=254, param2=0},

		-- z=3, y=1
		{name="default:stone", prob=254, param2=0},
		{name="default:gravel", prob=254, param2=0},
		{name="default:gravel", prob=254, param2=0},
		{name="default:gravel", prob=254, param2=0},
		{name="default:gravel", prob=254, param2=0},
		{name="default:gravel", prob=254, param2=0},
		{name="default:cobble", prob=254, param2=0},
		{name="default:cobble", prob=254, param2=0},
		{name="default:cobble", prob=254, param2=0},
		{name="default:stone", prob=254, param2=0},

		-- z=3, y=2
		{name="default:cobble", prob=254, param2=0},
		{name="air", prob=254, param2=0},
		{name="air", prob=254, param2=0},
		{name="stairs:stair_stone", prob=254, param2=20},
		{name="air", prob=254, param2=0},
		{name="air", prob=254, param2=0},
		{name="stairs:stair_cobble", prob=254, param2=1},
		{name="default:lava_flowing", prob=254, param2=7},
		{name="default:lava_source", prob=254, param2=0},
		{name="default:cobble", prob=254, param2=0},

		-- z=3, y=3
		{name="default:fence_wood", prob=254, param2=0},
		{name="air", prob=254, param2=0},
		{name="air", prob=254, param2=0},
		{name="air", prob=254, param2=0},
		{name="air", prob=254, param2=0},
		{name="air", prob=254, param2=0},
		{name="air", prob=254, param2=0},
		{name="stairs:slab_cobble", prob=254, param2=23},
		{name="air", prob=254, param2=0},
		{name="default:cobble", prob=254, param2=0},

		-- z=3, y=4
		{name="default:cobble", prob=254, param2=0},
		{name="air", prob=254, param2=0},
		{name="air", prob=254, param2=0},
		{name="air", prob=254, param2=0},
		{name="air", prob=254, param2=0},
		{name="air", prob=254, param2=0},
		{name="air", prob=254, param2=0},
		{name="default:cobble", prob=254, param2=0},
		{name="air", prob=254, param2=0},
		{name="default:cobble", prob=254, param2=0},

		-- z=3, y=5
		{name="default:stone", prob=254, param2=0},
		{name="default:stone", prob=254, param2=0},
		{name="default:stone", prob=254, param2=0},
		{name="default:stone", prob=254, param2=0},
		{name="default:stone", prob=254, param2=0},
		{name="default:stone", prob=254, param2=0},
		{name="default:stone", prob=254, param2=0},
		{name="default:cobble", prob=254, param2=0},
		{name="air", prob=254, param2=0},
		{name="default:cobble", prob=254, param2=0},

		-- z=3, y=6
		{name="air", prob=254, param2=0},
		{name="air", prob=254, param2=0},
		{name="air", prob=254, param2=0},
		{name="air", prob=254, param2=0},
		{name="air", prob=254, param2=0},
		{name="air", prob=254, param2=0},
		{name="air", prob=254, param2=0},
		{name="default:cobble", prob=254, param2=0},
		{name="air", prob=254, param2=0},
		{name="default:cobble", prob=254, param2=0},

		-- z=4, y=0
		{name="default:stone", prob=254, param2=0},
		{name="default:stone", prob=254, param2=0},
		{name="default:stone", prob=254, param2=0},
		{name="default:stone", prob=254, param2=0},
		{name="default:stone", prob=254, param2=0},
		{name="default:stone", prob=254, param2=0},
		{name="default:stone", prob=254, param2=0},
		{name="default:stone", prob=254, param2=0},
		{name="default:stone", prob=254, param2=0},
		{name="default:stone", prob=254, param2=0},

		-- z=4, y=1
		{name="default:stone", prob=254, param2=0},
		{name="default:gravel", prob=254, param2=0},
		{name="default:gravel", prob=254, param2=0},
		{name="default:gravel", prob=254, param2=0},
		{name="default:gravel", prob=254, param2=0},
		{name="default:gravel", prob=254, param2=0},
		{name="default:cobble", prob=254, param2=0},
		{name="default:cobble", prob=254, param2=0},
		{name="default:cobble", prob=254, param2=0},
		{name="default:stone", prob=254, param2=0},

		-- z=4, y=2
		{name="default:cobble", prob=254, param2=0},
		{name="air", prob=254, param2=0},
		{name="air", prob=254, param2=0},
		{name="air", prob=254, param2=0},
		{name="air", prob=254, param2=0},
		{name="air", prob=254, param2=0},
		{name="stairs:stair_cobble", prob=254, param2=1},
		{name="default:cobble", prob=254, param2=0},
		{name="default:cobble", prob=254, param2=0},
		{name="default:cobble", prob=254, param2=0},

		-- z=4, y=3
		{name="default:stone", prob=254, param2=0},
		{name="air", prob=254, param2=0},
		{name="air", prob=254, param2=0},
		{name="air", prob=254, param2=0},
		{name="air", prob=254, param2=0},
		{name="air", prob=254, param2=0},
		{name="air", prob=254, param2=0},
		{name="default:cobble", prob=254, param2=0},
		{name="default:cobble", prob=254, param2=0},
		{name="default:cobble", prob=254, param2=0},

		-- z=4, y=4
		{name="default:cobble", prob=254, param2=0},
		{name="air", prob=254, param2=0},
		{name="air", prob=254, param2=0},
		{name="air", prob=254, param2=0},
		{name="air", prob=254, param2=0},
		{name="air", prob=254, param2=0},
		{name="air", prob=254, param2=0},
		{name="air", prob=254, param2=0},
		{name="default:cobble", prob=254, param2=0},
		{name="air", prob=254, param2=0},

		-- z=4, y=5
		{name="default:stone", prob=254, param2=0},
		{name="default:stone", prob=254, param2=0},
		{name="default:stone", prob=254, param2=0},
		{name="default:stone", prob=254, param2=0},
		{name="default:stone", prob=254, param2=0},
		{name="default:stone", prob=254, param2=0},
		{name="default:stone", prob=254, param2=0},
		{name="default:stone", prob=254, param2=0},
		{name="default:cobble", prob=254, param2=0},
		{name="air", prob=254, param2=0},

		-- z=4, y=6
		{name="air", prob=254, param2=0},
		{name="air", prob=254, param2=0},
		{name="air", prob=254, param2=0},
		{name="air", prob=254, param2=0},
		{name="air", prob=254, param2=0},
		{name="air", prob=254, param2=0},
		{name="air", prob=254, param2=0},
		{name="air", prob=254, param2=0},
		{name="default:cobble", prob=254, param2=0},
		{name="air", prob=254, param2=0},

		-- z=5, y=0
		{name="default:stone", prob=254, param2=0},
		{name="default:stone", prob=254, param2=0},
		{name="default:stone", prob=254, param2=0},
		{name="default:stone", prob=254, param2=0},
		{name="default:stone", prob=254, param2=0},
		{name="default:stone", prob=254, param2=0},
		{name="default:stone", prob=254, param2=0},
		{name="default:stone", prob=254, param2=0},
		{name="default:stone", prob=254, param2=0},
		{name="default:stone", prob=254, param2=0},

		-- z=5, y=1
		{name="default:stone", prob=254, param2=0},
		{name="default:gravel", prob=254, param2=0},
		{name="default:gravel", prob=254, param2=0},
		{name="default:gravel", prob=254, param2=0},
		{name="default:gravel", prob=254, param2=0},
		{name="default:gravel", prob=254, param2=0},
		{name="default:gravel", prob=254, param2=0},
		{name="default:cobble", prob=254, param2=0},
		{name="default:stone", prob=254, param2=0},
		{name="default:dirt_with_grass", prob=254, param2=0},

		-- z=5, y=2
		{name="default:cobble", prob=254, param2=0},
		{name="air", prob=254, param2=0},
		{name="air", prob=254, param2=0},
		{name="air", prob=254, param2=0},
		{name="default:cobble", prob=254, param2=0},
		{name="default:cobble", prob=254, param2=0},
		{name="default:cobble", prob=254, param2=0},
		{name="default:cobble", prob=254, param2=0},
		{name="default:cobble", prob=254, param2=0},
		{name="air", prob=254, param2=0},

		-- z=5, y=3
		{name="default:cobble", prob=254, param2=0},
		{name="air", prob=254, param2=0},
		{name="air", prob=254, param2=0},
		{name="air", prob=254, param2=0},
		{name="default:fence_wood", prob=254, param2=0},
		{name="stairs:slab_cobble", prob=254, param2=3},
		{name="stairs:slab_cobble", prob=254, param2=3},
		{name="stairs:slab_cobble", prob=254, param2=3},
		{name="default:cobble", prob=254, param2=0},
		{name="air", prob=254, param2=0},

		-- z=5, y=4
		{name="default:cobble", prob=254, param2=0},
		{name="air", prob=254, param2=0},
		{name="air", prob=254, param2=0},
		{name="air", prob=254, param2=0},
		{name="default:fence_wood", prob=254, param2=0},
		{name="air", prob=254, param2=0},
		{name="air", prob=254, param2=0},
		{name="air", prob=254, param2=0},
		{name="default:cobble", prob=254, param2=0},
		{name="air", prob=254, param2=0},

		-- z=5, y=5
		{name="stairs:slab_cobble", prob=254, param2=3},
		{name="stairs:slab_cobble", prob=254, param2=3},
		{name="stairs:slab_cobble", prob=254, param2=3},
		{name="stairs:slab_cobble", prob=254, param2=3},
		{name="stairs:slab_cobble", prob=254, param2=3},
		{name="stairs:slab_cobble", prob=254, param2=3},
		{name="stairs:slab_cobble", prob=254, param2=3},
		{name="stairs:slab_cobble", prob=254, param2=3},
		{name="stairs:slab_cobble", prob=254, param2=3},
		{name="air", prob=254, param2=0},

		-- z=5, y=6
		{name="air", prob=254, param2=0},
		{name="air", prob=254, param2=0},
		{name="air", prob=254, param2=0},
		{name="air", prob=254, param2=0},
		{name="air", prob=254, param2=0},
		{name="air", prob=254, param2=0},
		{name="air", prob=254, param2=0},
		{name="air", prob=254, param2=0},
		{name="air", prob=254, param2=0},
		{name="air", prob=254, param2=0},

		-- z=6, y=0
		{name="default:stone", prob=254, param2=0},
		{name="default:stone", prob=254, param2=0},
		{name="default:stone", prob=254, param2=0},
		{name="default:stone", prob=254, param2=0},
		{name="default:stone", prob=254, param2=0},
		{name="default:stone", prob=254, param2=0},
		{name="default:stone", prob=254, param2=0},
		{name="default:stone", prob=254, param2=0},
		{name="default:stone", prob=254, param2=0},
		{name="default:stone", prob=254, param2=0},

		-- z=6, y=1
		{name="default:dirt_with_grass", prob=254, param2=0},
		{name="default:gravel", prob=254, param2=0},
		{name="default:gravel", prob=254, param2=0},
		{name="default:gravel", prob=254, param2=0},
		{name="default:dirt_with_grass", prob=254, param2=0},
		{name="default:dirt_with_grass", prob=254, param2=0},
		{name="default:dirt_with_grass", prob=254, param2=0},
		{name="default:dirt_with_grass", prob=254, param2=0},
		{name="default:dirt_with_grass", prob=254, param2=0},
		{name="default:dirt_with_grass", prob=254, param2=0},

		-- z=6, y=2
		{name="air", prob=254, param2=0},
		{name="air", prob=254, param2=0},
		{name="air", prob=254, param2=0},
		{name="air", prob=254, param2=0},
		{name="air", prob=254, param2=0},
		{name="air", prob=254, param2=0},
		{name="air", prob=254, param2=0},
		{name="air", prob=254, param2=0},
		{name="air", prob=254, param2=0},
		{name="air", prob=254, param2=0},

		-- z=6, y=3
		{name="air", prob=254, param2=0},
		{name="air", prob=254, param2=0},
		{name="air", prob=254, param2=0},
		{name="air", prob=254, param2=0},
		{name="air", prob=254, param2=0},
		{name="air", prob=254, param2=0},
		{name="air", prob=254, param2=0},
		{name="air", prob=254, param2=0},
		{name="air", prob=254, param2=0},
		{name="air", prob=254, param2=0},

		-- z=6, y=4
		{name="mg_villages:torch", prob=254, param2=5},
		{name="air", prob=254, param2=0},
		{name="air", prob=254, param2=0},
		{name="air", prob=254, param2=0},
		{name="air", prob=254, param2=0},
		{name="air", prob=254, param2=0},
		{name="air", prob=254, param2=0},
		{name="air", prob=254, param2=0},
		{name="mg_villages:torch", prob=254, param2=5},
		{name="air", prob=254, param2=0},

		-- z=6, y=5
		{name="air", prob=254, param2=0},
		{name="air", prob=254, param2=0},
		{name="air", prob=254, param2=0},
		{name="air", prob=254, param2=0},
		{name="air", prob=254, param2=0},
		{name="air", prob=254, param2=0},
		{name="air", prob=254, param2=0},
		{name="air", prob=254, param2=0},
		{name="air", prob=254, param2=0},
		{name="air", prob=254, param2=0},

		-- z=6, y=6
		{name="air", prob=254, param2=0},
		{name="air", prob=254, param2=0},
		{name="air", prob=254, param2=0},
		{name="air", prob=254, param2=0},
		{name="air", prob=254, param2=0},
		{name="air", prob=254, param2=0},
		{name="air", prob=254, param2=0},
		{name="air", prob=254, param2=0},
		{name="air", prob=254, param2=0},
		{name="air", prob=254, param2=0},
	},
}

return schematic