schematic = {
	size = {x=9, y=9, z=6},
	yslice_prob = {
		{ypos=0, prob=254},
		{ypos=1, prob=254},
		{ypos=2, prob=254},
		{ypos=3, prob=254},
		{ypos=4, prob=254},
		{ypos=5, prob=254},
		{ypos=6, prob=254},
		{ypos=7, prob=254},
		{ypos=8, prob=254},
	},
	data = {

		-- z=0, y=0
		{name="default:desert_sand", prob=254, param2=0},
		{name="default:sandstone", prob=254, param2=0},
		{name="default:sandstone", prob=254, param2=0},
		{name="default:sandstone", prob=254, param2=0},
		{name="default:desert_sand", prob=254, param2=0},
		{name="default:sandstone", prob=254, param2=0},
		{name="default:sandstone", prob=254, param2=0},
		{name="default:sandstone", prob=254, param2=0},
		{name="default:desert_sand", prob=254, param2=0},

		-- z=0, y=1
		{name="air", prob=254, param2=0},
		{name="default:sandstone", prob=254, param2=0},
		{name="default:sandstone", prob=254, param2=0},
		{name="default:sandstone", prob=254, param2=0},
		{name="default:ladder", prob=254, param2=2},
		{name="default:sandstone", prob=254, param2=0},
		{name="default:sandstone", prob=254, param2=0},
		{name="default:sandstone", prob=254, param2=0},
		{name="air", prob=254, param2=0},

		-- z=0, y=2
		{name="air", prob=254, param2=0},
		{name="default:sandstone", prob=254, param2=0},
		{name="default:sandstone", prob=254, param2=0},
		{name="default:sandstone", prob=254, param2=0},
		{name="default:ladder", prob=254, param2=2},
		{name="default:sandstone", prob=254, param2=0},
		{name="default:sandstone", prob=254, param2=0},
		{name="default:sandstone", prob=254, param2=0},
		{name="air", prob=254, param2=0},

		-- z=0, y=3
		{name="air", prob=254, param2=0},
		{name="default:sandstone", prob=254, param2=0},
		{name="default:sandstone", prob=254, param2=0},
		{name="default:sandstone", prob=254, param2=0},
		{name="default:ladder", prob=254, param2=2},
		{name="default:sandstone", prob=254, param2=0},
		{name="default:sandstone", prob=254, param2=0},
		{name="default:sandstone", prob=254, param2=0},
		{name="air", prob=254, param2=0},

		-- z=0, y=4
		{name="air", prob=254, param2=0},
		{name="default:sandstone", prob=254, param2=0},
		{name="default:sandstone", prob=254, param2=0},
		{name="default:sandstone", prob=254, param2=0},
		{name="default:ladder", prob=254, param2=2},
		{name="default:sandstone", prob=254, param2=0},
		{name="default:sandstone", prob=254, param2=0},
		{name="default:sandstone", prob=254, param2=0},
		{name="air", prob=254, param2=0},

		-- z=0, y=5
		{name="air", prob=254, param2=0},
		{name="default:sandstone", prob=254, param2=0},
		{name="default:sandstone", prob=254, param2=0},
		{name="default:sandstone", prob=254, param2=0},
		{name="default:ladder", prob=254, param2=2},
		{name="default:sandstone", prob=254, param2=0},
		{name="default:sandstone", prob=254, param2=0},
		{name="default:sandstone", prob=254, param2=0},
		{name="air", prob=254, param2=0},

		-- z=0, y=6
		{name="air", prob=254, param2=0},
		{name="air", prob=254, param2=0},
		{name="air", prob=254, param2=0},
		{name="air", prob=254, param2=0},
		{name="air", prob=254, param2=0},
		{name="air", prob=254, param2=0},
		{name="air", prob=254, param2=0},
		{name="air", prob=254, param2=0},
		{name="air", prob=254, param2=0},

		-- z=0, y=7
		{name="air", prob=254, param2=0},
		{name="air", prob=254, param2=0},
		{name="air", prob=254, param2=0},
		{name="air", prob=254, param2=0},
		{name="air", prob=254, param2=0},
		{name="air", prob=254, param2=0},
		{name="air", prob=254, param2=0},
		{name="air", prob=254, param2=0},
		{name="air", prob=254, param2=0},

		-- z=0, y=8
		{name="air", prob=254, param2=0},
		{name="air", prob=254, param2=0},
		{name="air", prob=254, param2=0},
		{name="air", prob=254, param2=0},
		{name="air", prob=254, param2=0},
		{name="air", prob=254, param2=0},
		{name="air", prob=254, param2=0},
		{name="air", prob=254, param2=0},
		{name="air", prob=254, param2=0},

		-- z=1, y=0
		{name="default:sandstone", prob=254, param2=0},
		{name="stairs:slab_sandstone", prob=254, param2=0},
		{name="stairs:slab_sandstone", prob=254, param2=0},
		{name="stairs:slab_sandstone", prob=254, param2=0},
		{name="default:sandstone", prob=254, param2=0},
		{name="stairs:slab_sandstone", prob=254, param2=0},
		{name="stairs:slab_sandstone", prob=254, param2=0},
		{name="stairs:slab_sandstone", prob=254, param2=0},
		{name="default:sandstone", prob=254, param2=0},

		-- z=1, y=1
		{name="default:sandstone", prob=254, param2=0},
		{name="air", prob=254, param2=0},
		{name="air", prob=254, param2=0},
		{name="air", prob=254, param2=0},
		{name="default:sandstone", prob=254, param2=0},
		{name="air", prob=254, param2=0},
		{name="air", prob=254, param2=0},
		{name="air", prob=254, param2=0},
		{name="default:sandstone", prob=254, param2=0},

		-- z=1, y=2
		{name="default:sandstone", prob=254, param2=0},
		{name="stairs:slab_sandstone", prob=254, param2=20},
		{name="stairs:slab_sandstone", prob=254, param2=20},
		{name="stairs:slab_sandstone", prob=254, param2=20},
		{name="default:sandstone", prob=254, param2=0},
		{name="stairs:slab_sandstone", prob=254, param2=20},
		{name="stairs:slab_sandstone", prob=254, param2=20},
		{name="stairs:slab_sandstone", prob=254, param2=20},
		{name="default:sandstone", prob=254, param2=0},

		-- z=1, y=3
		{name="default:sandstone", prob=254, param2=0},
		{name="air", prob=254, param2=0},
		{name="air", prob=254, param2=0},
		{name="air", prob=254, param2=0},
		{name="default:sandstone", prob=254, param2=0},
		{name="air", prob=254, param2=0},
		{name="air", prob=254, param2=0},
		{name="air", prob=254, param2=0},
		{name="default:sandstone", prob=254, param2=0},

		-- z=1, y=4
		{name="default:sandstone", prob=254, param2=0},
		{name="air", prob=254, param2=0},
		{name="air", prob=254, param2=0},
		{name="air", prob=254, param2=0},
		{name="default:sandstone", prob=254, param2=0},
		{name="air", prob=254, param2=0},
		{name="air", prob=254, param2=0},
		{name="air", prob=254, param2=0},
		{name="default:sandstone", prob=254, param2=0},

		-- z=1, y=5
		{name="default:sandstone", prob=254, param2=0},
		{name="stairs:slab_sandstone", prob=254, param2=0},
		{name="stairs:slab_sandstone", prob=254, param2=0},
		{name="stairs:slab_sandstone", prob=254, param2=0},
		{name="stairs:slab_sandstone", prob=254, param2=0},
		{name="stairs:slab_sandstone", prob=254, param2=0},
		{name="stairs:slab_sandstone", prob=254, param2=0},
		{name="stairs:slab_sandstone", prob=254, param2=0},
		{name="default:sandstone", prob=254, param2=0},

		-- z=1, y=6
		{name="air", prob=254, param2=0},
		{name="air", prob=254, param2=0},
		{name="air", prob=254, param2=0},
		{name="air", prob=254, param2=0},
		{name="air", prob=254, param2=0},
		{name="air", prob=254, param2=0},
		{name="air", prob=254, param2=0},
		{name="air", prob=254, param2=0},
		{name="air", prob=254, param2=0},

		-- z=1, y=7
		{name="air", prob=254, param2=0},
		{name="air", prob=254, param2=0},
		{name="air", prob=254, param2=0},
		{name="air", prob=254, param2=0},
		{name="air", prob=254, param2=0},
		{name="air", prob=254, param2=0},
		{name="air", prob=254, param2=0},
		{name="air", prob=254, param2=0},
		{name="air", prob=254, param2=0},

		-- z=1, y=8
		{name="air", prob=254, param2=0},
		{name="air", prob=254, param2=0},
		{name="air", prob=254, param2=0},
		{name="air", prob=254, param2=0},
		{name="air", prob=254, param2=0},
		{name="air", prob=254, param2=0},
		{name="air", prob=254, param2=0},
		{name="air", prob=254, param2=0},
		{name="air", prob=254, param2=0},

		-- z=2, y=0
		{name="default:sandstone", prob=254, param2=0},
		{name="stairs:slab_sandstone", prob=254, param2=0},
		{name="stairs:slab_sandstone", prob=254, param2=0},
		{name="stairs:slab_sandstone", prob=254, param2=0},
		{name="default:sandstone", prob=254, param2=0},
		{name="stairs:slab_sandstone", prob=254, param2=0},
		{name="stairs:slab_sandstone", prob=254, param2=0},
		{name="stairs:slab_sandstone", prob=254, param2=0},
		{name="default:sandstone", prob=254, param2=0},

		-- z=2, y=1
		{name="default:sandstone", prob=254, param2=0},
		{name="air", prob=254, param2=0},
		{name="air", prob=254, param2=0},
		{name="air", prob=254, param2=0},
		{name="default:sandstone", prob=254, param2=0},
		{name="air", prob=254, param2=0},
		{name="air", prob=254, param2=0},
		{name="air", prob=254, param2=0},
		{name="default:sandstone", prob=254, param2=0},

		-- z=2, y=2
		{name="default:sandstone", prob=254, param2=0},
		{name="stairs:slab_sandstone", prob=254, param2=20},
		{name="stairs:slab_sandstone", prob=254, param2=20},
		{name="stairs:slab_sandstone", prob=254, param2=20},
		{name="default:sandstone", prob=254, param2=0},
		{name="stairs:slab_sandstone", prob=254, param2=20},
		{name="stairs:slab_sandstone", prob=254, param2=20},
		{name="stairs:slab_sandstone", prob=254, param2=20},
		{name="default:sandstone", prob=254, param2=0},

		-- z=2, y=3
		{name="default:sandstone", prob=254, param2=0},
		{name="air", prob=254, param2=0},
		{name="air", prob=254, param2=0},
		{name="air", prob=254, param2=0},
		{name="default:sandstone", prob=254, param2=0},
		{name="air", prob=254, param2=0},
		{name="air", prob=254, param2=0},
		{name="air", prob=254, param2=0},
		{name="default:sandstone", prob=254, param2=0},

		-- z=2, y=4
		{name="default:sandstone", prob=254, param2=0},
		{name="air", prob=254, param2=0},
		{name="air", prob=254, param2=0},
		{name="air", prob=254, param2=0},
		{name="default:sandstone", prob=254, param2=0},
		{name="air", prob=254, param2=0},
		{name="air", prob=254, param2=0},
		{name="air", prob=254, param2=0},
		{name="default:sandstone", prob=254, param2=0},

		-- z=2, y=5
		{name="default:sandstone", prob=254, param2=0},
		{name="stairs:slab_sandstone", prob=254, param2=0},
		{name="stairs:slab_sandstone", prob=254, param2=0},
		{name="stairs:slab_sandstone", prob=254, param2=0},
		{name="stairs:slab_sandstone", prob=254, param2=0},
		{name="stairs:slab_sandstone", prob=254, param2=0},
		{name="stairs:slab_sandstone", prob=254, param2=0},
		{name="stairs:slab_sandstone", prob=254, param2=0},
		{name="default:sandstone", prob=254, param2=0},

		-- z=2, y=6
		{name="air", prob=254, param2=0},
		{name="air", prob=254, param2=0},
		{name="air", prob=254, param2=0},
		{name="air", prob=254, param2=0},
		{name="air", prob=254, param2=0},
		{name="air", prob=254, param2=0},
		{name="air", prob=254, param2=0},
		{name="air", prob=254, param2=0},
		{name="air", prob=254, param2=0},

		-- z=2, y=7
		{name="air", prob=254, param2=0},
		{name="air", prob=254, param2=0},
		{name="air", prob=254, param2=0},
		{name="air", prob=254, param2=0},
		{name="air", prob=254, param2=0},
		{name="air", prob=254, param2=0},
		{name="air", prob=254, param2=0},
		{name="air", prob=254, param2=0},
		{name="air", prob=254, param2=0},

		-- z=2, y=8
		{name="air", prob=254, param2=0},
		{name="air", prob=254, param2=0},
		{name="air", prob=254, param2=0},
		{name="air", prob=254, param2=0},
		{name="air", prob=254, param2=0},
		{name="air", prob=254, param2=0},
		{name="air", prob=254, param2=0},
		{name="air", prob=254, param2=0},
		{name="air", prob=254, param2=0},

		-- z=3, y=0
		{name="stairs:slab_sandstone", prob=254, param2=0},
		{name="stairs:slab_sandstone", prob=254, param2=0},
		{name="stairs:slab_sandstone", prob=254, param2=0},
		{name="stairs:slab_sandstone", prob=254, param2=0},
		{name="default:sandstone", prob=254, param2=0},
		{name="stairs:slab_sandstone", prob=254, param2=0},
		{name="stairs:slab_sandstone", prob=254, param2=0},
		{name="stairs:slab_sandstone", prob=254, param2=0},
		{name="stairs:slab_sandstone", prob=254, param2=0},

		-- z=3, y=1
		{name="air", prob=254, param2=0},
		{name="air", prob=254, param2=0},
		{name="air", prob=254, param2=0},
		{name="air", prob=254, param2=0},
		{name="default:sandstone", prob=254, param2=0},
		{name="air", prob=254, param2=0},
		{name="air", prob=254, param2=0},
		{name="air", prob=254, param2=0},
		{name="air", prob=254, param2=0},

		-- z=3, y=2
		{name="stairs:slab_sandstone", prob=254, param2=20},
		{name="stairs:slab_sandstone", prob=254, param2=20},
		{name="stairs:slab_sandstone", prob=254, param2=20},
		{name="stairs:slab_sandstone", prob=254, param2=20},
		{name="stairs:slab_sandstone", prob=254, param2=0},
		{name="stairs:slab_sandstone", prob=254, param2=20},
		{name="stairs:slab_sandstone", prob=254, param2=20},
		{name="stairs:slab_sandstone", prob=254, param2=20},
		{name="stairs:slab_sandstone", prob=254, param2=20},

		-- z=3, y=3
		{name="default:sandstone", prob=254, param2=0},
		{name="air", prob=254, param2=0},
		{name="air", prob=254, param2=0},
		{name="air", prob=254, param2=0},
		{name="air", prob=254, param2=0},
		{name="air", prob=254, param2=0},
		{name="air", prob=254, param2=0},
		{name="air", prob=254, param2=0},
		{name="default:sandstone", prob=254, param2=0},

		-- z=3, y=4
		{name="default:sandstone", prob=254, param2=0},
		{name="air", prob=254, param2=0},
		{name="air", prob=254, param2=0},
		{name="air", prob=254, param2=0},
		{name="air", prob=254, param2=0},
		{name="air", prob=254, param2=0},
		{name="air", prob=254, param2=0},
		{name="air", prob=254, param2=0},
		{name="default:sandstone", prob=254, param2=0},

		-- z=3, y=5
		{name="default:sandstone", prob=254, param2=0},
		{name="stairs:slab_sandstone", prob=254, param2=0},
		{name="stairs:slab_sandstone", prob=254, param2=0},
		{name="stairs:slab_sandstone", prob=254, param2=0},
		{name="stairs:slab_sandstone", prob=254, param2=0},
		{name="stairs:slab_sandstone", prob=254, param2=0},
		{name="stairs:slab_sandstone", prob=254, param2=0},
		{name="stairs:slab_sandstone", prob=254, param2=0},
		{name="default:sandstone", prob=254, param2=0},

		-- z=3, y=6
		{name="air", prob=254, param2=0},
		{name="air", prob=254, param2=0},
		{name="air", prob=254, param2=0},
		{name="air", prob=254, param2=0},
		{name="air", prob=254, param2=0},
		{name="air", prob=254, param2=0},
		{name="air", prob=254, param2=0},
		{name="air", prob=254, param2=0},
		{name="air", prob=254, param2=0},

		-- z=3, y=7
		{name="air", prob=254, param2=0},
		{name="air", prob=254, param2=0},
		{name="air", prob=254, param2=0},
		{name="air", prob=254, param2=0},
		{name="air", prob=254, param2=0},
		{name="air", prob=254, param2=0},
		{name="air", prob=254, param2=0},
		{name="air", prob=254, param2=0},
		{name="air", prob=254, param2=0},

		-- z=3, y=8
		{name="air", prob=254, param2=0},
		{name="air", prob=254, param2=0},
		{name="air", prob=254, param2=0},
		{name="air", prob=254, param2=0},
		{name="air", prob=254, param2=0},
		{name="air", prob=254, param2=0},
		{name="air", prob=254, param2=0},
		{name="air", prob=254, param2=0},
		{name="air", prob=254, param2=0},

		-- z=4, y=0
		{name="stairs:slab_sandstone", prob=254, param2=0},
		{name="default:sandstone", prob=254, param2=0},
		{name="default:sandstone", prob=254, param2=0},
		{name="default:sandstone", prob=254, param2=0},
		{name="default:sandstone", prob=254, param2=0},
		{name="default:sandstone", prob=254, param2=0},
		{name="default:sandstone", prob=254, param2=0},
		{name="default:sandstone", prob=254, param2=0},
		{name="stairs:slab_sandstone", prob=254, param2=0},

		-- z=4, y=1
		{name="air", prob=254, param2=0},
		{name="default:sandstone", prob=254, param2=0},
		{name="default:sandstone", prob=254, param2=0},
		{name="default:sandstone", prob=254, param2=0},
		{name="stairs:stair_sandstone", prob=254, param2=2},
		{name="default:sandstone", prob=254, param2=0},
		{name="default:sandstone", prob=254, param2=0},
		{name="default:sandstone", prob=254, param2=0},
		{name="air", prob=254, param2=0},

		-- z=4, y=2
		{name="air", prob=254, param2=0},
		{name="default:sandstone", prob=254, param2=0},
		{name="default:sandstone", prob=254, param2=0},
		{name="default:sandstone", prob=254, param2=0},
		{name="air", prob=254, param2=0},
		{name="default:sandstone", prob=254, param2=0},
		{name="default:sandstone", prob=254, param2=0},
		{name="default:sandstone", prob=254, param2=0},
		{name="air", prob=254, param2=0},

		-- z=4, y=3
		{name="air", prob=254, param2=0},
		{name="default:sandstone", prob=254, param2=0},
		{name="default:sandstone", prob=254, param2=0},
		{name="default:sandstone", prob=254, param2=0},
		{name="air", prob=254, param2=0},
		{name="default:sandstone", prob=254, param2=0},
		{name="default:sandstone", prob=254, param2=0},
		{name="default:sandstone", prob=254, param2=0},
		{name="air", prob=254, param2=0},

		-- z=4, y=4
		{name="air", prob=254, param2=0},
		{name="default:sandstone", prob=254, param2=0},
		{name="default:sandstone", prob=254, param2=0},
		{name="default:sandstone", prob=254, param2=0},
		{name="stairs:slab_sandstone", prob=254, param2=20},
		{name="default:sandstone", prob=254, param2=0},
		{name="default:sandstone", prob=254, param2=0},
		{name="default:sandstone", prob=254, param2=0},
		{name="air", prob=254, param2=0},

		-- z=4, y=5
		{name="air", prob=254, param2=0},
		{name="default:sandstone", prob=254, param2=0},
		{name="default:sandstone", prob=254, param2=0},
		{name="air", prob=254, param2=0},
		{name="stairs:slab_sandstone", prob=254, param2=0},
		{name="air", prob=254, param2=0},
		{name="default:sandstone", prob=254, param2=0},
		{name="default:sandstone", prob=254, param2=0},
		{name="air", prob=254, param2=0},

		-- z=4, y=6
		{name="air", prob=254, param2=0},
		{name="air", prob=254, param2=0},
		{name="air", prob=254, param2=0},
		{name="air", prob=254, param2=0},
		{name="air", prob=254, param2=0},
		{name="air", prob=254, param2=0},
		{name="air", prob=254, param2=0},
		{name="air", prob=254, param2=0},
		{name="air", prob=254, param2=0},

		-- z=4, y=7
		{name="air", prob=254, param2=0},
		{name="air", prob=254, param2=0},
		{name="air", prob=254, param2=0},
		{name="air", prob=254, param2=0},
		{name="air", prob=254, param2=0},
		{name="air", prob=254, param2=0},
		{name="air", prob=254, param2=0},
		{name="air", prob=254, param2=0},
		{name="air", prob=254, param2=0},

		-- z=4, y=8
		{name="air", prob=254, param2=0},
		{name="air", prob=254, param2=0},
		{name="air", prob=254, param2=0},
		{name="air", prob=254, param2=0},
		{name="air", prob=254, param2=0},
		{name="air", prob=254, param2=0},
		{name="air", prob=254, param2=0},
		{name="air", prob=254, param2=0},
		{name="air", prob=254, param2=0},

		-- z=5, y=0
		{name="default:sandstone", prob=254, param2=0},
		{name="default:sandstone", prob=254, param2=0},
		{name="default:sandstone", prob=254, param2=0},
		{name="default:sandstone", prob=254, param2=0},
		{name="default:sandstone", prob=254, param2=0},
		{name="default:sandstone", prob=254, param2=0},
		{name="default:sandstone", prob=254, param2=0},
		{name="default:sandstone", prob=254, param2=0},
		{name="default:sandstone", prob=254, param2=0},

		-- z=5, y=1
		{name="air", prob=254, param2=0},
		{name="air", prob=254, param2=0},
		{name="air", prob=254, param2=0},
		{name="default:ladder", prob=254, param2=5},
		{name="air", prob=254, param2=0},
		{name="default:ladder", prob=254, param2=5},
		{name="air", prob=254, param2=0},
		{name="air", prob=254, param2=0},
		{name="air", prob=254, param2=0},

		-- z=5, y=2
		{name="air", prob=254, param2=0},
		{name="air", prob=254, param2=0},
		{name="air", prob=254, param2=0},
		{name="default:ladder", prob=254, param2=5},
		{name="air", prob=254, param2=0},
		{name="default:ladder", prob=254, param2=5},
		{name="air", prob=254, param2=0},
		{name="air", prob=254, param2=0},
		{name="air", prob=254, param2=0},

		-- z=5, y=3
		{name="air", prob=254, param2=0},
		{name="default:torch", prob=254, param2=5},
		{name="air", prob=254, param2=0},
		{name="default:ladder", prob=254, param2=5},
		{name="air", prob=254, param2=0},
		{name="default:ladder", prob=254, param2=5},
		{name="air", prob=254, param2=0},
		{name="default:torch", prob=254, param2=5},
		{name="air", prob=254, param2=0},

		-- z=5, y=4
		{name="air", prob=254, param2=0},
		{name="air", prob=254, param2=0},
		{name="air", prob=254, param2=0},
		{name="default:ladder", prob=254, param2=5},
		{name="air", prob=254, param2=0},
		{name="default:ladder", prob=254, param2=5},
		{name="air", prob=254, param2=0},
		{name="air", prob=254, param2=0},
		{name="air", prob=254, param2=0},

		-- z=5, y=5
		{name="air", prob=254, param2=0},
		{name="air", prob=254, param2=0},
		{name="air", prob=254, param2=0},
		{name="air", prob=254, param2=0},
		{name="air", prob=254, param2=0},
		{name="air", prob=254, param2=0},
		{name="air", prob=254, param2=0},
		{name="air", prob=254, param2=0},
		{name="air", prob=254, param2=0},

		-- z=5, y=6
		{name="air", prob=254, param2=0},
		{name="air", prob=254, param2=0},
		{name="air", prob=254, param2=0},
		{name="air", prob=254, param2=0},
		{name="air", prob=254, param2=0},
		{name="air", prob=254, param2=0},
		{name="air", prob=254, param2=0},
		{name="air", prob=254, param2=0},
		{name="air", prob=254, param2=0},

		-- z=5, y=7
		{name="air", prob=254, param2=0},
		{name="air", prob=254, param2=0},
		{name="air", prob=254, param2=0},
		{name="air", prob=254, param2=0},
		{name="air", prob=254, param2=0},
		{name="air", prob=254, param2=0},
		{name="air", prob=254, param2=0},
		{name="air", prob=254, param2=0},
		{name="air", prob=254, param2=0},

		-- z=5, y=8
		{name="air", prob=254, param2=0},
		{name="air", prob=254, param2=0},
		{name="air", prob=254, param2=0},
		{name="air", prob=254, param2=0},
		{name="air", prob=254, param2=0},
		{name="air", prob=254, param2=0},
		{name="air", prob=254, param2=0},
		{name="air", prob=254, param2=0},
		{name="air", prob=254, param2=0},
	},
}

return schematic