schematic = {
	size = {x=7, y=3, z=7},
	yslice_prob = {
		{ypos=0, prob=254},
		{ypos=1, prob=254},
		{ypos=2, prob=254},
	},
	data = {

		-- z=0, y=0
		{name="default:gravel", prob=254, param2=0},
		{name="default:gravel", prob=254, param2=0},
		{name="default:gravel", prob=254, param2=0},
		{name="default:gravel", prob=254, param2=0},
		{name="default:gravel", prob=254, param2=0},
		{name="default:gravel", prob=254, param2=0},
		{name="default:gravel", prob=254, param2=0},

		-- z=0, y=1
		{name="default:tree", prob=254, param2=0},
		{name="stairs:slab_wood", prob=254, param2=0},
		{name="stairs:slab_wood", prob=254, param2=0},
		{name="default:tree", prob=254, param2=0},
		{name="stairs:slab_wood", prob=254, param2=0},
		{name="stairs:slab_wood", prob=254, param2=0},
		{name="default:tree", prob=254, param2=0},

		-- z=0, y=2
		{name="air", prob=254, param2=0},
		{name="air", prob=254, param2=0},
		{name="air", prob=254, param2=0},
		{name="air", prob=254, param2=0},
		{name="air", prob=254, param2=0},
		{name="air", prob=254, param2=0},
		{name="air", prob=254, param2=0},

		-- z=1, y=0
		{name="default:dirt", prob=254, param2=0},
		{name="default:dirt", prob=254, param2=0},
		{name="default:dirt", prob=254, param2=0},
		{name="default:dirt", prob=254, param2=0},
		{name="default:dirt", prob=254, param2=0},
		{name="default:dirt", prob=254, param2=0},
		{name="default:dirt", prob=254, param2=0},

		-- z=1, y=1
		{name="default:tree", prob=254, param2=3},
		{name="default:tree", prob=254, param2=3},
		{name="default:tree", prob=254, param2=3},
		{name="default:tree", prob=254, param2=3},
		{name="default:tree", prob=254, param2=3},
		{name="default:tree", prob=254, param2=3},
		{name="default:tree", prob=254, param2=3},

		-- z=1, y=2
		{name="default:fence_wood", prob=254, param2=0},
		{name="air", prob=254, param2=0},
		{name="air", prob=254, param2=0},
		{name="default:fence_wood", prob=254, param2=0},
		{name="air", prob=254, param2=0},
		{name="air", prob=254, param2=0},
		{name="default:fence_wood", prob=254, param2=0},

		-- z=2, y=0
		{name="default:dirt", prob=254, param2=0},
		{name="default:dirt", prob=254, param2=0},
		{name="default:dirt", prob=254, param2=0},
		{name="default:dirt", prob=254, param2=0},
		{name="default:dirt", prob=254, param2=0},
		{name="default:dirt", prob=254, param2=0},
		{name="default:dirt", prob=254, param2=0},

		-- z=2, y=1
		{name="default:tree", prob=254, param2=3},
		{name="farming:soil_wet", prob=254, param2=0},
		{name="farming:soil_wet", prob=254, param2=0},
		{name="default:water_source", prob=254, param2=0},
		{name="farming:soil_wet", prob=254, param2=0},
		{name="farming:soil_wet", prob=254, param2=0},
		{name="default:tree", prob=254, param2=3},

		-- z=2, y=2
		{name="default:fence_wood", prob=254, param2=0},
		{name="farming:cotton_8", prob=254, param2=0},
		{name="farming:cotton_8", prob=254, param2=0},
		{name="air", prob=254, param2=0},
		{name="farming:cotton_8", prob=254, param2=0},
		{name="farming:cotton_8", prob=254, param2=0},
		{name="default:fence_wood", prob=254, param2=0},

		-- z=3, y=0
		{name="default:dirt", prob=254, param2=0},
		{name="default:dirt", prob=254, param2=0},
		{name="default:dirt", prob=254, param2=0},
		{name="default:dirt", prob=254, param2=0},
		{name="default:dirt", prob=254, param2=0},
		{name="default:dirt", prob=254, param2=0},
		{name="default:dirt", prob=254, param2=0},

		-- z=3, y=1
		{name="default:tree", prob=254, param2=3},
		{name="farming:soil_wet", prob=254, param2=0},
		{name="farming:soil_wet", prob=254, param2=0},
		{name="default:water_source", prob=254, param2=0},
		{name="farming:soil_wet", prob=254, param2=0},
		{name="farming:soil_wet", prob=254, param2=0},
		{name="default:tree", prob=254, param2=3},

		-- z=3, y=2
		{name="default:fence_wood", prob=254, param2=0},
		{name="farming:cotton_8", prob=254, param2=0},
		{name="farming:cotton_8", prob=254, param2=0},
		{name="air", prob=254, param2=0},
		{name="farming:cotton_8", prob=254, param2=0},
		{name="farming:cotton_8", prob=254, param2=0},
		{name="default:fence_wood", prob=254, param2=0},

		-- z=4, y=0
		{name="default:dirt", prob=254, param2=0},
		{name="default:dirt", prob=254, param2=0},
		{name="default:dirt", prob=254, param2=0},
		{name="default:dirt", prob=254, param2=0},
		{name="default:dirt", prob=254, param2=0},
		{name="default:dirt", prob=254, param2=0},
		{name="default:dirt", prob=254, param2=0},

		-- z=4, y=1
		{name="default:tree", prob=254, param2=3},
		{name="farming:soil_wet", prob=254, param2=0},
		{name="farming:soil_wet", prob=254, param2=0},
		{name="default:water_source", prob=254, param2=0},
		{name="farming:soil_wet", prob=254, param2=0},
		{name="farming:soil_wet", prob=254, param2=0},
		{name="default:tree", prob=254, param2=3},

		-- z=4, y=2
		{name="default:fence_wood", prob=254, param2=0},
		{name="farming:cotton_8", prob=254, param2=0},
		{name="farming:cotton_8", prob=254, param2=0},
		{name="air", prob=254, param2=0},
		{name="farming:cotton_8", prob=254, param2=0},
		{name="farming:cotton_8", prob=254, param2=0},
		{name="default:fence_wood", prob=254, param2=0},

		-- z=5, y=0
		{name="default:dirt", prob=254, param2=0},
		{name="default:dirt", prob=254, param2=0},
		{name="default:dirt", prob=254, param2=0},
		{name="default:dirt", prob=254, param2=0},
		{name="default:dirt", prob=254, param2=0},
		{name="default:dirt", prob=254, param2=0},
		{name="default:dirt", prob=254, param2=0},

		-- z=5, y=1
		{name="default:tree", prob=254, param2=3},
		{name="farming:soil_wet", prob=254, param2=0},
		{name="farming:soil_wet", prob=254, param2=0},
		{name="default:water_source", prob=254, param2=0},
		{name="farming:soil_wet", prob=254, param2=0},
		{name="farming:soil_wet", prob=254, param2=0},
		{name="default:tree", prob=254, param2=3},

		-- z=5, y=2
		{name="default:fence_wood", prob=254, param2=0},
		{name="farming:cotton_8", prob=254, param2=0},
		{name="farming:cotton_8", prob=254, param2=0},
		{name="air", prob=254, param2=0},
		{name="farming:cotton_8", prob=254, param2=0},
		{name="farming:cotton_8", prob=254, param2=0},
		{name="default:fence_wood", prob=254, param2=0},

		-- z=6, y=0
		{name="default:dirt", prob=254, param2=0},
		{name="default:dirt", prob=254, param2=0},
		{name="default:dirt", prob=254, param2=0},
		{name="default:dirt", prob=254, param2=0},
		{name="default:dirt", prob=254, param2=0},
		{name="default:dirt", prob=254, param2=0},
		{name="default:dirt", prob=254, param2=0},

		-- z=6, y=1
		{name="default:tree", prob=254, param2=3},
		{name="default:tree", prob=254, param2=3},
		{name="default:tree", prob=254, param2=3},
		{name="default:tree", prob=254, param2=3},
		{name="default:tree", prob=254, param2=3},
		{name="default:tree", prob=254, param2=3},
		{name="default:tree", prob=254, param2=3},

		-- z=6, y=2
		{name="default:fence_wood", prob=254, param2=0},
		{name="default:fence_wood", prob=254, param2=0},
		{name="default:fence_wood", prob=254, param2=0},
		{name="default:fence_wood", prob=254, param2=0},
		{name="default:fence_wood", prob=254, param2=0},
		{name="default:fence_wood", prob=254, param2=0},
		{name="default:fence_wood", prob=254, param2=0},
	},
}

return schematic