schematic = {
	size = {x=12, y=9, z=18},
	yslice_prob = {
		{ypos=0, prob=254},
		{ypos=1, prob=254},
		{ypos=2, prob=254},
		{ypos=3, prob=254},
		{ypos=4, prob=254},
		{ypos=5, prob=254},
		{ypos=6, prob=254},
		{ypos=7, prob=254},
		{ypos=8, prob=254},
	},
	data = {

		-- z=0, y=0
		{name="air", prob=254, param2=0},
		{name="air", prob=254, param2=0},
		{name="air", prob=254, param2=0},
		{name="air", prob=254, param2=0},
		{name="air", prob=254, param2=0},
		{name="air", prob=254, param2=0},
		{name="air", prob=254, param2=0},
		{name="air", prob=254, param2=0},
		{name="air", prob=254, param2=0},
		{name="air", prob=254, param2=0},
		{name="air", prob=254, param2=0},
		{name="air", prob=254, param2=0},

		-- z=0, y=1
		{name="air", prob=254, param2=0},
		{name="air", prob=254, param2=0},
		{name="air", prob=254, param2=0},
		{name="air", prob=254, param2=0},
		{name="air", prob=254, param2=0},
		{name="air", prob=254, param2=0},
		{name="air", prob=254, param2=0},
		{name="air", prob=254, param2=0},
		{name="air", prob=254, param2=0},
		{name="air", prob=254, param2=0},
		{name="air", prob=254, param2=0},
		{name="air", prob=254, param2=0},

		-- z=0, y=2
		{name="air", prob=254, param2=0},
		{name="air", prob=254, param2=0},
		{name="air", prob=254, param2=0},
		{name="air", prob=254, param2=0},
		{name="air", prob=254, param2=0},
		{name="air", prob=254, param2=0},
		{name="air", prob=254, param2=0},
		{name="air", prob=254, param2=0},
		{name="air", prob=254, param2=0},
		{name="air", prob=254, param2=0},
		{name="air", prob=254, param2=0},
		{name="air", prob=254, param2=0},

		-- z=0, y=3
		{name="air", prob=254, param2=0},
		{name="air", prob=254, param2=0},
		{name="air", prob=254, param2=0},
		{name="air", prob=254, param2=0},
		{name="air", prob=254, param2=0},
		{name="air", prob=254, param2=0},
		{name="air", prob=254, param2=0},
		{name="air", prob=254, param2=0},
		{name="air", prob=254, param2=0},
		{name="air", prob=254, param2=0},
		{name="air", prob=254, param2=0},
		{name="air", prob=254, param2=0},

		-- z=0, y=4
		{name="air", prob=254, param2=0},
		{name="air", prob=254, param2=0},
		{name="air", prob=254, param2=0},
		{name="air", prob=254, param2=0},
		{name="air", prob=254, param2=0},
		{name="air", prob=254, param2=0},
		{name="air", prob=254, param2=0},
		{name="air", prob=254, param2=0},
		{name="air", prob=254, param2=0},
		{name="air", prob=254, param2=0},
		{name="air", prob=254, param2=0},
		{name="air", prob=254, param2=0},

		-- z=0, y=5
		{name="air", prob=254, param2=0},
		{name="air", prob=254, param2=0},
		{name="air", prob=254, param2=0},
		{name="air", prob=254, param2=0},
		{name="air", prob=254, param2=0},
		{name="air", prob=254, param2=0},
		{name="air", prob=254, param2=0},
		{name="air", prob=254, param2=0},
		{name="air", prob=254, param2=0},
		{name="air", prob=254, param2=0},
		{name="air", prob=254, param2=0},
		{name="air", prob=254, param2=0},

		-- z=0, y=6
		{name="air", prob=254, param2=0},
		{name="air", prob=254, param2=0},
		{name="air", prob=254, param2=0},
		{name="air", prob=254, param2=0},
		{name="air", prob=254, param2=0},
		{name="air", prob=254, param2=0},
		{name="air", prob=254, param2=0},
		{name="air", prob=254, param2=0},
		{name="air", prob=254, param2=0},
		{name="air", prob=254, param2=0},
		{name="air", prob=254, param2=0},
		{name="air", prob=254, param2=0},

		-- z=0, y=7
		{name="stairs:stair_cobble", prob=254, param2=1},
		{name="air", prob=254, param2=0},
		{name="air", prob=254, param2=0},
		{name="air", prob=254, param2=0},
		{name="air", prob=254, param2=0},
		{name="air", prob=254, param2=0},
		{name="air", prob=254, param2=0},
		{name="air", prob=254, param2=0},
		{name="air", prob=254, param2=0},
		{name="air", prob=254, param2=0},
		{name="air", prob=254, param2=0},
		{name="stairs:stair_cobble", prob=254, param2=3},

		-- z=0, y=8
		{name="air", prob=254, param2=0},
		{name="stairs:slab_cobble", prob=254, param2=3},
		{name="stairs:slab_cobble", prob=254, param2=3},
		{name="stairs:slab_cobble", prob=254, param2=3},
		{name="stairs:slab_cobble", prob=254, param2=3},
		{name="stairs:slab_cobble", prob=254, param2=3},
		{name="stairs:slab_cobble", prob=254, param2=3},
		{name="stairs:slab_cobble", prob=254, param2=3},
		{name="stairs:slab_cobble", prob=254, param2=3},
		{name="stairs:slab_cobble", prob=254, param2=3},
		{name="stairs:slab_cobble", prob=254, param2=3},
		{name="air", prob=254, param2=0},

		-- z=1, y=0
		{name="air", prob=254, param2=0},
		{name="default:tree", prob=254, param2=3},
		{name="default:fence_wood", prob=254, param2=0},
		{name="default:fence_wood", prob=254, param2=0},
		{name="default:fence_wood", prob=254, param2=0},
		{name="default:fence_wood", prob=254, param2=0},
		{name="default:fence_wood", prob=254, param2=0},
		{name="default:fence_wood", prob=254, param2=0},
		{name="default:fence_wood", prob=254, param2=0},
		{name="default:fence_wood", prob=254, param2=0},
		{name="default:tree", prob=254, param2=3},
		{name="air", prob=254, param2=0},

		-- z=1, y=1
		{name="air", prob=254, param2=0},
		{name="default:tree", prob=254, param2=3},
		{name="default:cobble", prob=254, param2=0},
		{name="default:cobble", prob=254, param2=0},
		{name="default:cobble", prob=254, param2=0},
		{name="default:cobble", prob=254, param2=0},
		{name="default:cobble", prob=254, param2=0},
		{name="default:cobble", prob=254, param2=0},
		{name="default:cobble", prob=254, param2=0},
		{name="default:cobble", prob=254, param2=0},
		{name="default:tree", prob=254, param2=3},
		{name="air", prob=254, param2=0},

		-- z=1, y=2
		{name="air", prob=254, param2=0},
		{name="default:tree", prob=254, param2=3},
		{name="default:wood", prob=254, param2=0},
		{name="default:wood", prob=254, param2=0},
		{name="default:wood", prob=254, param2=0},
		{name="default:wood", prob=254, param2=0},
		{name="default:wood", prob=254, param2=0},
		{name="default:wood", prob=254, param2=0},
		{name="default:wood", prob=254, param2=0},
		{name="default:wood", prob=254, param2=0},
		{name="default:tree", prob=254, param2=3},
		{name="air", prob=254, param2=0},

		-- z=1, y=3
		{name="air", prob=254, param2=0},
		{name="default:tree", prob=254, param2=3},
		{name="default:wood", prob=254, param2=0},
		{name="default:wood", prob=254, param2=0},
		{name="default:wood", prob=254, param2=0},
		{name="default:wood", prob=254, param2=0},
		{name="default:wood", prob=254, param2=0},
		{name="default:wood", prob=254, param2=0},
		{name="default:wood", prob=254, param2=0},
		{name="default:wood", prob=254, param2=0},
		{name="default:tree", prob=254, param2=3},
		{name="air", prob=254, param2=0},

		-- z=1, y=4
		{name="air", prob=254, param2=0},
		{name="default:tree", prob=254, param2=3},
		{name="default:wood", prob=254, param2=0},
		{name="default:wood", prob=254, param2=0},
		{name="default:wood", prob=254, param2=0},
		{name="default:wood", prob=254, param2=0},
		{name="default:wood", prob=254, param2=0},
		{name="default:wood", prob=254, param2=0},
		{name="default:wood", prob=254, param2=0},
		{name="default:wood", prob=254, param2=0},
		{name="default:tree", prob=254, param2=3},
		{name="air", prob=254, param2=0},

		-- z=1, y=5
		{name="air", prob=254, param2=0},
		{name="default:tree", prob=254, param2=3},
		{name="default:wood", prob=254, param2=0},
		{name="default:wood", prob=254, param2=0},
		{name="default:wood", prob=254, param2=0},
		{name="default:wood", prob=254, param2=0},
		{name="default:wood", prob=254, param2=0},
		{name="default:wood", prob=254, param2=0},
		{name="default:wood", prob=254, param2=0},
		{name="default:wood", prob=254, param2=0},
		{name="default:tree", prob=254, param2=3},
		{name="air", prob=254, param2=0},

		-- z=1, y=6
		{name="air", prob=254, param2=0},
		{name="default:tree", prob=254, param2=3},
		{name="default:wood", prob=254, param2=0},
		{name="default:wood", prob=254, param2=0},
		{name="default:wood", prob=254, param2=0},
		{name="default:wood", prob=254, param2=0},
		{name="default:wood", prob=254, param2=0},
		{name="default:wood", prob=254, param2=0},
		{name="default:wood", prob=254, param2=0},
		{name="default:wood", prob=254, param2=0},
		{name="default:tree", prob=254, param2=3},
		{name="air", prob=254, param2=0},

		-- z=1, y=7
		{name="stairs:stair_cobble", prob=254, param2=1},
		{name="default:tree", prob=254, param2=3},
		{name="default:wood", prob=254, param2=0},
		{name="default:wood", prob=254, param2=0},
		{name="default:wood", prob=254, param2=0},
		{name="default:wood", prob=254, param2=0},
		{name="default:wood", prob=254, param2=0},
		{name="default:wood", prob=254, param2=0},
		{name="default:wood", prob=254, param2=0},
		{name="default:wood", prob=254, param2=0},
		{name="default:tree", prob=254, param2=3},
		{name="stairs:stair_cobble", prob=254, param2=3},

		-- z=1, y=8
		{name="air", prob=254, param2=0},
		{name="stairs:slab_cobble", prob=254, param2=3},
		{name="stairs:slab_cobble", prob=254, param2=3},
		{name="stairs:slab_cobble", prob=254, param2=3},
		{name="stairs:slab_cobble", prob=254, param2=3},
		{name="stairs:slab_cobble", prob=254, param2=3},
		{name="stairs:slab_cobble", prob=254, param2=3},
		{name="stairs:slab_cobble", prob=254, param2=3},
		{name="stairs:slab_cobble", prob=254, param2=3},
		{name="stairs:slab_cobble", prob=254, param2=3},
		{name="stairs:slab_cobble", prob=254, param2=3},
		{name="air", prob=254, param2=0},

		-- z=2, y=0
		{name="air", prob=254, param2=0},
		{name="default:fence_wood", prob=254, param2=0},
		{name="default:wood", prob=254, param2=0},
		{name="default:wood", prob=254, param2=0},
		{name="default:wood", prob=254, param2=0},
		{name="default:wood", prob=254, param2=0},
		{name="default:wood", prob=254, param2=0},
		{name="default:wood", prob=254, param2=0},
		{name="default:wood", prob=254, param2=0},
		{name="default:wood", prob=254, param2=0},
		{name="default:fence_wood", prob=254, param2=0},
		{name="air", prob=254, param2=0},

		-- z=2, y=1
		{name="air", prob=254, param2=0},
		{name="default:cobble", prob=254, param2=0},
		{name="default:sign_wall", prob=254, param2=4},
		{name="air", prob=254, param2=0},
		{name="default:ladder", prob=254, param2=2},
		{name="default:bookshelf", prob=254, param2=0},
		{name="default:wood", prob=254, param2=0},
		{name="default:wood", prob=254, param2=0},
		{name="default:wood", prob=254, param2=0},
		{name="default:wood", prob=254, param2=0},
		{name="default:cobble", prob=254, param2=0},
		{name="air", prob=254, param2=0},

		-- z=2, y=2
		{name="air", prob=254, param2=0},
		{name="default:wood", prob=254, param2=0},
		{name="air", prob=254, param2=0},
		{name="air", prob=254, param2=0},
		{name="default:ladder", prob=254, param2=2},
		{name="default:bookshelf", prob=254, param2=0},
		{name="default:wood", prob=254, param2=0},
		{name="stairs:stair_cobble", prob=254, param2=3},
		{name="air", prob=254, param2=0},
		{name="air", prob=254, param2=0},
		{name="default:wood", prob=254, param2=0},
		{name="air", prob=254, param2=0},

		-- z=2, y=3
		{name="air", prob=254, param2=0},
		{name="default:wood", prob=254, param2=0},
		{name="default:torch_wall", prob=254, param2=5},
		{name="air", prob=254, param2=0},
		{name="air", prob=254, param2=0},
		{name="default:bookshelf", prob=254, param2=0},
		{name="stairs:stair_cobble", prob=254, param2=3},
		{name="air", prob=254, param2=0},
		{name="air", prob=254, param2=0},
		{name="air", prob=254, param2=0},
		{name="default:wood", prob=254, param2=0},
		{name="air", prob=254, param2=0},

		-- z=2, y=4
		{name="air", prob=254, param2=0},
		{name="default:wood", prob=254, param2=0},
		{name="default:wood", prob=254, param2=0},
		{name="default:wood", prob=254, param2=0},
		{name="default:wood", prob=254, param2=0},
		{name="stairs:stair_cobble", prob=254, param2=3},
		{name="air", prob=254, param2=0},
		{name="air", prob=254, param2=0},
		{name="air", prob=254, param2=0},
		{name="air", prob=254, param2=0},
		{name="default:wood", prob=254, param2=0},
		{name="stairs:stair_cobble", prob=254, param2=3},

		-- z=2, y=5
		{name="air", prob=254, param2=0},
		{name="default:wood", prob=254, param2=0},
		{name="default:cobble", prob=254, param2=0},
		{name="air", prob=254, param2=0},
		{name="air", prob=254, param2=0},
		{name="air", prob=254, param2=0},
		{name="air", prob=254, param2=0},
		{name="air", prob=254, param2=0},
		{name="air", prob=254, param2=0},
		{name="stairs:stair_cobble", prob=254, param2=3},
		{name="default:wood", prob=254, param2=0},
		{name="air", prob=254, param2=0},

		-- z=2, y=6
		{name="air", prob=254, param2=0},
		{name="default:wood", prob=254, param2=0},
		{name="default:junglegrass", prob=254, param2=0},
		{name="air", prob=254, param2=0},
		{name="air", prob=254, param2=0},
		{name="air", prob=254, param2=0},
		{name="air", prob=254, param2=0},
		{name="air", prob=254, param2=0},
		{name="air", prob=254, param2=0},
		{name="default:junglegrass", prob=254, param2=0},
		{name="default:wood", prob=254, param2=0},
		{name="air", prob=254, param2=0},

		-- z=2, y=7
		{name="stairs:stair_cobble", prob=254, param2=1},
		{name="default:wood", prob=254, param2=0},
		{name="air", prob=254, param2=0},
		{name="air", prob=254, param2=0},
		{name="air", prob=254, param2=0},
		{name="air", prob=254, param2=0},
		{name="air", prob=254, param2=0},
		{name="air", prob=254, param2=0},
		{name="air", prob=254, param2=0},
		{name="air", prob=254, param2=0},
		{name="default:wood", prob=254, param2=0},
		{name="stairs:stair_cobble", prob=254, param2=3},

		-- z=2, y=8
		{name="air", prob=254, param2=0},
		{name="stairs:slab_cobble", prob=254, param2=3},
		{name="stairs:slab_cobble", prob=254, param2=3},
		{name="stairs:slab_cobble", prob=254, param2=3},
		{name="stairs:slab_cobble", prob=254, param2=3},
		{name="stairs:slab_cobble", prob=254, param2=3},
		{name="stairs:slab_cobble", prob=254, param2=3},
		{name="stairs:slab_cobble", prob=254, param2=3},
		{name="stairs:slab_cobble", prob=254, param2=3},
		{name="stairs:slab_cobble", prob=254, param2=3},
		{name="stairs:slab_cobble", prob=254, param2=3},
		{name="air", prob=254, param2=0},

		-- z=3, y=0
		{name="air", prob=254, param2=0},
		{name="default:fence_wood", prob=254, param2=0},
		{name="default:wood", prob=254, param2=0},
		{name="default:wood", prob=254, param2=0},
		{name="default:wood", prob=254, param2=0},
		{name="default:wood", prob=254, param2=0},
		{name="default:wood", prob=254, param2=0},
		{name="default:wood", prob=254, param2=0},
		{name="default:wood", prob=254, param2=0},
		{name="default:wood", prob=254, param2=0},
		{name="default:fence_wood", prob=254, param2=0},
		{name="air", prob=254, param2=0},

		-- z=3, y=1
		{name="air", prob=254, param2=0},
		{name="default:cobble", prob=254, param2=0},
		{name="stairs:stair_wood", prob=254, param2=3},
		{name="air", prob=254, param2=0},
		{name="air", prob=254, param2=0},
		{name="default:bookshelf", prob=254, param2=0},
		{name="default:wood", prob=254, param2=0},
		{name="default:wood", prob=254, param2=0},
		{name="default:wood", prob=254, param2=0},
		{name="default:wood", prob=254, param2=0},
		{name="default:cobble", prob=254, param2=0},
		{name="air", prob=254, param2=0},

		-- z=3, y=2
		{name="air", prob=254, param2=0},
		{name="default:wood", prob=254, param2=0},
		{name="air", prob=254, param2=0},
		{name="air", prob=254, param2=0},
		{name="air", prob=254, param2=0},
		{name="default:bookshelf", prob=254, param2=0},
		{name="default:wood", prob=254, param2=0},
		{name="stairs:stair_cobble", prob=254, param2=3},
		{name="air", prob=254, param2=0},
		{name="air", prob=254, param2=0},
		{name="default:wood", prob=254, param2=0},
		{name="air", prob=254, param2=0},

		-- z=3, y=3
		{name="air", prob=254, param2=0},
		{name="default:wood", prob=254, param2=0},
		{name="air", prob=254, param2=0},
		{name="air", prob=254, param2=0},
		{name="air", prob=254, param2=0},
		{name="default:bookshelf", prob=254, param2=0},
		{name="stairs:stair_cobble", prob=254, param2=3},
		{name="air", prob=254, param2=0},
		{name="air", prob=254, param2=0},
		{name="air", prob=254, param2=0},
		{name="default:wood", prob=254, param2=0},
		{name="air", prob=254, param2=0},

		-- z=3, y=4
		{name="air", prob=254, param2=0},
		{name="default:wood", prob=254, param2=0},
		{name="default:wood", prob=254, param2=0},
		{name="default:wood", prob=254, param2=0},
		{name="default:wood", prob=254, param2=0},
		{name="stairs:stair_cobble", prob=254, param2=3},
		{name="air", prob=254, param2=0},
		{name="air", prob=254, param2=0},
		{name="air", prob=254, param2=0},
		{name="air", prob=254, param2=0},
		{name="default:wood", prob=254, param2=0},
		{name="stairs:stair_cobble", prob=254, param2=3},

		-- z=3, y=5
		{name="air", prob=254, param2=0},
		{name="default:wood", prob=254, param2=0},
		{name="air", prob=254, param2=0},
		{name="air", prob=254, param2=0},
		{name="air", prob=254, param2=0},
		{name="air", prob=254, param2=0},
		{name="air", prob=254, param2=0},
		{name="air", prob=254, param2=0},
		{name="air", prob=254, param2=0},
		{name="stairs:stair_cobble", prob=254, param2=3},
		{name="default:wood", prob=254, param2=0},
		{name="air", prob=254, param2=0},

		-- z=3, y=6
		{name="air", prob=254, param2=0},
		{name="default:wood", prob=254, param2=0},
		{name="air", prob=254, param2=0},
		{name="air", prob=254, param2=0},
		{name="air", prob=254, param2=0},
		{name="air", prob=254, param2=0},
		{name="air", prob=254, param2=0},
		{name="air", prob=254, param2=0},
		{name="air", prob=254, param2=0},
		{name="default:junglegrass", prob=254, param2=0},
		{name="default:wood", prob=254, param2=0},
		{name="air", prob=254, param2=0},

		-- z=3, y=7
		{name="stairs:stair_cobble", prob=254, param2=1},
		{name="default:wood", prob=254, param2=0},
		{name="air", prob=254, param2=0},
		{name="air", prob=254, param2=0},
		{name="air", prob=254, param2=0},
		{name="air", prob=254, param2=0},
		{name="air", prob=254, param2=0},
		{name="air", prob=254, param2=0},
		{name="air", prob=254, param2=0},
		{name="air", prob=254, param2=0},
		{name="default:wood", prob=254, param2=0},
		{name="stairs:stair_cobble", prob=254, param2=3},

		-- z=3, y=8
		{name="air", prob=254, param2=0},
		{name="stairs:slab_cobble", prob=254, param2=3},
		{name="stairs:slab_cobble", prob=254, param2=3},
		{name="stairs:slab_cobble", prob=254, param2=3},
		{name="stairs:slab_cobble", prob=254, param2=3},
		{name="stairs:slab_cobble", prob=254, param2=3},
		{name="stairs:slab_cobble", prob=254, param2=3},
		{name="stairs:slab_cobble", prob=254, param2=3},
		{name="stairs:slab_cobble", prob=254, param2=3},
		{name="stairs:slab_cobble", prob=254, param2=3},
		{name="stairs:slab_cobble", prob=254, param2=3},
		{name="air", prob=254, param2=0},

		-- z=4, y=0
		{name="air", prob=254, param2=0},
		{name="default:fence_wood", prob=254, param2=0},
		{name="default:wood", prob=254, param2=0},
		{name="default:wood", prob=254, param2=0},
		{name="default:wood", prob=254, param2=0},
		{name="default:wood", prob=254, param2=0},
		{name="default:wood", prob=254, param2=0},
		{name="default:wood", prob=254, param2=0},
		{name="default:wood", prob=254, param2=0},
		{name="default:wood", prob=254, param2=0},
		{name="default:fence_wood", prob=254, param2=0},
		{name="air", prob=254, param2=0},

		-- z=4, y=1
		{name="air", prob=254, param2=0},
		{name="default:cobble", prob=254, param2=0},
		{name="stairs:stair_wood", prob=254, param2=3},
		{name="air", prob=254, param2=0},
		{name="air", prob=254, param2=0},
		{name="default:tree", prob=254, param2=3},
		{name="default:tree", prob=254, param2=3},
		{name="default:tree", prob=254, param2=3},
		{name="stairs:stair_cobble", prob=254, param2=2},
		{name="stairs:stair_cobble", prob=254, param2=2},
		{name="default:cobble", prob=254, param2=0},
		{name="air", prob=254, param2=0},

		-- z=4, y=2
		{name="air", prob=254, param2=0},
		{name="default:wood", prob=254, param2=0},
		{name="air", prob=254, param2=0},
		{name="air", prob=254, param2=0},
		{name="air", prob=254, param2=0},
		{name="default:tree", prob=254, param2=3},
		{name="default:tree", prob=254, param2=3},
		{name="default:tree", prob=254, param2=3},
		{name="air", prob=254, param2=0},
		{name="air", prob=254, param2=0},
		{name="default:wood", prob=254, param2=0},
		{name="air", prob=254, param2=0},

		-- z=4, y=3
		{name="air", prob=254, param2=0},
		{name="default:wood", prob=254, param2=0},
		{name="air", prob=254, param2=0},
		{name="air", prob=254, param2=0},
		{name="air", prob=254, param2=0},
		{name="default:tree", prob=254, param2=3},
		{name="default:tree", prob=254, param2=3},
		{name="default:tree", prob=254, param2=3},
		{name="air", prob=254, param2=0},
		{name="air", prob=254, param2=0},
		{name="default:wood", prob=254, param2=0},
		{name="air", prob=254, param2=0},

		-- z=4, y=4
		{name="air", prob=254, param2=0},
		{name="default:wood", prob=254, param2=0},
		{name="default:wood", prob=254, param2=0},
		{name="default:wood", prob=254, param2=0},
		{name="default:wood", prob=254, param2=0},
		{name="default:tree", prob=254, param2=3},
		{name="default:tree", prob=254, param2=3},
		{name="default:tree", prob=254, param2=3},
		{name="default:tree", prob=254, param2=3},
		{name="default:tree", prob=254, param2=3},
		{name="default:wood", prob=254, param2=0},
		{name="stairs:stair_cobble", prob=254, param2=3},

		-- z=4, y=5
		{name="air", prob=254, param2=0},
		{name="default:wood", prob=254, param2=0},
		{name="air", prob=254, param2=0},
		{name="air", prob=254, param2=0},
		{name="air", prob=254, param2=0},
		{name="default:tree", prob=254, param2=3},
		{name="default:wood", prob=254, param2=0},
		{name="default:wood", prob=254, param2=0},
		{name="default:wood", prob=254, param2=0},
		{name="default:wood", prob=254, param2=0},
		{name="default:wood", prob=254, param2=0},
		{name="air", prob=254, param2=0},

		-- z=4, y=6
		{name="air", prob=254, param2=0},
		{name="default:wood", prob=254, param2=0},
		{name="air", prob=254, param2=0},
		{name="air", prob=254, param2=0},
		{name="default:torch_wall", prob=254, param2=2},
		{name="default:tree", prob=254, param2=3},
		{name="default:wood", prob=254, param2=0},
		{name="default:wood", prob=254, param2=0},
		{name="default:wood", prob=254, param2=0},
		{name="default:wood", prob=254, param2=0},
		{name="default:wood", prob=254, param2=0},
		{name="air", prob=254, param2=0},

		-- z=4, y=7
		{name="stairs:stair_cobble", prob=254, param2=1},
		{name="default:wood", prob=254, param2=0},
		{name="air", prob=254, param2=0},
		{name="air", prob=254, param2=0},
		{name="air", prob=254, param2=0},
		{name="default:tree", prob=254, param2=3},
		{name="default:wood", prob=254, param2=0},
		{name="default:wood", prob=254, param2=0},
		{name="default:wood", prob=254, param2=0},
		{name="default:wood", prob=254, param2=0},
		{name="default:wood", prob=254, param2=0},
		{name="stairs:stair_cobble", prob=254, param2=3},

		-- z=4, y=8
		{name="air", prob=254, param2=0},
		{name="stairs:slab_cobble", prob=254, param2=3},
		{name="stairs:slab_cobble", prob=254, param2=3},
		{name="stairs:slab_cobble", prob=254, param2=3},
		{name="stairs:slab_cobble", prob=254, param2=3},
		{name="stairs:slab_cobble", prob=254, param2=3},
		{name="stairs:slab_cobble", prob=254, param2=3},
		{name="stairs:slab_cobble", prob=254, param2=3},
		{name="stairs:slab_cobble", prob=254, param2=3},
		{name="stairs:slab_cobble", prob=254, param2=3},
		{name="stairs:slab_cobble", prob=254, param2=3},
		{name="air", prob=254, param2=0},

		-- z=5, y=0
		{name="air", prob=254, param2=0},
		{name="default:fence_wood", prob=254, param2=0},
		{name="default:wood", prob=254, param2=0},
		{name="default:wood", prob=254, param2=0},
		{name="default:wood", prob=254, param2=0},
		{name="default:wood", prob=254, param2=0},
		{name="default:wood", prob=254, param2=0},
		{name="default:wood", prob=254, param2=0},
		{name="default:wood", prob=254, param2=0},
		{name="default:wood", prob=254, param2=0},
		{name="default:fence_wood", prob=254, param2=0},
		{name="air", prob=254, param2=0},

		-- z=5, y=1
		{name="air", prob=254, param2=0},
		{name="default:cobble", prob=254, param2=0},
		{name="default:sign_wall", prob=254, param2=5},
		{name="air", prob=254, param2=0},
		{name="air", prob=254, param2=0},
		{name="air", prob=254, param2=0},
		{name="air", prob=254, param2=0},
		{name="air", prob=254, param2=0},
		{name="air", prob=254, param2=0},
		{name="air", prob=254, param2=0},
		{name="default:cobble", prob=254, param2=0},
		{name="air", prob=254, param2=0},

		-- z=5, y=2
		{name="air", prob=254, param2=0},
		{name="default:wood", prob=254, param2=0},
		{name="air", prob=254, param2=0},
		{name="air", prob=254, param2=0},
		{name="air", prob=254, param2=0},
		{name="air", prob=254, param2=0},
		{name="air", prob=254, param2=0},
		{name="air", prob=254, param2=0},
		{name="air", prob=254, param2=0},
		{name="air", prob=254, param2=0},
		{name="default:wood", prob=254, param2=0},
		{name="air", prob=254, param2=0},

		-- z=5, y=3
		{name="air", prob=254, param2=0},
		{name="default:wood", prob=254, param2=0},
		{name="air", prob=254, param2=0},
		{name="air", prob=254, param2=0},
		{name="air", prob=254, param2=0},
		{name="air", prob=254, param2=0},
		{name="air", prob=254, param2=0},
		{name="air", prob=254, param2=0},
		{name="air", prob=254, param2=0},
		{name="air", prob=254, param2=0},
		{name="default:wood", prob=254, param2=0},
		{name="air", prob=254, param2=0},

		-- z=5, y=4
		{name="air", prob=254, param2=0},
		{name="default:wood", prob=254, param2=0},
		{name="default:wood", prob=254, param2=0},
		{name="default:wood", prob=254, param2=0},
		{name="default:wood", prob=254, param2=0},
		{name="default:wood", prob=254, param2=0},
		{name="default:wood", prob=254, param2=0},
		{name="default:wood", prob=254, param2=0},
		{name="default:wood", prob=254, param2=0},
		{name="default:wood", prob=254, param2=0},
		{name="default:wood", prob=254, param2=0},
		{name="stairs:stair_cobble", prob=254, param2=3},

		-- z=5, y=5
		{name="air", prob=254, param2=0},
		{name="default:wood", prob=254, param2=0},
		{name="air", prob=254, param2=0},
		{name="air", prob=254, param2=0},
		{name="air", prob=254, param2=0},
		{name="default:cobble", prob=254, param2=0},
		{name="stairs:stair_cobble", prob=254, param2=3},
		{name="stairs:slab_sandstone", prob=254, param2=3},
		{name="stairs:slab_sandstone", prob=254, param2=3},
		{name="air", prob=254, param2=0},
		{name="default:wood", prob=254, param2=0},
		{name="air", prob=254, param2=0},

		-- z=5, y=6
		{name="air", prob=254, param2=0},
		{name="default:wood", prob=254, param2=0},
		{name="air", prob=254, param2=0},
		{name="air", prob=254, param2=0},
		{name="air", prob=254, param2=0},
		{name="default:wood", prob=254, param2=0},
		{name="air", prob=254, param2=0},
		{name="air", prob=254, param2=0},
		{name="air", prob=254, param2=0},
		{name="air", prob=254, param2=0},
		{name="default:wood", prob=254, param2=0},
		{name="air", prob=254, param2=0},

		-- z=5, y=7
		{name="stairs:stair_cobble", prob=254, param2=1},
		{name="default:wood", prob=254, param2=0},
		{name="air", prob=254, param2=0},
		{name="air", prob=254, param2=0},
		{name="air", prob=254, param2=0},
		{name="default:wood", prob=254, param2=0},
		{name="air", prob=254, param2=0},
		{name="air", prob=254, param2=0},
		{name="air", prob=254, param2=0},
		{name="air", prob=254, param2=0},
		{name="default:wood", prob=254, param2=0},
		{name="stairs:stair_cobble", prob=254, param2=3},

		-- z=5, y=8
		{name="air", prob=254, param2=0},
		{name="stairs:slab_cobble", prob=254, param2=3},
		{name="stairs:slab_cobble", prob=254, param2=3},
		{name="stairs:slab_cobble", prob=254, param2=3},
		{name="stairs:slab_cobble", prob=254, param2=3},
		{name="stairs:slab_cobble", prob=254, param2=3},
		{name="stairs:slab_cobble", prob=254, param2=3},
		{name="stairs:slab_cobble", prob=254, param2=3},
		{name="stairs:slab_cobble", prob=254, param2=3},
		{name="stairs:slab_cobble", prob=254, param2=3},
		{name="stairs:slab_cobble", prob=254, param2=3},
		{name="air", prob=254, param2=0},

		-- z=6, y=0
		{name="air", prob=254, param2=0},
		{name="default:fence_wood", prob=254, param2=0},
		{name="default:wood", prob=254, param2=0},
		{name="default:wood", prob=254, param2=0},
		{name="default:wood", prob=254, param2=0},
		{name="default:wood", prob=254, param2=0},
		{name="default:wood", prob=254, param2=0},
		{name="default:wood", prob=254, param2=0},
		{name="default:wood", prob=254, param2=0},
		{name="default:wood", prob=254, param2=0},
		{name="default:fence_wood", prob=254, param2=0},
		{name="air", prob=254, param2=0},

		-- z=6, y=1
		{name="air", prob=254, param2=0},
		{name="default:cobble", prob=254, param2=0},
		{name="air", prob=254, param2=0},
		{name="air", prob=254, param2=0},
		{name="air", prob=254, param2=0},
		{name="air", prob=254, param2=0},
		{name="default:sign_wall", prob=254, param2=4},
		{name="air", prob=254, param2=0},
		{name="air", prob=254, param2=0},
		{name="default:sign_wall", prob=254, param2=4},
		{name="default:cobble", prob=254, param2=0},
		{name="air", prob=254, param2=0},

		-- z=6, y=2
		{name="air", prob=254, param2=0},
		{name="default:wood", prob=254, param2=0},
		{name="air", prob=254, param2=0},
		{name="air", prob=254, param2=0},
		{name="air", prob=254, param2=0},
		{name="air", prob=254, param2=0},
		{name="air", prob=254, param2=0},
		{name="air", prob=254, param2=0},
		{name="air", prob=254, param2=0},
		{name="air", prob=254, param2=0},
		{name="default:wood", prob=254, param2=0},
		{name="air", prob=254, param2=0},

		-- z=6, y=3
		{name="air", prob=254, param2=0},
		{name="default:wood", prob=254, param2=0},
		{name="air", prob=254, param2=0},
		{name="air", prob=254, param2=0},
		{name="air", prob=254, param2=0},
		{name="air", prob=254, param2=0},
		{name="air", prob=254, param2=0},
		{name="air", prob=254, param2=0},
		{name="air", prob=254, param2=0},
		{name="air", prob=254, param2=0},
		{name="default:wood", prob=254, param2=0},
		{name="air", prob=254, param2=0},

		-- z=6, y=4
		{name="air", prob=254, param2=0},
		{name="default:wood", prob=254, param2=0},
		{name="default:wood", prob=254, param2=0},
		{name="default:wood", prob=254, param2=0},
		{name="default:wood", prob=254, param2=0},
		{name="default:wood", prob=254, param2=0},
		{name="default:wood", prob=254, param2=0},
		{name="default:wood", prob=254, param2=0},
		{name="default:wood", prob=254, param2=0},
		{name="default:wood", prob=254, param2=0},
		{name="default:wood", prob=254, param2=0},
		{name="stairs:stair_cobble", prob=254, param2=3},

		-- z=6, y=5
		{name="air", prob=254, param2=0},
		{name="default:wood", prob=254, param2=0},
		{name="air", prob=254, param2=0},
		{name="air", prob=254, param2=0},
		{name="air", prob=254, param2=0},
		{name="default:cobble", prob=254, param2=0},
		{name="stairs:stair_cobble", prob=254, param2=3},
		{name="stairs:slab_sandstone", prob=254, param2=3},
		{name="stairs:slab_sandstone", prob=254, param2=3},
		{name="air", prob=254, param2=0},
		{name="stairs:stair_wood", prob=254, param2=3},
		{name="air", prob=254, param2=0},

		-- z=6, y=6
		{name="air", prob=254, param2=0},
		{name="default:wood", prob=254, param2=0},
		{name="air", prob=254, param2=0},
		{name="air", prob=254, param2=0},
		{name="air", prob=254, param2=0},
		{name="default:wood", prob=254, param2=0},
		{name="air", prob=254, param2=0},
		{name="air", prob=254, param2=0},
		{name="air", prob=254, param2=0},
		{name="air", prob=254, param2=0},
		{name="default:glass", prob=254, param2=0},
		{name="air", prob=254, param2=0},

		-- z=6, y=7
		{name="stairs:stair_cobble", prob=254, param2=1},
		{name="default:wood", prob=254, param2=0},
		{name="air", prob=254, param2=0},
		{name="air", prob=254, param2=0},
		{name="air", prob=254, param2=0},
		{name="default:wood", prob=254, param2=0},
		{name="air", prob=254, param2=0},
		{name="air", prob=254, param2=0},
		{name="air", prob=254, param2=0},
		{name="air", prob=254, param2=0},
		{name="default:wood", prob=254, param2=0},
		{name="stairs:stair_cobble", prob=254, param2=3},

		-- z=6, y=8
		{name="air", prob=254, param2=0},
		{name="stairs:slab_cobble", prob=254, param2=3},
		{name="stairs:slab_cobble", prob=254, param2=3},
		{name="stairs:slab_cobble", prob=254, param2=3},
		{name="stairs:slab_cobble", prob=254, param2=3},
		{name="stairs:slab_cobble", prob=254, param2=3},
		{name="stairs:slab_cobble", prob=254, param2=3},
		{name="stairs:slab_cobble", prob=254, param2=3},
		{name="stairs:slab_cobble", prob=254, param2=3},
		{name="stairs:slab_cobble", prob=254, param2=3},
		{name="stairs:slab_cobble", prob=254, param2=3},
		{name="air", prob=254, param2=0},

		-- z=7, y=0
		{name="air", prob=254, param2=0},
		{name="default:fence_wood", prob=254, param2=0},
		{name="default:wood", prob=254, param2=0},
		{name="default:wood", prob=254, param2=0},
		{name="default:wood", prob=254, param2=0},
		{name="default:wood", prob=254, param2=0},
		{name="default:wood", prob=254, param2=0},
		{name="default:wood", prob=254, param2=0},
		{name="default:wood", prob=254, param2=0},
		{name="default:wood", prob=254, param2=0},
		{name="default:fence_wood", prob=254, param2=0},
		{name="air", prob=254, param2=0},

		-- z=7, y=1
		{name="air", prob=254, param2=0},
		{name="default:cobble", prob=254, param2=0},
		{name="default:bookshelf", prob=254, param2=0},
		{name="air", prob=254, param2=0},
		{name="air", prob=254, param2=0},
		{name="stairs:stair_cobble", prob=254, param2=20},
		{name="stairs:stair_wood", prob=254, param2=3},
		{name="air", prob=254, param2=0},
		{name="air", prob=254, param2=0},
		{name="stairs:stair_wood", prob=254, param2=1},
		{name="stairs:stair_cobble", prob=254, param2=3},
		{name="air", prob=254, param2=0},

		-- z=7, y=2
		{name="air", prob=254, param2=0},
		{name="default:wood", prob=254, param2=0},
		{name="default:torch_wall", prob=254, param2=1},
		{name="air", prob=254, param2=0},
		{name="air", prob=254, param2=0},
		{name="default:junglegrass", prob=254, param2=0},
		{name="air", prob=254, param2=0},
		{name="air", prob=254, param2=0},
		{name="air", prob=254, param2=0},
		{name="air", prob=254, param2=0},
		{name="default:glass", prob=254, param2=0},
		{name="air", prob=254, param2=0},

		-- z=7, y=3
		{name="air", prob=254, param2=0},
		{name="default:wood", prob=254, param2=0},
		{name="air", prob=254, param2=0},
		{name="air", prob=254, param2=0},
		{name="air", prob=254, param2=0},
		{name="air", prob=254, param2=0},
		{name="air", prob=254, param2=0},
		{name="air", prob=254, param2=0},
		{name="air", prob=254, param2=0},
		{name="air", prob=254, param2=0},
		{name="default:wood", prob=254, param2=0},
		{name="air", prob=254, param2=0},

		-- z=7, y=4
		{name="air", prob=254, param2=0},
		{name="default:wood", prob=254, param2=0},
		{name="default:wood", prob=254, param2=0},
		{name="default:wood", prob=254, param2=0},
		{name="default:wood", prob=254, param2=0},
		{name="default:wood", prob=254, param2=0},
		{name="default:wood", prob=254, param2=0},
		{name="default:wood", prob=254, param2=0},
		{name="default:wood", prob=254, param2=0},
		{name="default:wood", prob=254, param2=0},
		{name="default:wood", prob=254, param2=0},
		{name="stairs:stair_cobble", prob=254, param2=3},

		-- z=7, y=5
		{name="air", prob=254, param2=0},
		{name="default:wood", prob=254, param2=0},
		{name="air", prob=254, param2=0},
		{name="air", prob=254, param2=0},
		{name="air", prob=254, param2=0},
		{name="default:cobble", prob=254, param2=0},
		{name="air", prob=254, param2=0},
		{name="air", prob=254, param2=0},
		{name="air", prob=254, param2=0},
		{name="air", prob=254, param2=0},
		{name="stairs:stair_wood", prob=254, param2=3},
		{name="air", prob=254, param2=0},

		-- z=7, y=6
		{name="air", prob=254, param2=0},
		{name="default:wood", prob=254, param2=0},
		{name="air", prob=254, param2=0},
		{name="air", prob=254, param2=0},
		{name="air", prob=254, param2=0},
		{name="default:wood", prob=254, param2=0},
		{name="air", prob=254, param2=0},
		{name="air", prob=254, param2=0},
		{name="air", prob=254, param2=0},
		{name="air", prob=254, param2=0},
		{name="default:glass", prob=254, param2=0},
		{name="air", prob=254, param2=0},

		-- z=7, y=7
		{name="stairs:stair_cobble", prob=254, param2=1},
		{name="default:wood", prob=254, param2=0},
		{name="air", prob=254, param2=0},
		{name="air", prob=254, param2=0},
		{name="air", prob=254, param2=0},
		{name="default:wood", prob=254, param2=0},
		{name="air", prob=254, param2=0},
		{name="air", prob=254, param2=0},
		{name="air", prob=254, param2=0},
		{name="air", prob=254, param2=0},
		{name="default:wood", prob=254, param2=0},
		{name="stairs:stair_cobble", prob=254, param2=3},

		-- z=7, y=8
		{name="air", prob=254, param2=0},
		{name="stairs:slab_cobble", prob=254, param2=3},
		{name="stairs:slab_cobble", prob=254, param2=3},
		{name="stairs:slab_cobble", prob=254, param2=3},
		{name="stairs:slab_cobble", prob=254, param2=3},
		{name="stairs:slab_cobble", prob=254, param2=3},
		{name="stairs:slab_cobble", prob=254, param2=3},
		{name="stairs:slab_cobble", prob=254, param2=3},
		{name="stairs:slab_cobble", prob=254, param2=3},
		{name="stairs:slab_cobble", prob=254, param2=3},
		{name="stairs:slab_cobble", prob=254, param2=3},
		{name="air", prob=254, param2=0},

		-- z=8, y=0
		{name="air", prob=254, param2=0},
		{name="default:fence_wood", prob=254, param2=0},
		{name="default:wood", prob=254, param2=0},
		{name="default:wood", prob=254, param2=0},
		{name="default:wood", prob=254, param2=0},
		{name="default:wood", prob=254, param2=0},
		{name="default:wood", prob=254, param2=0},
		{name="default:wood", prob=254, param2=0},
		{name="default:wood", prob=254, param2=0},
		{name="default:wood", prob=254, param2=0},
		{name="default:fence_wood", prob=254, param2=0},
		{name="air", prob=254, param2=0},

		-- z=8, y=1
		{name="air", prob=254, param2=0},
		{name="default:cobble", prob=254, param2=0},
		{name="default:bookshelf", prob=254, param2=0},
		{name="air", prob=254, param2=0},
		{name="air", prob=254, param2=0},
		{name="stairs:slab_cobble", prob=254, param2=23},
		{name="stairs:stair_wood", prob=254, param2=3},
		{name="air", prob=254, param2=0},
		{name="air", prob=254, param2=0},
		{name="stairs:stair_wood", prob=254, param2=1},
		{name="stairs:stair_cobble", prob=254, param2=3},
		{name="air", prob=254, param2=0},

		-- z=8, y=2
		{name="air", prob=254, param2=0},
		{name="default:wood", prob=254, param2=0},
		{name="air", prob=254, param2=0},
		{name="air", prob=254, param2=0},
		{name="air", prob=254, param2=0},
		{name="default:junglegrass", prob=254, param2=0},
		{name="air", prob=254, param2=0},
		{name="air", prob=254, param2=0},
		{name="air", prob=254, param2=0},
		{name="air", prob=254, param2=0},
		{name="default:glass", prob=254, param2=0},
		{name="air", prob=254, param2=0},

		-- z=8, y=3
		{name="air", prob=254, param2=0},
		{name="default:wood", prob=254, param2=0},
		{name="air", prob=254, param2=0},
		{name="air", prob=254, param2=0},
		{name="air", prob=254, param2=0},
		{name="air", prob=254, param2=0},
		{name="air", prob=254, param2=0},
		{name="air", prob=254, param2=0},
		{name="air", prob=254, param2=0},
		{name="air", prob=254, param2=0},
		{name="default:wood", prob=254, param2=0},
		{name="air", prob=254, param2=0},

		-- z=8, y=4
		{name="air", prob=254, param2=0},
		{name="default:wood", prob=254, param2=0},
		{name="default:wood", prob=254, param2=0},
		{name="default:wood", prob=254, param2=0},
		{name="default:wood", prob=254, param2=0},
		{name="default:wood", prob=254, param2=0},
		{name="default:wood", prob=254, param2=0},
		{name="default:wood", prob=254, param2=0},
		{name="default:wood", prob=254, param2=0},
		{name="default:wood", prob=254, param2=0},
		{name="default:wood", prob=254, param2=0},
		{name="stairs:stair_cobble", prob=254, param2=3},

		-- z=8, y=5
		{name="air", prob=254, param2=0},
		{name="default:wood", prob=254, param2=0},
		{name="air", prob=254, param2=0},
		{name="air", prob=254, param2=0},
		{name="air", prob=254, param2=0},
		{name="doors:door_wood_a", prob=254, param2=1},
		{name="air", prob=254, param2=0},
		{name="air", prob=254, param2=0},
		{name="air", prob=254, param2=0},
		{name="air", prob=254, param2=0},
		{name="stairs:stair_wood", prob=254, param2=3},
		{name="air", prob=254, param2=0},

		-- z=8, y=6
		{name="air", prob=254, param2=0},
		{name="default:wood", prob=254, param2=0},
		{name="air", prob=254, param2=0},
		{name="air", prob=254, param2=0},
		{name="air", prob=254, param2=0},
		{name="air", prob=254, param2=1},
		{name="air", prob=254, param2=0},
		{name="air", prob=254, param2=0},
		{name="air", prob=254, param2=0},
		{name="air", prob=254, param2=0},
		{name="default:glass", prob=254, param2=0},
		{name="air", prob=254, param2=0},

		-- z=8, y=7
		{name="stairs:stair_cobble", prob=254, param2=1},
		{name="default:wood", prob=254, param2=0},
		{name="air", prob=254, param2=0},
		{name="air", prob=254, param2=0},
		{name="air", prob=254, param2=0},
		{name="default:wood", prob=254, param2=0},
		{name="air", prob=254, param2=0},
		{name="air", prob=254, param2=0},
		{name="air", prob=254, param2=0},
		{name="air", prob=254, param2=0},
		{name="default:wood", prob=254, param2=0},
		{name="stairs:stair_cobble", prob=254, param2=3},

		-- z=8, y=8
		{name="air", prob=254, param2=0},
		{name="stairs:slab_cobble", prob=254, param2=3},
		{name="stairs:slab_cobble", prob=254, param2=3},
		{name="stairs:slab_cobble", prob=254, param2=3},
		{name="stairs:slab_cobble", prob=254, param2=3},
		{name="stairs:slab_cobble", prob=254, param2=3},
		{name="stairs:slab_cobble", prob=254, param2=3},
		{name="stairs:slab_cobble", prob=254, param2=3},
		{name="stairs:slab_cobble", prob=254, param2=3},
		{name="stairs:slab_cobble", prob=254, param2=3},
		{name="stairs:slab_cobble", prob=254, param2=3},
		{name="air", prob=254, param2=0},

		-- z=9, y=0
		{name="air", prob=254, param2=0},
		{name="default:fence_wood", prob=254, param2=0},
		{name="default:wood", prob=254, param2=0},
		{name="default:wood", prob=254, param2=0},
		{name="default:wood", prob=254, param2=0},
		{name="default:wood", prob=254, param2=0},
		{name="default:wood", prob=254, param2=0},
		{name="default:wood", prob=254, param2=0},
		{name="default:wood", prob=254, param2=0},
		{name="default:wood", prob=254, param2=0},
		{name="default:fence_wood", prob=254, param2=0},
		{name="air", prob=254, param2=0},

		-- z=9, y=1
		{name="air", prob=254, param2=0},
		{name="default:cobble", prob=254, param2=0},
		{name="default:bookshelf", prob=254, param2=0},
		{name="air", prob=254, param2=0},
		{name="air", prob=254, param2=0},
		{name="stairs:stair_cobble", prob=254, param2=22},
		{name="stairs:stair_wood", prob=254, param2=3},
		{name="air", prob=254, param2=0},
		{name="air", prob=254, param2=0},
		{name="stairs:stair_wood", prob=254, param2=1},
		{name="stairs:stair_cobble", prob=254, param2=3},
		{name="air", prob=254, param2=0},

		-- z=9, y=2
		{name="air", prob=254, param2=0},
		{name="default:wood", prob=254, param2=0},
		{name="default:torch_wall", prob=254, param2=1},
		{name="air", prob=254, param2=0},
		{name="air", prob=254, param2=0},
		{name="default:junglegrass", prob=254, param2=0},
		{name="air", prob=254, param2=0},
		{name="air", prob=254, param2=0},
		{name="air", prob=254, param2=0},
		{name="air", prob=254, param2=0},
		{name="default:glass", prob=254, param2=0},
		{name="air", prob=254, param2=0},

		-- z=9, y=3
		{name="air", prob=254, param2=0},
		{name="default:wood", prob=254, param2=0},
		{name="air", prob=254, param2=0},
		{name="air", prob=254, param2=0},
		{name="air", prob=254, param2=0},
		{name="air", prob=254, param2=0},
		{name="air", prob=254, param2=0},
		{name="air", prob=254, param2=0},
		{name="air", prob=254, param2=0},
		{name="air", prob=254, param2=0},
		{name="default:wood", prob=254, param2=0},
		{name="air", prob=254, param2=0},

		-- z=9, y=4
		{name="air", prob=254, param2=0},
		{name="default:wood", prob=254, param2=0},
		{name="default:wood", prob=254, param2=0},
		{name="default:wood", prob=254, param2=0},
		{name="default:wood", prob=254, param2=0},
		{name="default:wood", prob=254, param2=0},
		{name="default:wood", prob=254, param2=0},
		{name="default:wood", prob=254, param2=0},
		{name="default:wood", prob=254, param2=0},
		{name="default:wood", prob=254, param2=0},
		{name="default:wood", prob=254, param2=0},
		{name="stairs:stair_cobble", prob=254, param2=3},

		-- z=9, y=5
		{name="air", prob=254, param2=0},
		{name="default:wood", prob=254, param2=0},
		{name="air", prob=254, param2=0},
		{name="air", prob=254, param2=0},
		{name="air", prob=254, param2=0},
		{name="default:cobble", prob=254, param2=0},
		{name="default:sign_wall", prob=254, param2=2},
		{name="stairs:stair_wood", prob=254, param2=0},
		{name="default:sign_wall", prob=254, param2=3},
		{name="default:bookshelf", prob=254, param2=0},
		{name="default:wood", prob=254, param2=0},
		{name="air", prob=254, param2=0},

		-- z=9, y=6
		{name="air", prob=254, param2=0},
		{name="default:wood", prob=254, param2=0},
		{name="air", prob=254, param2=0},
		{name="air", prob=254, param2=0},
		{name="air", prob=254, param2=0},
		{name="default:wood", prob=254, param2=0},
		{name="air", prob=254, param2=0},
		{name="air", prob=254, param2=0},
		{name="air", prob=254, param2=0},
		{name="default:torch_wall", prob=254, param2=1},
		{name="default:wood", prob=254, param2=0},
		{name="air", prob=254, param2=0},

		-- z=9, y=7
		{name="stairs:stair_cobble", prob=254, param2=1},
		{name="default:wood", prob=254, param2=0},
		{name="air", prob=254, param2=0},
		{name="air", prob=254, param2=0},
		{name="air", prob=254, param2=0},
		{name="default:wood", prob=254, param2=0},
		{name="air", prob=254, param2=0},
		{name="air", prob=254, param2=0},
		{name="air", prob=254, param2=0},
		{name="air", prob=254, param2=0},
		{name="default:wood", prob=254, param2=0},
		{name="stairs:stair_cobble", prob=254, param2=3},

		-- z=9, y=8
		{name="air", prob=254, param2=0},
		{name="stairs:slab_cobble", prob=254, param2=3},
		{name="stairs:slab_cobble", prob=254, param2=3},
		{name="stairs:slab_cobble", prob=254, param2=3},
		{name="stairs:slab_cobble", prob=254, param2=3},
		{name="stairs:slab_cobble", prob=254, param2=3},
		{name="stairs:slab_cobble", prob=254, param2=3},
		{name="stairs:slab_cobble", prob=254, param2=3},
		{name="stairs:slab_cobble", prob=254, param2=3},
		{name="stairs:slab_cobble", prob=254, param2=3},
		{name="stairs:slab_cobble", prob=254, param2=3},
		{name="air", prob=254, param2=0},

		-- z=10, y=0
		{name="air", prob=254, param2=0},
		{name="default:fence_wood", prob=254, param2=0},
		{name="default:wood", prob=254, param2=0},
		{name="default:wood", prob=254, param2=0},
		{name="default:wood", prob=254, param2=0},
		{name="default:wood", prob=254, param2=0},
		{name="default:wood", prob=254, param2=0},
		{name="default:wood", prob=254, param2=0},
		{name="default:wood", prob=254, param2=0},
		{name="default:wood", prob=254, param2=0},
		{name="default:fence_wood", prob=254, param2=0},
		{name="air", prob=254, param2=0},

		-- z=10, y=1
		{name="air", prob=254, param2=0},
		{name="default:cobble", prob=254, param2=0},
		{name="air", prob=254, param2=0},
		{name="air", prob=254, param2=0},
		{name="air", prob=254, param2=0},
		{name="air", prob=254, param2=0},
		{name="default:sign_wall", prob=254, param2=5},
		{name="air", prob=254, param2=0},
		{name="air", prob=254, param2=0},
		{name="default:sign_wall", prob=254, param2=5},
		{name="default:cobble", prob=254, param2=0},
		{name="air", prob=254, param2=0},

		-- z=10, y=2
		{name="air", prob=254, param2=0},
		{name="default:wood", prob=254, param2=0},
		{name="air", prob=254, param2=0},
		{name="air", prob=254, param2=0},
		{name="air", prob=254, param2=0},
		{name="air", prob=254, param2=0},
		{name="air", prob=254, param2=0},
		{name="air", prob=254, param2=0},
		{name="air", prob=254, param2=0},
		{name="default:torch_wall", prob=254, param2=4},
		{name="default:wood", prob=254, param2=0},
		{name="air", prob=254, param2=0},

		-- z=10, y=3
		{name="air", prob=254, param2=0},
		{name="default:wood", prob=254, param2=0},
		{name="air", prob=254, param2=0},
		{name="air", prob=254, param2=0},
		{name="air", prob=254, param2=0},
		{name="air", prob=254, param2=0},
		{name="air", prob=254, param2=0},
		{name="air", prob=254, param2=0},
		{name="air", prob=254, param2=0},
		{name="air", prob=254, param2=0},
		{name="default:wood", prob=254, param2=0},
		{name="air", prob=254, param2=0},

		-- z=10, y=4
		{name="air", prob=254, param2=0},
		{name="default:wood", prob=254, param2=0},
		{name="default:wood", prob=254, param2=0},
		{name="default:wood", prob=254, param2=0},
		{name="default:wood", prob=254, param2=0},
		{name="default:wood", prob=254, param2=0},
		{name="default:wood", prob=254, param2=0},
		{name="default:wood", prob=254, param2=0},
		{name="default:wood", prob=254, param2=0},
		{name="default:wood", prob=254, param2=0},
		{name="default:wood", prob=254, param2=0},
		{name="stairs:stair_cobble", prob=254, param2=3},

		-- z=10, y=5
		{name="air", prob=254, param2=0},
		{name="default:wood", prob=254, param2=0},
		{name="air", prob=254, param2=0},
		{name="air", prob=254, param2=0},
		{name="air", prob=254, param2=0},
		{name="default:tree", prob=254, param2=3},
		{name="default:cobble", prob=254, param2=0},
		{name="default:cobble", prob=254, param2=0},
		{name="default:cobble", prob=254, param2=0},
		{name="default:cobble", prob=254, param2=0},
		{name="default:wood", prob=254, param2=0},
		{name="air", prob=254, param2=0},

		-- z=10, y=6
		{name="air", prob=254, param2=0},
		{name="default:wood", prob=254, param2=0},
		{name="air", prob=254, param2=0},
		{name="air", prob=254, param2=0},
		{name="default:torch_wall", prob=254, param2=2},
		{name="default:tree", prob=254, param2=3},
		{name="default:wood", prob=254, param2=0},
		{name="default:wood", prob=254, param2=0},
		{name="default:wood", prob=254, param2=0},
		{name="default:wood", prob=254, param2=0},
		{name="default:wood", prob=254, param2=0},
		{name="air", prob=254, param2=0},

		-- z=10, y=7
		{name="stairs:stair_cobble", prob=254, param2=1},
		{name="default:wood", prob=254, param2=0},
		{name="air", prob=254, param2=0},
		{name="air", prob=254, param2=0},
		{name="air", prob=254, param2=0},
		{name="default:tree", prob=254, param2=3},
		{name="default:wood", prob=254, param2=0},
		{name="default:wood", prob=254, param2=0},
		{name="default:wood", prob=254, param2=0},
		{name="default:wood", prob=254, param2=0},
		{name="default:wood", prob=254, param2=0},
		{name="stairs:stair_cobble", prob=254, param2=3},

		-- z=10, y=8
		{name="air", prob=254, param2=0},
		{name="stairs:slab_cobble", prob=254, param2=3},
		{name="stairs:slab_cobble", prob=254, param2=3},
		{name="stairs:slab_cobble", prob=254, param2=3},
		{name="stairs:slab_cobble", prob=254, param2=3},
		{name="stairs:slab_cobble", prob=254, param2=3},
		{name="stairs:slab_cobble", prob=254, param2=3},
		{name="stairs:slab_cobble", prob=254, param2=3},
		{name="stairs:slab_cobble", prob=254, param2=3},
		{name="stairs:slab_cobble", prob=254, param2=3},
		{name="stairs:slab_cobble", prob=254, param2=3},
		{name="air", prob=254, param2=0},

		-- z=11, y=0
		{name="air", prob=254, param2=0},
		{name="default:fence_wood", prob=254, param2=0},
		{name="default:wood", prob=254, param2=0},
		{name="default:wood", prob=254, param2=0},
		{name="default:wood", prob=254, param2=0},
		{name="default:wood", prob=254, param2=0},
		{name="default:wood", prob=254, param2=0},
		{name="default:wood", prob=254, param2=0},
		{name="default:wood", prob=254, param2=0},
		{name="default:wood", prob=254, param2=0},
		{name="default:tree", prob=254, param2=3},
		{name="air", prob=254, param2=0},

		-- z=11, y=1
		{name="air", prob=254, param2=0},
		{name="default:cobble", prob=254, param2=0},
		{name="air", prob=254, param2=0},
		{name="air", prob=254, param2=0},
		{name="default:tree", prob=254, param2=3},
		{name="air", prob=254, param2=0},
		{name="air", prob=254, param2=0},
		{name="air", prob=254, param2=0},
		{name="default:cobble", prob=254, param2=0},
		{name="default:cobble", prob=254, param2=0},
		{name="default:tree", prob=254, param2=3},
		{name="air", prob=254, param2=0},

		-- z=11, y=2
		{name="air", prob=254, param2=0},
		{name="default:wood", prob=254, param2=0},
		{name="air", prob=254, param2=0},
		{name="air", prob=254, param2=0},
		{name="default:tree", prob=254, param2=3},
		{name="air", prob=254, param2=0},
		{name="air", prob=254, param2=0},
		{name="air", prob=254, param2=0},
		{name="default:cobble", prob=254, param2=0},
		{name="default:cobble", prob=254, param2=0},
		{name="default:tree", prob=254, param2=3},
		{name="default:torch_wall", prob=254, param2=3},

		-- z=11, y=3
		{name="air", prob=254, param2=0},
		{name="default:wood", prob=254, param2=0},
		{name="air", prob=254, param2=0},
		{name="air", prob=254, param2=0},
		{name="default:tree", prob=254, param2=3},
		{name="air", prob=254, param2=0},
		{name="air", prob=254, param2=0},
		{name="air", prob=254, param2=0},
		{name="default:cobble", prob=254, param2=0},
		{name="default:cobble", prob=254, param2=0},
		{name="default:tree", prob=254, param2=3},
		{name="air", prob=254, param2=0},

		-- z=11, y=4
		{name="air", prob=254, param2=0},
		{name="default:wood", prob=254, param2=0},
		{name="default:wood", prob=254, param2=0},
		{name="default:wood", prob=254, param2=0},
		{name="default:wood", prob=254, param2=0},
		{name="default:wood", prob=254, param2=0},
		{name="default:wood", prob=254, param2=0},
		{name="default:wood", prob=254, param2=0},
		{name="default:wood", prob=254, param2=0},
		{name="default:wood", prob=254, param2=0},
		{name="default:wood", prob=254, param2=0},
		{name="stairs:stair_cobble", prob=254, param2=3},

		-- z=11, y=5
		{name="air", prob=254, param2=0},
		{name="default:wood", prob=254, param2=0},
		{name="air", prob=254, param2=0},
		{name="air", prob=254, param2=0},
		{name="air", prob=254, param2=0},
		{name="default:cobble", prob=254, param2=0},
		{name="default:sign_wall", prob=254, param2=2},
		{name="stairs:stair_wood", prob=254, param2=2},
		{name="default:sign_wall", prob=254, param2=3},
		{name="default:bookshelf", prob=254, param2=0},
		{name="default:wood", prob=254, param2=0},
		{name="air", prob=254, param2=0},

		-- z=11, y=6
		{name="air", prob=254, param2=0},
		{name="default:wood", prob=254, param2=0},
		{name="air", prob=254, param2=0},
		{name="air", prob=254, param2=0},
		{name="air", prob=254, param2=0},
		{name="default:wood", prob=254, param2=0},
		{name="air", prob=254, param2=0},
		{name="air", prob=254, param2=0},
		{name="air", prob=254, param2=0},
		{name="default:torch_wall", prob=254, param2=1},
		{name="default:wood", prob=254, param2=0},
		{name="air", prob=254, param2=0},

		-- z=11, y=7
		{name="stairs:stair_cobble", prob=254, param2=1},
		{name="default:wood", prob=254, param2=0},
		{name="air", prob=254, param2=0},
		{name="air", prob=254, param2=0},
		{name="air", prob=254, param2=0},
		{name="default:wood", prob=254, param2=0},
		{name="air", prob=254, param2=0},
		{name="air", prob=254, param2=0},
		{name="air", prob=254, param2=0},
		{name="air", prob=254, param2=0},
		{name="default:wood", prob=254, param2=0},
		{name="stairs:stair_cobble", prob=254, param2=3},

		-- z=11, y=8
		{name="air", prob=254, param2=0},
		{name="stairs:slab_cobble", prob=254, param2=3},
		{name="stairs:slab_cobble", prob=254, param2=3},
		{name="stairs:slab_cobble", prob=254, param2=3},
		{name="stairs:slab_cobble", prob=254, param2=3},
		{name="stairs:slab_cobble", prob=254, param2=3},
		{name="stairs:slab_cobble", prob=254, param2=3},
		{name="stairs:slab_cobble", prob=254, param2=3},
		{name="stairs:slab_cobble", prob=254, param2=3},
		{name="stairs:slab_cobble", prob=254, param2=3},
		{name="stairs:slab_cobble", prob=254, param2=3},
		{name="air", prob=254, param2=0},

		-- z=12, y=0
		{name="air", prob=254, param2=0},
		{name="default:fence_wood", prob=254, param2=0},
		{name="default:wood", prob=254, param2=0},
		{name="default:wood", prob=254, param2=0},
		{name="default:wood", prob=254, param2=0},
		{name="default:wood", prob=254, param2=0},
		{name="default:wood", prob=254, param2=0},
		{name="default:wood", prob=254, param2=0},
		{name="default:tree", prob=254, param2=3},
		{name="default:wood", prob=254, param2=0},
		{name="stairs:stair_wood", prob=254, param2=3},
		{name="air", prob=254, param2=0},

		-- z=12, y=1
		{name="air", prob=254, param2=0},
		{name="default:cobble", prob=254, param2=0},
		{name="air", prob=254, param2=0},
		{name="air", prob=254, param2=0},
		{name="stairs:stair_cobble", prob=254, param2=20},
		{name="air", prob=254, param2=0},
		{name="air", prob=254, param2=0},
		{name="air", prob=254, param2=0},
		{name="default:tree", prob=254, param2=3},
		{name="air", prob=254, param2=0},
		{name="air", prob=254, param2=0},
		{name="air", prob=254, param2=0},

		-- z=12, y=2
		{name="air", prob=254, param2=0},
		{name="default:wood", prob=254, param2=0},
		{name="air", prob=254, param2=0},
		{name="air", prob=254, param2=0},
		{name="air", prob=254, param2=0},
		{name="air", prob=254, param2=0},
		{name="air", prob=254, param2=0},
		{name="air", prob=254, param2=0},
		{name="default:tree", prob=254, param2=3},
		{name="air", prob=254, param2=0},
		{name="air", prob=254, param2=0},
		{name="air", prob=254, param2=0},

		-- z=12, y=3
		{name="air", prob=254, param2=0},
		{name="default:wood", prob=254, param2=0},
		{name="air", prob=254, param2=0},
		{name="air", prob=254, param2=0},
		{name="default:fence_wood", prob=254, param2=0},
		{name="air", prob=254, param2=0},
		{name="air", prob=254, param2=0},
		{name="air", prob=254, param2=0},
		{name="default:tree", prob=254, param2=3},
		{name="default:torch_wall", prob=254, param2=3},
		{name="air", prob=254, param2=0},
		{name="air", prob=254, param2=0},

		-- z=12, y=4
		{name="air", prob=254, param2=0},
		{name="default:wood", prob=254, param2=0},
		{name="default:wood", prob=254, param2=0},
		{name="default:wood", prob=254, param2=0},
		{name="default:wood", prob=254, param2=0},
		{name="default:wood", prob=254, param2=0},
		{name="default:wood", prob=254, param2=0},
		{name="default:wood", prob=254, param2=0},
		{name="default:wood", prob=254, param2=0},
		{name="default:wood", prob=254, param2=0},
		{name="default:wood", prob=254, param2=0},
		{name="stairs:stair_cobble", prob=254, param2=3},

		-- z=12, y=5
		{name="air", prob=254, param2=0},
		{name="default:wood", prob=254, param2=0},
		{name="air", prob=254, param2=0},
		{name="air", prob=254, param2=0},
		{name="air", prob=254, param2=0},
		{name="doors:door_wood_a", prob=254, param2=1},
		{name="air", prob=254, param2=0},
		{name="air", prob=254, param2=0},
		{name="air", prob=254, param2=0},
		{name="air", prob=254, param2=0},
		{name="stairs:stair_wood", prob=254, param2=3},
		{name="air", prob=254, param2=0},

		-- z=12, y=6
		{name="air", prob=254, param2=0},
		{name="default:wood", prob=254, param2=0},
		{name="air", prob=254, param2=0},
		{name="air", prob=254, param2=0},
		{name="air", prob=254, param2=0},
		{name="air", prob=254, param2=1},
		{name="air", prob=254, param2=0},
		{name="air", prob=254, param2=0},
		{name="air", prob=254, param2=0},
		{name="air", prob=254, param2=0},
		{name="default:glass", prob=254, param2=0},
		{name="air", prob=254, param2=0},

		-- z=12, y=7
		{name="stairs:stair_cobble", prob=254, param2=1},
		{name="default:wood", prob=254, param2=0},
		{name="air", prob=254, param2=0},
		{name="air", prob=254, param2=0},
		{name="air", prob=254, param2=0},
		{name="default:wood", prob=254, param2=0},
		{name="air", prob=254, param2=0},
		{name="air", prob=254, param2=0},
		{name="air", prob=254, param2=0},
		{name="air", prob=254, param2=0},
		{name="default:wood", prob=254, param2=0},
		{name="stairs:stair_cobble", prob=254, param2=3},

		-- z=12, y=8
		{name="air", prob=254, param2=0},
		{name="stairs:slab_cobble", prob=254, param2=3},
		{name="stairs:slab_cobble", prob=254, param2=3},
		{name="stairs:slab_cobble", prob=254, param2=3},
		{name="stairs:slab_cobble", prob=254, param2=3},
		{name="stairs:slab_cobble", prob=254, param2=3},
		{name="stairs:slab_cobble", prob=254, param2=3},
		{name="stairs:slab_cobble", prob=254, param2=3},
		{name="stairs:slab_cobble", prob=254, param2=3},
		{name="stairs:slab_cobble", prob=254, param2=3},
		{name="stairs:slab_cobble", prob=254, param2=3},
		{name="air", prob=254, param2=0},

		-- z=13, y=0
		{name="air", prob=254, param2=0},
		{name="default:fence_wood", prob=254, param2=0},
		{name="default:wood", prob=254, param2=0},
		{name="default:wood", prob=254, param2=0},
		{name="default:wood", prob=254, param2=0},
		{name="default:wood", prob=254, param2=0},
		{name="default:wood", prob=254, param2=0},
		{name="default:wood", prob=254, param2=0},
		{name="default:wood", prob=254, param2=0},
		{name="default:wood", prob=254, param2=0},
		{name="stairs:stair_wood", prob=254, param2=3},
		{name="air", prob=254, param2=0},

		-- z=13, y=1
		{name="air", prob=254, param2=0},
		{name="default:cobble", prob=254, param2=0},
		{name="air", prob=254, param2=0},
		{name="air", prob=254, param2=0},
		{name="stairs:slab_cobble", prob=254, param2=23},
		{name="air", prob=254, param2=0},
		{name="air", prob=254, param2=0},
		{name="air", prob=254, param2=0},
		{name="doors:door_wood_a", prob=254, param2=1},
		{name="air", prob=254, param2=0},
		{name="air", prob=254, param2=0},
		{name="air", prob=254, param2=0},

		-- z=13, y=2
		{name="air", prob=254, param2=0},
		{name="default:wood", prob=254, param2=0},
		{name="air", prob=254, param2=0},
		{name="air", prob=254, param2=0},
		{name="air", prob=254, param2=0},
		{name="air", prob=254, param2=0},
		{name="air", prob=254, param2=0},
		{name="air", prob=254, param2=0},
		{name="air", prob=254, param2=1},
		{name="air", prob=254, param2=0},
		{name="air", prob=254, param2=0},
		{name="air", prob=254, param2=0},

		-- z=13, y=3
		{name="air", prob=254, param2=0},
		{name="default:wood", prob=254, param2=0},
		{name="air", prob=254, param2=0},
		{name="air", prob=254, param2=0},
		{name="default:fence_wood", prob=254, param2=0},
		{name="air", prob=254, param2=0},
		{name="air", prob=254, param2=0},
		{name="air", prob=254, param2=0},
		{name="default:cobble", prob=254, param2=0},
		{name="air", prob=254, param2=0},
		{name="air", prob=254, param2=0},
		{name="air", prob=254, param2=0},

		-- z=13, y=4
		{name="air", prob=254, param2=0},
		{name="default:wood", prob=254, param2=0},
		{name="default:wood", prob=254, param2=0},
		{name="default:wood", prob=254, param2=0},
		{name="default:wood", prob=254, param2=0},
		{name="default:wood", prob=254, param2=0},
		{name="default:wood", prob=254, param2=0},
		{name="default:wood", prob=254, param2=0},
		{name="default:wood", prob=254, param2=0},
		{name="default:wood", prob=254, param2=0},
		{name="default:wood", prob=254, param2=0},
		{name="stairs:stair_cobble", prob=254, param2=3},

		-- z=13, y=5
		{name="air", prob=254, param2=0},
		{name="default:wood", prob=254, param2=0},
		{name="air", prob=254, param2=0},
		{name="air", prob=254, param2=0},
		{name="air", prob=254, param2=0},
		{name="default:cobble", prob=254, param2=0},
		{name="air", prob=254, param2=0},
		{name="air", prob=254, param2=0},
		{name="air", prob=254, param2=0},
		{name="air", prob=254, param2=0},
		{name="stairs:stair_wood", prob=254, param2=3},
		{name="air", prob=254, param2=0},

		-- z=13, y=6
		{name="air", prob=254, param2=0},
		{name="default:wood", prob=254, param2=0},
		{name="air", prob=254, param2=0},
		{name="air", prob=254, param2=0},
		{name="air", prob=254, param2=0},
		{name="default:wood", prob=254, param2=0},
		{name="air", prob=254, param2=0},
		{name="air", prob=254, param2=0},
		{name="air", prob=254, param2=0},
		{name="air", prob=254, param2=0},
		{name="default:glass", prob=254, param2=0},
		{name="air", prob=254, param2=0},

		-- z=13, y=7
		{name="stairs:stair_cobble", prob=254, param2=1},
		{name="default:wood", prob=254, param2=0},
		{name="air", prob=254, param2=0},
		{name="air", prob=254, param2=0},
		{name="air", prob=254, param2=0},
		{name="default:wood", prob=254, param2=0},
		{name="air", prob=254, param2=0},
		{name="air", prob=254, param2=0},
		{name="air", prob=254, param2=0},
		{name="air", prob=254, param2=0},
		{name="default:wood", prob=254, param2=0},
		{name="stairs:stair_cobble", prob=254, param2=3},

		-- z=13, y=8
		{name="air", prob=254, param2=0},
		{name="stairs:slab_cobble", prob=254, param2=3},
		{name="stairs:slab_cobble", prob=254, param2=3},
		{name="stairs:slab_cobble", prob=254, param2=3},
		{name="stairs:slab_cobble", prob=254, param2=3},
		{name="stairs:slab_cobble", prob=254, param2=3},
		{name="stairs:slab_cobble", prob=254, param2=3},
		{name="stairs:slab_cobble", prob=254, param2=3},
		{name="stairs:slab_cobble", prob=254, param2=3},
		{name="stairs:slab_cobble", prob=254, param2=3},
		{name="stairs:slab_cobble", prob=254, param2=3},
		{name="air", prob=254, param2=0},

		-- z=14, y=0
		{name="air", prob=254, param2=0},
		{name="default:fence_wood", prob=254, param2=0},
		{name="default:wood", prob=254, param2=0},
		{name="default:wood", prob=254, param2=0},
		{name="default:wood", prob=254, param2=0},
		{name="default:wood", prob=254, param2=0},
		{name="default:wood", prob=254, param2=0},
		{name="default:wood", prob=254, param2=0},
		{name="default:tree", prob=254, param2=3},
		{name="default:wood", prob=254, param2=0},
		{name="stairs:stair_wood", prob=254, param2=3},
		{name="air", prob=254, param2=0},

		-- z=14, y=1
		{name="air", prob=254, param2=0},
		{name="default:cobble", prob=254, param2=0},
		{name="air", prob=254, param2=0},
		{name="air", prob=254, param2=0},
		{name="stairs:stair_cobble", prob=254, param2=22},
		{name="air", prob=254, param2=0},
		{name="air", prob=254, param2=0},
		{name="air", prob=254, param2=0},
		{name="default:tree", prob=254, param2=3},
		{name="air", prob=254, param2=0},
		{name="air", prob=254, param2=0},
		{name="air", prob=254, param2=0},

		-- z=14, y=2
		{name="air", prob=254, param2=0},
		{name="default:wood", prob=254, param2=0},
		{name="air", prob=254, param2=0},
		{name="air", prob=254, param2=0},
		{name="air", prob=254, param2=0},
		{name="air", prob=254, param2=0},
		{name="air", prob=254, param2=0},
		{name="air", prob=254, param2=0},
		{name="default:tree", prob=254, param2=3},
		{name="air", prob=254, param2=0},
		{name="air", prob=254, param2=0},
		{name="air", prob=254, param2=0},

		-- z=14, y=3
		{name="air", prob=254, param2=0},
		{name="default:wood", prob=254, param2=0},
		{name="air", prob=254, param2=0},
		{name="air", prob=254, param2=0},
		{name="default:fence_wood", prob=254, param2=0},
		{name="air", prob=254, param2=0},
		{name="air", prob=254, param2=0},
		{name="air", prob=254, param2=0},
		{name="default:tree", prob=254, param2=3},
		{name="default:torch_wall", prob=254, param2=3},
		{name="air", prob=254, param2=0},
		{name="air", prob=254, param2=0},

		-- z=14, y=4
		{name="air", prob=254, param2=0},
		{name="default:wood", prob=254, param2=0},
		{name="default:wood", prob=254, param2=0},
		{name="default:wood", prob=254, param2=0},
		{name="default:wood", prob=254, param2=0},
		{name="default:wood", prob=254, param2=0},
		{name="default:wood", prob=254, param2=0},
		{name="default:wood", prob=254, param2=0},
		{name="default:wood", prob=254, param2=0},
		{name="default:wood", prob=254, param2=0},
		{name="default:wood", prob=254, param2=0},
		{name="stairs:stair_cobble", prob=254, param2=3},

		-- z=14, y=5
		{name="air", prob=254, param2=0},
		{name="default:wood", prob=254, param2=0},
		{name="air", prob=254, param2=0},
		{name="air", prob=254, param2=0},
		{name="air", prob=254, param2=0},
		{name="default:cobble", prob=254, param2=0},
		{name="stairs:stair_cobble", prob=254, param2=3},
		{name="stairs:slab_sandstone", prob=254, param2=3},
		{name="stairs:slab_sandstone", prob=254, param2=3},
		{name="air", prob=254, param2=0},
		{name="stairs:stair_wood", prob=254, param2=3},
		{name="air", prob=254, param2=0},

		-- z=14, y=6
		{name="air", prob=254, param2=0},
		{name="default:wood", prob=254, param2=0},
		{name="air", prob=254, param2=0},
		{name="air", prob=254, param2=0},
		{name="air", prob=254, param2=0},
		{name="default:wood", prob=254, param2=0},
		{name="air", prob=254, param2=0},
		{name="air", prob=254, param2=0},
		{name="air", prob=254, param2=0},
		{name="air", prob=254, param2=0},
		{name="default:glass", prob=254, param2=0},
		{name="air", prob=254, param2=0},

		-- z=14, y=7
		{name="stairs:stair_cobble", prob=254, param2=1},
		{name="default:wood", prob=254, param2=0},
		{name="air", prob=254, param2=0},
		{name="air", prob=254, param2=0},
		{name="air", prob=254, param2=0},
		{name="default:wood", prob=254, param2=0},
		{name="stairs:slab_cobble", prob=254, param2=3},
		{name="stairs:slab_cobble", prob=254, param2=3},
		{name="stairs:slab_cobble", prob=254, param2=3},
		{name="air", prob=254, param2=0},
		{name="default:wood", prob=254, param2=0},
		{name="stairs:stair_cobble", prob=254, param2=3},

		-- z=14, y=8
		{name="air", prob=254, param2=0},
		{name="stairs:slab_cobble", prob=254, param2=3},
		{name="stairs:slab_cobble", prob=254, param2=3},
		{name="stairs:slab_cobble", prob=254, param2=3},
		{name="stairs:slab_cobble", prob=254, param2=3},
		{name="stairs:slab_cobble", prob=254, param2=3},
		{name="stairs:slab_cobble", prob=254, param2=3},
		{name="stairs:slab_cobble", prob=254, param2=3},
		{name="stairs:slab_cobble", prob=254, param2=3},
		{name="stairs:slab_cobble", prob=254, param2=3},
		{name="stairs:slab_cobble", prob=254, param2=3},
		{name="air", prob=254, param2=0},

		-- z=15, y=0
		{name="air", prob=254, param2=0},
		{name="default:fence_wood", prob=254, param2=0},
		{name="default:wood", prob=254, param2=0},
		{name="default:wood", prob=254, param2=0},
		{name="default:wood", prob=254, param2=0},
		{name="default:wood", prob=254, param2=0},
		{name="default:wood", prob=254, param2=0},
		{name="default:wood", prob=254, param2=0},
		{name="default:wood", prob=254, param2=0},
		{name="default:wood", prob=254, param2=0},
		{name="stairs:stair_wood", prob=254, param2=3},
		{name="air", prob=254, param2=0},

		-- z=15, y=1
		{name="air", prob=254, param2=0},
		{name="default:cobble", prob=254, param2=0},
		{name="default:bookshelf", prob=254, param2=0},
		{name="default:bookshelf", prob=254, param2=0},
		{name="default:tree", prob=254, param2=3},
		{name="stairs:stair_cobble", prob=254, param2=0},
		{name="stairs:stair_cobble", prob=254, param2=0},
		{name="stairs:stair_cobble", prob=254, param2=0},
		{name="default:cobble", prob=254, param2=0},
		{name="air", prob=254, param2=0},
		{name="air", prob=254, param2=0},
		{name="air", prob=254, param2=0},

		-- z=15, y=2
		{name="air", prob=254, param2=0},
		{name="default:wood", prob=254, param2=0},
		{name="air", prob=254, param2=0},
		{name="air", prob=254, param2=0},
		{name="default:tree", prob=254, param2=3},
		{name="air", prob=254, param2=0},
		{name="air", prob=254, param2=0},
		{name="air", prob=254, param2=0},
		{name="default:wood", prob=254, param2=0},
		{name="default:sign_wall", prob=254, param2=3},
		{name="air", prob=254, param2=0},
		{name="air", prob=254, param2=0},

		-- z=15, y=3
		{name="air", prob=254, param2=0},
		{name="default:wood", prob=254, param2=0},
		{name="air", prob=254, param2=0},
		{name="default:torch_wall", prob=254, param2=2},
		{name="default:tree", prob=254, param2=3},
		{name="air", prob=254, param2=0},
		{name="air", prob=254, param2=0},
		{name="air", prob=254, param2=0},
		{name="default:cobble", prob=254, param2=0},
		{name="air", prob=254, param2=0},
		{name="air", prob=254, param2=0},
		{name="air", prob=254, param2=0},

		-- z=15, y=4
		{name="air", prob=254, param2=0},
		{name="default:wood", prob=254, param2=0},
		{name="default:wood", prob=254, param2=0},
		{name="default:wood", prob=254, param2=0},
		{name="default:wood", prob=254, param2=0},
		{name="default:wood", prob=254, param2=0},
		{name="default:wood", prob=254, param2=0},
		{name="default:wood", prob=254, param2=0},
		{name="default:wood", prob=254, param2=0},
		{name="default:wood", prob=254, param2=0},
		{name="default:wood", prob=254, param2=0},
		{name="stairs:stair_cobble", prob=254, param2=3},

		-- z=15, y=5
		{name="air", prob=254, param2=0},
		{name="default:wood", prob=254, param2=0},
		{name="air", prob=254, param2=0},
		{name="default:cobble", prob=254, param2=0},
		{name="air", prob=254, param2=0},
		{name="default:cobble", prob=254, param2=0},
		{name="stairs:stair_cobble", prob=254, param2=3},
		{name="stairs:slab_sandstone", prob=254, param2=3},
		{name="stairs:slab_sandstone", prob=254, param2=3},
		{name="air", prob=254, param2=0},
		{name="default:wood", prob=254, param2=0},
		{name="air", prob=254, param2=0},

		-- z=15, y=6
		{name="air", prob=254, param2=0},
		{name="default:wood", prob=254, param2=0},
		{name="air", prob=254, param2=0},
		{name="default:junglegrass", prob=254, param2=0},
		{name="air", prob=254, param2=0},
		{name="default:wood", prob=254, param2=0},
		{name="air", prob=254, param2=0},
		{name="air", prob=254, param2=0},
		{name="air", prob=254, param2=0},
		{name="air", prob=254, param2=0},
		{name="default:wood", prob=254, param2=0},
		{name="air", prob=254, param2=0},

		-- z=15, y=7
		{name="stairs:stair_cobble", prob=254, param2=1},
		{name="default:wood", prob=254, param2=0},
		{name="default:torch_wall", prob=254, param2=3},
		{name="air", prob=254, param2=0},
		{name="default:torch_wall", prob=254, param2=2},
		{name="default:wood", prob=254, param2=0},
		{name="stairs:slab_cobble", prob=254, param2=3},
		{name="stairs:slab_cobble", prob=254, param2=3},
		{name="stairs:slab_cobble", prob=254, param2=3},
		{name="air", prob=254, param2=0},
		{name="default:wood", prob=254, param2=0},
		{name="stairs:stair_cobble", prob=254, param2=3},

		-- z=15, y=8
		{name="air", prob=254, param2=0},
		{name="stairs:slab_cobble", prob=254, param2=3},
		{name="stairs:slab_cobble", prob=254, param2=3},
		{name="stairs:slab_cobble", prob=254, param2=3},
		{name="stairs:slab_cobble", prob=254, param2=3},
		{name="stairs:slab_cobble", prob=254, param2=3},
		{name="stairs:slab_cobble", prob=254, param2=3},
		{name="stairs:slab_cobble", prob=254, param2=3},
		{name="stairs:slab_cobble", prob=254, param2=3},
		{name="stairs:slab_cobble", prob=254, param2=3},
		{name="stairs:slab_cobble", prob=254, param2=3},
		{name="air", prob=254, param2=0},

		-- z=16, y=0
		{name="air", prob=254, param2=0},
		{name="default:tree", prob=254, param2=3},
		{name="default:fence_wood", prob=254, param2=0},
		{name="default:fence_wood", prob=254, param2=0},
		{name="default:fence_wood", prob=254, param2=0},
		{name="default:fence_wood", prob=254, param2=0},
		{name="default:fence_wood", prob=254, param2=0},
		{name="default:fence_wood", prob=254, param2=0},
		{name="default:tree", prob=254, param2=3},
		{name="default:wood", prob=254, param2=0},
		{name="default:tree", prob=254, param2=3},
		{name="air", prob=254, param2=0},

		-- z=16, y=1
		{name="air", prob=254, param2=0},
		{name="default:tree", prob=254, param2=3},
		{name="default:cobble", prob=254, param2=0},
		{name="default:cobble", prob=254, param2=0},
		{name="default:cobble", prob=254, param2=0},
		{name="stairs:stair_cobble", prob=254, param2=2},
		{name="stairs:stair_cobble", prob=254, param2=2},
		{name="stairs:stair_cobble", prob=254, param2=2},
		{name="default:tree", prob=254, param2=3},
		{name="default:fence_wood", prob=254, param2=0},
		{name="default:tree", prob=254, param2=3},
		{name="air", prob=254, param2=0},

		-- z=16, y=2
		{name="air", prob=254, param2=0},
		{name="default:tree", prob=254, param2=3},
		{name="default:wood", prob=254, param2=0},
		{name="default:wood", prob=254, param2=0},
		{name="default:wood", prob=254, param2=0},
		{name="default:glass", prob=254, param2=0},
		{name="default:glass", prob=254, param2=0},
		{name="default:glass", prob=254, param2=0},
		{name="default:tree", prob=254, param2=3},
		{name="default:fence_wood", prob=254, param2=0},
		{name="default:tree", prob=254, param2=3},
		{name="default:torch_wall", prob=254, param2=3},

		-- z=16, y=3
		{name="air", prob=254, param2=0},
		{name="default:tree", prob=254, param2=3},
		{name="default:wood", prob=254, param2=0},
		{name="default:wood", prob=254, param2=0},
		{name="default:wood", prob=254, param2=0},
		{name="default:wood", prob=254, param2=0},
		{name="default:wood", prob=254, param2=0},
		{name="default:wood", prob=254, param2=0},
		{name="default:tree", prob=254, param2=3},
		{name="default:cobble", prob=254, param2=0},
		{name="default:tree", prob=254, param2=3},
		{name="air", prob=254, param2=0},

		-- z=16, y=4
		{name="air", prob=254, param2=0},
		{name="default:tree", prob=254, param2=3},
		{name="default:wood", prob=254, param2=0},
		{name="default:wood", prob=254, param2=0},
		{name="default:wood", prob=254, param2=0},
		{name="default:wood", prob=254, param2=0},
		{name="default:wood", prob=254, param2=0},
		{name="default:wood", prob=254, param2=0},
		{name="default:wood", prob=254, param2=0},
		{name="default:wood", prob=254, param2=0},
		{name="default:tree", prob=254, param2=3},
		{name="air", prob=254, param2=0},

		-- z=16, y=5
		{name="air", prob=254, param2=0},
		{name="default:tree", prob=254, param2=3},
		{name="default:wood", prob=254, param2=0},
		{name="default:wood", prob=254, param2=0},
		{name="default:wood", prob=254, param2=0},
		{name="default:wood", prob=254, param2=0},
		{name="default:wood", prob=254, param2=0},
		{name="default:wood", prob=254, param2=0},
		{name="default:wood", prob=254, param2=0},
		{name="default:wood", prob=254, param2=0},
		{name="default:tree", prob=254, param2=3},
		{name="air", prob=254, param2=0},

		-- z=16, y=6
		{name="air", prob=254, param2=0},
		{name="default:tree", prob=254, param2=3},
		{name="default:wood", prob=254, param2=0},
		{name="default:wood", prob=254, param2=0},
		{name="default:wood", prob=254, param2=0},
		{name="default:wood", prob=254, param2=0},
		{name="default:wood", prob=254, param2=0},
		{name="default:wood", prob=254, param2=0},
		{name="default:wood", prob=254, param2=0},
		{name="default:wood", prob=254, param2=0},
		{name="default:tree", prob=254, param2=3},
		{name="air", prob=254, param2=0},

		-- z=16, y=7
		{name="stairs:stair_cobble", prob=254, param2=1},
		{name="default:tree", prob=254, param2=3},
		{name="default:wood", prob=254, param2=0},
		{name="default:wood", prob=254, param2=0},
		{name="default:wood", prob=254, param2=0},
		{name="default:wood", prob=254, param2=0},
		{name="default:wood", prob=254, param2=0},
		{name="default:wood", prob=254, param2=0},
		{name="default:wood", prob=254, param2=0},
		{name="default:wood", prob=254, param2=0},
		{name="default:tree", prob=254, param2=3},
		{name="stairs:stair_cobble", prob=254, param2=3},

		-- z=16, y=8
		{name="air", prob=254, param2=0},
		{name="stairs:slab_cobble", prob=254, param2=3},
		{name="stairs:slab_cobble", prob=254, param2=3},
		{name="stairs:slab_cobble", prob=254, param2=3},
		{name="stairs:slab_cobble", prob=254, param2=3},
		{name="stairs:slab_cobble", prob=254, param2=3},
		{name="stairs:slab_cobble", prob=254, param2=3},
		{name="stairs:slab_cobble", prob=254, param2=3},
		{name="stairs:slab_cobble", prob=254, param2=3},
		{name="stairs:slab_cobble", prob=254, param2=3},
		{name="stairs:slab_cobble", prob=254, param2=3},
		{name="air", prob=254, param2=0},

		-- z=17, y=0
		{name="air", prob=254, param2=0},
		{name="air", prob=254, param2=0},
		{name="air", prob=254, param2=0},
		{name="air", prob=254, param2=0},
		{name="air", prob=254, param2=0},
		{name="air", prob=254, param2=0},
		{name="air", prob=254, param2=0},
		{name="air", prob=254, param2=0},
		{name="air", prob=254, param2=0},
		{name="air", prob=254, param2=0},
		{name="air", prob=254, param2=0},
		{name="air", prob=254, param2=0},

		-- z=17, y=1
		{name="air", prob=254, param2=0},
		{name="air", prob=254, param2=0},
		{name="air", prob=254, param2=0},
		{name="air", prob=254, param2=0},
		{name="air", prob=254, param2=0},
		{name="air", prob=254, param2=0},
		{name="air", prob=254, param2=0},
		{name="air", prob=254, param2=0},
		{name="air", prob=254, param2=0},
		{name="air", prob=254, param2=0},
		{name="air", prob=254, param2=0},
		{name="air", prob=254, param2=0},

		-- z=17, y=2
		{name="air", prob=254, param2=0},
		{name="air", prob=254, param2=0},
		{name="air", prob=254, param2=0},
		{name="air", prob=254, param2=0},
		{name="air", prob=254, param2=0},
		{name="air", prob=254, param2=0},
		{name="air", prob=254, param2=0},
		{name="air", prob=254, param2=0},
		{name="air", prob=254, param2=0},
		{name="air", prob=254, param2=0},
		{name="air", prob=254, param2=0},
		{name="air", prob=254, param2=0},

		-- z=17, y=3
		{name="air", prob=254, param2=0},
		{name="air", prob=254, param2=0},
		{name="air", prob=254, param2=0},
		{name="air", prob=254, param2=0},
		{name="air", prob=254, param2=0},
		{name="air", prob=254, param2=0},
		{name="air", prob=254, param2=0},
		{name="air", prob=254, param2=0},
		{name="air", prob=254, param2=0},
		{name="air", prob=254, param2=0},
		{name="air", prob=254, param2=0},
		{name="air", prob=254, param2=0},

		-- z=17, y=4
		{name="air", prob=254, param2=0},
		{name="air", prob=254, param2=0},
		{name="air", prob=254, param2=0},
		{name="air", prob=254, param2=0},
		{name="air", prob=254, param2=0},
		{name="air", prob=254, param2=0},
		{name="air", prob=254, param2=0},
		{name="air", prob=254, param2=0},
		{name="air", prob=254, param2=0},
		{name="air", prob=254, param2=0},
		{name="air", prob=254, param2=0},
		{name="air", prob=254, param2=0},

		-- z=17, y=5
		{name="air", prob=254, param2=0},
		{name="air", prob=254, param2=0},
		{name="air", prob=254, param2=0},
		{name="air", prob=254, param2=0},
		{name="air", prob=254, param2=0},
		{name="air", prob=254, param2=0},
		{name="air", prob=254, param2=0},
		{name="air", prob=254, param2=0},
		{name="air", prob=254, param2=0},
		{name="air", prob=254, param2=0},
		{name="air", prob=254, param2=0},
		{name="air", prob=254, param2=0},

		-- z=17, y=6
		{name="air", prob=254, param2=0},
		{name="air", prob=254, param2=0},
		{name="air", prob=254, param2=0},
		{name="air", prob=254, param2=0},
		{name="air", prob=254, param2=0},
		{name="air", prob=254, param2=0},
		{name="air", prob=254, param2=0},
		{name="air", prob=254, param2=0},
		{name="air", prob=254, param2=0},
		{name="air", prob=254, param2=0},
		{name="air", prob=254, param2=0},
		{name="air", prob=254, param2=0},

		-- z=17, y=7
		{name="stairs:stair_cobble", prob=254, param2=1},
		{name="air", prob=254, param2=0},
		{name="air", prob=254, param2=0},
		{name="air", prob=254, param2=0},
		{name="air", prob=254, param2=0},
		{name="air", prob=254, param2=0},
		{name="air", prob=254, param2=0},
		{name="air", prob=254, param2=0},
		{name="air", prob=254, param2=0},
		{name="air", prob=254, param2=0},
		{name="air", prob=254, param2=0},
		{name="stairs:stair_cobble", prob=254, param2=3},

		-- z=17, y=8
		{name="air", prob=254, param2=0},
		{name="stairs:slab_cobble", prob=254, param2=3},
		{name="stairs:slab_cobble", prob=254, param2=3},
		{name="stairs:slab_cobble", prob=254, param2=3},
		{name="stairs:slab_cobble", prob=254, param2=3},
		{name="stairs:slab_cobble", prob=254, param2=3},
		{name="stairs:slab_cobble", prob=254, param2=3},
		{name="stairs:slab_cobble", prob=254, param2=3},
		{name="stairs:slab_cobble", prob=254, param2=3},
		{name="stairs:slab_cobble", prob=254, param2=3},
		{name="stairs:slab_cobble", prob=254, param2=3},
		{name="air", prob=254, param2=0},
	},
}

return schematic