schematic = {
	size = {x=7, y=2, z=3},
	yslice_prob = {
		{ypos=0, prob=254},
		{ypos=1, prob=254},
	},
	data = {

		-- z=0, y=0
		{name="default:dirt_with_grass", prob=254, param2=0},
		{name="default:dirt", prob=254, param2=0},
		{name="default:dirt_with_grass", prob=254, param2=0},
		{name="default:dirt_with_grass", prob=254, param2=0},
		{name="default:dirt_with_grass", prob=254, param2=0},
		{name="default:dirt_with_grass", prob=254, param2=0},
		{name="default:dirt_with_grass", prob=254, param2=0},

		-- z=0, y=1
		{name="air", prob=254, param2=0},
		{name="air", prob=254, param2=0},
		{name="air", prob=254, param2=0},
		{name="air", prob=254, param2=0},
		{name="air", prob=254, param2=0},
		{name="air", prob=254, param2=0},
		{name="air", prob=254, param2=0},

		-- z=1, y=0
		{name="default:dirt_with_grass", prob=254, param2=0},
		{name="default:dirt", prob=254, param2=0},
		{name="default:dirt_with_grass", prob=254, param2=0},
		{name="default:dirt_with_grass", prob=254, param2=0},
		{name="default:dirt", prob=254, param2=0},
		{name="default:dirt_with_grass", prob=254, param2=0},
		{name="default:dirt_with_grass", prob=254, param2=0},

		-- z=1, y=1
		{name="air", prob=254, param2=0},
		{name="default:cobble", prob=254, param2=0},
		{name="stairs:stair_wood", prob=254, param2=0},
		{name="stairs:stair_wood", prob=254, param2=0},
		{name="default:cobble", prob=254, param2=0},
		{name="default:sapling", prob=254, param2=0},
		{name="air", prob=254, param2=0},

		-- z=2, y=0
		{name="default:dirt_with_grass", prob=254, param2=0},
		{name="default:dirt_with_grass", prob=254, param2=0},
		{name="default:dirt_with_grass", prob=254, param2=0},
		{name="default:dirt_with_grass", prob=254, param2=0},
		{name="default:dirt_with_grass", prob=254, param2=0},
		{name="default:dirt_with_grass", prob=254, param2=0},
		{name="default:dirt_with_grass", prob=254, param2=0},

		-- z=2, y=1
		{name="air", prob=254, param2=0},
		{name="air", prob=254, param2=0},
		{name="air", prob=254, param2=0},
		{name="air", prob=254, param2=0},
		{name="air", prob=254, param2=0},
		{name="air", prob=254, param2=0},
		{name="air", prob=254, param2=0},
	},
}

return schematic