schematic = {
	size = {x=6, y=3, z=6},
	yslice_prob = {
		{ypos=0, prob=254},
		{ypos=1, prob=254},
		{ypos=2, prob=254},
	},
	data = {

		-- z=0, y=0
		{name="default:sand", prob=254, param2=0},
		{name="default:sand", prob=254, param2=0},
		{name="default:sand", prob=254, param2=0},
		{name="default:sand", prob=254, param2=0},
		{name="default:sand", prob=254, param2=0},
		{name="default:sand", prob=254, param2=0},

		-- z=0, y=1
		{name="default:sand", prob=254, param2=0},
		{name="default:sand", prob=254, param2=0},
		{name="default:sand", prob=254, param2=0},
		{name="default:sand", prob=254, param2=0},
		{name="default:sand", prob=254, param2=0},
		{name="default:sand", prob=254, param2=0},

		-- z=0, y=2
		{name="air", prob=254, param2=0},
		{name="air", prob=254, param2=0},
		{name="air", prob=254, param2=0},
		{name="air", prob=254, param2=0},
		{name="air", prob=254, param2=0},
		{name="air", prob=254, param2=0},

		-- z=1, y=0
		{name="default:sand", prob=254, param2=0},
		{name="default:sand", prob=254, param2=0},
		{name="default:sand", prob=254, param2=0},
		{name="default:sand", prob=254, param2=0},
		{name="default:sand", prob=254, param2=0},
		{name="default:sand", prob=254, param2=0},

		-- z=1, y=1
		{name="default:sand", prob=254, param2=0},
		{name="default:sand", prob=254, param2=0},
		{name="default:sand", prob=254, param2=0},
		{name="default:sand", prob=254, param2=0},
		{name="default:sand", prob=254, param2=0},
		{name="default:sand", prob=254, param2=0},

		-- z=1, y=2
		{name="air", prob=254, param2=0},
		{name="air", prob=254, param2=0},
		{name="air", prob=254, param2=0},
		{name="air", prob=254, param2=0},
		{name="air", prob=254, param2=0},
		{name="air", prob=254, param2=0},

		-- z=2, y=0
		{name="default:sand", prob=254, param2=0},
		{name="default:clay", prob=254, param2=0},
		{name="default:clay", prob=254, param2=0},
		{name="default:sand", prob=254, param2=0},
		{name="default:sand", prob=254, param2=0},
		{name="default:sand", prob=254, param2=0},

		-- z=2, y=1
		{name="default:sand", prob=254, param2=0},
		{name="air", prob=254, param2=0},
		{name="air", prob=254, param2=0},
		{name="air", prob=254, param2=0},
		{name="default:sand", prob=254, param2=0},
		{name="default:sand", prob=254, param2=0},

		-- z=2, y=2
		{name="air", prob=254, param2=0},
		{name="air", prob=254, param2=0},
		{name="air", prob=254, param2=0},
		{name="air", prob=254, param2=0},
		{name="air", prob=254, param2=0},
		{name="air", prob=254, param2=0},

		-- z=3, y=0
		{name="default:sand", prob=254, param2=0},
		{name="default:sand", prob=254, param2=0},
		{name="default:clay", prob=254, param2=0},
		{name="default:clay", prob=254, param2=0},
		{name="default:sand", prob=254, param2=0},
		{name="default:sand", prob=254, param2=0},

		-- z=3, y=1
		{name="default:sand", prob=254, param2=0},
		{name="default:sand", prob=254, param2=0},
		{name="default:clay", prob=254, param2=0},
		{name="air", prob=254, param2=0},
		{name="mg_villages:mob_workplace_marker", prob=254, param2=1},
		{name="default:sand", prob=254, param2=0},

		-- z=3, y=2
		{name="air", prob=254, param2=0},
		{name="air", prob=254, param2=0},
		{name="air", prob=254, param2=0},
		{name="air", prob=254, param2=0},
		{name="air", prob=254, param2=0},
		{name="air", prob=254, param2=0},

		-- z=4, y=0
		{name="default:sand", prob=254, param2=0},
		{name="default:sand", prob=254, param2=0},
		{name="default:sand", prob=254, param2=0},
		{name="default:sand", prob=254, param2=0},
		{name="default:sand", prob=254, param2=0},
		{name="default:sand", prob=254, param2=0},

		-- z=4, y=1
		{name="default:sand", prob=254, param2=0},
		{name="default:sand", prob=254, param2=0},
		{name="default:sand", prob=254, param2=0},
		{name="default:sand", prob=254, param2=0},
		{name="default:sand", prob=254, param2=0},
		{name="default:sand", prob=254, param2=0},

		-- z=4, y=2
		{name="air", prob=254, param2=0},
		{name="air", prob=254, param2=0},
		{name="air", prob=254, param2=0},
		{name="air", prob=254, param2=0},
		{name="air", prob=254, param2=0},
		{name="air", prob=254, param2=0},

		-- z=5, y=0
		{name="default:sand", prob=254, param2=0},
		{name="default:sand", prob=254, param2=0},
		{name="default:sand", prob=254, param2=0},
		{name="default:sand", prob=254, param2=0},
		{name="default:sand", prob=254, param2=0},
		{name="default:sand", prob=254, param2=0},

		-- z=5, y=1
		{name="default:sand", prob=254, param2=0},
		{name="default:sand", prob=254, param2=0},
		{name="default:sand", prob=254, param2=0},
		{name="default:sand", prob=254, param2=0},
		{name="default:sand", prob=254, param2=0},
		{name="default:sand", prob=254, param2=0},

		-- z=5, y=2
		{name="air", prob=254, param2=0},
		{name="air", prob=254, param2=0},
		{name="air", prob=254, param2=0},
		{name="air", prob=254, param2=0},
		{name="air", prob=254, param2=0},
		{name="air", prob=254, param2=0},
	},
}

return schematic