schematic = {
	size = {x=5, y=14, z=5},
	yslice_prob = {
		{ypos=0, prob=254},
		{ypos=1, prob=254},
		{ypos=2, prob=254},
		{ypos=3, prob=254},
		{ypos=4, prob=254},
		{ypos=5, prob=254},
		{ypos=6, prob=254},
		{ypos=7, prob=254},
		{ypos=8, prob=254},
		{ypos=9, prob=254},
		{ypos=10, prob=254},
		{ypos=11, prob=254},
		{ypos=12, prob=254},
		{ypos=13, prob=254},
	},
	data = {

		-- z=0, y=0
		{name="default:dirt", prob=254, param2=0},
		{name="default:dirt", prob=254, param2=0},
		{name="default:dirt", prob=254, param2=0},
		{name="default:dirt", prob=254, param2=0},
		{name="default:dirt", prob=254, param2=0},

		-- z=0, y=1
		{name="default:dirt", prob=254, param2=0},
		{name="default:dirt", prob=254, param2=0},
		{name="default:dirt", prob=254, param2=0},
		{name="default:dirt", prob=254, param2=0},
		{name="default:dirt", prob=254, param2=0},

		-- z=0, y=2
		{name="default:dirt", prob=254, param2=0},
		{name="default:sandstonebrick", prob=254, param2=0},
		{name="default:sandstonebrick", prob=254, param2=0},
		{name="default:sandstonebrick", prob=254, param2=0},
		{name="default:dirt", prob=254, param2=0},

		-- z=0, y=3
		{name="default:dirt", prob=254, param2=0},
		{name="default:sandstonebrick", prob=254, param2=0},
		{name="default:sandstonebrick", prob=254, param2=0},
		{name="default:sandstonebrick", prob=254, param2=0},
		{name="default:dirt", prob=254, param2=0},

		-- z=0, y=4
		{name="default:dirt", prob=254, param2=0},
		{name="default:sandstonebrick", prob=254, param2=0},
		{name="default:sandstonebrick", prob=254, param2=0},
		{name="default:sandstonebrick", prob=254, param2=0},
		{name="default:dirt", prob=254, param2=0},

		-- z=0, y=5
		{name="default:dirt", prob=254, param2=0},
		{name="default:dirt", prob=254, param2=0},
		{name="default:dirt", prob=254, param2=0},
		{name="default:dirt", prob=254, param2=0},
		{name="default:dirt", prob=254, param2=0},

		-- z=0, y=6
		{name="default:dirt", prob=254, param2=0},
		{name="default:dirt", prob=254, param2=0},
		{name="default:dirt", prob=254, param2=0},
		{name="default:dirt", prob=254, param2=0},
		{name="default:dirt", prob=254, param2=0},

		-- z=0, y=7
		{name="default:desert_sand", prob=254, param2=0},
		{name="default:desert_sand", prob=254, param2=0},
		{name="default:desert_sand", prob=254, param2=0},
		{name="default:desert_sand", prob=254, param2=0},
		{name="default:desert_sand", prob=254, param2=0},

		-- z=0, y=8
		{name="air", prob=254, param2=0},
		{name="air", prob=254, param2=0},
		{name="air", prob=254, param2=0},
		{name="air", prob=254, param2=0},
		{name="air", prob=254, param2=0},

		-- z=0, y=9
		{name="air", prob=254, param2=0},
		{name="air", prob=254, param2=0},
		{name="air", prob=254, param2=0},
		{name="air", prob=254, param2=0},
		{name="air", prob=254, param2=0},

		-- z=0, y=10
		{name="air", prob=254, param2=0},
		{name="dryplants:wetreed_roof_corner", prob=254, param2=1},
		{name="dryplants:wetreed_roof", prob=254, param2=0},
		{name="dryplants:wetreed_roof_corner", prob=254, param2=0},
		{name="air", prob=254, param2=0},

		-- z=0, y=11
		{name="air", prob=254, param2=0},
		{name="air", prob=254, param2=0},
		{name="air", prob=254, param2=0},
		{name="air", prob=254, param2=0},
		{name="air", prob=254, param2=0},

		-- z=0, y=12
		{name="air", prob=254, param2=0},
		{name="air", prob=254, param2=0},
		{name="air", prob=254, param2=0},
		{name="air", prob=254, param2=0},
		{name="air", prob=254, param2=0},

		-- z=0, y=13
		{name="air", prob=254, param2=0},
		{name="air", prob=254, param2=0},
		{name="air", prob=254, param2=0},
		{name="air", prob=254, param2=0},
		{name="air", prob=254, param2=0},

		-- z=1, y=0
		{name="default:dirt", prob=254, param2=0},
		{name="default:dirt", prob=254, param2=0},
		{name="default:dirt", prob=254, param2=0},
		{name="default:dirt", prob=254, param2=0},
		{name="default:dirt", prob=254, param2=0},

		-- z=1, y=1
		{name="default:dirt", prob=254, param2=0},
		{name="default:sandstonebrick", prob=254, param2=0},
		{name="default:sandstonebrick", prob=254, param2=0},
		{name="default:sandstonebrick", prob=254, param2=0},
		{name="default:dirt", prob=254, param2=0},

		-- z=1, y=2
		{name="default:sandstonebrick", prob=254, param2=0},
		{name="default:river_water_source", prob=254, param2=0},
		{name="default:river_water_source", prob=254, param2=0},
		{name="default:river_water_source", prob=254, param2=0},
		{name="default:sandstonebrick", prob=254, param2=0},

		-- z=1, y=3
		{name="default:sandstonebrick", prob=254, param2=0},
		{name="default:river_water_source", prob=254, param2=0},
		{name="default:river_water_source", prob=254, param2=0},
		{name="default:river_water_source", prob=254, param2=0},
		{name="default:sandstonebrick", prob=254, param2=0},

		-- z=1, y=4
		{name="default:sandstonebrick", prob=254, param2=0},
		{name="default:river_water_source", prob=254, param2=0},
		{name="default:river_water_source", prob=254, param2=0},
		{name="default:river_water_source", prob=254, param2=0},
		{name="default:sandstonebrick", prob=254, param2=0},

		-- z=1, y=5
		{name="default:dirt", prob=254, param2=0},
		{name="default:sandstonebrick", prob=254, param2=0},
		{name="default:sandstonebrick", prob=254, param2=0},
		{name="default:sandstonebrick", prob=254, param2=0},
		{name="default:dirt", prob=254, param2=0},

		-- z=1, y=6
		{name="default:dirt", prob=254, param2=0},
		{name="default:dirt", prob=254, param2=0},
		{name="default:sandstonebrick", prob=254, param2=0},
		{name="default:dirt", prob=254, param2=0},
		{name="default:dirt", prob=254, param2=0},

		-- z=1, y=7
		{name="default:desert_sand", prob=254, param2=0},
		{name="default:sandstonebrick", prob=254, param2=0},
		{name="default:sandstonebrick", prob=254, param2=0},
		{name="default:sandstonebrick", prob=254, param2=0},
		{name="default:desert_sand", prob=254, param2=0},

		-- z=1, y=8
		{name="air", prob=254, param2=0},
		{name="default:sandstonebrick", prob=254, param2=0},
		{name="cottages:half_door", prob=254, param2=0},
		{name="default:sandstonebrick", prob=254, param2=0},
		{name="air", prob=254, param2=0},

		-- z=1, y=9
		{name="air", prob=254, param2=0},
		{name="default:fence_wood", prob=254, param2=0},
		{name="air", prob=254, param2=0},
		{name="default:fence_wood", prob=254, param2=0},
		{name="air", prob=254, param2=0},

		-- z=1, y=10
		{name="dryplants:wetreed_roof_corner", prob=254, param2=1},
		{name="dryplants:wetreed_roof_corner", prob=254, param2=3},
		{name="cottages:half_door", prob=254, param2=0},
		{name="dryplants:wetreed_roof_corner", prob=254, param2=2},
		{name="dryplants:wetreed_roof_corner", prob=254, param2=0},

		-- z=1, y=11
		{name="air", prob=254, param2=0},
		{name="dryplants:wetreed_roof_corner", prob=254, param2=1},
		{name="dryplants:wetreed_roof", prob=254, param2=0},
		{name="dryplants:wetreed_roof_corner", prob=254, param2=0},
		{name="air", prob=254, param2=0},

		-- z=1, y=12
		{name="air", prob=254, param2=0},
		{name="air", prob=254, param2=0},
		{name="air", prob=254, param2=0},
		{name="air", prob=254, param2=0},
		{name="air", prob=254, param2=0},

		-- z=1, y=13
		{name="air", prob=254, param2=0},
		{name="air", prob=254, param2=0},
		{name="air", prob=254, param2=0},
		{name="air", prob=254, param2=0},
		{name="air", prob=254, param2=0},

		-- z=2, y=0
		{name="default:dirt", prob=254, param2=0},
		{name="default:dirt", prob=254, param2=0},
		{name="default:dirt", prob=254, param2=0},
		{name="default:dirt", prob=254, param2=0},
		{name="default:dirt", prob=254, param2=0},

		-- z=2, y=1
		{name="default:dirt", prob=254, param2=0},
		{name="default:sandstonebrick", prob=254, param2=0},
		{name="default:sandstonebrick", prob=254, param2=0},
		{name="default:sandstonebrick", prob=254, param2=0},
		{name="default:dirt", prob=254, param2=0},

		-- z=2, y=2
		{name="default:sandstonebrick", prob=254, param2=0},
		{name="default:river_water_flowing", prob=254, param2=7},
		{name="default:river_water_source", prob=254, param2=0},
		{name="default:river_water_source", prob=254, param2=0},
		{name="default:sandstonebrick", prob=254, param2=0},

		-- z=2, y=3
		{name="default:sandstonebrick", prob=254, param2=0},
		{name="default:river_water_source", prob=254, param2=0},
		{name="default:river_water_flowing", prob=254, param2=7},
		{name="default:river_water_source", prob=254, param2=0},
		{name="default:sandstonebrick", prob=254, param2=0},

		-- z=2, y=4
		{name="default:sandstonebrick", prob=254, param2=0},
		{name="default:river_water_flowing", prob=254, param2=7},
		{name="default:river_water_flowing", prob=254, param2=15},
		{name="default:river_water_source", prob=254, param2=0},
		{name="default:sandstonebrick", prob=254, param2=0},

		-- z=2, y=5
		{name="default:dirt", prob=254, param2=0},
		{name="default:sandstonebrick", prob=254, param2=0},
		{name="default:ladder_wood", prob=254, param2=4},
		{name="default:sandstonebrick", prob=254, param2=0},
		{name="default:dirt", prob=254, param2=0},

		-- z=2, y=6
		{name="default:dirt", prob=254, param2=0},
		{name="default:sandstonebrick", prob=254, param2=0},
		{name="default:ladder_wood", prob=254, param2=4},
		{name="default:sandstonebrick", prob=254, param2=0},
		{name="default:dirt", prob=254, param2=0},

		-- z=2, y=7
		{name="default:desert_sand", prob=254, param2=0},
		{name="default:sandstonebrick", prob=254, param2=0},
		{name="default:ladder_wood", prob=254, param2=4},
		{name="default:sandstonebrick", prob=254, param2=0},
		{name="default:desert_sand", prob=254, param2=0},

		-- z=2, y=8
		{name="air", prob=254, param2=0},
		{name="default:sandstonebrick", prob=254, param2=3},
		{name="default:ladder_wood", prob=254, param2=4},
		{name="default:sandstonebrick", prob=254, param2=1},
		{name="air", prob=254, param2=0},

		-- z=2, y=9
		{name="air", prob=254, param2=0},
		{name="air", prob=254, param2=0},
		{name="cottages:wood_flat", prob=254, param2=21},
		{name="air", prob=254, param2=0},
		{name="air", prob=254, param2=0},

		-- z=2, y=10
		{name="dryplants:wetreed_roof", prob=254, param2=1},
		{name="cottages:wood_flat", prob=254, param2=18},
		{name="default:fence_wood", prob=254, param2=0},
		{name="cottages:wood_flat", prob=254, param2=12},
		{name="dryplants:wetreed_roof", prob=254, param2=3},

		-- z=2, y=11
		{name="air", prob=254, param2=0},
		{name="dryplants:wetreed_roof", prob=254, param2=1},
		{name="default:fence_wood", prob=254, param2=0},
		{name="dryplants:wetreed_roof", prob=254, param2=3},
		{name="air", prob=254, param2=0},

		-- z=2, y=12
		{name="air", prob=254, param2=0},
		{name="air", prob=254, param2=0},
		{name="dryplants:wetreed_slab", prob=254, param2=1},
		{name="air", prob=254, param2=0},
		{name="air", prob=254, param2=0},

		-- z=2, y=13
		{name="air", prob=254, param2=0},
		{name="air", prob=254, param2=0},
		{name="air", prob=254, param2=0},
		{name="air", prob=254, param2=0},
		{name="air", prob=254, param2=0},

		-- z=3, y=0
		{name="default:dirt", prob=254, param2=0},
		{name="default:dirt", prob=254, param2=0},
		{name="default:dirt", prob=254, param2=0},
		{name="default:dirt", prob=254, param2=0},
		{name="default:dirt", prob=254, param2=0},

		-- z=3, y=1
		{name="default:dirt", prob=254, param2=0},
		{name="default:sandstonebrick", prob=254, param2=0},
		{name="default:sandstonebrick", prob=254, param2=0},
		{name="default:sandstonebrick", prob=254, param2=0},
		{name="default:dirt", prob=254, param2=0},

		-- z=3, y=2
		{name="default:sandstonebrick", prob=254, param2=0},
		{name="default:river_water_source", prob=254, param2=0},
		{name="default:river_water_source", prob=254, param2=0},
		{name="default:river_water_source", prob=254, param2=0},
		{name="default:sandstonebrick", prob=254, param2=0},

		-- z=3, y=3
		{name="default:sandstonebrick", prob=254, param2=0},
		{name="default:river_water_source", prob=254, param2=0},
		{name="default:river_water_flowing", prob=254, param2=7},
		{name="default:river_water_source", prob=254, param2=0},
		{name="default:sandstonebrick", prob=254, param2=0},

		-- z=3, y=4
		{name="default:sandstonebrick", prob=254, param2=0},
		{name="default:river_water_source", prob=254, param2=0},
		{name="default:river_water_source", prob=254, param2=0},
		{name="default:river_water_source", prob=254, param2=0},
		{name="default:sandstonebrick", prob=254, param2=0},

		-- z=3, y=5
		{name="default:dirt", prob=254, param2=0},
		{name="default:sandstonebrick", prob=254, param2=0},
		{name="default:sandstonebrick", prob=254, param2=0},
		{name="default:sandstonebrick", prob=254, param2=0},
		{name="default:dirt", prob=254, param2=0},

		-- z=3, y=6
		{name="default:dirt", prob=254, param2=0},
		{name="default:dirt", prob=254, param2=0},
		{name="default:sandstonebrick", prob=254, param2=0},
		{name="default:dirt", prob=254, param2=0},
		{name="default:dirt", prob=254, param2=0},

		-- z=3, y=7
		{name="default:desert_sand", prob=254, param2=0},
		{name="default:sandstonebrick", prob=254, param2=0},
		{name="default:sandstonebrick", prob=254, param2=0},
		{name="default:sandstonebrick", prob=254, param2=0},
		{name="default:desert_sand", prob=254, param2=0},

		-- z=3, y=8
		{name="air", prob=254, param2=0},
		{name="default:sandstonebrick", prob=254, param2=0},
		{name="default:sandstonebrick", prob=254, param2=0},
		{name="default:sandstonebrick", prob=254, param2=0},
		{name="air", prob=254, param2=0},

		-- z=3, y=9
		{name="air", prob=254, param2=0},
		{name="default:fence_wood", prob=254, param2=0},
		{name="air", prob=254, param2=0},
		{name="default:fence_wood", prob=254, param2=0},
		{name="air", prob=254, param2=0},

		-- z=3, y=10
		{name="dryplants:wetreed_roof_corner", prob=254, param2=2},
		{name="dryplants:wetreed_roof_corner", prob=254, param2=0},
		{name="cottages:wood_flat", prob=254, param2=7},
		{name="dryplants:wetreed_roof_corner", prob=254, param2=1},
		{name="dryplants:wetreed_roof_corner", prob=254, param2=3},

		-- z=3, y=11
		{name="air", prob=254, param2=0},
		{name="dryplants:wetreed_roof_corner", prob=254, param2=2},
		{name="dryplants:wetreed_roof", prob=254, param2=2},
		{name="dryplants:wetreed_roof_corner", prob=254, param2=3},
		{name="air", prob=254, param2=0},

		-- z=3, y=12
		{name="air", prob=254, param2=0},
		{name="air", prob=254, param2=0},
		{name="air", prob=254, param2=0},
		{name="air", prob=254, param2=0},
		{name="air", prob=254, param2=0},

		-- z=3, y=13
		{name="air", prob=254, param2=0},
		{name="air", prob=254, param2=0},
		{name="air", prob=254, param2=0},
		{name="air", prob=254, param2=0},
		{name="air", prob=254, param2=0},

		-- z=4, y=0
		{name="default:dirt", prob=254, param2=0},
		{name="default:dirt", prob=254, param2=0},
		{name="default:dirt", prob=254, param2=0},
		{name="default:dirt", prob=254, param2=0},
		{name="default:dirt", prob=254, param2=0},

		-- z=4, y=1
		{name="default:dirt", prob=254, param2=0},
		{name="default:dirt", prob=254, param2=0},
		{name="default:dirt", prob=254, param2=0},
		{name="default:dirt", prob=254, param2=0},
		{name="default:dirt", prob=254, param2=0},

		-- z=4, y=2
		{name="default:dirt", prob=254, param2=0},
		{name="default:sandstonebrick", prob=254, param2=0},
		{name="default:sandstonebrick", prob=254, param2=0},
		{name="default:sandstonebrick", prob=254, param2=0},
		{name="default:dirt", prob=254, param2=0},

		-- z=4, y=3
		{name="default:dirt", prob=254, param2=0},
		{name="default:sandstonebrick", prob=254, param2=0},
		{name="default:chest", prob=254, param2=0},
		{name="default:sandstonebrick", prob=254, param2=0},
		{name="default:dirt", prob=254, param2=0},

		-- z=4, y=4
		{name="default:dirt", prob=254, param2=0},
		{name="default:sandstonebrick", prob=254, param2=0},
		{name="default:sandstonebrick", prob=254, param2=0},
		{name="default:sandstonebrick", prob=254, param2=0},
		{name="default:dirt", prob=254, param2=0},

		-- z=4, y=5
		{name="default:dirt", prob=254, param2=0},
		{name="default:dirt", prob=254, param2=0},
		{name="default:dirt", prob=254, param2=0},
		{name="default:dirt", prob=254, param2=0},
		{name="default:dirt", prob=254, param2=0},

		-- z=4, y=6
		{name="default:dirt", prob=254, param2=0},
		{name="default:dirt", prob=254, param2=0},
		{name="default:dirt", prob=254, param2=0},
		{name="default:dirt", prob=254, param2=0},
		{name="default:dirt", prob=254, param2=0},

		-- z=4, y=7
		{name="default:desert_sand", prob=254, param2=0},
		{name="default:desert_sand", prob=254, param2=0},
		{name="default:desert_sand", prob=254, param2=0},
		{name="default:desert_sand", prob=254, param2=0},
		{name="default:desert_sand", prob=254, param2=0},

		-- z=4, y=8
		{name="air", prob=254, param2=0},
		{name="air", prob=254, param2=0},
		{name="air", prob=254, param2=0},
		{name="air", prob=254, param2=0},
		{name="air", prob=254, param2=0},

		-- z=4, y=9
		{name="air", prob=254, param2=0},
		{name="air", prob=254, param2=0},
		{name="air", prob=254, param2=0},
		{name="air", prob=254, param2=0},
		{name="air", prob=254, param2=0},

		-- z=4, y=10
		{name="air", prob=254, param2=0},
		{name="dryplants:wetreed_roof_corner", prob=254, param2=2},
		{name="dryplants:wetreed_roof", prob=254, param2=2},
		{name="dryplants:wetreed_roof_corner", prob=254, param2=3},
		{name="air", prob=254, param2=0},

		-- z=4, y=11
		{name="air", prob=254, param2=0},
		{name="air", prob=254, param2=0},
		{name="air", prob=254, param2=0},
		{name="air", prob=254, param2=0},
		{name="air", prob=254, param2=0},

		-- z=4, y=12
		{name="air", prob=254, param2=0},
		{name="air", prob=254, param2=0},
		{name="air", prob=254, param2=0},
		{name="air", prob=254, param2=0},
		{name="air", prob=254, param2=0},

		-- z=4, y=13
		{name="air", prob=254, param2=0},
		{name="air", prob=254, param2=0},
		{name="air", prob=254, param2=0},
		{name="air", prob=254, param2=0},
		{name="air", prob=254, param2=0},
	},
}

return schematic