schematic = {
	size = {x=5, y=7, z=5},
	yslice_prob = {
		{ypos=0, prob=254},
		{ypos=1, prob=254},
		{ypos=2, prob=254},
		{ypos=3, prob=254},
		{ypos=4, prob=254},
		{ypos=5, prob=254},
		{ypos=6, prob=254},
	},
	data = {

		-- z=0, y=0
		{name="default:cobble", prob=254, param2=0},
		{name="default:cobble", prob=254, param2=0},
		{name="default:cobble", prob=254, param2=0},
		{name="default:cobble", prob=254, param2=0},
		{name="default:cobble", prob=254, param2=0},

		-- z=0, y=1
		{name="default:tree", prob=254, param2=3},
		{name="default:wood", prob=254, param2=3},
		{name="default:wood", prob=254, param2=3},
		{name="default:wood", prob=254, param2=3},
		{name="default:tree", prob=254, param2=3},

		-- z=0, y=2
		{name="default:tree", prob=254, param2=3},
		{name="default:wood", prob=254, param2=3},
		{name="default:glass", prob=254, param2=0},
		{name="default:wood", prob=254, param2=3},
		{name="default:tree", prob=254, param2=3},

		-- z=0, y=3
		{name="default:wood", prob=254, param2=3},
		{name="default:wood", prob=254, param2=3},
		{name="default:wood", prob=254, param2=3},
		{name="default:wood", prob=254, param2=3},
		{name="default:wood", prob=254, param2=3},

		-- z=0, y=4
		{name="stairs:slab_wood", prob=254, param2=3},
		{name="stairs:stair_wood", prob=254, param2=0},
		{name="stairs:stair_wood", prob=254, param2=0},
		{name="stairs:stair_wood", prob=254, param2=0},
		{name="stairs:slab_wood", prob=254, param2=3},

		-- z=0, y=5
		{name="air", prob=254, param2=0},
		{name="air", prob=254, param2=0},
		{name="air", prob=254, param2=0},
		{name="air", prob=254, param2=0},
		{name="air", prob=254, param2=0},

		-- z=0, y=6
		{name="air", prob=254, param2=0},
		{name="air", prob=254, param2=0},
		{name="air", prob=254, param2=0},
		{name="air", prob=254, param2=0},
		{name="air", prob=254, param2=0},

		-- z=1, y=0
		{name="default:cobble", prob=254, param2=0},
		{name="default:cobble", prob=254, param2=0},
		{name="default:cobble", prob=254, param2=0},
		{name="default:cobble", prob=254, param2=0},
		{name="default:cobble", prob=254, param2=0},

		-- z=1, y=1
		{name="default:wood", prob=254, param2=3},
		{name="default:chest", prob=254, param2=2},
		{name="beds:bed_bottom", prob=254, param2=1},
		{name="beds:bed_top", prob=254, param2=1},
		{name="default:wood", prob=254, param2=3},

		-- z=1, y=2
		{name="default:wood", prob=254, param2=3},
		{name="air", prob=254, param2=0},
		{name="air", prob=254, param2=0},
		{name="air", prob=254, param2=0},
		{name="default:wood", prob=254, param2=3},

		-- z=1, y=3
		{name="default:wood", prob=254, param2=3},
		{name="air", prob=254, param2=0},
		{name="air", prob=254, param2=0},
		{name="air", prob=254, param2=0},
		{name="default:wood", prob=254, param2=3},

		-- z=1, y=4
		{name="stairs:stair_wood", prob=254, param2=1},
		{name="default:wood", prob=254, param2=3},
		{name="default:wood", prob=254, param2=3},
		{name="default:wood", prob=254, param2=3},
		{name="stairs:stair_wood", prob=254, param2=3},

		-- z=1, y=5
		{name="air", prob=254, param2=0},
		{name="stairs:slab_wood", prob=254, param2=3},
		{name="stairs:stair_wood", prob=254, param2=0},
		{name="stairs:slab_wood", prob=254, param2=3},
		{name="air", prob=254, param2=0},

		-- z=1, y=6
		{name="air", prob=254, param2=0},
		{name="air", prob=254, param2=0},
		{name="air", prob=254, param2=0},
		{name="air", prob=254, param2=0},
		{name="air", prob=254, param2=0},

		-- z=2, y=0
		{name="default:cobble", prob=254, param2=0},
		{name="default:cobble", prob=254, param2=0},
		{name="default:cobble", prob=254, param2=0},
		{name="default:cobble", prob=254, param2=0},
		{name="default:cobble", prob=254, param2=0},

		-- z=2, y=1
		{name="doors:door_wood_a", prob=254, param2=1},
		{name="air", prob=254, param2=0},
		{name="air", prob=254, param2=0},
		{name="air", prob=254, param2=0},
		{name="default:wood", prob=254, param2=3},

		-- z=2, y=2
		{name="doors:hidden", prob=254, param2=1},
		{name="air", prob=254, param2=0},
		{name="air", prob=254, param2=0},
		{name="air", prob=254, param2=0},
		{name="default:wood", prob=254, param2=3},

		-- z=2, y=3
		{name="default:wood", prob=254, param2=3},
		{name="air", prob=254, param2=0},
		{name="air", prob=254, param2=0},
		{name="default:torch_wall", prob=254, param2=2},
		{name="default:wood", prob=254, param2=3},

		-- z=2, y=4
		{name="stairs:stair_wood", prob=254, param2=1},
		{name="default:wood", prob=254, param2=3},
		{name="air", prob=254, param2=0},
		{name="default:wood", prob=254, param2=3},
		{name="stairs:stair_wood", prob=254, param2=3},

		-- z=2, y=5
		{name="air", prob=254, param2=0},
		{name="stairs:stair_wood", prob=254, param2=1},
		{name="default:wood", prob=254, param2=3},
		{name="stairs:stair_wood", prob=254, param2=3},
		{name="air", prob=254, param2=0},

		-- z=2, y=6
		{name="air", prob=254, param2=0},
		{name="air", prob=254, param2=0},
		{name="air", prob=254, param2=0},
		{name="air", prob=254, param2=0},
		{name="air", prob=254, param2=0},

		-- z=3, y=0
		{name="default:cobble", prob=254, param2=0},
		{name="default:cobble", prob=254, param2=0},
		{name="default:cobble", prob=254, param2=0},
		{name="default:cobble", prob=254, param2=0},
		{name="default:cobble", prob=254, param2=0},

		-- z=3, y=1
		{name="default:wood", prob=254, param2=3},
		{name="air", prob=254, param2=0},
		{name="air", prob=254, param2=0},
		{name="air", prob=254, param2=0},
		{name="default:wood", prob=254, param2=3},

		-- z=3, y=2
		{name="default:wood", prob=254, param2=3},
		{name="air", prob=254, param2=0},
		{name="air", prob=254, param2=0},
		{name="air", prob=254, param2=0},
		{name="default:wood", prob=254, param2=3},

		-- z=3, y=3
		{name="default:wood", prob=254, param2=3},
		{name="air", prob=254, param2=0},
		{name="air", prob=254, param2=0},
		{name="air", prob=254, param2=0},
		{name="default:wood", prob=254, param2=3},

		-- z=3, y=4
		{name="stairs:stair_wood", prob=254, param2=1},
		{name="default:wood", prob=254, param2=3},
		{name="default:wood", prob=254, param2=3},
		{name="default:wood", prob=254, param2=3},
		{name="stairs:stair_wood", prob=254, param2=3},

		-- z=3, y=5
		{name="air", prob=254, param2=0},
		{name="stairs:slab_wood", prob=254, param2=3},
		{name="stairs:stair_wood", prob=254, param2=2},
		{name="stairs:slab_wood", prob=254, param2=3},
		{name="air", prob=254, param2=0},

		-- z=3, y=6
		{name="air", prob=254, param2=0},
		{name="air", prob=254, param2=0},
		{name="air", prob=254, param2=0},
		{name="air", prob=254, param2=0},
		{name="air", prob=254, param2=0},

		-- z=4, y=0
		{name="default:cobble", prob=254, param2=0},
		{name="default:cobble", prob=254, param2=0},
		{name="default:cobble", prob=254, param2=0},
		{name="default:cobble", prob=254, param2=0},
		{name="default:cobble", prob=254, param2=0},

		-- z=4, y=1
		{name="default:tree", prob=254, param2=3},
		{name="default:wood", prob=254, param2=3},
		{name="default:wood", prob=254, param2=3},
		{name="default:wood", prob=254, param2=3},
		{name="default:tree", prob=254, param2=3},

		-- z=4, y=2
		{name="default:tree", prob=254, param2=3},
		{name="default:wood", prob=254, param2=3},
		{name="default:glass", prob=254, param2=0},
		{name="default:wood", prob=254, param2=3},
		{name="default:tree", prob=254, param2=3},

		-- z=4, y=3
		{name="default:wood", prob=254, param2=3},
		{name="default:wood", prob=254, param2=3},
		{name="default:wood", prob=254, param2=3},
		{name="default:wood", prob=254, param2=3},
		{name="default:wood", prob=254, param2=3},

		-- z=4, y=4
		{name="stairs:slab_wood", prob=254, param2=3},
		{name="stairs:stair_wood", prob=254, param2=2},
		{name="stairs:stair_wood", prob=254, param2=2},
		{name="stairs:stair_wood", prob=254, param2=2},
		{name="stairs:slab_wood", prob=254, param2=3},

		-- z=4, y=5
		{name="air", prob=254, param2=0},
		{name="air", prob=254, param2=0},
		{name="air", prob=254, param2=0},
		{name="air", prob=254, param2=0},
		{name="air", prob=254, param2=0},

		-- z=4, y=6
		{name="air", prob=254, param2=0},
		{name="air", prob=254, param2=0},
		{name="air", prob=254, param2=0},
		{name="air", prob=254, param2=0},
		{name="air", prob=254, param2=0},
	},
}

return schematic