schematic = {
	size = {x=6, y=7, z=6},
	yslice_prob = {
		{ypos=0, prob=254},
		{ypos=1, prob=254},
		{ypos=2, prob=254},
		{ypos=3, prob=254},
		{ypos=4, prob=254},
		{ypos=5, prob=254},
		{ypos=6, prob=254},
	},
	data = {

		-- z=0, y=0
		{name="default:gravel", prob=254, param2=0},
		{name="default:gravel", prob=254, param2=0},
		{name="default:gravel", prob=254, param2=0},
		{name="default:gravel", prob=254, param2=0},
		{name="default:gravel", prob=254, param2=0},
		{name="default:gravel", prob=254, param2=0},

		-- z=0, y=1
		{name="air", prob=254, param2=0},
		{name="cottages:wool_tent", prob=254, param2=9},
		{name="air", prob=254, param2=0},
		{name="air", prob=254, param2=0},
		{name="cottages:wool_tent", prob=254, param2=9},
		{name="air", prob=254, param2=0},

		-- z=0, y=2
		{name="air", prob=254, param2=0},
		{name="cottages:wool_tent", prob=254, param2=9},
		{name="air", prob=254, param2=0},
		{name="air", prob=254, param2=0},
		{name="cottages:wool_tent", prob=254, param2=9},
		{name="air", prob=254, param2=0},

		-- z=0, y=3
		{name="air", prob=254, param2=0},
		{name="cottages:wool_tent", prob=254, param2=9},
		{name="cottages:wool_tent", prob=254, param2=9},
		{name="cottages:wool_tent", prob=254, param2=9},
		{name="cottages:wool_tent", prob=254, param2=9},
		{name="air", prob=254, param2=0},

		-- z=0, y=4
		{name="air", prob=254, param2=0},
		{name="air", prob=254, param2=0},
		{name="air", prob=254, param2=0},
		{name="air", prob=254, param2=0},
		{name="air", prob=254, param2=0},
		{name="air", prob=254, param2=0},

		-- z=0, y=5
		{name="air", prob=254, param2=0},
		{name="air", prob=254, param2=0},
		{name="air", prob=254, param2=0},
		{name="air", prob=254, param2=0},
		{name="air", prob=254, param2=0},
		{name="air", prob=254, param2=0},

		-- z=0, y=6
		{name="air", prob=254, param2=0},
		{name="air", prob=254, param2=0},
		{name="air", prob=254, param2=0},
		{name="air", prob=254, param2=0},
		{name="air", prob=254, param2=0},
		{name="air", prob=254, param2=0},

		-- z=1, y=0
		{name="default:gravel", prob=254, param2=0},
		{name="default:gravel", prob=254, param2=0},
		{name="default:gravel", prob=254, param2=0},
		{name="default:gravel", prob=254, param2=0},
		{name="default:gravel", prob=254, param2=0},
		{name="default:gravel", prob=254, param2=0},

		-- z=1, y=1
		{name="cottages:wool_tent", prob=254, param2=18},
		{name="default:fence_wood", prob=254, param2=0},
		{name="doors:door_wood_a", prob=254, param2=0},
		{name="doors:door_wood_b", prob=254, param2=0},
		{name="default:fence_wood", prob=254, param2=0},
		{name="cottages:wool_tent", prob=254, param2=12},

		-- z=1, y=2
		{name="cottages:wool_tent", prob=254, param2=18},
		{name="default:fence_wood", prob=254, param2=0},
		{name="doors:hidden", prob=254, param2=0},
		{name="doors:hidden", prob=254, param2=0},
		{name="default:fence_wood", prob=254, param2=0},
		{name="cottages:wool_tent", prob=254, param2=12},

		-- z=1, y=3
		{name="cottages:wool_tent", prob=254, param2=18},
		{name="default:chest", prob=254, param2=3},
		{name="air", prob=254, param2=0},
		{name="air", prob=254, param2=0},
		{name="default:chest", prob=254, param2=1},
		{name="cottages:wool_tent", prob=254, param2=12},

		-- z=1, y=4
		{name="air", prob=254, param2=0},
		{name="cottages:wool_tent", prob=254, param2=3},
		{name="cottages:wool_tent", prob=254, param2=3},
		{name="cottages:wool_tent", prob=254, param2=3},
		{name="cottages:wool_tent", prob=254, param2=3},
		{name="air", prob=254, param2=0},

		-- z=1, y=5
		{name="air", prob=254, param2=0},
		{name="air", prob=254, param2=0},
		{name="air", prob=254, param2=0},
		{name="air", prob=254, param2=0},
		{name="air", prob=254, param2=0},
		{name="air", prob=254, param2=0},

		-- z=1, y=6
		{name="air", prob=254, param2=0},
		{name="air", prob=254, param2=0},
		{name="air", prob=254, param2=0},
		{name="air", prob=254, param2=0},
		{name="air", prob=254, param2=0},
		{name="air", prob=254, param2=0},

		-- z=2, y=0
		{name="default:gravel", prob=254, param2=0},
		{name="default:gravel", prob=254, param2=0},
		{name="default:gravel", prob=254, param2=0},
		{name="default:gravel", prob=254, param2=0},
		{name="default:gravel", prob=254, param2=0},
		{name="default:gravel", prob=254, param2=0},

		-- z=2, y=1
		{name="cottages:wool_tent", prob=254, param2=18},
		{name="cottages:bench", prob=254, param2=3},
		{name="air", prob=254, param2=0},
		{name="mg_villages:mob_workplace_marker", prob=254, param2=1},
		{name="cottages:barrel", prob=254, param2=0},
		{name="cottages:wool_tent", prob=254, param2=12},

		-- z=2, y=2
		{name="cottages:hatch_wood", prob=254, param2=17},
		{name="air", prob=254, param2=0},
		{name="air", prob=254, param2=0},
		{name="air", prob=254, param2=0},
		{name="default:torch_wall", prob=254, param2=2},
		{name="cottages:wool_tent", prob=254, param2=12},

		-- z=2, y=3
		{name="cottages:wool_tent", prob=254, param2=18},
		{name="cottages:wool_tent", prob=254, param2=3},
		{name="cottages:wool_tent", prob=254, param2=23},
		{name="cottages:wool_tent", prob=254, param2=20},
		{name="cottages:wool_tent", prob=254, param2=3},
		{name="cottages:wool_tent", prob=254, param2=12},

		-- z=2, y=4
		{name="air", prob=254, param2=0},
		{name="cottages:wool_tent", prob=254, param2=3},
		{name="air", prob=254, param2=0},
		{name="air", prob=254, param2=0},
		{name="cottages:wool_tent", prob=254, param2=3},
		{name="air", prob=254, param2=0},

		-- z=2, y=5
		{name="air", prob=254, param2=0},
		{name="air", prob=254, param2=0},
		{name="air", prob=254, param2=0},
		{name="air", prob=254, param2=0},
		{name="air", prob=254, param2=0},
		{name="air", prob=254, param2=0},

		-- z=2, y=6
		{name="air", prob=254, param2=0},
		{name="air", prob=254, param2=0},
		{name="air", prob=254, param2=0},
		{name="air", prob=254, param2=0},
		{name="air", prob=254, param2=0},
		{name="air", prob=254, param2=0},

		-- z=3, y=0
		{name="default:gravel", prob=254, param2=0},
		{name="default:gravel", prob=254, param2=0},
		{name="default:gravel", prob=254, param2=0},
		{name="default:gravel", prob=254, param2=0},
		{name="default:gravel", prob=254, param2=0},
		{name="default:gravel", prob=254, param2=0},

		-- z=3, y=1
		{name="cottages:wool_tent", prob=254, param2=18},
		{name="cottages:bench", prob=254, param2=3},
		{name="cottages:table", prob=254, param2=0},
		{name="cottages:table", prob=254, param2=0},
		{name="cottages:bench", prob=254, param2=1},
		{name="cottages:wool_tent", prob=254, param2=12},

		-- z=3, y=2
		{name="cottages:wool_tent", prob=254, param2=18},
		{name="default:torch_wall", prob=254, param2=3},
		{name="air", prob=254, param2=0},
		{name="air", prob=254, param2=0},
		{name="air", prob=254, param2=0},
		{name="cottages:hatch_wood", prob=254, param2=15},

		-- z=3, y=3
		{name="cottages:wool_tent", prob=254, param2=18},
		{name="cottages:wool_tent", prob=254, param2=3},
		{name="cottages:wool_tent", prob=254, param2=20},
		{name="cottages:wool_tent", prob=254, param2=23},
		{name="cottages:wool_tent", prob=254, param2=3},
		{name="cottages:wool_tent", prob=254, param2=12},

		-- z=3, y=4
		{name="air", prob=254, param2=0},
		{name="cottages:wool_tent", prob=254, param2=3},
		{name="air", prob=254, param2=0},
		{name="air", prob=254, param2=0},
		{name="cottages:wool_tent", prob=254, param2=3},
		{name="air", prob=254, param2=0},

		-- z=3, y=5
		{name="air", prob=254, param2=0},
		{name="air", prob=254, param2=0},
		{name="air", prob=254, param2=0},
		{name="air", prob=254, param2=0},
		{name="air", prob=254, param2=0},
		{name="air", prob=254, param2=0},

		-- z=3, y=6
		{name="air", prob=254, param2=0},
		{name="air", prob=254, param2=0},
		{name="air", prob=254, param2=0},
		{name="air", prob=254, param2=0},
		{name="air", prob=254, param2=0},
		{name="air", prob=254, param2=0},

		-- z=4, y=0
		{name="default:gravel", prob=254, param2=0},
		{name="default:gravel", prob=254, param2=0},
		{name="default:gravel", prob=254, param2=0},
		{name="default:gravel", prob=254, param2=0},
		{name="default:gravel", prob=254, param2=0},
		{name="default:gravel", prob=254, param2=0},

		-- z=4, y=1
		{name="cottages:wool_tent", prob=254, param2=18},
		{name="default:fence_wood", prob=254, param2=0},
		{name="cottages:bench", prob=254, param2=0},
		{name="cottages:bench", prob=254, param2=0},
		{name="default:fence_wood", prob=254, param2=0},
		{name="cottages:wool_tent", prob=254, param2=12},

		-- z=4, y=2
		{name="cottages:wool_tent", prob=254, param2=18},
		{name="default:fence_wood", prob=254, param2=0},
		{name="air", prob=254, param2=0},
		{name="air", prob=254, param2=0},
		{name="default:fence_wood", prob=254, param2=0},
		{name="cottages:wool_tent", prob=254, param2=12},

		-- z=4, y=3
		{name="cottages:wool_tent", prob=254, param2=18},
		{name="default:chest", prob=254, param2=3},
		{name="air", prob=254, param2=0},
		{name="air", prob=254, param2=0},
		{name="default:chest", prob=254, param2=1},
		{name="cottages:wool_tent", prob=254, param2=12},

		-- z=4, y=4
		{name="air", prob=254, param2=0},
		{name="cottages:wool_tent", prob=254, param2=3},
		{name="cottages:wool_tent", prob=254, param2=3},
		{name="cottages:wool_tent", prob=254, param2=3},
		{name="cottages:wool_tent", prob=254, param2=3},
		{name="air", prob=254, param2=0},

		-- z=4, y=5
		{name="air", prob=254, param2=0},
		{name="air", prob=254, param2=0},
		{name="air", prob=254, param2=0},
		{name="air", prob=254, param2=0},
		{name="air", prob=254, param2=0},
		{name="air", prob=254, param2=0},

		-- z=4, y=6
		{name="air", prob=254, param2=0},
		{name="air", prob=254, param2=0},
		{name="air", prob=254, param2=0},
		{name="air", prob=254, param2=0},
		{name="air", prob=254, param2=0},
		{name="air", prob=254, param2=0},

		-- z=5, y=0
		{name="default:gravel", prob=254, param2=0},
		{name="default:gravel", prob=254, param2=0},
		{name="default:gravel", prob=254, param2=0},
		{name="default:gravel", prob=254, param2=0},
		{name="default:gravel", prob=254, param2=0},
		{name="default:gravel", prob=254, param2=0},

		-- z=5, y=1
		{name="air", prob=254, param2=0},
		{name="cottages:wool_tent", prob=254, param2=7},
		{name="cottages:wool_tent", prob=254, param2=7},
		{name="cottages:wool_tent", prob=254, param2=7},
		{name="cottages:wool_tent", prob=254, param2=7},
		{name="air", prob=254, param2=0},

		-- z=5, y=2
		{name="air", prob=254, param2=0},
		{name="cottages:wool_tent", prob=254, param2=7},
		{name="cottages:wool_tent", prob=254, param2=7},
		{name="cottages:wool_tent", prob=254, param2=7},
		{name="cottages:wool_tent", prob=254, param2=7},
		{name="air", prob=254, param2=0},

		-- z=5, y=3
		{name="air", prob=254, param2=0},
		{name="cottages:wool_tent", prob=254, param2=7},
		{name="cottages:wool_tent", prob=254, param2=7},
		{name="cottages:wool_tent", prob=254, param2=7},
		{name="cottages:wool_tent", prob=254, param2=7},
		{name="air", prob=254, param2=0},

		-- z=5, y=4
		{name="air", prob=254, param2=0},
		{name="air", prob=254, param2=0},
		{name="air", prob=254, param2=0},
		{name="air", prob=254, param2=0},
		{name="air", prob=254, param2=0},
		{name="air", prob=254, param2=0},

		-- z=5, y=5
		{name="air", prob=254, param2=0},
		{name="air", prob=254, param2=0},
		{name="air", prob=254, param2=0},
		{name="air", prob=254, param2=0},
		{name="air", prob=254, param2=0},
		{name="air", prob=254, param2=0},

		-- z=5, y=6
		{name="air", prob=254, param2=0},
		{name="air", prob=254, param2=0},
		{name="air", prob=254, param2=0},
		{name="air", prob=254, param2=0},
		{name="air", prob=254, param2=0},
		{name="air", prob=254, param2=0},
	},
}

return schematic