schematic = {
	size = {x=7, y=2, z=7},
	yslice_prob = {
		{ypos=0, prob=254},
		{ypos=1, prob=254},
	},
	data = {

		-- z=0, y=0
		{name="default:dirt_with_grass", prob=254, param2=0},
		{name="default:dirt_with_grass", prob=254, param2=0},
		{name="default:dirt_with_grass", prob=254, param2=0},
		{name="default:dirt_with_grass", prob=254, param2=0},
		{name="default:dirt_with_grass", prob=254, param2=0},
		{name="default:dirt_with_grass", prob=254, param2=0},
		{name="default:dirt_with_grass", prob=254, param2=0},

		-- z=0, y=1
		{name="default:fence_wood", prob=254, param2=0},
		{name="default:fence_wood", prob=254, param2=3},
		{name="default:fence_wood", prob=254, param2=0},
		{name="cottages:gate_closed", prob=254, param2=0},
		{name="default:fence_wood", prob=254, param2=3},
		{name="default:fence_wood", prob=254, param2=2},
		{name="default:fence_wood", prob=254, param2=2},

		-- z=1, y=0
		{name="default:dirt_with_grass", prob=254, param2=0},
		{name="default:dirt_with_grass", prob=254, param2=0},
		{name="default:dirt_with_grass", prob=254, param2=0},
		{name="default:dirt_with_grass", prob=254, param2=0},
		{name="default:dirt_with_grass", prob=254, param2=0},
		{name="default:dirt_with_grass", prob=254, param2=0},
		{name="default:dirt_with_grass", prob=254, param2=0},

		-- z=1, y=1
		{name="default:fence_wood", prob=254, param2=0},
		{name="air", prob=254, param2=0},
		{name="air", prob=254, param2=0},
		{name="air", prob=254, param2=0},
		{name="air", prob=254, param2=0},
		{name="air", prob=254, param2=0},
		{name="default:fence_wood", prob=254, param2=2},

		-- z=2, y=0
		{name="default:dirt_with_grass", prob=254, param2=0},
		{name="default:dirt_with_grass", prob=254, param2=0},
		{name="default:dirt_with_grass", prob=254, param2=0},
		{name="default:dirt_with_grass", prob=254, param2=0},
		{name="default:water_source", prob=254, param2=0},
		{name="default:dirt_with_grass", prob=254, param2=0},
		{name="default:dirt_with_grass", prob=254, param2=0},

		-- z=2, y=1
		{name="default:fence_wood", prob=254, param2=0},
		{name="air", prob=254, param2=0},
		{name="air", prob=254, param2=0},
		{name="air", prob=254, param2=0},
		{name="cottages:washing", prob=254, param2=0},
		{name="air", prob=254, param2=0},
		{name="default:fence_wood", prob=254, param2=2},

		-- z=3, y=0
		{name="default:dirt_with_grass", prob=254, param2=0},
		{name="default:dirt_with_grass", prob=254, param2=0},
		{name="default:dirt_with_grass", prob=254, param2=0},
		{name="default:dirt_with_grass", prob=254, param2=0},
		{name="default:dirt", prob=254, param2=0},
		{name="default:dirt_with_grass", prob=254, param2=0},
		{name="default:dirt_with_grass", prob=254, param2=0},

		-- z=3, y=1
		{name="default:fence_wood", prob=254, param2=0},
		{name="air", prob=254, param2=0},
		{name="air", prob=254, param2=0},
		{name="air", prob=254, param2=0},
		{name="default:sapling", prob=254, param2=0},
		{name="air", prob=254, param2=0},
		{name="default:fence_wood", prob=254, param2=2},

		-- z=4, y=0
		{name="default:dirt_with_grass", prob=254, param2=0},
		{name="default:dirt_with_grass", prob=254, param2=0},
		{name="default:dirt_with_grass", prob=254, param2=0},
		{name="default:dirt_with_grass", prob=254, param2=0},
		{name="default:dirt_with_grass", prob=254, param2=0},
		{name="default:dirt_with_grass", prob=254, param2=0},
		{name="default:dirt_with_grass", prob=254, param2=0},

		-- z=4, y=1
		{name="default:fence_wood", prob=254, param2=0},
		{name="air", prob=254, param2=0},
		{name="air", prob=254, param2=0},
		{name="air", prob=254, param2=0},
		{name="cottages:tub", prob=254, param2=0},
		{name="air", prob=254, param2=0},
		{name="default:fence_wood", prob=254, param2=2},

		-- z=5, y=0
		{name="default:dirt_with_grass", prob=254, param2=0},
		{name="default:dirt_with_grass", prob=254, param2=0},
		{name="default:dirt_with_grass", prob=254, param2=0},
		{name="default:dirt_with_grass", prob=254, param2=0},
		{name="default:dirt_with_grass", prob=254, param2=0},
		{name="default:dirt_with_grass", prob=254, param2=0},
		{name="default:dirt_with_grass", prob=254, param2=0},

		-- z=5, y=1
		{name="default:fence_wood", prob=254, param2=0},
		{name="air", prob=254, param2=0},
		{name="air", prob=254, param2=0},
		{name="air", prob=254, param2=0},
		{name="air", prob=254, param2=0},
		{name="air", prob=254, param2=0},
		{name="default:fence_wood", prob=254, param2=1},

		-- z=6, y=0
		{name="default:dirt_with_grass", prob=254, param2=0},
		{name="default:dirt_with_grass", prob=254, param2=0},
		{name="default:dirt_with_grass", prob=254, param2=0},
		{name="default:dirt_with_grass", prob=254, param2=0},
		{name="default:dirt_with_grass", prob=254, param2=0},
		{name="default:dirt_with_grass", prob=254, param2=0},
		{name="default:dirt_with_grass", prob=254, param2=0},

		-- z=6, y=1
		{name="default:fence_wood", prob=254, param2=1},
		{name="default:fence_wood", prob=254, param2=1},
		{name="default:fence_wood", prob=254, param2=1},
		{name="cottages:gate_closed", prob=254, param2=2},
		{name="default:fence_wood", prob=254, param2=1},
		{name="default:fence_wood", prob=254, param2=1},
		{name="default:fence_wood", prob=254, param2=1},
	},
}

return schematic