schematic = {
	size = {x=4, y=11, z=4},
	yslice_prob = {
		{ypos=0, prob=254},
		{ypos=1, prob=254},
		{ypos=2, prob=254},
		{ypos=3, prob=254},
		{ypos=4, prob=254},
		{ypos=5, prob=254},
		{ypos=6, prob=254},
		{ypos=7, prob=254},
		{ypos=8, prob=254},
		{ypos=9, prob=254},
		{ypos=10, prob=254},
	},
	data = {

		-- z=0, y=0
		{name="default:cobble", prob=254, param2=0},
		{name="default:cobble", prob=254, param2=0},
		{name="default:cobble", prob=254, param2=0},
		{name="default:cobble", prob=254, param2=0},

		-- z=0, y=1
		{name="default:cobble", prob=254, param2=0},
		{name="default:cobble", prob=254, param2=0},
		{name="default:cobble", prob=254, param2=0},
		{name="default:cobble", prob=254, param2=0},

		-- z=0, y=2
		{name="default:cobble", prob=254, param2=0},
		{name="default:cobble", prob=254, param2=0},
		{name="default:cobble", prob=254, param2=0},
		{name="default:cobble", prob=254, param2=0},

		-- z=0, y=3
		{name="default:cobble", prob=254, param2=0},
		{name="default:cobble", prob=254, param2=0},
		{name="default:cobble", prob=254, param2=0},
		{name="default:cobble", prob=254, param2=0},

		-- z=0, y=4
		{name="default:cobble", prob=254, param2=0},
		{name="default:cobble", prob=254, param2=0},
		{name="default:cobble", prob=254, param2=0},
		{name="default:cobble", prob=254, param2=0},

		-- z=0, y=5
		{name="default:cobble", prob=254, param2=0},
		{name="default:cobble", prob=254, param2=0},
		{name="default:cobble", prob=254, param2=0},
		{name="default:cobble", prob=254, param2=0},

		-- z=0, y=6
		{name="default:cobble", prob=254, param2=0},
		{name="default:cobble", prob=254, param2=0},
		{name="default:cobble", prob=254, param2=0},
		{name="default:cobble", prob=254, param2=0},

		-- z=0, y=7
		{name="default:fence_wood", prob=254, param2=0},
		{name="air", prob=254, param2=0},
		{name="air", prob=254, param2=0},
		{name="default:fence_wood", prob=254, param2=0},

		-- z=0, y=8
		{name="default:fence_wood", prob=254, param2=0},
		{name="air", prob=254, param2=0},
		{name="air", prob=254, param2=0},
		{name="default:fence_wood", prob=254, param2=0},

		-- z=0, y=9
		{name="default:fence_wood", prob=254, param2=0},
		{name="air", prob=254, param2=0},
		{name="air", prob=254, param2=0},
		{name="default:fence_wood", prob=254, param2=0},

		-- z=0, y=10
		{name="default:cobble", prob=254, param2=0},
		{name="default:cobble", prob=254, param2=0},
		{name="default:cobble", prob=254, param2=0},
		{name="default:cobble", prob=254, param2=0},

		-- z=1, y=0
		{name="default:cobble", prob=254, param2=0},
		{name="default:cobble", prob=254, param2=0},
		{name="default:cobble", prob=254, param2=0},
		{name="default:cobble", prob=254, param2=0},

		-- z=1, y=1
		{name="default:cobble", prob=254, param2=0},
		{name="default:water_source", prob=254, param2=0},
		{name="default:water_source", prob=254, param2=0},
		{name="default:cobble", prob=254, param2=0},

		-- z=1, y=2
		{name="default:cobble", prob=254, param2=0},
		{name="default:water_source", prob=254, param2=0},
		{name="default:water_source", prob=254, param2=0},
		{name="default:cobble", prob=254, param2=0},

		-- z=1, y=3
		{name="default:cobble", prob=254, param2=0},
		{name="default:water_source", prob=254, param2=0},
		{name="default:water_source", prob=254, param2=0},
		{name="default:cobble", prob=254, param2=0},

		-- z=1, y=4
		{name="default:cobble", prob=254, param2=0},
		{name="default:water_source", prob=254, param2=0},
		{name="default:water_source", prob=254, param2=0},
		{name="default:cobble", prob=254, param2=0},

		-- z=1, y=5
		{name="default:cobble", prob=254, param2=0},
		{name="default:water_source", prob=254, param2=0},
		{name="default:water_source", prob=254, param2=0},
		{name="default:cobble", prob=254, param2=0},

		-- z=1, y=6
		{name="default:cobble", prob=254, param2=0},
		{name="air", prob=254, param2=0},
		{name="air", prob=254, param2=0},
		{name="default:cobble", prob=254, param2=0},

		-- z=1, y=7
		{name="air", prob=254, param2=0},
		{name="air", prob=254, param2=0},
		{name="air", prob=254, param2=0},
		{name="air", prob=254, param2=0},

		-- z=1, y=8
		{name="air", prob=254, param2=0},
		{name="air", prob=254, param2=0},
		{name="air", prob=254, param2=0},
		{name="air", prob=254, param2=0},

		-- z=1, y=9
		{name="air", prob=254, param2=0},
		{name="air", prob=254, param2=0},
		{name="air", prob=254, param2=0},
		{name="air", prob=254, param2=0},

		-- z=1, y=10
		{name="default:cobble", prob=254, param2=0},
		{name="default:cobble", prob=254, param2=0},
		{name="default:cobble", prob=254, param2=0},
		{name="default:cobble", prob=254, param2=0},

		-- z=2, y=0
		{name="default:cobble", prob=254, param2=0},
		{name="default:cobble", prob=254, param2=0},
		{name="default:cobble", prob=254, param2=0},
		{name="default:cobble", prob=254, param2=0},

		-- z=2, y=1
		{name="default:cobble", prob=254, param2=0},
		{name="default:water_source", prob=254, param2=0},
		{name="default:water_source", prob=254, param2=0},
		{name="default:cobble", prob=254, param2=0},

		-- z=2, y=2
		{name="default:cobble", prob=254, param2=0},
		{name="default:water_source", prob=254, param2=0},
		{name="default:water_source", prob=254, param2=0},
		{name="default:cobble", prob=254, param2=0},

		-- z=2, y=3
		{name="default:cobble", prob=254, param2=0},
		{name="default:water_source", prob=254, param2=0},
		{name="default:water_source", prob=254, param2=0},
		{name="default:cobble", prob=254, param2=0},

		-- z=2, y=4
		{name="default:cobble", prob=254, param2=0},
		{name="default:water_source", prob=254, param2=0},
		{name="default:water_source", prob=254, param2=0},
		{name="default:cobble", prob=254, param2=0},

		-- z=2, y=5
		{name="default:cobble", prob=254, param2=0},
		{name="default:water_source", prob=254, param2=0},
		{name="default:water_source", prob=254, param2=0},
		{name="default:cobble", prob=254, param2=0},

		-- z=2, y=6
		{name="default:cobble", prob=254, param2=0},
		{name="air", prob=254, param2=0},
		{name="air", prob=254, param2=0},
		{name="default:cobble", prob=254, param2=0},

		-- z=2, y=7
		{name="air", prob=254, param2=0},
		{name="air", prob=254, param2=0},
		{name="air", prob=254, param2=0},
		{name="air", prob=254, param2=0},

		-- z=2, y=8
		{name="air", prob=254, param2=0},
		{name="air", prob=254, param2=0},
		{name="air", prob=254, param2=0},
		{name="air", prob=254, param2=0},

		-- z=2, y=9
		{name="air", prob=254, param2=0},
		{name="air", prob=254, param2=0},
		{name="air", prob=254, param2=0},
		{name="air", prob=254, param2=0},

		-- z=2, y=10
		{name="default:cobble", prob=254, param2=0},
		{name="default:cobble", prob=254, param2=0},
		{name="default:cobble", prob=254, param2=0},
		{name="default:cobble", prob=254, param2=0},

		-- z=3, y=0
		{name="default:cobble", prob=254, param2=0},
		{name="default:cobble", prob=254, param2=0},
		{name="default:cobble", prob=254, param2=0},
		{name="default:cobble", prob=254, param2=0},

		-- z=3, y=1
		{name="default:cobble", prob=254, param2=0},
		{name="default:cobble", prob=254, param2=0},
		{name="default:cobble", prob=254, param2=0},
		{name="default:cobble", prob=254, param2=0},

		-- z=3, y=2
		{name="default:cobble", prob=254, param2=0},
		{name="default:cobble", prob=254, param2=0},
		{name="default:cobble", prob=254, param2=0},
		{name="default:cobble", prob=254, param2=0},

		-- z=3, y=3
		{name="default:cobble", prob=254, param2=0},
		{name="default:cobble", prob=254, param2=0},
		{name="default:cobble", prob=254, param2=0},
		{name="default:cobble", prob=254, param2=0},

		-- z=3, y=4
		{name="default:cobble", prob=254, param2=0},
		{name="default:cobble", prob=254, param2=0},
		{name="default:cobble", prob=254, param2=0},
		{name="default:cobble", prob=254, param2=0},

		-- z=3, y=5
		{name="default:cobble", prob=254, param2=0},
		{name="default:cobble", prob=254, param2=0},
		{name="default:cobble", prob=254, param2=0},
		{name="default:cobble", prob=254, param2=0},

		-- z=3, y=6
		{name="default:cobble", prob=254, param2=0},
		{name="default:cobble", prob=254, param2=0},
		{name="default:cobble", prob=254, param2=0},
		{name="default:cobble", prob=254, param2=0},

		-- z=3, y=7
		{name="default:fence_wood", prob=254, param2=0},
		{name="air", prob=254, param2=0},
		{name="air", prob=254, param2=0},
		{name="default:fence_wood", prob=254, param2=0},

		-- z=3, y=8
		{name="default:fence_wood", prob=254, param2=0},
		{name="air", prob=254, param2=0},
		{name="air", prob=254, param2=0},
		{name="default:fence_wood", prob=254, param2=0},

		-- z=3, y=9
		{name="default:fence_wood", prob=254, param2=0},
		{name="air", prob=254, param2=0},
		{name="air", prob=254, param2=0},
		{name="default:fence_wood", prob=254, param2=0},

		-- z=3, y=10
		{name="default:cobble", prob=254, param2=0},
		{name="default:cobble", prob=254, param2=0},
		{name="default:cobble", prob=254, param2=0},
		{name="default:cobble", prob=254, param2=0},
	},
}

return schematic